2016-09-02 10:02:19,186 ERROR: Exception on /tomcat/node_list [POST] [in /home/www/.demo/lib/python2.7/site-packages/flask/app.py:1423]
Traceback (most recent call last):
  File "/home/www/.demo/lib/python2.7/site-packages/flask/app.py", line 1817, in wsgi_app
    response = self.full_dispatch_request()
  File "/home/www/.demo/lib/python2.7/site-packages/flask/app.py", line 1477, in full_dispatch_request
    rv = self.handle_user_exception(e)
  File "/home/www/.demo/lib/python2.7/site-packages/flask/app.py", line 1381, in handle_user_exception
    reraise(exc_type, exc_value, tb)
  File "/home/www/.demo/lib/python2.7/site-packages/flask/app.py", line 1475, in full_dispatch_request
    rv = self.dispatch_request()
  File "/home/www/.demo/lib/python2.7/site-packages/flask/app.py", line 1461, in dispatch_request
    return self.view_functions[rule.endpoint](**req.view_args)
  File "/home/www/aud2/app/views/tomcat.py", line 601, in node_list
    form_sorce = models.App_nodes.query.filter_by(app_name=app_name)[0]
  File "/home/www/.demo/lib/python2.7/site-packages/sqlalchemy/orm/query.py", line 2236, in __getitem__
    return list(self[item:item + 1])[0]
IndexError: list index out of range
2016-09-02 10:03:31,554 ERROR: Exception on /tomcat/addrestart/ [POST] [in /home/www/.demo/lib/python2.7/site-packages/flask/app.py:1423]
Traceback (most recent call last):
  File "/home/www/.demo/lib/python2.7/site-packages/flask/app.py", line 1817, in wsgi_app
    response = self.full_dispatch_request()
  File "/home/www/.demo/lib/python2.7/site-packages/flask/app.py", line 1477, in full_dispatch_request
    rv = self.handle_user_exception(e)
  File "/home/www/.demo/lib/python2.7/site-packages/flask/app.py", line 1381, in handle_user_exception
    reraise(exc_type, exc_value, tb)
  File "/home/www/.demo/lib/python2.7/site-packages/flask/app.py", line 1475, in full_dispatch_request
    rv = self.dispatch_request()
  File "/home/www/.demo/lib/python2.7/site-packages/flask/app.py", line 1461, in dispatch_request
    return self.view_functions[rule.endpoint](**req.view_args)
  File "/home/www/aud2/app/views/tomcat.py", line 645, in addrestart
    node_ip = node_list[0]
IndexError: list index out of range
2016-09-02 10:04:19,632 ERROR: Exception on /favicon.ico [GET] [in /home/www/.demo/lib/python2.7/site-packages/flask/app.py:1423]
Traceback (most recent call last):
  File "/home/www/.demo/lib/python2.7/site-packages/flask/app.py", line 1817, in wsgi_app
    response = self.full_dispatch_request()
  File "/home/www/.demo/lib/python2.7/site-packages/flask/app.py", line 1477, in full_dispatch_request
    rv = self.handle_user_exception(e)
  File "/home/www/.demo/lib/python2.7/site-packages/flask/app.py", line 1370, in handle_user_exception
    return self.handle_http_exception(e)
  File "/home/www/.demo/lib/python2.7/site-packages/flask/app.py", line 1330, in handle_http_exception
    return handler(e)
  File "/home/www/aud2/app/__init__.py", line 150, in page_404
    return render_template('errors/404.html'), 404
  File "/home/www/.demo/lib/python2.7/site-packages/flask/templating.py", line 128, in render_template
    context, ctx.app)
  File "/home/www/.demo/lib/python2.7/site-packages/flask/templating.py", line 110, in _render
    rv = template.render(context)
  File "/home/www/.demo/lib/python2.7/site-packages/jinja2/environment.py", line 969, in render
    return self.environment.handle_exception(exc_info, True)
  File "/home/www/.demo/lib/python2.7/site-packages/jinja2/environment.py", line 742, in handle_exception
    reraise(exc_type, exc_value, tb)
  File "/home/www/aud2/app/templates/errors/404.html", line 2, in top-level template code
    {% extends "base.html" %}
  File "/home/www/aud2/app/templates/base.html", line 26, in top-level template code
    {% include 'nav.html' %}
  File "/home/www/aud2/app/templates/nav.html", line 221, in top-level template code
    {% if g.user.is_admin() %}
UndefinedError: 'werkzeug.local.LocalProxy object' has no attribute 'is_admin'
2016-09-02 10:04:22,763 ERROR: Exception on /favicon.ico [GET] [in /home/www/.demo/lib/python2.7/site-packages/flask/app.py:1423]
Traceback (most recent call last):
  File "/home/www/.demo/lib/python2.7/site-packages/flask/app.py", line 1817, in wsgi_app
    response = self.full_dispatch_request()
  File "/home/www/.demo/lib/python2.7/site-packages/flask/app.py", line 1477, in full_dispatch_request
    rv = self.handle_user_exception(e)
  File "/home/www/.demo/lib/python2.7/site-packages/flask/app.py", line 1370, in handle_user_exception
    return self.handle_http_exception(e)
  File "/home/www/.demo/lib/python2.7/site-packages/flask/app.py", line 1330, in handle_http_exception
    return handler(e)
  File "/home/www/aud2/app/__init__.py", line 150, in page_404
    return render_template('errors/404.html'), 404
  File "/home/www/.demo/lib/python2.7/site-packages/flask/templating.py", line 128, in render_template
    context, ctx.app)
  File "/home/www/.demo/lib/python2.7/site-packages/flask/templating.py", line 110, in _render
    rv = template.render(context)
  File "/home/www/.demo/lib/python2.7/site-packages/jinja2/environment.py", line 969, in render
    return self.environment.handle_exception(exc_info, True)
  File "/home/www/.demo/lib/python2.7/site-packages/jinja2/environment.py", line 742, in handle_exception
    reraise(exc_type, exc_value, tb)
  File "/home/www/aud2/app/templates/errors/404.html", line 2, in top-level template code
    {% extends "base.html" %}
  File "/home/www/aud2/app/templates/base.html", line 26, in top-level template code
    {% include 'nav.html' %}
  File "/home/www/aud2/app/templates/nav.html", line 221, in top-level template code
    {% if g.user.is_admin() %}
UndefinedError: 'werkzeug.local.LocalProxy object' has no attribute 'is_admin'
2016-09-02 10:04:24,650 ERROR: Exception on /tomcat/node_list [POST] [in /home/www/.demo/lib/python2.7/site-packages/flask/app.py:1423]
Traceback (most recent call last):
  File "/home/www/.demo/lib/python2.7/site-packages/flask/app.py", line 1817, in wsgi_app
    response = self.full_dispatch_request()
  File "/home/www/.demo/lib/python2.7/site-packages/flask/app.py", line 1477, in full_dispatch_request
    rv = self.handle_user_exception(e)
  File "/home/www/.demo/lib/python2.7/site-packages/flask/app.py", line 1381, in handle_user_exception
    reraise(exc_type, exc_value, tb)
  File "/home/www/.demo/lib/python2.7/site-packages/flask/app.py", line 1475, in full_dispatch_request
    rv = self.dispatch_request()
  File "/home/www/.demo/lib/python2.7/site-packages/flask/app.py", line 1461, in dispatch_request
    return self.view_functions[rule.endpoint](**req.view_args)
  File "/home/www/aud2/app/views/tomcat.py", line 601, in node_list
    form_sorce = models.App_nodes.query.filter_by(app_name=app_name)[0]
  File "/home/www/.demo/lib/python2.7/site-packages/sqlalchemy/orm/query.py", line 2236, in __getitem__
    return list(self[item:item + 1])[0]
IndexError: list index out of range
2016-09-02 10:05:25,582 ERROR: Exception on /tomcat/node_list [POST] [in /home/www/.demo/lib/python2.7/site-packages/flask/app.py:1423]
Traceback (most recent call last):
  File "/home/www/.demo/lib/python2.7/site-packages/flask/app.py", line 1817, in wsgi_app
    response = self.full_dispatch_request()
  File "/home/www/.demo/lib/python2.7/site-packages/flask/app.py", line 1477, in full_dispatch_request
    rv = self.handle_user_exception(e)
  File "/home/www/.demo/lib/python2.7/site-packages/flask/app.py", line 1381, in handle_user_exception
    reraise(exc_type, exc_value, tb)
  File "/home/www/.demo/lib/python2.7/site-packages/flask/app.py", line 1475, in full_dispatch_request
    rv = self.dispatch_request()
  File "/home/www/.demo/lib/python2.7/site-packages/flask/app.py", line 1461, in dispatch_request
    return self.view_functions[rule.endpoint](**req.view_args)
  File "/home/www/aud2/app/views/tomcat.py", line 601, in node_list
    form_sorce = models.App_nodes.query.filter_by(app_name=app_name)[0]
  File "/home/www/.demo/lib/python2.7/site-packages/sqlalchemy/orm/query.py", line 2236, in __getitem__
    return list(self[item:item + 1])[0]
IndexError: list index out of range
2016-09-02 10:05:45,602 ERROR: Exception on /tomcat/node_list [POST] [in /home/www/.demo/lib/python2.7/site-packages/flask/app.py:1423]
Traceback (most recent call last):
  File "/home/www/.demo/lib/python2.7/site-packages/flask/app.py", line 1817, in wsgi_app
    response = self.full_dispatch_request()
  File "/home/www/.demo/lib/python2.7/site-packages/flask/app.py", line 1477, in full_dispatch_request
    rv = self.handle_user_exception(e)
  File "/home/www/.demo/lib/python2.7/site-packages/flask/app.py", line 1381, in handle_user_exception
    reraise(exc_type, exc_value, tb)
  File "/home/www/.demo/lib/python2.7/site-packages/flask/app.py", line 1475, in full_dispatch_request
    rv = self.dispatch_request()
  File "/home/www/.demo/lib/python2.7/site-packages/flask/app.py", line 1461, in dispatch_request
    return self.view_functions[rule.endpoint](**req.view_args)
  File "/home/www/aud2/app/views/tomcat.py", line 601, in node_list
    form_sorce = models.App_nodes.query.filter_by(app_name=app_name)[0]
  File "/home/www/.demo/lib/python2.7/site-packages/sqlalchemy/orm/query.py", line 2236, in __getitem__
    return list(self[item:item + 1])[0]
IndexError: list index out of range
2016-09-02 10:08:38,148 ERROR: Exception on /favicon.ico [GET] [in /home/www/.demo/lib/python2.7/site-packages/flask/app.py:1423]
Traceback (most recent call last):
  File "/home/www/.demo/lib/python2.7/site-packages/flask/app.py", line 1817, in wsgi_app
    response = self.full_dispatch_request()
  File "/home/www/.demo/lib/python2.7/site-packages/flask/app.py", line 1477, in full_dispatch_request
    rv = self.handle_user_exception(e)
  File "/home/www/.demo/lib/python2.7/site-packages/flask/app.py", line 1370, in handle_user_exception
    return self.handle_http_exception(e)
  File "/home/www/.demo/lib/python2.7/site-packages/flask/app.py", line 1330, in handle_http_exception
    return handler(e)
  File "/home/www/aud2/app/__init__.py", line 150, in page_404
    return render_template('errors/404.html'), 404
  File "/home/www/.demo/lib/python2.7/site-packages/flask/templating.py", line 128, in render_template
    context, ctx.app)
  File "/home/www/.demo/lib/python2.7/site-packages/flask/templating.py", line 110, in _render
    rv = template.render(context)
  File "/home/www/.demo/lib/python2.7/site-packages/jinja2/environment.py", line 969, in render
    return self.environment.handle_exception(exc_info, True)
  File "/home/www/.demo/lib/python2.7/site-packages/jinja2/environment.py", line 742, in handle_exception
    reraise(exc_type, exc_value, tb)
  File "/home/www/aud2/app/templates/errors/404.html", line 2, in top-level template code
    {% extends "base.html" %}
  File "/home/www/aud2/app/templates/base.html", line 26, in top-level template code
    {% include 'nav.html' %}
  File "/home/www/aud2/app/templates/nav.html", line 221, in top-level template code
    {% if g.user.is_admin() %}
UndefinedError: 'werkzeug.local.LocalProxy object' has no attribute 'is_admin'
2016-09-02 10:08:58,672 ERROR: Exception on /tomcat/node_list [POST] [in /home/www/.demo/lib/python2.7/site-packages/flask/app.py:1423]
Traceback (most recent call last):
  File "/home/www/.demo/lib/python2.7/site-packages/flask/app.py", line 1817, in wsgi_app
    response = self.full_dispatch_request()
  File "/home/www/.demo/lib/python2.7/site-packages/flask/app.py", line 1477, in full_dispatch_request
    rv = self.handle_user_exception(e)
  File "/home/www/.demo/lib/python2.7/site-packages/flask/app.py", line 1381, in handle_user_exception
    reraise(exc_type, exc_value, tb)
  File "/home/www/.demo/lib/python2.7/site-packages/flask/app.py", line 1475, in full_dispatch_request
    rv = self.dispatch_request()
  File "/home/www/.demo/lib/python2.7/site-packages/flask/app.py", line 1461, in dispatch_request
    return self.view_functions[rule.endpoint](**req.view_args)
  File "/home/www/aud2/app/views/tomcat.py", line 601, in node_list
    form_sorce = models.App_nodes.query.filter_by(app_name=app_name)[0]
  File "/home/www/.demo/lib/python2.7/site-packages/sqlalchemy/orm/query.py", line 2236, in __getitem__
    return list(self[item:item + 1])[0]
IndexError: list index out of range
2016-09-02 10:12:12,254 ERROR: Exception on /api/v1.0/node_task/modify_status/88fe3073a930591b9f157ccae974d13c [POST] [in /home/www/.demo/lib/python2.7/site-packages/flask/app.py:1423]
Traceback (most recent call last):
  File "/home/www/.demo/lib/python2.7/site-packages/flask/app.py", line 1817, in wsgi_app
    response = self.full_dispatch_request()
  File "/home/www/.demo/lib/python2.7/site-packages/flask/app.py", line 1477, in full_dispatch_request
    rv = self.handle_user_exception(e)
  File "/home/www/.demo/lib/python2.7/site-packages/flask/app.py", line 1381, in handle_user_exception
    reraise(exc_type, exc_value, tb)
  File "/home/www/.demo/lib/python2.7/site-packages/flask/app.py", line 1475, in full_dispatch_request
    rv = self.dispatch_request()
  File "/home/www/.demo/lib/python2.7/site-packages/flask/app.py", line 1461, in dispatch_request
    return self.view_functions[rule.endpoint](**req.view_args)
  File "/home/www/aud2/app/views/site.py", line 875, in modify_node_task_status
    mes.sendEmail()
  File "/home/www/aud2/app/utils/message.py", line 45, in sendEmail
    thr = Thread(target=send_async_email, args=[receiver + '@aicai.com', subject, html])
TypeError: unsupported operand type(s) for +: 'NoneType' and 'str'
2016-09-02 10:13:07,472 ERROR: Exception on /favicon.ico [GET] [in /home/www/.demo/lib/python2.7/site-packages/flask/app.py:1423]
Traceback (most recent call last):
  File "/home/www/.demo/lib/python2.7/site-packages/flask/app.py", line 1817, in wsgi_app
    response = self.full_dispatch_request()
  File "/home/www/.demo/lib/python2.7/site-packages/flask/app.py", line 1477, in full_dispatch_request
    rv = self.handle_user_exception(e)
  File "/home/www/.demo/lib/python2.7/site-packages/flask/app.py", line 1370, in handle_user_exception
    return self.handle_http_exception(e)
  File "/home/www/.demo/lib/python2.7/site-packages/flask/app.py", line 1330, in handle_http_exception
    return handler(e)
  File "/home/www/aud2/app/__init__.py", line 150, in page_404
    return render_template('errors/404.html'), 404
  File "/home/www/.demo/lib/python2.7/site-packages/flask/templating.py", line 128, in render_template
    context, ctx.app)
  File "/home/www/.demo/lib/python2.7/site-packages/flask/templating.py", line 110, in _render
    rv = template.render(context)
  File "/home/www/.demo/lib/python2.7/site-packages/jinja2/environment.py", line 969, in render
    return self.environment.handle_exception(exc_info, True)
  File "/home/www/.demo/lib/python2.7/site-packages/jinja2/environment.py", line 742, in handle_exception
    reraise(exc_type, exc_value, tb)
  File "/home/www/aud2/app/templates/errors/404.html", line 2, in top-level template code
    {% extends "base.html" %}
  File "/home/www/aud2/app/templates/base.html", line 26, in top-level template code
    {% include 'nav.html' %}
  File "/home/www/aud2/app/templates/nav.html", line 221, in top-level template code
    {% if g.user.is_admin() %}
UndefinedError: 'werkzeug.local.LocalProxy object' has no attribute 'is_admin'
2016-09-02 10:15:52,477 ERROR: Exception on /self/app [POST] [in /home/www/.demo/lib/python2.7/site-packages/flask/app.py:1423]
Traceback (most recent call last):
  File "/home/www/.demo/lib/python2.7/site-packages/flask/app.py", line 1817, in wsgi_app
    response = self.full_dispatch_request()
  File "/home/www/.demo/lib/python2.7/site-packages/flask/app.py", line 1477, in full_dispatch_request
    rv = self.handle_user_exception(e)
  File "/home/www/.demo/lib/python2.7/site-packages/flask/app.py", line 1381, in handle_user_exception
    reraise(exc_type, exc_value, tb)
  File "/home/www/.demo/lib/python2.7/site-packages/flask/app.py", line 1475, in full_dispatch_request
    rv = self.dispatch_request()
  File "/home/www/.demo/lib/python2.7/site-packages/flask/app.py", line 1461, in dispatch_request
    return self.view_functions[rule.endpoint](**req.view_args)
  File "/home/www/.demo/lib/python2.7/site-packages/flask_login.py", line 758, in decorated_view
    return func(*args, **kwargs)
  File "/home/www/aud2/app/views/self.py", line 41, in app
    models.App_sites.id == int(item.site)).first()[0]
TypeError: 'NoneType' object has no attribute '__getitem__'
2016-09-02 11:21:24,940 ERROR: Exception on /deploy/adddeploy [POST] [in /home/www/.demo/lib/python2.7/site-packages/flask/app.py:1423]
Traceback (most recent call last):
  File "/home/www/.demo/lib/python2.7/site-packages/flask/app.py", line 1817, in wsgi_app
    response = self.full_dispatch_request()
  File "/home/www/.demo/lib/python2.7/site-packages/flask/app.py", line 1477, in full_dispatch_request
    rv = self.handle_user_exception(e)
  File "/home/www/.demo/lib/python2.7/site-packages/flask/app.py", line 1381, in handle_user_exception
    reraise(exc_type, exc_value, tb)
  File "/home/www/.demo/lib/python2.7/site-packages/flask/app.py", line 1475, in full_dispatch_request
    rv = self.dispatch_request()
  File "/home/www/.demo/lib/python2.7/site-packages/flask/app.py", line 1461, in dispatch_request
    return self.view_functions[rule.endpoint](**req.view_args)
  File "/home/www/.demo/lib/python2.7/site-packages/flask_login.py", line 758, in decorated_view
    return func(*args, **kwargs)
  File "/home/www/aud2/app/views/deploy.py", line 384, in adddeploy
    print business_num.business_id
AttributeError: 'NoneType' object has no attribute 'business_id'
2016-09-02 11:21:48,260 ERROR: Exception on /deploy/adddeploy [POST] [in /home/www/.demo/lib/python2.7/site-packages/flask/app.py:1423]
Traceback (most recent call last):
  File "/home/www/.demo/lib/python2.7/site-packages/flask/app.py", line 1817, in wsgi_app
    response = self.full_dispatch_request()
  File "/home/www/.demo/lib/python2.7/site-packages/flask/app.py", line 1477, in full_dispatch_request
    rv = self.handle_user_exception(e)
  File "/home/www/.demo/lib/python2.7/site-packages/flask/app.py", line 1381, in handle_user_exception
    reraise(exc_type, exc_value, tb)
  File "/home/www/.demo/lib/python2.7/site-packages/flask/app.py", line 1475, in full_dispatch_request
    rv = self.dispatch_request()
  File "/home/www/.demo/lib/python2.7/site-packages/flask/app.py", line 1461, in dispatch_request
    return self.view_functions[rule.endpoint](**req.view_args)
  File "/home/www/.demo/lib/python2.7/site-packages/flask_login.py", line 758, in decorated_view
    return func(*args, **kwargs)
  File "/home/www/aud2/app/views/deploy.py", line 384, in adddeploy
    print business_num.business_id
AttributeError: 'NoneType' object has no attribute 'business_id'
2016-09-02 11:39:45,085 ERROR: Exception on /deploy/adddeploy [POST] [in /home/www/.demo/lib/python2.7/site-packages/flask/app.py:1423]
Traceback (most recent call last):
  File "/home/www/.demo/lib/python2.7/site-packages/flask/app.py", line 1817, in wsgi_app
    response = self.full_dispatch_request()
  File "/home/www/.demo/lib/python2.7/site-packages/flask/app.py", line 1477, in full_dispatch_request
    rv = self.handle_user_exception(e)
  File "/home/www/.demo/lib/python2.7/site-packages/flask/app.py", line 1381, in handle_user_exception
    reraise(exc_type, exc_value, tb)
  File "/home/www/.demo/lib/python2.7/site-packages/flask/app.py", line 1475, in full_dispatch_request
    rv = self.dispatch_request()
  File "/home/www/.demo/lib/python2.7/site-packages/flask/app.py", line 1461, in dispatch_request
    return self.view_functions[rule.endpoint](**req.view_args)
  File "/home/www/.demo/lib/python2.7/site-packages/flask_login.py", line 758, in decorated_view
    return func(*args, **kwargs)
  File "/home/www/aud2/app/views/deploy.py", line 384, in adddeploy
    print business_num.business_id
AttributeError: 'NoneType' object has no attribute 'business_id'
2016-09-02 11:43:52,811 ERROR: Exception on /api/v1.0/node_task/modify_status/612e26493c9d1baf131b030f7d0aec91 [POST] [in /home/www/.demo/lib/python2.7/site-packages/flask/app.py:1423]
Traceback (most recent call last):
  File "/home/www/.demo/lib/python2.7/site-packages/flask/app.py", line 1817, in wsgi_app
    response = self.full_dispatch_request()
  File "/home/www/.demo/lib/python2.7/site-packages/flask/app.py", line 1477, in full_dispatch_request
    rv = self.handle_user_exception(e)
  File "/home/www/.demo/lib/python2.7/site-packages/flask/app.py", line 1381, in handle_user_exception
    reraise(exc_type, exc_value, tb)
  File "/home/www/.demo/lib/python2.7/site-packages/flask/app.py", line 1475, in full_dispatch_request
    rv = self.dispatch_request()
  File "/home/www/.demo/lib/python2.7/site-packages/flask/app.py", line 1461, in dispatch_request
    return self.view_functions[rule.endpoint](**req.view_args)
  File "/home/www/aud2/app/views/site.py", line 875, in modify_node_task_status
    mes.sendEmail()
  File "/home/www/aud2/app/utils/message.py", line 45, in sendEmail
    thr = Thread(target=send_async_email, args=[receiver + '@aicai.com', subject, html])
TypeError: unsupported operand type(s) for +: 'NoneType' and 'str'
2016-09-02 11:46:08,287 ERROR: Exception on /api/v1.0/node_task/modify_status/a3062984cdc0398ebd8fd9660b24a614 [POST] [in /home/www/.demo/lib/python2.7/site-packages/flask/app.py:1423]
Traceback (most recent call last):
  File "/home/www/.demo/lib/python2.7/site-packages/flask/app.py", line 1817, in wsgi_app
    response = self.full_dispatch_request()
  File "/home/www/.demo/lib/python2.7/site-packages/flask/app.py", line 1477, in full_dispatch_request
    rv = self.handle_user_exception(e)
  File "/home/www/.demo/lib/python2.7/site-packages/flask/app.py", line 1381, in handle_user_exception
    reraise(exc_type, exc_value, tb)
  File "/home/www/.demo/lib/python2.7/site-packages/flask/app.py", line 1475, in full_dispatch_request
    rv = self.dispatch_request()
  File "/home/www/.demo/lib/python2.7/site-packages/flask/app.py", line 1461, in dispatch_request
    return self.view_functions[rule.endpoint](**req.view_args)
  File "/home/www/aud2/app/views/site.py", line 875, in modify_node_task_status
    mes.sendEmail()
  File "/home/www/aud2/app/utils/message.py", line 45, in sendEmail
    thr = Thread(target=send_async_email, args=[receiver + '@aicai.com', subject, html])
TypeError: unsupported operand type(s) for +: 'NoneType' and 'str'
2016-09-02 13:47:12,452 ERROR: Exception on /favicon.ico [GET] [in /home/www/.demo/lib/python2.7/site-packages/flask/app.py:1423]
Traceback (most recent call last):
  File "/home/www/.demo/lib/python2.7/site-packages/flask/app.py", line 1817, in wsgi_app
    response = self.full_dispatch_request()
  File "/home/www/.demo/lib/python2.7/site-packages/flask/app.py", line 1477, in full_dispatch_request
    rv = self.handle_user_exception(e)
  File "/home/www/.demo/lib/python2.7/site-packages/flask/app.py", line 1370, in handle_user_exception
    return self.handle_http_exception(e)
  File "/home/www/.demo/lib/python2.7/site-packages/flask/app.py", line 1330, in handle_http_exception
    return handler(e)
  File "/home/www/aud2/app/__init__.py", line 150, in page_404
    return render_template('errors/404.html'), 404
  File "/home/www/.demo/lib/python2.7/site-packages/flask/templating.py", line 128, in render_template
    context, ctx.app)
  File "/home/www/.demo/lib/python2.7/site-packages/flask/templating.py", line 110, in _render
    rv = template.render(context)
  File "/home/www/.demo/lib/python2.7/site-packages/jinja2/environment.py", line 969, in render
    return self.environment.handle_exception(exc_info, True)
  File "/home/www/.demo/lib/python2.7/site-packages/jinja2/environment.py", line 742, in handle_exception
    reraise(exc_type, exc_value, tb)
  File "/home/www/aud2/app/templates/errors/404.html", line 2, in top-level template code
    {% extends "base.html" %}
  File "/home/www/aud2/app/templates/base.html", line 26, in top-level template code
    {% include 'nav.html' %}
  File "/home/www/aud2/app/templates/nav.html", line 221, in top-level template code
    {% if g.user.is_admin() %}
UndefinedError: 'werkzeug.local.LocalProxy object' has no attribute 'is_admin'
2016-09-02 14:16:25,576 ERROR: Exception on /api/v1.0/node_task/modify_status/72b3707d6f9dacb5656f7bf0c31fa002 [POST] [in /home/www/.demo/lib/python2.7/site-packages/flask/app.py:1423]
Traceback (most recent call last):
  File "/home/www/.demo/lib/python2.7/site-packages/flask/app.py", line 1817, in wsgi_app
    response = self.full_dispatch_request()
  File "/home/www/.demo/lib/python2.7/site-packages/flask/app.py", line 1477, in full_dispatch_request
    rv = self.handle_user_exception(e)
  File "/home/www/.demo/lib/python2.7/site-packages/flask/app.py", line 1381, in handle_user_exception
    reraise(exc_type, exc_value, tb)
  File "/home/www/.demo/lib/python2.7/site-packages/flask/app.py", line 1475, in full_dispatch_request
    rv = self.dispatch_request()
  File "/home/www/.demo/lib/python2.7/site-packages/flask/app.py", line 1461, in dispatch_request
    return self.view_functions[rule.endpoint](**req.view_args)
  File "/home/www/aud2/app/views/site.py", line 875, in modify_node_task_status
    mes.sendEmail()
  File "/home/www/aud2/app/utils/message.py", line 45, in sendEmail
    thr = Thread(target=send_async_email, args=[receiver + '@aicai.com', subject, html])
TypeError: unsupported operand type(s) for +: 'NoneType' and 'str'
2016-09-02 14:20:17,254 ERROR: Exception on /api/v1.0/node_task/modify_status/de94ce0c74eb1a4c8141913cc6571663 [POST] [in /home/www/.demo/lib/python2.7/site-packages/flask/app.py:1423]
Traceback (most recent call last):
  File "/home/www/.demo/lib/python2.7/site-packages/flask/app.py", line 1817, in wsgi_app
    response = self.full_dispatch_request()
  File "/home/www/.demo/lib/python2.7/site-packages/flask/app.py", line 1477, in full_dispatch_request
    rv = self.handle_user_exception(e)
  File "/home/www/.demo/lib/python2.7/site-packages/flask/app.py", line 1381, in handle_user_exception
    reraise(exc_type, exc_value, tb)
  File "/home/www/.demo/lib/python2.7/site-packages/flask/app.py", line 1475, in full_dispatch_request
    rv = self.dispatch_request()
  File "/home/www/.demo/lib/python2.7/site-packages/flask/app.py", line 1461, in dispatch_request
    return self.view_functions[rule.endpoint](**req.view_args)
  File "/home/www/aud2/app/views/site.py", line 875, in modify_node_task_status
    mes.sendEmail()
  File "/home/www/aud2/app/utils/message.py", line 45, in sendEmail
    thr = Thread(target=send_async_email, args=[receiver + '@aicai.com', subject, html])
TypeError: unsupported operand type(s) for +: 'NoneType' and 'str'
2016-09-02 14:22:18,786 ERROR: Exception on /api/v1.0/node_task/modify_status/6ecbc20a57e0e93265237320bc383324 [POST] [in /home/www/.demo/lib/python2.7/site-packages/flask/app.py:1423]
Traceback (most recent call last):
  File "/home/www/.demo/lib/python2.7/site-packages/flask/app.py", line 1817, in wsgi_app
    response = self.full_dispatch_request()
  File "/home/www/.demo/lib/python2.7/site-packages/flask/app.py", line 1477, in full_dispatch_request
    rv = self.handle_user_exception(e)
  File "/home/www/.demo/lib/python2.7/site-packages/flask/app.py", line 1381, in handle_user_exception
    reraise(exc_type, exc_value, tb)
  File "/home/www/.demo/lib/python2.7/site-packages/flask/app.py", line 1475, in full_dispatch_request
    rv = self.dispatch_request()
  File "/home/www/.demo/lib/python2.7/site-packages/flask/app.py", line 1461, in dispatch_request
    return self.view_functions[rule.endpoint](**req.view_args)
  File "/home/www/aud2/app/views/site.py", line 875, in modify_node_task_status
    mes.sendEmail()
  File "/home/www/aud2/app/utils/message.py", line 45, in sendEmail
    thr = Thread(target=send_async_email, args=[receiver + '@aicai.com', subject, html])
TypeError: unsupported operand type(s) for +: 'NoneType' and 'str'
2016-09-02 14:23:58,395 ERROR: Exception on /api/v1.0/node_task/modify_status/523e83d3b448e591528583a4ab3d3422 [POST] [in /home/www/.demo/lib/python2.7/site-packages/flask/app.py:1423]
Traceback (most recent call last):
  File "/home/www/.demo/lib/python2.7/site-packages/flask/app.py", line 1817, in wsgi_app
    response = self.full_dispatch_request()
  File "/home/www/.demo/lib/python2.7/site-packages/flask/app.py", line 1477, in full_dispatch_request
    rv = self.handle_user_exception(e)
  File "/home/www/.demo/lib/python2.7/site-packages/flask/app.py", line 1381, in handle_user_exception
    reraise(exc_type, exc_value, tb)
  File "/home/www/.demo/lib/python2.7/site-packages/flask/app.py", line 1475, in full_dispatch_request
    rv = self.dispatch_request()
  File "/home/www/.demo/lib/python2.7/site-packages/flask/app.py", line 1461, in dispatch_request
    return self.view_functions[rule.endpoint](**req.view_args)
  File "/home/www/aud2/app/views/site.py", line 875, in modify_node_task_status
    mes.sendEmail()
  File "/home/www/aud2/app/utils/message.py", line 45, in sendEmail
    thr = Thread(target=send_async_email, args=[receiver + '@aicai.com', subject, html])
TypeError: unsupported operand type(s) for +: 'NoneType' and 'str'
2016-09-02 14:24:24,681 ERROR: Exception on /api/v1.0/node_task/modify_status/978c58fa4feb1153ef58931920a5f3bf [POST] [in /home/www/.demo/lib/python2.7/site-packages/flask/app.py:1423]
Traceback (most recent call last):
  File "/home/www/.demo/lib/python2.7/site-packages/flask/app.py", line 1817, in wsgi_app
    response = self.full_dispatch_request()
  File "/home/www/.demo/lib/python2.7/site-packages/flask/app.py", line 1477, in full_dispatch_request
    rv = self.handle_user_exception(e)
  File "/home/www/.demo/lib/python2.7/site-packages/flask/app.py", line 1381, in handle_user_exception
    reraise(exc_type, exc_value, tb)
  File "/home/www/.demo/lib/python2.7/site-packages/flask/app.py", line 1475, in full_dispatch_request
    rv = self.dispatch_request()
  File "/home/www/.demo/lib/python2.7/site-packages/flask/app.py", line 1461, in dispatch_request
    return self.view_functions[rule.endpoint](**req.view_args)
  File "/home/www/aud2/app/views/site.py", line 875, in modify_node_task_status
    mes.sendEmail()
  File "/home/www/aud2/app/utils/message.py", line 45, in sendEmail
    thr = Thread(target=send_async_email, args=[receiver + '@aicai.com', subject, html])
TypeError: unsupported operand type(s) for +: 'NoneType' and 'str'
2016-09-02 14:43:27,736 ERROR: Exception on /api/v1.0/node_task/modify_status/bb5dd24e53dbaf70a99ebb3ffc72533a [POST] [in /home/www/.demo/lib/python2.7/site-packages/flask/app.py:1423]
Traceback (most recent call last):
  File "/home/www/.demo/lib/python2.7/site-packages/flask/app.py", line 1817, in wsgi_app
    response = self.full_dispatch_request()
  File "/home/www/.demo/lib/python2.7/site-packages/flask/app.py", line 1477, in full_dispatch_request
    rv = self.handle_user_exception(e)
  File "/home/www/.demo/lib/python2.7/site-packages/flask/app.py", line 1381, in handle_user_exception
    reraise(exc_type, exc_value, tb)
  File "/home/www/.demo/lib/python2.7/site-packages/flask/app.py", line 1475, in full_dispatch_request
    rv = self.dispatch_request()
  File "/home/www/.demo/lib/python2.7/site-packages/flask/app.py", line 1461, in dispatch_request
    return self.view_functions[rule.endpoint](**req.view_args)
  File "/home/www/aud2/app/views/site.py", line 875, in modify_node_task_status
    mes.sendEmail()
  File "/home/www/aud2/app/utils/message.py", line 45, in sendEmail
    thr = Thread(target=send_async_email, args=[receiver + '@aicai.com', subject, html])
TypeError: unsupported operand type(s) for +: 'NoneType' and 'str'
2016-09-02 14:49:08,027 ERROR: Exception on /favicon.ico [GET] [in /home/www/.demo/lib/python2.7/site-packages/flask/app.py:1423]
Traceback (most recent call last):
  File "/home/www/.demo/lib/python2.7/site-packages/flask/app.py", line 1817, in wsgi_app
    response = self.full_dispatch_request()
  File "/home/www/.demo/lib/python2.7/site-packages/flask/app.py", line 1477, in full_dispatch_request
    rv = self.handle_user_exception(e)
  File "/home/www/.demo/lib/python2.7/site-packages/flask/app.py", line 1370, in handle_user_exception
    return self.handle_http_exception(e)
  File "/home/www/.demo/lib/python2.7/site-packages/flask/app.py", line 1330, in handle_http_exception
    return handler(e)
  File "/home/www/aud2/app/__init__.py", line 150, in page_404
    return render_template('errors/404.html'), 404
  File "/home/www/.demo/lib/python2.7/site-packages/flask/templating.py", line 128, in render_template
    context, ctx.app)
  File "/home/www/.demo/lib/python2.7/site-packages/flask/templating.py", line 110, in _render
    rv = template.render(context)
  File "/home/www/.demo/lib/python2.7/site-packages/jinja2/environment.py", line 969, in render
    return self.environment.handle_exception(exc_info, True)
  File "/home/www/.demo/lib/python2.7/site-packages/jinja2/environment.py", line 742, in handle_exception
    reraise(exc_type, exc_value, tb)
  File "/home/www/aud2/app/templates/errors/404.html", line 2, in top-level template code
    {% extends "base.html" %}
  File "/home/www/aud2/app/templates/base.html", line 26, in top-level template code
    {% include 'nav.html' %}
  File "/home/www/aud2/app/templates/nav.html", line 221, in top-level template code
    {% if g.user.is_admin() %}
UndefinedError: 'werkzeug.local.LocalProxy object' has no attribute 'is_admin'
2016-09-02 14:49:08,042 ERROR: Exception on /favicon.ico [GET] [in /home/www/.demo/lib/python2.7/site-packages/flask/app.py:1423]
Traceback (most recent call last):
  File "/home/www/.demo/lib/python2.7/site-packages/flask/app.py", line 1817, in wsgi_app
    response = self.full_dispatch_request()
  File "/home/www/.demo/lib/python2.7/site-packages/flask/app.py", line 1477, in full_dispatch_request
    rv = self.handle_user_exception(e)
  File "/home/www/.demo/lib/python2.7/site-packages/flask/app.py", line 1370, in handle_user_exception
    return self.handle_http_exception(e)
  File "/home/www/.demo/lib/python2.7/site-packages/flask/app.py", line 1330, in handle_http_exception
    return handler(e)
  File "/home/www/aud2/app/__init__.py", line 150, in page_404
    return render_template('errors/404.html'), 404
  File "/home/www/.demo/lib/python2.7/site-packages/flask/templating.py", line 128, in render_template
    context, ctx.app)
  File "/home/www/.demo/lib/python2.7/site-packages/flask/templating.py", line 110, in _render
    rv = template.render(context)
  File "/home/www/.demo/lib/python2.7/site-packages/jinja2/environment.py", line 969, in render
    return self.environment.handle_exception(exc_info, True)
  File "/home/www/.demo/lib/python2.7/site-packages/jinja2/environment.py", line 742, in handle_exception
    reraise(exc_type, exc_value, tb)
  File "/home/www/aud2/app/templates/errors/404.html", line 2, in top-level template code
    {% extends "base.html" %}
  File "/home/www/aud2/app/templates/base.html", line 26, in top-level template code
    {% include 'nav.html' %}
  File "/home/www/aud2/app/templates/nav.html", line 221, in top-level template code
    {% if g.user.is_admin() %}
UndefinedError: 'werkzeug.local.LocalProxy object' has no attribute 'is_admin'
2016-09-02 14:55:19,440 ERROR: Exception on /api/v1.0/node_task/modify_status/664a17ef22ad4112672e99055d336ea0 [POST] [in /home/www/.demo/lib/python2.7/site-packages/flask/app.py:1423]
Traceback (most recent call last):
  File "/home/www/.demo/lib/python2.7/site-packages/flask/app.py", line 1817, in wsgi_app
    response = self.full_dispatch_request()
  File "/home/www/.demo/lib/python2.7/site-packages/flask/app.py", line 1477, in full_dispatch_request
    rv = self.handle_user_exception(e)
  File "/home/www/.demo/lib/python2.7/site-packages/flask/app.py", line 1381, in handle_user_exception
    reraise(exc_type, exc_value, tb)
  File "/home/www/.demo/lib/python2.7/site-packages/flask/app.py", line 1475, in full_dispatch_request
    rv = self.dispatch_request()
  File "/home/www/.demo/lib/python2.7/site-packages/flask/app.py", line 1461, in dispatch_request
    return self.view_functions[rule.endpoint](**req.view_args)
  File "/home/www/aud2/app/views/site.py", line 875, in modify_node_task_status
    mes.sendEmail()
  File "/home/www/aud2/app/utils/message.py", line 45, in sendEmail
    thr = Thread(target=send_async_email, args=[receiver + '@aicai.com', subject, html])
TypeError: unsupported operand type(s) for +: 'NoneType' and 'str'
2016-09-02 15:17:29,598 ERROR: Exception on /favicon.ico [GET] [in /home/www/.demo/lib/python2.7/site-packages/flask/app.py:1423]
Traceback (most recent call last):
  File "/home/www/.demo/lib/python2.7/site-packages/flask/app.py", line 1817, in wsgi_app
    response = self.full_dispatch_request()
  File "/home/www/.demo/lib/python2.7/site-packages/flask/app.py", line 1477, in full_dispatch_request
    rv = self.handle_user_exception(e)
  File "/home/www/.demo/lib/python2.7/site-packages/flask/app.py", line 1370, in handle_user_exception
    return self.handle_http_exception(e)
  File "/home/www/.demo/lib/python2.7/site-packages/flask/app.py", line 1330, in handle_http_exception
    return handler(e)
  File "/home/www/aud2/app/__init__.py", line 150, in page_404
    return render_template('errors/404.html'), 404
  File "/home/www/.demo/lib/python2.7/site-packages/flask/templating.py", line 128, in render_template
    context, ctx.app)
  File "/home/www/.demo/lib/python2.7/site-packages/flask/templating.py", line 110, in _render
    rv = template.render(context)
  File "/home/www/.demo/lib/python2.7/site-packages/jinja2/environment.py", line 969, in render
    return self.environment.handle_exception(exc_info, True)
  File "/home/www/.demo/lib/python2.7/site-packages/jinja2/environment.py", line 742, in handle_exception
    reraise(exc_type, exc_value, tb)
  File "/home/www/aud2/app/templates/errors/404.html", line 2, in top-level template code
    {% extends "base.html" %}
  File "/home/www/aud2/app/templates/base.html", line 26, in top-level template code
    {% include 'nav.html' %}
  File "/home/www/aud2/app/templates/nav.html", line 221, in top-level template code
    {% if g.user.is_admin() %}
UndefinedError: 'werkzeug.local.LocalProxy object' has no attribute 'is_admin'
2016-09-02 16:01:15,508 ERROR: Exception on /favicon.ico [GET] [in /home/www/.demo/lib/python2.7/site-packages/flask/app.py:1423]
Traceback (most recent call last):
  File "/home/www/.demo/lib/python2.7/site-packages/flask/app.py", line 1817, in wsgi_app
    response = self.full_dispatch_request()
  File "/home/www/.demo/lib/python2.7/site-packages/flask/app.py", line 1477, in full_dispatch_request
    rv = self.handle_user_exception(e)
  File "/home/www/.demo/lib/python2.7/site-packages/flask/app.py", line 1370, in handle_user_exception
    return self.handle_http_exception(e)
  File "/home/www/.demo/lib/python2.7/site-packages/flask/app.py", line 1330, in handle_http_exception
    return handler(e)
  File "/home/www/aud2/app/__init__.py", line 150, in page_404
    return render_template('errors/404.html'), 404
  File "/home/www/.demo/lib/python2.7/site-packages/flask/templating.py", line 128, in render_template
    context, ctx.app)
  File "/home/www/.demo/lib/python2.7/site-packages/flask/templating.py", line 110, in _render
    rv = template.render(context)
  File "/home/www/.demo/lib/python2.7/site-packages/jinja2/environment.py", line 969, in render
    return self.environment.handle_exception(exc_info, True)
  File "/home/www/.demo/lib/python2.7/site-packages/jinja2/environment.py", line 742, in handle_exception
    reraise(exc_type, exc_value, tb)
  File "/home/www/aud2/app/templates/errors/404.html", line 2, in top-level template code
    {% extends "base.html" %}
  File "/home/www/aud2/app/templates/base.html", line 26, in top-level template code
    {% include 'nav.html' %}
  File "/home/www/aud2/app/templates/nav.html", line 221, in top-level template code
    {% if g.user.is_admin() %}
UndefinedError: 'werkzeug.local.LocalProxy object' has no attribute 'is_admin'
2016-09-02 16:10:50,272 ERROR: Exception on /api/v1.0/node_task/modify_status/9aa0c3e355eb3c7bc6144201ebdf3927 [POST] [in /home/www/.demo/lib/python2.7/site-packages/flask/app.py:1423]
Traceback (most recent call last):
  File "/home/www/.demo/lib/python2.7/site-packages/flask/app.py", line 1817, in wsgi_app
    response = self.full_dispatch_request()
  File "/home/www/.demo/lib/python2.7/site-packages/flask/app.py", line 1477, in full_dispatch_request
    rv = self.handle_user_exception(e)
  File "/home/www/.demo/lib/python2.7/site-packages/flask/app.py", line 1381, in handle_user_exception
    reraise(exc_type, exc_value, tb)
  File "/home/www/.demo/lib/python2.7/site-packages/flask/app.py", line 1475, in full_dispatch_request
    rv = self.dispatch_request()
  File "/home/www/.demo/lib/python2.7/site-packages/flask/app.py", line 1461, in dispatch_request
    return self.view_functions[rule.endpoint](**req.view_args)
  File "/home/www/aud2/app/views/site.py", line 875, in modify_node_task_status
    mes.sendEmail()
  File "/home/www/aud2/app/utils/message.py", line 45, in sendEmail
    thr = Thread(target=send_async_email, args=[receiver + '@aicai.com', subject, html])
TypeError: unsupported operand type(s) for +: 'NoneType' and 'str'
2016-09-02 16:17:39,993 ERROR: Exception on /favicon.ico [GET] [in /home/www/.demo/lib/python2.7/site-packages/flask/app.py:1423]
Traceback (most recent call last):
  File "/home/www/.demo/lib/python2.7/site-packages/flask/app.py", line 1817, in wsgi_app
    response = self.full_dispatch_request()
  File "/home/www/.demo/lib/python2.7/site-packages/flask/app.py", line 1477, in full_dispatch_request
    rv = self.handle_user_exception(e)
  File "/home/www/.demo/lib/python2.7/site-packages/flask/app.py", line 1370, in handle_user_exception
    return self.handle_http_exception(e)
  File "/home/www/.demo/lib/python2.7/site-packages/flask/app.py", line 1330, in handle_http_exception
    return handler(e)
  File "/home/www/aud2/app/__init__.py", line 150, in page_404
    return render_template('errors/404.html'), 404
  File "/home/www/.demo/lib/python2.7/site-packages/flask/templating.py", line 128, in render_template
    context, ctx.app)
  File "/home/www/.demo/lib/python2.7/site-packages/flask/templating.py", line 110, in _render
    rv = template.render(context)
  File "/home/www/.demo/lib/python2.7/site-packages/jinja2/environment.py", line 969, in render
    return self.environment.handle_exception(exc_info, True)
  File "/home/www/.demo/lib/python2.7/site-packages/jinja2/environment.py", line 742, in handle_exception
    reraise(exc_type, exc_value, tb)
  File "/home/www/aud2/app/templates/errors/404.html", line 2, in top-level template code
    {% extends "base.html" %}
  File "/home/www/aud2/app/templates/base.html", line 26, in top-level template code
    {% include 'nav.html' %}
  File "/home/www/aud2/app/templates/nav.html", line 221, in top-level template code
    {% if g.user.is_admin() %}
UndefinedError: 'werkzeug.local.LocalProxy object' has no attribute 'is_admin'
2016-09-02 16:17:52,943 ERROR: Exception on /favicon.ico [GET] [in /home/www/.demo/lib/python2.7/site-packages/flask/app.py:1423]
Traceback (most recent call last):
  File "/home/www/.demo/lib/python2.7/site-packages/flask/app.py", line 1817, in wsgi_app
    response = self.full_dispatch_request()
  File "/home/www/.demo/lib/python2.7/site-packages/flask/app.py", line 1477, in full_dispatch_request
    rv = self.handle_user_exception(e)
  File "/home/www/.demo/lib/python2.7/site-packages/flask/app.py", line 1370, in handle_user_exception
    return self.handle_http_exception(e)
  File "/home/www/.demo/lib/python2.7/site-packages/flask/app.py", line 1330, in handle_http_exception
    return handler(e)
  File "/home/www/aud2/app/__init__.py", line 150, in page_404
    return render_template('errors/404.html'), 404
  File "/home/www/.demo/lib/python2.7/site-packages/flask/templating.py", line 128, in render_template
    context, ctx.app)
  File "/home/www/.demo/lib/python2.7/site-packages/flask/templating.py", line 110, in _render
    rv = template.render(context)
  File "/home/www/.demo/lib/python2.7/site-packages/jinja2/environment.py", line 969, in render
    return self.environment.handle_exception(exc_info, True)
  File "/home/www/.demo/lib/python2.7/site-packages/jinja2/environment.py", line 742, in handle_exception
    reraise(exc_type, exc_value, tb)
  File "/home/www/aud2/app/templates/errors/404.html", line 2, in top-level template code
    {% extends "base.html" %}
  File "/home/www/aud2/app/templates/base.html", line 26, in top-level template code
    {% include 'nav.html' %}
  File "/home/www/aud2/app/templates/nav.html", line 221, in top-level template code
    {% if g.user.is_admin() %}
UndefinedError: 'werkzeug.local.LocalProxy object' has no attribute 'is_admin'
2016-09-02 16:17:52,956 ERROR: Exception on /favicon.ico [GET] [in /home/www/.demo/lib/python2.7/site-packages/flask/app.py:1423]
Traceback (most recent call last):
  File "/home/www/.demo/lib/python2.7/site-packages/flask/app.py", line 1817, in wsgi_app
    response = self.full_dispatch_request()
  File "/home/www/.demo/lib/python2.7/site-packages/flask/app.py", line 1477, in full_dispatch_request
    rv = self.handle_user_exception(e)
  File "/home/www/.demo/lib/python2.7/site-packages/flask/app.py", line 1370, in handle_user_exception
    return self.handle_http_exception(e)
  File "/home/www/.demo/lib/python2.7/site-packages/flask/app.py", line 1330, in handle_http_exception
    return handler(e)
  File "/home/www/aud2/app/__init__.py", line 150, in page_404
    return render_template('errors/404.html'), 404
  File "/home/www/.demo/lib/python2.7/site-packages/flask/templating.py", line 128, in render_template
    context, ctx.app)
  File "/home/www/.demo/lib/python2.7/site-packages/flask/templating.py", line 110, in _render
    rv = template.render(context)
  File "/home/www/.demo/lib/python2.7/site-packages/jinja2/environment.py", line 969, in render
    return self.environment.handle_exception(exc_info, True)
  File "/home/www/.demo/lib/python2.7/site-packages/jinja2/environment.py", line 742, in handle_exception
    reraise(exc_type, exc_value, tb)
  File "/home/www/aud2/app/templates/errors/404.html", line 2, in top-level template code
    {% extends "base.html" %}
  File "/home/www/aud2/app/templates/base.html", line 26, in top-level template code
    {% include 'nav.html' %}
  File "/home/www/aud2/app/templates/nav.html", line 221, in top-level template code
    {% if g.user.is_admin() %}
UndefinedError: 'werkzeug.local.LocalProxy object' has no attribute 'is_admin'
2016-09-02 16:21:36,609 ERROR: Exception on /favicon.ico [GET] [in /home/www/.demo/lib/python2.7/site-packages/flask/app.py:1423]
Traceback (most recent call last):
  File "/home/www/.demo/lib/python2.7/site-packages/flask/app.py", line 1817, in wsgi_app
    response = self.full_dispatch_request()
  File "/home/www/.demo/lib/python2.7/site-packages/flask/app.py", line 1477, in full_dispatch_request
    rv = self.handle_user_exception(e)
  File "/home/www/.demo/lib/python2.7/site-packages/flask/app.py", line 1370, in handle_user_exception
    return self.handle_http_exception(e)
  File "/home/www/.demo/lib/python2.7/site-packages/flask/app.py", line 1330, in handle_http_exception
    return handler(e)
  File "/home/www/aud2/app/__init__.py", line 150, in page_404
    return render_template('errors/404.html'), 404
  File "/home/www/.demo/lib/python2.7/site-packages/flask/templating.py", line 128, in render_template
    context, ctx.app)
  File "/home/www/.demo/lib/python2.7/site-packages/flask/templating.py", line 110, in _render
    rv = template.render(context)
  File "/home/www/.demo/lib/python2.7/site-packages/jinja2/environment.py", line 969, in render
    return self.environment.handle_exception(exc_info, True)
  File "/home/www/.demo/lib/python2.7/site-packages/jinja2/environment.py", line 742, in handle_exception
    reraise(exc_type, exc_value, tb)
  File "/home/www/aud2/app/templates/errors/404.html", line 2, in top-level template code
    {% extends "base.html" %}
  File "/home/www/aud2/app/templates/base.html", line 26, in top-level template code
    {% include 'nav.html' %}
  File "/home/www/aud2/app/templates/nav.html", line 221, in top-level template code
    {% if g.user.is_admin() %}
UndefinedError: 'werkzeug.local.LocalProxy object' has no attribute 'is_admin'
2016-09-02 16:21:36,634 ERROR: Exception on /favicon.ico [GET] [in /home/www/.demo/lib/python2.7/site-packages/flask/app.py:1423]
Traceback (most recent call last):
  File "/home/www/.demo/lib/python2.7/site-packages/flask/app.py", line 1817, in wsgi_app
    response = self.full_dispatch_request()
  File "/home/www/.demo/lib/python2.7/site-packages/flask/app.py", line 1477, in full_dispatch_request
    rv = self.handle_user_exception(e)
  File "/home/www/.demo/lib/python2.7/site-packages/flask/app.py", line 1370, in handle_user_exception
    return self.handle_http_exception(e)
  File "/home/www/.demo/lib/python2.7/site-packages/flask/app.py", line 1330, in handle_http_exception
    return handler(e)
  File "/home/www/aud2/app/__init__.py", line 150, in page_404
    return render_template('errors/404.html'), 404
  File "/home/www/.demo/lib/python2.7/site-packages/flask/templating.py", line 128, in render_template
    context, ctx.app)
  File "/home/www/.demo/lib/python2.7/site-packages/flask/templating.py", line 110, in _render
    rv = template.render(context)
  File "/home/www/.demo/lib/python2.7/site-packages/jinja2/environment.py", line 969, in render
    return self.environment.handle_exception(exc_info, True)
  File "/home/www/.demo/lib/python2.7/site-packages/jinja2/environment.py", line 742, in handle_exception
    reraise(exc_type, exc_value, tb)
  File "/home/www/aud2/app/templates/errors/404.html", line 2, in top-level template code
    {% extends "base.html" %}
  File "/home/www/aud2/app/templates/base.html", line 26, in top-level template code
    {% include 'nav.html' %}
  File "/home/www/aud2/app/templates/nav.html", line 221, in top-level template code
    {% if g.user.is_admin() %}
UndefinedError: 'werkzeug.local.LocalProxy object' has no attribute 'is_admin'
2016-09-02 16:21:37,551 ERROR: Exception on /favicon.ico [GET] [in /home/www/.demo/lib/python2.7/site-packages/flask/app.py:1423]
Traceback (most recent call last):
  File "/home/www/.demo/lib/python2.7/site-packages/flask/app.py", line 1817, in wsgi_app
    response = self.full_dispatch_request()
  File "/home/www/.demo/lib/python2.7/site-packages/flask/app.py", line 1477, in full_dispatch_request
    rv = self.handle_user_exception(e)
  File "/home/www/.demo/lib/python2.7/site-packages/flask/app.py", line 1370, in handle_user_exception
    return self.handle_http_exception(e)
  File "/home/www/.demo/lib/python2.7/site-packages/flask/app.py", line 1330, in handle_http_exception
    return handler(e)
  File "/home/www/aud2/app/__init__.py", line 150, in page_404
    return render_template('errors/404.html'), 404
  File "/home/www/.demo/lib/python2.7/site-packages/flask/templating.py", line 128, in render_template
    context, ctx.app)
  File "/home/www/.demo/lib/python2.7/site-packages/flask/templating.py", line 110, in _render
    rv = template.render(context)
  File "/home/www/.demo/lib/python2.7/site-packages/jinja2/environment.py", line 969, in render
    return self.environment.handle_exception(exc_info, True)
  File "/home/www/.demo/lib/python2.7/site-packages/jinja2/environment.py", line 742, in handle_exception
    reraise(exc_type, exc_value, tb)
  File "/home/www/aud2/app/templates/errors/404.html", line 2, in top-level template code
    {% extends "base.html" %}
  File "/home/www/aud2/app/templates/base.html", line 26, in top-level template code
    {% include 'nav.html' %}
  File "/home/www/aud2/app/templates/nav.html", line 221, in top-level template code
    {% if g.user.is_admin() %}
UndefinedError: 'werkzeug.local.LocalProxy object' has no attribute 'is_admin'
2016-09-02 16:27:22,762 ERROR: Exception on /favicon.ico [GET] [in /home/www/.demo/lib/python2.7/site-packages/flask/app.py:1423]
Traceback (most recent call last):
  File "/home/www/.demo/lib/python2.7/site-packages/flask/app.py", line 1817, in wsgi_app
    response = self.full_dispatch_request()
  File "/home/www/.demo/lib/python2.7/site-packages/flask/app.py", line 1477, in full_dispatch_request
    rv = self.handle_user_exception(e)
  File "/home/www/.demo/lib/python2.7/site-packages/flask/app.py", line 1370, in handle_user_exception
    return self.handle_http_exception(e)
  File "/home/www/.demo/lib/python2.7/site-packages/flask/app.py", line 1330, in handle_http_exception
    return handler(e)
  File "/home/www/aud2/app/__init__.py", line 150, in page_404
    return render_template('errors/404.html'), 404
  File "/home/www/.demo/lib/python2.7/site-packages/flask/templating.py", line 128, in render_template
    context, ctx.app)
  File "/home/www/.demo/lib/python2.7/site-packages/flask/templating.py", line 110, in _render
    rv = template.render(context)
  File "/home/www/.demo/lib/python2.7/site-packages/jinja2/environment.py", line 969, in render
    return self.environment.handle_exception(exc_info, True)
  File "/home/www/.demo/lib/python2.7/site-packages/jinja2/environment.py", line 742, in handle_exception
    reraise(exc_type, exc_value, tb)
  File "/home/www/aud2/app/templates/errors/404.html", line 2, in top-level template code
    {% extends "base.html" %}
  File "/home/www/aud2/app/templates/base.html", line 26, in top-level template code
    {% include 'nav.html' %}
  File "/home/www/aud2/app/templates/nav.html", line 221, in top-level template code
    {% if g.user.is_admin() %}
UndefinedError: 'werkzeug.local.LocalProxy object' has no attribute 'is_admin'
2016-09-02 16:27:24,881 ERROR: Exception on /favicon.ico [GET] [in /home/www/.demo/lib/python2.7/site-packages/flask/app.py:1423]
Traceback (most recent call last):
  File "/home/www/.demo/lib/python2.7/site-packages/flask/app.py", line 1817, in wsgi_app
    response = self.full_dispatch_request()
  File "/home/www/.demo/lib/python2.7/site-packages/flask/app.py", line 1477, in full_dispatch_request
    rv = self.handle_user_exception(e)
  File "/home/www/.demo/lib/python2.7/site-packages/flask/app.py", line 1370, in handle_user_exception
    return self.handle_http_exception(e)
  File "/home/www/.demo/lib/python2.7/site-packages/flask/app.py", line 1330, in handle_http_exception
    return handler(e)
  File "/home/www/aud2/app/__init__.py", line 150, in page_404
    return render_template('errors/404.html'), 404
  File "/home/www/.demo/lib/python2.7/site-packages/flask/templating.py", line 128, in render_template
    context, ctx.app)
  File "/home/www/.demo/lib/python2.7/site-packages/flask/templating.py", line 110, in _render
    rv = template.render(context)
  File "/home/www/.demo/lib/python2.7/site-packages/jinja2/environment.py", line 969, in render
    return self.environment.handle_exception(exc_info, True)
  File "/home/www/.demo/lib/python2.7/site-packages/jinja2/environment.py", line 742, in handle_exception
    reraise(exc_type, exc_value, tb)
  File "/home/www/aud2/app/templates/errors/404.html", line 2, in top-level template code
    {% extends "base.html" %}
  File "/home/www/aud2/app/templates/base.html", line 26, in top-level template code
    {% include 'nav.html' %}
  File "/home/www/aud2/app/templates/nav.html", line 221, in top-level template code
    {% if g.user.is_admin() %}
UndefinedError: 'werkzeug.local.LocalProxy object' has no attribute 'is_admin'
2016-09-02 17:12:58,002 ERROR: Exception on /favicon.ico [GET] [in /home/www/.demo/lib/python2.7/site-packages/flask/app.py:1423]
Traceback (most recent call last):
  File "/home/www/.demo/lib/python2.7/site-packages/flask/app.py", line 1817, in wsgi_app
    response = self.full_dispatch_request()
  File "/home/www/.demo/lib/python2.7/site-packages/flask/app.py", line 1477, in full_dispatch_request
    rv = self.handle_user_exception(e)
  File "/home/www/.demo/lib/python2.7/site-packages/flask/app.py", line 1370, in handle_user_exception
    return self.handle_http_exception(e)
  File "/home/www/.demo/lib/python2.7/site-packages/flask/app.py", line 1330, in handle_http_exception
    return handler(e)
  File "/home/www/aud2/app/__init__.py", line 150, in page_404
    return render_template('errors/404.html'), 404
  File "/home/www/.demo/lib/python2.7/site-packages/flask/templating.py", line 128, in render_template
    context, ctx.app)
  File "/home/www/.demo/lib/python2.7/site-packages/flask/templating.py", line 110, in _render
    rv = template.render(context)
  File "/home/www/.demo/lib/python2.7/site-packages/jinja2/environment.py", line 969, in render
    return self.environment.handle_exception(exc_info, True)
  File "/home/www/.demo/lib/python2.7/site-packages/jinja2/environment.py", line 742, in handle_exception
    reraise(exc_type, exc_value, tb)
  File "/home/www/aud2/app/templates/errors/404.html", line 2, in top-level template code
    {% extends "base.html" %}
  File "/home/www/aud2/app/templates/base.html", line 26, in top-level template code
    {% include 'nav.html' %}
  File "/home/www/aud2/app/templates/nav.html", line 221, in top-level template code
    {% if g.user.is_admin() %}
UndefinedError: 'werkzeug.local.LocalProxy object' has no attribute 'is_admin'
2016-09-02 17:12:58,017 ERROR: Exception on /favicon.ico [GET] [in /home/www/.demo/lib/python2.7/site-packages/flask/app.py:1423]
Traceback (most recent call last):
  File "/home/www/.demo/lib/python2.7/site-packages/flask/app.py", line 1817, in wsgi_app
    response = self.full_dispatch_request()
  File "/home/www/.demo/lib/python2.7/site-packages/flask/app.py", line 1477, in full_dispatch_request
    rv = self.handle_user_exception(e)
  File "/home/www/.demo/lib/python2.7/site-packages/flask/app.py", line 1370, in handle_user_exception
    return self.handle_http_exception(e)
  File "/home/www/.demo/lib/python2.7/site-packages/flask/app.py", line 1330, in handle_http_exception
    return handler(e)
  File "/home/www/aud2/app/__init__.py", line 150, in page_404
    return render_template('errors/404.html'), 404
  File "/home/www/.demo/lib/python2.7/site-packages/flask/templating.py", line 128, in render_template
    context, ctx.app)
  File "/home/www/.demo/lib/python2.7/site-packages/flask/templating.py", line 110, in _render
    rv = template.render(context)
  File "/home/www/.demo/lib/python2.7/site-packages/jinja2/environment.py", line 969, in render
    return self.environment.handle_exception(exc_info, True)
  File "/home/www/.demo/lib/python2.7/site-packages/jinja2/environment.py", line 742, in handle_exception
    reraise(exc_type, exc_value, tb)
  File "/home/www/aud2/app/templates/errors/404.html", line 2, in top-level template code
    {% extends "base.html" %}
  File "/home/www/aud2/app/templates/base.html", line 26, in top-level template code
    {% include 'nav.html' %}
  File "/home/www/aud2/app/templates/nav.html", line 221, in top-level template code
    {% if g.user.is_admin() %}
UndefinedError: 'werkzeug.local.LocalProxy object' has no attribute 'is_admin'
2016-09-02 17:18:13,075 ERROR: Exception on /api/v1.0/node_task/modify_status/a9871b45d83802d294a48ffb7292b819 [POST] [in /home/www/.demo/lib/python2.7/site-packages/flask/app.py:1423]
Traceback (most recent call last):
  File "/home/www/.demo/lib/python2.7/site-packages/flask/app.py", line 1817, in wsgi_app
    response = self.full_dispatch_request()
  File "/home/www/.demo/lib/python2.7/site-packages/flask/app.py", line 1477, in full_dispatch_request
    rv = self.handle_user_exception(e)
  File "/home/www/.demo/lib/python2.7/site-packages/flask/app.py", line 1381, in handle_user_exception
    reraise(exc_type, exc_value, tb)
  File "/home/www/.demo/lib/python2.7/site-packages/flask/app.py", line 1475, in full_dispatch_request
    rv = self.dispatch_request()
  File "/home/www/.demo/lib/python2.7/site-packages/flask/app.py", line 1461, in dispatch_request
    return self.view_functions[rule.endpoint](**req.view_args)
  File "/home/www/aud2/app/views/site.py", line 875, in modify_node_task_status
    mes.sendEmail()
  File "/home/www/aud2/app/utils/message.py", line 45, in sendEmail
    thr = Thread(target=send_async_email, args=[receiver + '@aicai.com', subject, html])
TypeError: unsupported operand type(s) for +: 'NoneType' and 'str'
2016-09-02 17:20:38,403 ERROR: Exception on /api/v1.0/node_task/modify_status/0236ae25e55dadbe293ec4ad9e9e638a [POST] [in /home/www/.demo/lib/python2.7/site-packages/flask/app.py:1423]
Traceback (most recent call last):
  File "/home/www/.demo/lib/python2.7/site-packages/flask/app.py", line 1817, in wsgi_app
    response = self.full_dispatch_request()
  File "/home/www/.demo/lib/python2.7/site-packages/flask/app.py", line 1477, in full_dispatch_request
    rv = self.handle_user_exception(e)
  File "/home/www/.demo/lib/python2.7/site-packages/flask/app.py", line 1381, in handle_user_exception
    reraise(exc_type, exc_value, tb)
  File "/home/www/.demo/lib/python2.7/site-packages/flask/app.py", line 1475, in full_dispatch_request
    rv = self.dispatch_request()
  File "/home/www/.demo/lib/python2.7/site-packages/flask/app.py", line 1461, in dispatch_request
    return self.view_functions[rule.endpoint](**req.view_args)
  File "/home/www/aud2/app/views/site.py", line 875, in modify_node_task_status
    mes.sendEmail()
  File "/home/www/aud2/app/utils/message.py", line 45, in sendEmail
    thr = Thread(target=send_async_email, args=[receiver + '@aicai.com', subject, html])
TypeError: unsupported operand type(s) for +: 'NoneType' and 'str'
2016-09-02 17:45:45,845 ERROR: Exception on /favicon.ico [GET] [in /home/www/.demo/lib/python2.7/site-packages/flask/app.py:1423]
Traceback (most recent call last):
  File "/home/www/.demo/lib/python2.7/site-packages/flask/app.py", line 1817, in wsgi_app
    response = self.full_dispatch_request()
  File "/home/www/.demo/lib/python2.7/site-packages/flask/app.py", line 1477, in full_dispatch_request
    rv = self.handle_user_exception(e)
  File "/home/www/.demo/lib/python2.7/site-packages/flask/app.py", line 1370, in handle_user_exception
    return self.handle_http_exception(e)
  File "/home/www/.demo/lib/python2.7/site-packages/flask/app.py", line 1330, in handle_http_exception
    return handler(e)
  File "/home/www/aud2/app/__init__.py", line 150, in page_404
    return render_template('errors/404.html'), 404
  File "/home/www/.demo/lib/python2.7/site-packages/flask/templating.py", line 128, in render_template
    context, ctx.app)
  File "/home/www/.demo/lib/python2.7/site-packages/flask/templating.py", line 110, in _render
    rv = template.render(context)
  File "/home/www/.demo/lib/python2.7/site-packages/jinja2/environment.py", line 969, in render
    return self.environment.handle_exception(exc_info, True)
  File "/home/www/.demo/lib/python2.7/site-packages/jinja2/environment.py", line 742, in handle_exception
    reraise(exc_type, exc_value, tb)
  File "/home/www/aud2/app/templates/errors/404.html", line 2, in top-level template code
    {% extends "base.html" %}
  File "/home/www/aud2/app/templates/base.html", line 26, in top-level template code
    {% include 'nav.html' %}
  File "/home/www/aud2/app/templates/nav.html", line 221, in top-level template code
    {% if g.user.is_admin() %}
UndefinedError: 'werkzeug.local.LocalProxy object' has no attribute 'is_admin'
2016-09-02 18:02:21,941 ERROR: Exception on /api/v1.0/node_task/modify_status/89e0e2ef788f92754a6c2e7514feb2ee [POST] [in /home/www/.demo/lib/python2.7/site-packages/flask/app.py:1423]
Traceback (most recent call last):
  File "/home/www/.demo/lib/python2.7/site-packages/flask/app.py", line 1817, in wsgi_app
    response = self.full_dispatch_request()
  File "/home/www/.demo/lib/python2.7/site-packages/flask/app.py", line 1477, in full_dispatch_request
    rv = self.handle_user_exception(e)
  File "/home/www/.demo/lib/python2.7/site-packages/flask/app.py", line 1381, in handle_user_exception
    reraise(exc_type, exc_value, tb)
  File "/home/www/.demo/lib/python2.7/site-packages/flask/app.py", line 1475, in full_dispatch_request
    rv = self.dispatch_request()
  File "/home/www/.demo/lib/python2.7/site-packages/flask/app.py", line 1461, in dispatch_request
    return self.view_functions[rule.endpoint](**req.view_args)
  File "/home/www/aud2/app/views/site.py", line 875, in modify_node_task_status
    mes.sendEmail()
  File "/home/www/aud2/app/utils/message.py", line 45, in sendEmail
    thr = Thread(target=send_async_email, args=[receiver + '@aicai.com', subject, html])
TypeError: unsupported operand type(s) for +: 'NoneType' and 'str'
2016-09-02 18:03:40,412 ERROR: Exception on /api/v1.0/node_task/modify_status/183bbbbcd6314b1df7722ccd6651b469 [POST] [in /home/www/.demo/lib/python2.7/site-packages/flask/app.py:1423]
Traceback (most recent call last):
  File "/home/www/.demo/lib/python2.7/site-packages/flask/app.py", line 1817, in wsgi_app
    response = self.full_dispatch_request()
  File "/home/www/.demo/lib/python2.7/site-packages/flask/app.py", line 1477, in full_dispatch_request
    rv = self.handle_user_exception(e)
  File "/home/www/.demo/lib/python2.7/site-packages/flask/app.py", line 1381, in handle_user_exception
    reraise(exc_type, exc_value, tb)
  File "/home/www/.demo/lib/python2.7/site-packages/flask/app.py", line 1475, in full_dispatch_request
    rv = self.dispatch_request()
  File "/home/www/.demo/lib/python2.7/site-packages/flask/app.py", line 1461, in dispatch_request
    return self.view_functions[rule.endpoint](**req.view_args)
  File "/home/www/aud2/app/views/site.py", line 875, in modify_node_task_status
    mes.sendEmail()
  File "/home/www/aud2/app/utils/message.py", line 45, in sendEmail
    thr = Thread(target=send_async_email, args=[receiver + '@aicai.com', subject, html])
TypeError: unsupported operand type(s) for +: 'NoneType' and 'str'
2016-09-02 18:48:45,804 ERROR: Exception on /favicon.ico [GET] [in /home/www/.demo/lib/python2.7/site-packages/flask/app.py:1423]
Traceback (most recent call last):
  File "/home/www/.demo/lib/python2.7/site-packages/flask/app.py", line 1817, in wsgi_app
    response = self.full_dispatch_request()
  File "/home/www/.demo/lib/python2.7/site-packages/flask/app.py", line 1477, in full_dispatch_request
    rv = self.handle_user_exception(e)
  File "/home/www/.demo/lib/python2.7/site-packages/flask/app.py", line 1370, in handle_user_exception
    return self.handle_http_exception(e)
  File "/home/www/.demo/lib/python2.7/site-packages/flask/app.py", line 1330, in handle_http_exception
    return handler(e)
  File "/home/www/aud2/app/__init__.py", line 150, in page_404
    return render_template('errors/404.html'), 404
  File "/home/www/.demo/lib/python2.7/site-packages/flask/templating.py", line 128, in render_template
    context, ctx.app)
  File "/home/www/.demo/lib/python2.7/site-packages/flask/templating.py", line 110, in _render
    rv = template.render(context)
  File "/home/www/.demo/lib/python2.7/site-packages/jinja2/environment.py", line 969, in render
    return self.environment.handle_exception(exc_info, True)
  File "/home/www/.demo/lib/python2.7/site-packages/jinja2/environment.py", line 742, in handle_exception
    reraise(exc_type, exc_value, tb)
  File "/home/www/aud2/app/templates/errors/404.html", line 2, in top-level template code
    {% extends "base.html" %}
  File "/home/www/aud2/app/templates/base.html", line 26, in top-level template code
    {% include 'nav.html' %}
  File "/home/www/aud2/app/templates/nav.html", line 221, in top-level template code
    {% if g.user.is_admin() %}
UndefinedError: 'werkzeug.local.LocalProxy object' has no attribute 'is_admin'
2016-09-02 19:37:31,710 ERROR: Exception on /favicon.ico [GET] [in /home/www/.demo/lib/python2.7/site-packages/flask/app.py:1423]
Traceback (most recent call last):
  File "/home/www/.demo/lib/python2.7/site-packages/flask/app.py", line 1817, in wsgi_app
    response = self.full_dispatch_request()
  File "/home/www/.demo/lib/python2.7/site-packages/flask/app.py", line 1477, in full_dispatch_request
    rv = self.handle_user_exception(e)
  File "/home/www/.demo/lib/python2.7/site-packages/flask/app.py", line 1370, in handle_user_exception
    return self.handle_http_exception(e)
  File "/home/www/.demo/lib/python2.7/site-packages/flask/app.py", line 1330, in handle_http_exception
    return handler(e)
  File "/home/www/aud2/app/__init__.py", line 150, in page_404
    return render_template('errors/404.html'), 404
  File "/home/www/.demo/lib/python2.7/site-packages/flask/templating.py", line 128, in render_template
    context, ctx.app)
  File "/home/www/.demo/lib/python2.7/site-packages/flask/templating.py", line 110, in _render
    rv = template.render(context)
  File "/home/www/.demo/lib/python2.7/site-packages/jinja2/environment.py", line 969, in render
    return self.environment.handle_exception(exc_info, True)
  File "/home/www/.demo/lib/python2.7/site-packages/jinja2/environment.py", line 742, in handle_exception
    reraise(exc_type, exc_value, tb)
  File "/home/www/aud2/app/templates/errors/404.html", line 2, in top-level template code
    {% extends "base.html" %}
  File "/home/www/aud2/app/templates/base.html", line 26, in top-level template code
    {% include 'nav.html' %}
  File "/home/www/aud2/app/templates/nav.html", line 221, in top-level template code
    {% if g.user.is_admin() %}
UndefinedError: 'werkzeug.local.LocalProxy object' has no attribute 'is_admin'
2016-09-02 19:39:36,386 ERROR: Exception on /api/v1.0/node_task/modify_status/e6f090ca98d43cf25eba0de56459ff71 [POST] [in /home/www/.demo/lib/python2.7/site-packages/flask/app.py:1423]
Traceback (most recent call last):
  File "/home/www/.demo/lib/python2.7/site-packages/flask/app.py", line 1817, in wsgi_app
    response = self.full_dispatch_request()
  File "/home/www/.demo/lib/python2.7/site-packages/flask/app.py", line 1477, in full_dispatch_request
    rv = self.handle_user_exception(e)
  File "/home/www/.demo/lib/python2.7/site-packages/flask/app.py", line 1381, in handle_user_exception
    reraise(exc_type, exc_value, tb)
  File "/home/www/.demo/lib/python2.7/site-packages/flask/app.py", line 1475, in full_dispatch_request
    rv = self.dispatch_request()
  File "/home/www/.demo/lib/python2.7/site-packages/flask/app.py", line 1461, in dispatch_request
    return self.view_functions[rule.endpoint](**req.view_args)
  File "/home/www/aud2/app/views/site.py", line 875, in modify_node_task_status
    mes.sendEmail()
  File "/home/www/aud2/app/utils/message.py", line 45, in sendEmail
    thr = Thread(target=send_async_email, args=[receiver + '@aicai.com', subject, html])
TypeError: unsupported operand type(s) for +: 'NoneType' and 'str'
2016-09-03 09:37:21,839 ERROR: Exception on /api/v1.0/node_task/modify_status/fc437327c22f6802235d758934fc66c1 [POST] [in /home/www/.demo/lib/python2.7/site-packages/flask/app.py:1423]
Traceback (most recent call last):
  File "/home/www/.demo/lib/python2.7/site-packages/flask/app.py", line 1817, in wsgi_app
    response = self.full_dispatch_request()
  File "/home/www/.demo/lib/python2.7/site-packages/flask/app.py", line 1477, in full_dispatch_request
    rv = self.handle_user_exception(e)
  File "/home/www/.demo/lib/python2.7/site-packages/flask/app.py", line 1381, in handle_user_exception
    reraise(exc_type, exc_value, tb)
  File "/home/www/.demo/lib/python2.7/site-packages/flask/app.py", line 1475, in full_dispatch_request
    rv = self.dispatch_request()
  File "/home/www/.demo/lib/python2.7/site-packages/flask/app.py", line 1461, in dispatch_request
    return self.view_functions[rule.endpoint](**req.view_args)
  File "/home/www/aud2/app/views/site.py", line 875, in modify_node_task_status
    mes.sendEmail()
  File "/home/www/aud2/app/utils/message.py", line 45, in sendEmail
    thr = Thread(target=send_async_email, args=[receiver + '@aicai.com', subject, html])
TypeError: unsupported operand type(s) for +: 'NoneType' and 'str'
2016-09-04 15:58:03,070 ERROR: Exception on /api/v1.0/node_task/modify_status/a08ff12af8ce03ff57ad6bd0760db98e [POST] [in /home/www/.demo/lib/python2.7/site-packages/flask/app.py:1423]
Traceback (most recent call last):
  File "/home/www/.demo/lib/python2.7/site-packages/flask/app.py", line 1817, in wsgi_app
    response = self.full_dispatch_request()
  File "/home/www/.demo/lib/python2.7/site-packages/flask/app.py", line 1477, in full_dispatch_request
    rv = self.handle_user_exception(e)
  File "/home/www/.demo/lib/python2.7/site-packages/flask/app.py", line 1381, in handle_user_exception
    reraise(exc_type, exc_value, tb)
  File "/home/www/.demo/lib/python2.7/site-packages/flask/app.py", line 1475, in full_dispatch_request
    rv = self.dispatch_request()
  File "/home/www/.demo/lib/python2.7/site-packages/flask/app.py", line 1461, in dispatch_request
    return self.view_functions[rule.endpoint](**req.view_args)
  File "/home/www/aud2/app/views/site.py", line 875, in modify_node_task_status
    mes.sendEmail()
  File "/home/www/aud2/app/utils/message.py", line 45, in sendEmail
    thr = Thread(target=send_async_email, args=[receiver + '@aicai.com', subject, html])
TypeError: unsupported operand type(s) for +: 'NoneType' and 'str'
2016-09-04 22:16:44,605 ERROR: Exception on /favicon.ico [GET] [in /home/www/.demo/lib/python2.7/site-packages/flask/app.py:1423]
Traceback (most recent call last):
  File "/home/www/.demo/lib/python2.7/site-packages/flask/app.py", line 1817, in wsgi_app
    response = self.full_dispatch_request()
  File "/home/www/.demo/lib/python2.7/site-packages/flask/app.py", line 1477, in full_dispatch_request
    rv = self.handle_user_exception(e)
  File "/home/www/.demo/lib/python2.7/site-packages/flask/app.py", line 1370, in handle_user_exception
    return self.handle_http_exception(e)
  File "/home/www/.demo/lib/python2.7/site-packages/flask/app.py", line 1330, in handle_http_exception
    return handler(e)
  File "/home/www/aud2/app/__init__.py", line 150, in page_404
    return render_template('errors/404.html'), 404
  File "/home/www/.demo/lib/python2.7/site-packages/flask/templating.py", line 128, in render_template
    context, ctx.app)
  File "/home/www/.demo/lib/python2.7/site-packages/flask/templating.py", line 110, in _render
    rv = template.render(context)
  File "/home/www/.demo/lib/python2.7/site-packages/jinja2/environment.py", line 969, in render
    return self.environment.handle_exception(exc_info, True)
  File "/home/www/.demo/lib/python2.7/site-packages/jinja2/environment.py", line 742, in handle_exception
    reraise(exc_type, exc_value, tb)
  File "/home/www/aud2/app/templates/errors/404.html", line 2, in top-level template code
    {% extends "base.html" %}
  File "/home/www/aud2/app/templates/base.html", line 26, in top-level template code
    {% include 'nav.html' %}
  File "/home/www/aud2/app/templates/nav.html", line 221, in top-level template code
    {% if g.user.is_admin() %}
UndefinedError: 'werkzeug.local.LocalProxy object' has no attribute 'is_admin'
2016-09-05 09:34:03,212 ERROR: Exception on /favicon.ico [GET] [in /home/www/.demo/lib/python2.7/site-packages/flask/app.py:1423]
Traceback (most recent call last):
  File "/home/www/.demo/lib/python2.7/site-packages/flask/app.py", line 1817, in wsgi_app
    response = self.full_dispatch_request()
  File "/home/www/.demo/lib/python2.7/site-packages/flask/app.py", line 1477, in full_dispatch_request
    rv = self.handle_user_exception(e)
  File "/home/www/.demo/lib/python2.7/site-packages/flask/app.py", line 1370, in handle_user_exception
    return self.handle_http_exception(e)
  File "/home/www/.demo/lib/python2.7/site-packages/flask/app.py", line 1330, in handle_http_exception
    return handler(e)
  File "/home/www/aud2/app/__init__.py", line 150, in page_404
    return render_template('errors/404.html'), 404
  File "/home/www/.demo/lib/python2.7/site-packages/flask/templating.py", line 128, in render_template
    context, ctx.app)
  File "/home/www/.demo/lib/python2.7/site-packages/flask/templating.py", line 110, in _render
    rv = template.render(context)
  File "/home/www/.demo/lib/python2.7/site-packages/jinja2/environment.py", line 969, in render
    return self.environment.handle_exception(exc_info, True)
  File "/home/www/.demo/lib/python2.7/site-packages/jinja2/environment.py", line 742, in handle_exception
    reraise(exc_type, exc_value, tb)
  File "/home/www/aud2/app/templates/errors/404.html", line 2, in top-level template code
    {% extends "base.html" %}
  File "/home/www/aud2/app/templates/base.html", line 26, in top-level template code
    {% include 'nav.html' %}
  File "/home/www/aud2/app/templates/nav.html", line 221, in top-level template code
    {% if g.user.is_admin() %}
UndefinedError: 'werkzeug.local.LocalProxy object' has no attribute 'is_admin'
2016-09-05 09:38:31,078 ERROR: Exception on /api/v1.0/node_task/modify_status/0d546f65a877c40e0006a74501921758 [POST] [in /home/www/.demo/lib/python2.7/site-packages/flask/app.py:1423]
Traceback (most recent call last):
  File "/home/www/.demo/lib/python2.7/site-packages/flask/app.py", line 1817, in wsgi_app
    response = self.full_dispatch_request()
  File "/home/www/.demo/lib/python2.7/site-packages/flask/app.py", line 1477, in full_dispatch_request
    rv = self.handle_user_exception(e)
  File "/home/www/.demo/lib/python2.7/site-packages/flask/app.py", line 1381, in handle_user_exception
    reraise(exc_type, exc_value, tb)
  File "/home/www/.demo/lib/python2.7/site-packages/flask/app.py", line 1475, in full_dispatch_request
    rv = self.dispatch_request()
  File "/home/www/.demo/lib/python2.7/site-packages/flask/app.py", line 1461, in dispatch_request
    return self.view_functions[rule.endpoint](**req.view_args)
  File "/home/www/aud2/app/views/site.py", line 875, in modify_node_task_status
    mes.sendEmail()
  File "/home/www/aud2/app/utils/message.py", line 45, in sendEmail
    thr = Thread(target=send_async_email, args=[receiver + '@aicai.com', subject, html])
TypeError: unsupported operand type(s) for +: 'NoneType' and 'str'
2016-09-05 09:54:15,111 ERROR: Exception on /favicon.ico [GET] [in /home/www/.demo/lib/python2.7/site-packages/flask/app.py:1423]
Traceback (most recent call last):
  File "/home/www/.demo/lib/python2.7/site-packages/flask/app.py", line 1817, in wsgi_app
    response = self.full_dispatch_request()
  File "/home/www/.demo/lib/python2.7/site-packages/flask/app.py", line 1477, in full_dispatch_request
    rv = self.handle_user_exception(e)
  File "/home/www/.demo/lib/python2.7/site-packages/flask/app.py", line 1370, in handle_user_exception
    return self.handle_http_exception(e)
  File "/home/www/.demo/lib/python2.7/site-packages/flask/app.py", line 1330, in handle_http_exception
    return handler(e)
  File "/home/www/aud2/app/__init__.py", line 150, in page_404
    return render_template('errors/404.html'), 404
  File "/home/www/.demo/lib/python2.7/site-packages/flask/templating.py", line 128, in render_template
    context, ctx.app)
  File "/home/www/.demo/lib/python2.7/site-packages/flask/templating.py", line 110, in _render
    rv = template.render(context)
  File "/home/www/.demo/lib/python2.7/site-packages/jinja2/environment.py", line 969, in render
    return self.environment.handle_exception(exc_info, True)
  File "/home/www/.demo/lib/python2.7/site-packages/jinja2/environment.py", line 742, in handle_exception
    reraise(exc_type, exc_value, tb)
  File "/home/www/aud2/app/templates/errors/404.html", line 2, in top-level template code
    {% extends "base.html" %}
  File "/home/www/aud2/app/templates/base.html", line 26, in top-level template code
    {% include 'nav.html' %}
  File "/home/www/aud2/app/templates/nav.html", line 221, in top-level template code
    {% if g.user.is_admin() %}
UndefinedError: 'werkzeug.local.LocalProxy object' has no attribute 'is_admin'
2016-09-05 09:54:24,419 ERROR: Exception on /favicon.ico [GET] [in /home/www/.demo/lib/python2.7/site-packages/flask/app.py:1423]
Traceback (most recent call last):
  File "/home/www/.demo/lib/python2.7/site-packages/flask/app.py", line 1817, in wsgi_app
    response = self.full_dispatch_request()
  File "/home/www/.demo/lib/python2.7/site-packages/flask/app.py", line 1477, in full_dispatch_request
    rv = self.handle_user_exception(e)
  File "/home/www/.demo/lib/python2.7/site-packages/flask/app.py", line 1370, in handle_user_exception
    return self.handle_http_exception(e)
  File "/home/www/.demo/lib/python2.7/site-packages/flask/app.py", line 1330, in handle_http_exception
    return handler(e)
  File "/home/www/aud2/app/__init__.py", line 150, in page_404
    return render_template('errors/404.html'), 404
  File "/home/www/.demo/lib/python2.7/site-packages/flask/templating.py", line 128, in render_template
    context, ctx.app)
  File "/home/www/.demo/lib/python2.7/site-packages/flask/templating.py", line 110, in _render
    rv = template.render(context)
  File "/home/www/.demo/lib/python2.7/site-packages/jinja2/environment.py", line 969, in render
    return self.environment.handle_exception(exc_info, True)
  File "/home/www/.demo/lib/python2.7/site-packages/jinja2/environment.py", line 742, in handle_exception
    reraise(exc_type, exc_value, tb)
  File "/home/www/aud2/app/templates/errors/404.html", line 2, in top-level template code
    {% extends "base.html" %}
  File "/home/www/aud2/app/templates/base.html", line 26, in top-level template code
    {% include 'nav.html' %}
  File "/home/www/aud2/app/templates/nav.html", line 221, in top-level template code
    {% if g.user.is_admin() %}
UndefinedError: 'werkzeug.local.LocalProxy object' has no attribute 'is_admin'
2016-09-05 09:57:47,505 ERROR: Exception on /api/v1.0/node_task/modify_status/d27f792d7c0c918851dbb92b366be14c [POST] [in /home/www/.demo/lib/python2.7/site-packages/flask/app.py:1423]
Traceback (most recent call last):
  File "/home/www/.demo/lib/python2.7/site-packages/flask/app.py", line 1817, in wsgi_app
    response = self.full_dispatch_request()
  File "/home/www/.demo/lib/python2.7/site-packages/flask/app.py", line 1477, in full_dispatch_request
    rv = self.handle_user_exception(e)
  File "/home/www/.demo/lib/python2.7/site-packages/flask/app.py", line 1381, in handle_user_exception
    reraise(exc_type, exc_value, tb)
  File "/home/www/.demo/lib/python2.7/site-packages/flask/app.py", line 1475, in full_dispatch_request
    rv = self.dispatch_request()
  File "/home/www/.demo/lib/python2.7/site-packages/flask/app.py", line 1461, in dispatch_request
    return self.view_functions[rule.endpoint](**req.view_args)
  File "/home/www/aud2/app/views/site.py", line 875, in modify_node_task_status
    mes.sendEmail()
  File "/home/www/aud2/app/utils/message.py", line 45, in sendEmail
    thr = Thread(target=send_async_email, args=[receiver + '@aicai.com', subject, html])
TypeError: unsupported operand type(s) for +: 'NoneType' and 'str'
2016-09-05 10:02:30,260 ERROR: Exception on /favicon.ico [GET] [in /home/www/.demo/lib/python2.7/site-packages/flask/app.py:1423]
Traceback (most recent call last):
  File "/home/www/.demo/lib/python2.7/site-packages/flask/app.py", line 1817, in wsgi_app
    response = self.full_dispatch_request()
  File "/home/www/.demo/lib/python2.7/site-packages/flask/app.py", line 1477, in full_dispatch_request
    rv = self.handle_user_exception(e)
  File "/home/www/.demo/lib/python2.7/site-packages/flask/app.py", line 1370, in handle_user_exception
    return self.handle_http_exception(e)
  File "/home/www/.demo/lib/python2.7/site-packages/flask/app.py", line 1330, in handle_http_exception
    return handler(e)
  File "/home/www/aud2/app/__init__.py", line 150, in page_404
    return render_template('errors/404.html'), 404
  File "/home/www/.demo/lib/python2.7/site-packages/flask/templating.py", line 128, in render_template
    context, ctx.app)
  File "/home/www/.demo/lib/python2.7/site-packages/flask/templating.py", line 110, in _render
    rv = template.render(context)
  File "/home/www/.demo/lib/python2.7/site-packages/jinja2/environment.py", line 969, in render
    return self.environment.handle_exception(exc_info, True)
  File "/home/www/.demo/lib/python2.7/site-packages/jinja2/environment.py", line 742, in handle_exception
    reraise(exc_type, exc_value, tb)
  File "/home/www/aud2/app/templates/errors/404.html", line 2, in top-level template code
    {% extends "base.html" %}
  File "/home/www/aud2/app/templates/base.html", line 26, in top-level template code
    {% include 'nav.html' %}
  File "/home/www/aud2/app/templates/nav.html", line 221, in top-level template code
    {% if g.user.is_admin() %}
UndefinedError: 'werkzeug.local.LocalProxy object' has no attribute 'is_admin'
2016-09-05 10:28:03,937 ERROR: Exception on /favicon.ico [GET] [in /home/www/.demo/lib/python2.7/site-packages/flask/app.py:1423]
Traceback (most recent call last):
  File "/home/www/.demo/lib/python2.7/site-packages/flask/app.py", line 1817, in wsgi_app
    response = self.full_dispatch_request()
  File "/home/www/.demo/lib/python2.7/site-packages/flask/app.py", line 1477, in full_dispatch_request
    rv = self.handle_user_exception(e)
  File "/home/www/.demo/lib/python2.7/site-packages/flask/app.py", line 1370, in handle_user_exception
    return self.handle_http_exception(e)
  File "/home/www/.demo/lib/python2.7/site-packages/flask/app.py", line 1330, in handle_http_exception
    return handler(e)
  File "/home/www/aud2/app/__init__.py", line 150, in page_404
    return render_template('errors/404.html'), 404
  File "/home/www/.demo/lib/python2.7/site-packages/flask/templating.py", line 128, in render_template
    context, ctx.app)
  File "/home/www/.demo/lib/python2.7/site-packages/flask/templating.py", line 110, in _render
    rv = template.render(context)
  File "/home/www/.demo/lib/python2.7/site-packages/jinja2/environment.py", line 969, in render
    return self.environment.handle_exception(exc_info, True)
  File "/home/www/.demo/lib/python2.7/site-packages/jinja2/environment.py", line 742, in handle_exception
    reraise(exc_type, exc_value, tb)
  File "/home/www/aud2/app/templates/errors/404.html", line 2, in top-level template code
    {% extends "base.html" %}
  File "/home/www/aud2/app/templates/base.html", line 26, in top-level template code
    {% include 'nav.html' %}
  File "/home/www/aud2/app/templates/nav.html", line 221, in top-level template code
    {% if g.user.is_admin() %}
UndefinedError: 'werkzeug.local.LocalProxy object' has no attribute 'is_admin'
2016-09-05 10:34:11,710 ERROR: Exception on /tomcat/tomcat_task/ [POST] [in /home/www/.demo/lib/python2.7/site-packages/flask/app.py:1423]
Traceback (most recent call last):
  File "/home/www/.demo/lib/python2.7/site-packages/flask/app.py", line 1817, in wsgi_app
    response = self.full_dispatch_request()
  File "/home/www/.demo/lib/python2.7/site-packages/flask/app.py", line 1477, in full_dispatch_request
    rv = self.handle_user_exception(e)
  File "/home/www/.demo/lib/python2.7/site-packages/flask/app.py", line 1381, in handle_user_exception
    reraise(exc_type, exc_value, tb)
  File "/home/www/.demo/lib/python2.7/site-packages/flask/app.py", line 1475, in full_dispatch_request
    rv = self.dispatch_request()
  File "/home/www/.demo/lib/python2.7/site-packages/flask/app.py", line 1461, in dispatch_request
    return self.view_functions[rule.endpoint](**req.view_args)
  File "/home/www/.demo/lib/python2.7/site-packages/flask_login.py", line 758, in decorated_view
    return func(*args, **kwargs)
  File "/home/www/.demo/lib/python2.7/site-packages/permission/permission.py", line 19, in decorator
    return func(*args, **kwargs)
  File "/home/www/aud2/app/views/tomcat.py", line 408, in tomcat_task
    q.put(task_json)
  File "/home/www/aud2/app/utils/redisqueue.py", line 24, in put
    self.__db.rpush(self.key, item)
  File "/home/www/.demo/lib/python2.7/site-packages/redis/client.py", line 1265, in rpush
    return self.execute_command('RPUSH', name, *values)
  File "/home/www/.demo/lib/python2.7/site-packages/redis/client.py", line 565, in execute_command
    return self.parse_response(connection, command_name, **options)
  File "/home/www/.demo/lib/python2.7/site-packages/redis/client.py", line 577, in parse_response
    response = connection.read_response()
  File "/home/www/.demo/lib/python2.7/site-packages/redis/connection.py", line 574, in read_response
    raise response
ResponseError: MISCONF Redis is configured to save RDB snapshots, but is currently not able to persist on disk. Commands that may modify the data set are disabled. Please check Redis logs for details about the error.
2016-09-05 10:34:57,493 ERROR: Exception on /tomcat/tomcat_task/ [POST] [in /home/www/.demo/lib/python2.7/site-packages/flask/app.py:1423]
Traceback (most recent call last):
  File "/home/www/.demo/lib/python2.7/site-packages/flask/app.py", line 1817, in wsgi_app
    response = self.full_dispatch_request()
  File "/home/www/.demo/lib/python2.7/site-packages/flask/app.py", line 1477, in full_dispatch_request
    rv = self.handle_user_exception(e)
  File "/home/www/.demo/lib/python2.7/site-packages/flask/app.py", line 1381, in handle_user_exception
    reraise(exc_type, exc_value, tb)
  File "/home/www/.demo/lib/python2.7/site-packages/flask/app.py", line 1475, in full_dispatch_request
    rv = self.dispatch_request()
  File "/home/www/.demo/lib/python2.7/site-packages/flask/app.py", line 1461, in dispatch_request
    return self.view_functions[rule.endpoint](**req.view_args)
  File "/home/www/.demo/lib/python2.7/site-packages/flask_login.py", line 758, in decorated_view
    return func(*args, **kwargs)
  File "/home/www/.demo/lib/python2.7/site-packages/permission/permission.py", line 19, in decorator
    return func(*args, **kwargs)
  File "/home/www/aud2/app/views/tomcat.py", line 408, in tomcat_task
    q.put(task_json)
  File "/home/www/aud2/app/utils/redisqueue.py", line 24, in put
    self.__db.rpush(self.key, item)
  File "/home/www/.demo/lib/python2.7/site-packages/redis/client.py", line 1265, in rpush
    return self.execute_command('RPUSH', name, *values)
  File "/home/www/.demo/lib/python2.7/site-packages/redis/client.py", line 565, in execute_command
    return self.parse_response(connection, command_name, **options)
  File "/home/www/.demo/lib/python2.7/site-packages/redis/client.py", line 577, in parse_response
    response = connection.read_response()
  File "/home/www/.demo/lib/python2.7/site-packages/redis/connection.py", line 574, in read_response
    raise response
ResponseError: MISCONF Redis is configured to save RDB snapshots, but is currently not able to persist on disk. Commands that may modify the data set are disabled. Please check Redis logs for details about the error.
2016-09-05 10:40:38,188 ERROR: Exception on /tomcat/tomcat_task/ [POST] [in /home/www/.demo/lib/python2.7/site-packages/flask/app.py:1423]
Traceback (most recent call last):
  File "/home/www/.demo/lib/python2.7/site-packages/flask/app.py", line 1817, in wsgi_app
    response = self.full_dispatch_request()
  File "/home/www/.demo/lib/python2.7/site-packages/flask/app.py", line 1477, in full_dispatch_request
    rv = self.handle_user_exception(e)
  File "/home/www/.demo/lib/python2.7/site-packages/flask/app.py", line 1381, in handle_user_exception
    reraise(exc_type, exc_value, tb)
  File "/home/www/.demo/lib/python2.7/site-packages/flask/app.py", line 1475, in full_dispatch_request
    rv = self.dispatch_request()
  File "/home/www/.demo/lib/python2.7/site-packages/flask/app.py", line 1461, in dispatch_request
    return self.view_functions[rule.endpoint](**req.view_args)
  File "/home/www/.demo/lib/python2.7/site-packages/flask_login.py", line 758, in decorated_view
    return func(*args, **kwargs)
  File "/home/www/.demo/lib/python2.7/site-packages/permission/permission.py", line 19, in decorator
    return func(*args, **kwargs)
  File "/home/www/aud2/app/views/tomcat.py", line 408, in tomcat_task
    q.put(task_json)
  File "/home/www/aud2/app/utils/redisqueue.py", line 24, in put
    self.__db.rpush(self.key, item)
  File "/home/www/.demo/lib/python2.7/site-packages/redis/client.py", line 1265, in rpush
    return self.execute_command('RPUSH', name, *values)
  File "/home/www/.demo/lib/python2.7/site-packages/redis/client.py", line 565, in execute_command
    return self.parse_response(connection, command_name, **options)
  File "/home/www/.demo/lib/python2.7/site-packages/redis/client.py", line 577, in parse_response
    response = connection.read_response()
  File "/home/www/.demo/lib/python2.7/site-packages/redis/connection.py", line 574, in read_response
    raise response
ResponseError: MISCONF Redis is configured to save RDB snapshots, but is currently not able to persist on disk. Commands that may modify the data set are disabled. Please check Redis logs for details about the error.
2016-09-05 10:43:32,141 ERROR: Exception on /api/v1.0/tomcat_task/modify_status/TC-worldcup-10-71-64-197-20160905104310 [POST] [in /home/www/.demo/lib/python2.7/site-packages/flask/app.py:1423]
Traceback (most recent call last):
  File "/home/www/.demo/lib/python2.7/site-packages/flask/app.py", line 1817, in wsgi_app
    response = self.full_dispatch_request()
  File "/home/www/.demo/lib/python2.7/site-packages/flask/app.py", line 1477, in full_dispatch_request
    rv = self.handle_user_exception(e)
  File "/home/www/.demo/lib/python2.7/site-packages/flask/app.py", line 1370, in handle_user_exception
    return self.handle_http_exception(e)
  File "/home/www/.demo/lib/python2.7/site-packages/flask/app.py", line 1330, in handle_http_exception
    return handler(e)
  File "/home/www/aud2/app/__init__.py", line 150, in page_404
    return render_template('errors/404.html'), 404
  File "/home/www/.demo/lib/python2.7/site-packages/flask/templating.py", line 128, in render_template
    context, ctx.app)
  File "/home/www/.demo/lib/python2.7/site-packages/flask/templating.py", line 110, in _render
    rv = template.render(context)
  File "/home/www/.demo/lib/python2.7/site-packages/jinja2/environment.py", line 969, in render
    return self.environment.handle_exception(exc_info, True)
  File "/home/www/.demo/lib/python2.7/site-packages/jinja2/environment.py", line 742, in handle_exception
    reraise(exc_type, exc_value, tb)
  File "/home/www/aud2/app/templates/errors/404.html", line 2, in top-level template code
    {% extends "base.html" %}
  File "/home/www/aud2/app/templates/base.html", line 26, in top-level template code
    {% include 'nav.html' %}
  File "/home/www/aud2/app/templates/nav.html", line 221, in top-level template code
    {% if g.user.is_admin() %}
UndefinedError: 'werkzeug.local.LocalProxy object' has no attribute 'is_admin'
2016-09-05 10:49:26,025 ERROR: Exception on /tomcat/tomcat_task/ [GET] [in /home/www/.demo/lib/python2.7/site-packages/flask/app.py:1423]
Traceback (most recent call last):
  File "/home/www/.demo/lib/python2.7/site-packages/flask/app.py", line 1817, in wsgi_app
    response = self.full_dispatch_request()
  File "/home/www/.demo/lib/python2.7/site-packages/flask/app.py", line 1477, in full_dispatch_request
    rv = self.handle_user_exception(e)
  File "/home/www/.demo/lib/python2.7/site-packages/flask/app.py", line 1381, in handle_user_exception
    reraise(exc_type, exc_value, tb)
  File "/home/www/.demo/lib/python2.7/site-packages/flask/app.py", line 1475, in full_dispatch_request
    rv = self.dispatch_request()
  File "/home/www/.demo/lib/python2.7/site-packages/flask/app.py", line 1461, in dispatch_request
    return self.view_functions[rule.endpoint](**req.view_args)
  File "/home/www/.demo/lib/python2.7/site-packages/flask_login.py", line 758, in decorated_view
    return func(*args, **kwargs)
  File "/home/www/.demo/lib/python2.7/site-packages/permission/permission.py", line 19, in decorator
    return func(*args, **kwargs)
  File "/home/www/aud2/app/views/tomcat.py", line 514, in tomcat_task
    q.put(task_json)
  File "/home/www/aud2/app/utils/redisqueue.py", line 24, in put
    self.__db.rpush(self.key, item)
  File "/home/www/.demo/lib/python2.7/site-packages/redis/client.py", line 1265, in rpush
    return self.execute_command('RPUSH', name, *values)
  File "/home/www/.demo/lib/python2.7/site-packages/redis/client.py", line 565, in execute_command
    return self.parse_response(connection, command_name, **options)
  File "/home/www/.demo/lib/python2.7/site-packages/redis/client.py", line 577, in parse_response
    response = connection.read_response()
  File "/home/www/.demo/lib/python2.7/site-packages/redis/connection.py", line 574, in read_response
    raise response
ResponseError: MISCONF Redis is configured to save RDB snapshots, but is currently not able to persist on disk. Commands that may modify the data set are disabled. Please check Redis logs for details about the error.
