2016-08-24 14:56:29,928 ERROR: Exception on /api/v1.0/node_task/modify_status/2c6940475e55e7fc9510667510d4dedd [POST] [in /home/www/.demo/lib/python2.7/site-packages/flask/app.py:1423]
Traceback (most recent call last):
  File "/home/www/.demo/lib/python2.7/site-packages/flask/app.py", line 1817, in wsgi_app
    response = self.full_dispatch_request()
  File "/home/www/.demo/lib/python2.7/site-packages/flask/app.py", line 1477, in full_dispatch_request
    rv = self.handle_user_exception(e)
  File "/home/www/.demo/lib/python2.7/site-packages/flask/app.py", line 1381, in handle_user_exception
    reraise(exc_type, exc_value, tb)
  File "/home/www/.demo/lib/python2.7/site-packages/flask/app.py", line 1475, in full_dispatch_request
    rv = self.dispatch_request()
  File "/home/www/.demo/lib/python2.7/site-packages/flask/app.py", line 1461, in dispatch_request
    return self.view_functions[rule.endpoint](**req.view_args)
  File "/home/www/aud2/app/views/site.py", line 875, in modify_node_task_status
    mes.sendEmail()
  File "/home/www/aud2/app/utils/message.py", line 45, in sendEmail
    thr = Thread(target=send_async_email, args=[receiver + '@aicai.com', subject, html])
TypeError: unsupported operand type(s) for +: 'NoneType' and 'str'
2016-08-24 15:06:11,144 ERROR: Exception on /favicon.ico [GET] [in /home/www/.demo/lib/python2.7/site-packages/flask/app.py:1423]
Traceback (most recent call last):
  File "/home/www/.demo/lib/python2.7/site-packages/flask/app.py", line 1817, in wsgi_app
    response = self.full_dispatch_request()
  File "/home/www/.demo/lib/python2.7/site-packages/flask/app.py", line 1477, in full_dispatch_request
    rv = self.handle_user_exception(e)
  File "/home/www/.demo/lib/python2.7/site-packages/flask/app.py", line 1370, in handle_user_exception
    return self.handle_http_exception(e)
  File "/home/www/.demo/lib/python2.7/site-packages/flask/app.py", line 1330, in handle_http_exception
    return handler(e)
  File "/home/www/aud2/app/__init__.py", line 150, in page_404
    return render_template('errors/404.html'), 404
  File "/home/www/.demo/lib/python2.7/site-packages/flask/templating.py", line 128, in render_template
    context, ctx.app)
  File "/home/www/.demo/lib/python2.7/site-packages/flask/templating.py", line 110, in _render
    rv = template.render(context)
  File "/home/www/.demo/lib/python2.7/site-packages/jinja2/environment.py", line 969, in render
    return self.environment.handle_exception(exc_info, True)
  File "/home/www/.demo/lib/python2.7/site-packages/jinja2/environment.py", line 742, in handle_exception
    reraise(exc_type, exc_value, tb)
  File "/home/www/aud2/app/templates/errors/404.html", line 2, in top-level template code
    {% extends "base.html" %}
  File "/home/www/aud2/app/templates/base.html", line 26, in top-level template code
    {% include 'nav.html' %}
  File "/home/www/aud2/app/templates/nav.html", line 221, in top-level template code
    {% if g.user.is_admin() %}
UndefinedError: 'werkzeug.local.LocalProxy object' has no attribute 'is_admin'
2016-08-24 17:00:37,974 ERROR: Exception on /favicon.ico [GET] [in /home/www/.demo/lib/python2.7/site-packages/flask/app.py:1423]
Traceback (most recent call last):
  File "/home/www/.demo/lib/python2.7/site-packages/flask/app.py", line 1817, in wsgi_app
    response = self.full_dispatch_request()
  File "/home/www/.demo/lib/python2.7/site-packages/flask/app.py", line 1477, in full_dispatch_request
    rv = self.handle_user_exception(e)
  File "/home/www/.demo/lib/python2.7/site-packages/flask/app.py", line 1370, in handle_user_exception
    return self.handle_http_exception(e)
  File "/home/www/.demo/lib/python2.7/site-packages/flask/app.py", line 1330, in handle_http_exception
    return handler(e)
  File "/home/www/aud2/app/__init__.py", line 150, in page_404
    return render_template('errors/404.html'), 404
  File "/home/www/.demo/lib/python2.7/site-packages/flask/templating.py", line 128, in render_template
    context, ctx.app)
  File "/home/www/.demo/lib/python2.7/site-packages/flask/templating.py", line 110, in _render
    rv = template.render(context)
  File "/home/www/.demo/lib/python2.7/site-packages/jinja2/environment.py", line 969, in render
    return self.environment.handle_exception(exc_info, True)
  File "/home/www/.demo/lib/python2.7/site-packages/jinja2/environment.py", line 742, in handle_exception
    reraise(exc_type, exc_value, tb)
  File "/home/www/aud2/app/templates/errors/404.html", line 2, in top-level template code
    {% extends "base.html" %}
  File "/home/www/aud2/app/templates/base.html", line 26, in top-level template code
    {% include 'nav.html' %}
  File "/home/www/aud2/app/templates/nav.html", line 221, in top-level template code
    {% if g.user.is_admin() %}
UndefinedError: 'werkzeug.local.LocalProxy object' has no attribute 'is_admin'
2016-08-24 17:00:37,985 ERROR: Exception on /favicon.ico [GET] [in /home/www/.demo/lib/python2.7/site-packages/flask/app.py:1423]
Traceback (most recent call last):
  File "/home/www/.demo/lib/python2.7/site-packages/flask/app.py", line 1817, in wsgi_app
    response = self.full_dispatch_request()
  File "/home/www/.demo/lib/python2.7/site-packages/flask/app.py", line 1477, in full_dispatch_request
    rv = self.handle_user_exception(e)
  File "/home/www/.demo/lib/python2.7/site-packages/flask/app.py", line 1370, in handle_user_exception
    return self.handle_http_exception(e)
  File "/home/www/.demo/lib/python2.7/site-packages/flask/app.py", line 1330, in handle_http_exception
    return handler(e)
  File "/home/www/aud2/app/__init__.py", line 150, in page_404
    return render_template('errors/404.html'), 404
  File "/home/www/.demo/lib/python2.7/site-packages/flask/templating.py", line 128, in render_template
    context, ctx.app)
  File "/home/www/.demo/lib/python2.7/site-packages/flask/templating.py", line 110, in _render
    rv = template.render(context)
  File "/home/www/.demo/lib/python2.7/site-packages/jinja2/environment.py", line 969, in render
    return self.environment.handle_exception(exc_info, True)
  File "/home/www/.demo/lib/python2.7/site-packages/jinja2/environment.py", line 742, in handle_exception
    reraise(exc_type, exc_value, tb)
  File "/home/www/aud2/app/templates/errors/404.html", line 2, in top-level template code
    {% extends "base.html" %}
  File "/home/www/aud2/app/templates/base.html", line 26, in top-level template code
    {% include 'nav.html' %}
  File "/home/www/aud2/app/templates/nav.html", line 221, in top-level template code
    {% if g.user.is_admin() %}
UndefinedError: 'werkzeug.local.LocalProxy object' has no attribute 'is_admin'
2016-08-24 17:07:09,205 ERROR: Exception on /favicon.ico [GET] [in /home/www/.demo/lib/python2.7/site-packages/flask/app.py:1423]
Traceback (most recent call last):
  File "/home/www/.demo/lib/python2.7/site-packages/flask/app.py", line 1817, in wsgi_app
    response = self.full_dispatch_request()
  File "/home/www/.demo/lib/python2.7/site-packages/flask/app.py", line 1477, in full_dispatch_request
    rv = self.handle_user_exception(e)
  File "/home/www/.demo/lib/python2.7/site-packages/flask/app.py", line 1370, in handle_user_exception
    return self.handle_http_exception(e)
  File "/home/www/.demo/lib/python2.7/site-packages/flask/app.py", line 1330, in handle_http_exception
    return handler(e)
  File "/home/www/aud2/app/__init__.py", line 150, in page_404
    return render_template('errors/404.html'), 404
  File "/home/www/.demo/lib/python2.7/site-packages/flask/templating.py", line 128, in render_template
    context, ctx.app)
  File "/home/www/.demo/lib/python2.7/site-packages/flask/templating.py", line 110, in _render
    rv = template.render(context)
  File "/home/www/.demo/lib/python2.7/site-packages/jinja2/environment.py", line 969, in render
    return self.environment.handle_exception(exc_info, True)
  File "/home/www/.demo/lib/python2.7/site-packages/jinja2/environment.py", line 742, in handle_exception
    reraise(exc_type, exc_value, tb)
  File "/home/www/aud2/app/templates/errors/404.html", line 2, in top-level template code
    {% extends "base.html" %}
  File "/home/www/aud2/app/templates/base.html", line 26, in top-level template code
    {% include 'nav.html' %}
  File "/home/www/aud2/app/templates/nav.html", line 221, in top-level template code
    {% if g.user.is_admin() %}
UndefinedError: 'werkzeug.local.LocalProxy object' has no attribute 'is_admin'
2016-08-24 17:07:09,254 ERROR: Exception on /favicon.ico [GET] [in /home/www/.demo/lib/python2.7/site-packages/flask/app.py:1423]
Traceback (most recent call last):
  File "/home/www/.demo/lib/python2.7/site-packages/flask/app.py", line 1817, in wsgi_app
    response = self.full_dispatch_request()
  File "/home/www/.demo/lib/python2.7/site-packages/flask/app.py", line 1477, in full_dispatch_request
    rv = self.handle_user_exception(e)
  File "/home/www/.demo/lib/python2.7/site-packages/flask/app.py", line 1370, in handle_user_exception
    return self.handle_http_exception(e)
  File "/home/www/.demo/lib/python2.7/site-packages/flask/app.py", line 1330, in handle_http_exception
    return handler(e)
  File "/home/www/aud2/app/__init__.py", line 150, in page_404
    return render_template('errors/404.html'), 404
  File "/home/www/.demo/lib/python2.7/site-packages/flask/templating.py", line 128, in render_template
    context, ctx.app)
  File "/home/www/.demo/lib/python2.7/site-packages/flask/templating.py", line 110, in _render
    rv = template.render(context)
  File "/home/www/.demo/lib/python2.7/site-packages/jinja2/environment.py", line 969, in render
    return self.environment.handle_exception(exc_info, True)
  File "/home/www/.demo/lib/python2.7/site-packages/jinja2/environment.py", line 742, in handle_exception
    reraise(exc_type, exc_value, tb)
  File "/home/www/aud2/app/templates/errors/404.html", line 2, in top-level template code
    {% extends "base.html" %}
  File "/home/www/aud2/app/templates/base.html", line 26, in top-level template code
    {% include 'nav.html' %}
  File "/home/www/aud2/app/templates/nav.html", line 221, in top-level template code
    {% if g.user.is_admin() %}
UndefinedError: 'werkzeug.local.LocalProxy object' has no attribute 'is_admin'
2016-08-24 17:09:18,809 ERROR: Exception on /favicon.ico [GET] [in /home/www/.demo/lib/python2.7/site-packages/flask/app.py:1423]
Traceback (most recent call last):
  File "/home/www/.demo/lib/python2.7/site-packages/flask/app.py", line 1817, in wsgi_app
    response = self.full_dispatch_request()
  File "/home/www/.demo/lib/python2.7/site-packages/flask/app.py", line 1477, in full_dispatch_request
    rv = self.handle_user_exception(e)
  File "/home/www/.demo/lib/python2.7/site-packages/flask/app.py", line 1370, in handle_user_exception
    return self.handle_http_exception(e)
  File "/home/www/.demo/lib/python2.7/site-packages/flask/app.py", line 1330, in handle_http_exception
    return handler(e)
  File "/home/www/aud2/app/__init__.py", line 150, in page_404
    return render_template('errors/404.html'), 404
  File "/home/www/.demo/lib/python2.7/site-packages/flask/templating.py", line 128, in render_template
    context, ctx.app)
  File "/home/www/.demo/lib/python2.7/site-packages/flask/templating.py", line 110, in _render
    rv = template.render(context)
  File "/home/www/.demo/lib/python2.7/site-packages/jinja2/environment.py", line 969, in render
    return self.environment.handle_exception(exc_info, True)
  File "/home/www/.demo/lib/python2.7/site-packages/jinja2/environment.py", line 742, in handle_exception
    reraise(exc_type, exc_value, tb)
  File "/home/www/aud2/app/templates/errors/404.html", line 2, in top-level template code
    {% extends "base.html" %}
  File "/home/www/aud2/app/templates/base.html", line 26, in top-level template code
    {% include 'nav.html' %}
  File "/home/www/aud2/app/templates/nav.html", line 221, in top-level template code
    {% if g.user.is_admin() %}
UndefinedError: 'werkzeug.local.LocalProxy object' has no attribute 'is_admin'
2016-08-24 17:10:05,653 ERROR: Exception on /api/v1.0/node_task/modify_status/c10c8db5312b465ce217e0f14b68372d [POST] [in /home/www/.demo/lib/python2.7/site-packages/flask/app.py:1423]
Traceback (most recent call last):
  File "/home/www/.demo/lib/python2.7/site-packages/flask/app.py", line 1817, in wsgi_app
    response = self.full_dispatch_request()
  File "/home/www/.demo/lib/python2.7/site-packages/flask/app.py", line 1477, in full_dispatch_request
    rv = self.handle_user_exception(e)
  File "/home/www/.demo/lib/python2.7/site-packages/flask/app.py", line 1381, in handle_user_exception
    reraise(exc_type, exc_value, tb)
  File "/home/www/.demo/lib/python2.7/site-packages/flask/app.py", line 1475, in full_dispatch_request
    rv = self.dispatch_request()
  File "/home/www/.demo/lib/python2.7/site-packages/flask/app.py", line 1461, in dispatch_request
    return self.view_functions[rule.endpoint](**req.view_args)
  File "/home/www/aud2/app/views/site.py", line 875, in modify_node_task_status
    mes.sendEmail()
  File "/home/www/aud2/app/utils/message.py", line 45, in sendEmail
    thr = Thread(target=send_async_email, args=[receiver + '@aicai.com', subject, html])
TypeError: unsupported operand type(s) for +: 'NoneType' and 'str'
2016-08-24 17:33:24,622 ERROR: Exception on /favicon.ico [GET] [in /home/www/.demo/lib/python2.7/site-packages/flask/app.py:1423]
Traceback (most recent call last):
  File "/home/www/.demo/lib/python2.7/site-packages/flask/app.py", line 1817, in wsgi_app
    response = self.full_dispatch_request()
  File "/home/www/.demo/lib/python2.7/site-packages/flask/app.py", line 1477, in full_dispatch_request
    rv = self.handle_user_exception(e)
  File "/home/www/.demo/lib/python2.7/site-packages/flask/app.py", line 1370, in handle_user_exception
    return self.handle_http_exception(e)
  File "/home/www/.demo/lib/python2.7/site-packages/flask/app.py", line 1330, in handle_http_exception
    return handler(e)
  File "/home/www/aud2/app/__init__.py", line 150, in page_404
    return render_template('errors/404.html'), 404
  File "/home/www/.demo/lib/python2.7/site-packages/flask/templating.py", line 128, in render_template
    context, ctx.app)
  File "/home/www/.demo/lib/python2.7/site-packages/flask/templating.py", line 110, in _render
    rv = template.render(context)
  File "/home/www/.demo/lib/python2.7/site-packages/jinja2/environment.py", line 969, in render
    return self.environment.handle_exception(exc_info, True)
  File "/home/www/.demo/lib/python2.7/site-packages/jinja2/environment.py", line 742, in handle_exception
    reraise(exc_type, exc_value, tb)
  File "/home/www/aud2/app/templates/errors/404.html", line 2, in top-level template code
    {% extends "base.html" %}
  File "/home/www/aud2/app/templates/base.html", line 26, in top-level template code
    {% include 'nav.html' %}
  File "/home/www/aud2/app/templates/nav.html", line 221, in top-level template code
    {% if g.user.is_admin() %}
UndefinedError: 'werkzeug.local.LocalProxy object' has no attribute 'is_admin'
2016-08-24 17:33:24,642 ERROR: Exception on /favicon.ico [GET] [in /home/www/.demo/lib/python2.7/site-packages/flask/app.py:1423]
Traceback (most recent call last):
  File "/home/www/.demo/lib/python2.7/site-packages/flask/app.py", line 1817, in wsgi_app
    response = self.full_dispatch_request()
  File "/home/www/.demo/lib/python2.7/site-packages/flask/app.py", line 1477, in full_dispatch_request
    rv = self.handle_user_exception(e)
  File "/home/www/.demo/lib/python2.7/site-packages/flask/app.py", line 1370, in handle_user_exception
    return self.handle_http_exception(e)
  File "/home/www/.demo/lib/python2.7/site-packages/flask/app.py", line 1330, in handle_http_exception
    return handler(e)
  File "/home/www/aud2/app/__init__.py", line 150, in page_404
    return render_template('errors/404.html'), 404
  File "/home/www/.demo/lib/python2.7/site-packages/flask/templating.py", line 128, in render_template
    context, ctx.app)
  File "/home/www/.demo/lib/python2.7/site-packages/flask/templating.py", line 110, in _render
    rv = template.render(context)
  File "/home/www/.demo/lib/python2.7/site-packages/jinja2/environment.py", line 969, in render
    return self.environment.handle_exception(exc_info, True)
  File "/home/www/.demo/lib/python2.7/site-packages/jinja2/environment.py", line 742, in handle_exception
    reraise(exc_type, exc_value, tb)
  File "/home/www/aud2/app/templates/errors/404.html", line 2, in top-level template code
    {% extends "base.html" %}
  File "/home/www/aud2/app/templates/base.html", line 26, in top-level template code
    {% include 'nav.html' %}
  File "/home/www/aud2/app/templates/nav.html", line 221, in top-level template code
    {% if g.user.is_admin() %}
UndefinedError: 'werkzeug.local.LocalProxy object' has no attribute 'is_admin'
2016-08-24 17:33:48,548 ERROR: Exception on /api/v1.0/node_task/modify_status/5d8f2a28240896ec851429ca01cea3e4 [POST] [in /home/www/.demo/lib/python2.7/site-packages/flask/app.py:1423]
Traceback (most recent call last):
  File "/home/www/.demo/lib/python2.7/site-packages/flask/app.py", line 1817, in wsgi_app
    response = self.full_dispatch_request()
  File "/home/www/.demo/lib/python2.7/site-packages/flask/app.py", line 1477, in full_dispatch_request
    rv = self.handle_user_exception(e)
  File "/home/www/.demo/lib/python2.7/site-packages/flask/app.py", line 1381, in handle_user_exception
    reraise(exc_type, exc_value, tb)
  File "/home/www/.demo/lib/python2.7/site-packages/flask/app.py", line 1475, in full_dispatch_request
    rv = self.dispatch_request()
  File "/home/www/.demo/lib/python2.7/site-packages/flask/app.py", line 1461, in dispatch_request
    return self.view_functions[rule.endpoint](**req.view_args)
  File "/home/www/aud2/app/views/site.py", line 875, in modify_node_task_status
    mes.sendEmail()
  File "/home/www/aud2/app/utils/message.py", line 45, in sendEmail
    thr = Thread(target=send_async_email, args=[receiver + '@aicai.com', subject, html])
TypeError: unsupported operand type(s) for +: 'NoneType' and 'str'
2016-08-24 17:48:35,476 ERROR: Exception on /api/v1.0/node_task/modify_status/02035c17650d9c24ac4adc1701a256f4 [POST] [in /home/www/.demo/lib/python2.7/site-packages/flask/app.py:1423]
Traceback (most recent call last):
  File "/home/www/.demo/lib/python2.7/site-packages/flask/app.py", line 1817, in wsgi_app
    response = self.full_dispatch_request()
  File "/home/www/.demo/lib/python2.7/site-packages/flask/app.py", line 1477, in full_dispatch_request
    rv = self.handle_user_exception(e)
  File "/home/www/.demo/lib/python2.7/site-packages/flask/app.py", line 1381, in handle_user_exception
    reraise(exc_type, exc_value, tb)
  File "/home/www/.demo/lib/python2.7/site-packages/flask/app.py", line 1475, in full_dispatch_request
    rv = self.dispatch_request()
  File "/home/www/.demo/lib/python2.7/site-packages/flask/app.py", line 1461, in dispatch_request
    return self.view_functions[rule.endpoint](**req.view_args)
  File "/home/www/aud2/app/views/site.py", line 875, in modify_node_task_status
    mes.sendEmail()
  File "/home/www/aud2/app/utils/message.py", line 45, in sendEmail
    thr = Thread(target=send_async_email, args=[receiver + '@aicai.com', subject, html])
TypeError: unsupported operand type(s) for +: 'NoneType' and 'str'
2016-08-24 19:23:10,107 ERROR: Exception on /favicon.ico [GET] [in /home/www/.demo/lib/python2.7/site-packages/flask/app.py:1423]
Traceback (most recent call last):
  File "/home/www/.demo/lib/python2.7/site-packages/flask/app.py", line 1817, in wsgi_app
    response = self.full_dispatch_request()
  File "/home/www/.demo/lib/python2.7/site-packages/flask/app.py", line 1477, in full_dispatch_request
    rv = self.handle_user_exception(e)
  File "/home/www/.demo/lib/python2.7/site-packages/flask/app.py", line 1370, in handle_user_exception
    return self.handle_http_exception(e)
  File "/home/www/.demo/lib/python2.7/site-packages/flask/app.py", line 1330, in handle_http_exception
    return handler(e)
  File "/home/www/aud2/app/__init__.py", line 150, in page_404
    return render_template('errors/404.html'), 404
  File "/home/www/.demo/lib/python2.7/site-packages/flask/templating.py", line 128, in render_template
    context, ctx.app)
  File "/home/www/.demo/lib/python2.7/site-packages/flask/templating.py", line 110, in _render
    rv = template.render(context)
  File "/home/www/.demo/lib/python2.7/site-packages/jinja2/environment.py", line 969, in render
    return self.environment.handle_exception(exc_info, True)
  File "/home/www/.demo/lib/python2.7/site-packages/jinja2/environment.py", line 742, in handle_exception
    reraise(exc_type, exc_value, tb)
  File "/home/www/aud2/app/templates/errors/404.html", line 2, in top-level template code
    {% extends "base.html" %}
  File "/home/www/aud2/app/templates/base.html", line 26, in top-level template code
    {% include 'nav.html' %}
  File "/home/www/aud2/app/templates/nav.html", line 221, in top-level template code
    {% if g.user.is_admin() %}
UndefinedError: 'werkzeug.local.LocalProxy object' has no attribute 'is_admin'
2016-08-24 19:23:24,374 ERROR: Exception on /favicon.ico [GET] [in /home/www/.demo/lib/python2.7/site-packages/flask/app.py:1423]
Traceback (most recent call last):
  File "/home/www/.demo/lib/python2.7/site-packages/flask/app.py", line 1817, in wsgi_app
    response = self.full_dispatch_request()
  File "/home/www/.demo/lib/python2.7/site-packages/flask/app.py", line 1477, in full_dispatch_request
    rv = self.handle_user_exception(e)
  File "/home/www/.demo/lib/python2.7/site-packages/flask/app.py", line 1370, in handle_user_exception
    return self.handle_http_exception(e)
  File "/home/www/.demo/lib/python2.7/site-packages/flask/app.py", line 1330, in handle_http_exception
    return handler(e)
  File "/home/www/aud2/app/__init__.py", line 150, in page_404
    return render_template('errors/404.html'), 404
  File "/home/www/.demo/lib/python2.7/site-packages/flask/templating.py", line 128, in render_template
    context, ctx.app)
  File "/home/www/.demo/lib/python2.7/site-packages/flask/templating.py", line 110, in _render
    rv = template.render(context)
  File "/home/www/.demo/lib/python2.7/site-packages/jinja2/environment.py", line 969, in render
    return self.environment.handle_exception(exc_info, True)
  File "/home/www/.demo/lib/python2.7/site-packages/jinja2/environment.py", line 742, in handle_exception
    reraise(exc_type, exc_value, tb)
  File "/home/www/aud2/app/templates/errors/404.html", line 2, in top-level template code
    {% extends "base.html" %}
  File "/home/www/aud2/app/templates/base.html", line 26, in top-level template code
    {% include 'nav.html' %}
  File "/home/www/aud2/app/templates/nav.html", line 221, in top-level template code
    {% if g.user.is_admin() %}
UndefinedError: 'werkzeug.local.LocalProxy object' has no attribute 'is_admin'
2016-08-24 19:25:12,562 ERROR: Exception on /api/v1.0/node_task/modify_status/83c40010ebe2c08a8dfdea27d51fb700 [POST] [in /home/www/.demo/lib/python2.7/site-packages/flask/app.py:1423]
Traceback (most recent call last):
  File "/home/www/.demo/lib/python2.7/site-packages/flask/app.py", line 1817, in wsgi_app
    response = self.full_dispatch_request()
  File "/home/www/.demo/lib/python2.7/site-packages/flask/app.py", line 1477, in full_dispatch_request
    rv = self.handle_user_exception(e)
  File "/home/www/.demo/lib/python2.7/site-packages/flask/app.py", line 1381, in handle_user_exception
    reraise(exc_type, exc_value, tb)
  File "/home/www/.demo/lib/python2.7/site-packages/flask/app.py", line 1475, in full_dispatch_request
    rv = self.dispatch_request()
  File "/home/www/.demo/lib/python2.7/site-packages/flask/app.py", line 1461, in dispatch_request
    return self.view_functions[rule.endpoint](**req.view_args)
  File "/home/www/aud2/app/views/site.py", line 875, in modify_node_task_status
    mes.sendEmail()
  File "/home/www/aud2/app/utils/message.py", line 45, in sendEmail
    thr = Thread(target=send_async_email, args=[receiver + '@aicai.com', subject, html])
TypeError: unsupported operand type(s) for +: 'NoneType' and 'str'
2016-08-24 19:25:17,347 ERROR: Exception on /api/v1.0/node_task/modify_status/ab4fda84e552940d5640a4eeabd6b9f0 [POST] [in /home/www/.demo/lib/python2.7/site-packages/flask/app.py:1423]
Traceback (most recent call last):
  File "/home/www/.demo/lib/python2.7/site-packages/flask/app.py", line 1817, in wsgi_app
    response = self.full_dispatch_request()
  File "/home/www/.demo/lib/python2.7/site-packages/flask/app.py", line 1477, in full_dispatch_request
    rv = self.handle_user_exception(e)
  File "/home/www/.demo/lib/python2.7/site-packages/flask/app.py", line 1381, in handle_user_exception
    reraise(exc_type, exc_value, tb)
  File "/home/www/.demo/lib/python2.7/site-packages/flask/app.py", line 1475, in full_dispatch_request
    rv = self.dispatch_request()
  File "/home/www/.demo/lib/python2.7/site-packages/flask/app.py", line 1461, in dispatch_request
    return self.view_functions[rule.endpoint](**req.view_args)
  File "/home/www/aud2/app/views/site.py", line 875, in modify_node_task_status
    mes.sendEmail()
  File "/home/www/aud2/app/utils/message.py", line 45, in sendEmail
    thr = Thread(target=send_async_email, args=[receiver + '@aicai.com', subject, html])
TypeError: unsupported operand type(s) for +: 'NoneType' and 'str'
2016-08-24 19:25:19,278 ERROR: Exception on /api/v1.0/node_task/modify_status/9d68ff6cc68b215305e7ebb66381952d [POST] [in /home/www/.demo/lib/python2.7/site-packages/flask/app.py:1423]
Traceback (most recent call last):
  File "/home/www/.demo/lib/python2.7/site-packages/flask/app.py", line 1817, in wsgi_app
    response = self.full_dispatch_request()
  File "/home/www/.demo/lib/python2.7/site-packages/flask/app.py", line 1477, in full_dispatch_request
    rv = self.handle_user_exception(e)
  File "/home/www/.demo/lib/python2.7/site-packages/flask/app.py", line 1381, in handle_user_exception
    reraise(exc_type, exc_value, tb)
  File "/home/www/.demo/lib/python2.7/site-packages/flask/app.py", line 1475, in full_dispatch_request
    rv = self.dispatch_request()
  File "/home/www/.demo/lib/python2.7/site-packages/flask/app.py", line 1461, in dispatch_request
    return self.view_functions[rule.endpoint](**req.view_args)
  File "/home/www/aud2/app/views/site.py", line 875, in modify_node_task_status
    mes.sendEmail()
  File "/home/www/aud2/app/utils/message.py", line 45, in sendEmail
    thr = Thread(target=send_async_email, args=[receiver + '@aicai.com', subject, html])
TypeError: unsupported operand type(s) for +: 'NoneType' and 'str'
2016-08-24 19:25:38,966 ERROR: Exception on /api/v1.0/node_task/modify_status/99013a4775b32c0e6bb54abc6d58c13d [POST] [in /home/www/.demo/lib/python2.7/site-packages/flask/app.py:1423]
Traceback (most recent call last):
  File "/home/www/.demo/lib/python2.7/site-packages/flask/app.py", line 1817, in wsgi_app
    response = self.full_dispatch_request()
  File "/home/www/.demo/lib/python2.7/site-packages/flask/app.py", line 1477, in full_dispatch_request
    rv = self.handle_user_exception(e)
  File "/home/www/.demo/lib/python2.7/site-packages/flask/app.py", line 1381, in handle_user_exception
    reraise(exc_type, exc_value, tb)
  File "/home/www/.demo/lib/python2.7/site-packages/flask/app.py", line 1475, in full_dispatch_request
    rv = self.dispatch_request()
  File "/home/www/.demo/lib/python2.7/site-packages/flask/app.py", line 1461, in dispatch_request
    return self.view_functions[rule.endpoint](**req.view_args)
  File "/home/www/aud2/app/views/site.py", line 875, in modify_node_task_status
    mes.sendEmail()
  File "/home/www/aud2/app/utils/message.py", line 45, in sendEmail
    thr = Thread(target=send_async_email, args=[receiver + '@aicai.com', subject, html])
TypeError: unsupported operand type(s) for +: 'NoneType' and 'str'
2016-08-24 19:25:56,450 ERROR: Exception on /api/v1.0/node_task/modify_status/cb6244009ee1ecd2a6a19cc2c2b4fa04 [POST] [in /home/www/.demo/lib/python2.7/site-packages/flask/app.py:1423]
Traceback (most recent call last):
  File "/home/www/.demo/lib/python2.7/site-packages/flask/app.py", line 1817, in wsgi_app
    response = self.full_dispatch_request()
  File "/home/www/.demo/lib/python2.7/site-packages/flask/app.py", line 1477, in full_dispatch_request
    rv = self.handle_user_exception(e)
  File "/home/www/.demo/lib/python2.7/site-packages/flask/app.py", line 1381, in handle_user_exception
    reraise(exc_type, exc_value, tb)
  File "/home/www/.demo/lib/python2.7/site-packages/flask/app.py", line 1475, in full_dispatch_request
    rv = self.dispatch_request()
  File "/home/www/.demo/lib/python2.7/site-packages/flask/app.py", line 1461, in dispatch_request
    return self.view_functions[rule.endpoint](**req.view_args)
  File "/home/www/aud2/app/views/site.py", line 875, in modify_node_task_status
    mes.sendEmail()
  File "/home/www/aud2/app/utils/message.py", line 45, in sendEmail
    thr = Thread(target=send_async_email, args=[receiver + '@aicai.com', subject, html])
TypeError: unsupported operand type(s) for +: 'NoneType' and 'str'
2016-08-25 09:40:43,324 ERROR: Exception on /favicon.ico [GET] [in /home/www/.demo/lib/python2.7/site-packages/flask/app.py:1423]
Traceback (most recent call last):
  File "/home/www/.demo/lib/python2.7/site-packages/flask/app.py", line 1817, in wsgi_app
    response = self.full_dispatch_request()
  File "/home/www/.demo/lib/python2.7/site-packages/flask/app.py", line 1477, in full_dispatch_request
    rv = self.handle_user_exception(e)
  File "/home/www/.demo/lib/python2.7/site-packages/flask/app.py", line 1370, in handle_user_exception
    return self.handle_http_exception(e)
  File "/home/www/.demo/lib/python2.7/site-packages/flask/app.py", line 1330, in handle_http_exception
    return handler(e)
  File "/home/www/aud2/app/__init__.py", line 150, in page_404
    return render_template('errors/404.html'), 404
  File "/home/www/.demo/lib/python2.7/site-packages/flask/templating.py", line 128, in render_template
    context, ctx.app)
  File "/home/www/.demo/lib/python2.7/site-packages/flask/templating.py", line 110, in _render
    rv = template.render(context)
  File "/home/www/.demo/lib/python2.7/site-packages/jinja2/environment.py", line 969, in render
    return self.environment.handle_exception(exc_info, True)
  File "/home/www/.demo/lib/python2.7/site-packages/jinja2/environment.py", line 742, in handle_exception
    reraise(exc_type, exc_value, tb)
  File "/home/www/aud2/app/templates/errors/404.html", line 2, in top-level template code
    {% extends "base.html" %}
  File "/home/www/aud2/app/templates/base.html", line 26, in top-level template code
    {% include 'nav.html' %}
  File "/home/www/aud2/app/templates/nav.html", line 221, in top-level template code
    {% if g.user.is_admin() %}
UndefinedError: 'werkzeug.local.LocalProxy object' has no attribute 'is_admin'
2016-08-25 09:40:43,339 ERROR: Exception on /favicon.ico [GET] [in /home/www/.demo/lib/python2.7/site-packages/flask/app.py:1423]
Traceback (most recent call last):
  File "/home/www/.demo/lib/python2.7/site-packages/flask/app.py", line 1817, in wsgi_app
    response = self.full_dispatch_request()
  File "/home/www/.demo/lib/python2.7/site-packages/flask/app.py", line 1477, in full_dispatch_request
    rv = self.handle_user_exception(e)
  File "/home/www/.demo/lib/python2.7/site-packages/flask/app.py", line 1370, in handle_user_exception
    return self.handle_http_exception(e)
  File "/home/www/.demo/lib/python2.7/site-packages/flask/app.py", line 1330, in handle_http_exception
    return handler(e)
  File "/home/www/aud2/app/__init__.py", line 150, in page_404
    return render_template('errors/404.html'), 404
  File "/home/www/.demo/lib/python2.7/site-packages/flask/templating.py", line 128, in render_template
    context, ctx.app)
  File "/home/www/.demo/lib/python2.7/site-packages/flask/templating.py", line 110, in _render
    rv = template.render(context)
  File "/home/www/.demo/lib/python2.7/site-packages/jinja2/environment.py", line 969, in render
    return self.environment.handle_exception(exc_info, True)
  File "/home/www/.demo/lib/python2.7/site-packages/jinja2/environment.py", line 742, in handle_exception
    reraise(exc_type, exc_value, tb)
  File "/home/www/aud2/app/templates/errors/404.html", line 2, in top-level template code
    {% extends "base.html" %}
  File "/home/www/aud2/app/templates/base.html", line 26, in top-level template code
    {% include 'nav.html' %}
  File "/home/www/aud2/app/templates/nav.html", line 221, in top-level template code
    {% if g.user.is_admin() %}
UndefinedError: 'werkzeug.local.LocalProxy object' has no attribute 'is_admin'
2016-08-25 14:23:07,443 ERROR: Exception on /favicon.ico [GET] [in /home/www/.demo/lib/python2.7/site-packages/flask/app.py:1423]
Traceback (most recent call last):
  File "/home/www/.demo/lib/python2.7/site-packages/flask/app.py", line 1817, in wsgi_app
    response = self.full_dispatch_request()
  File "/home/www/.demo/lib/python2.7/site-packages/flask/app.py", line 1477, in full_dispatch_request
    rv = self.handle_user_exception(e)
  File "/home/www/.demo/lib/python2.7/site-packages/flask/app.py", line 1370, in handle_user_exception
    return self.handle_http_exception(e)
  File "/home/www/.demo/lib/python2.7/site-packages/flask/app.py", line 1330, in handle_http_exception
    return handler(e)
  File "/home/www/aud2/app/__init__.py", line 150, in page_404
    return render_template('errors/404.html'), 404
  File "/home/www/.demo/lib/python2.7/site-packages/flask/templating.py", line 128, in render_template
    context, ctx.app)
  File "/home/www/.demo/lib/python2.7/site-packages/flask/templating.py", line 110, in _render
    rv = template.render(context)
  File "/home/www/.demo/lib/python2.7/site-packages/jinja2/environment.py", line 969, in render
    return self.environment.handle_exception(exc_info, True)
  File "/home/www/.demo/lib/python2.7/site-packages/jinja2/environment.py", line 742, in handle_exception
    reraise(exc_type, exc_value, tb)
  File "/home/www/aud2/app/templates/errors/404.html", line 2, in top-level template code
    {% extends "base.html" %}
  File "/home/www/aud2/app/templates/base.html", line 26, in top-level template code
    {% include 'nav.html' %}
  File "/home/www/aud2/app/templates/nav.html", line 221, in top-level template code
    {% if g.user.is_admin() %}
UndefinedError: 'werkzeug.local.LocalProxy object' has no attribute 'is_admin'
2016-08-25 15:18:42,541 ERROR: Exception on /favicon.ico [GET] [in /home/www/.demo/lib/python2.7/site-packages/flask/app.py:1423]
Traceback (most recent call last):
  File "/home/www/.demo/lib/python2.7/site-packages/flask/app.py", line 1817, in wsgi_app
    response = self.full_dispatch_request()
  File "/home/www/.demo/lib/python2.7/site-packages/flask/app.py", line 1477, in full_dispatch_request
    rv = self.handle_user_exception(e)
  File "/home/www/.demo/lib/python2.7/site-packages/flask/app.py", line 1370, in handle_user_exception
    return self.handle_http_exception(e)
  File "/home/www/.demo/lib/python2.7/site-packages/flask/app.py", line 1330, in handle_http_exception
    return handler(e)
  File "/home/www/aud2/app/__init__.py", line 150, in page_404
    return render_template('errors/404.html'), 404
  File "/home/www/.demo/lib/python2.7/site-packages/flask/templating.py", line 128, in render_template
    context, ctx.app)
  File "/home/www/.demo/lib/python2.7/site-packages/flask/templating.py", line 110, in _render
    rv = template.render(context)
  File "/home/www/.demo/lib/python2.7/site-packages/jinja2/environment.py", line 969, in render
    return self.environment.handle_exception(exc_info, True)
  File "/home/www/.demo/lib/python2.7/site-packages/jinja2/environment.py", line 742, in handle_exception
    reraise(exc_type, exc_value, tb)
  File "/home/www/aud2/app/templates/errors/404.html", line 2, in top-level template code
    {% extends "base.html" %}
  File "/home/www/aud2/app/templates/base.html", line 26, in top-level template code
    {% include 'nav.html' %}
  File "/home/www/aud2/app/templates/nav.html", line 221, in top-level template code
    {% if g.user.is_admin() %}
UndefinedError: 'werkzeug.local.LocalProxy object' has no attribute 'is_admin'
2016-08-25 17:21:02,281 ERROR: Exception on /api/v1.0/node_task/modify_status/107a5afb296a7ecc2c1c30815f1eec26 [POST] [in /home/www/.demo/lib/python2.7/site-packages/flask/app.py:1423]
Traceback (most recent call last):
  File "/home/www/.demo/lib/python2.7/site-packages/flask/app.py", line 1817, in wsgi_app
    response = self.full_dispatch_request()
  File "/home/www/.demo/lib/python2.7/site-packages/flask/app.py", line 1477, in full_dispatch_request
    rv = self.handle_user_exception(e)
  File "/home/www/.demo/lib/python2.7/site-packages/flask/app.py", line 1381, in handle_user_exception
    reraise(exc_type, exc_value, tb)
  File "/home/www/.demo/lib/python2.7/site-packages/flask/app.py", line 1475, in full_dispatch_request
    rv = self.dispatch_request()
  File "/home/www/.demo/lib/python2.7/site-packages/flask/app.py", line 1461, in dispatch_request
    return self.view_functions[rule.endpoint](**req.view_args)
  File "/home/www/aud2/app/views/site.py", line 875, in modify_node_task_status
    mes.sendEmail()
  File "/home/www/aud2/app/utils/message.py", line 45, in sendEmail
    thr = Thread(target=send_async_email, args=[receiver + '@aicai.com', subject, html])
TypeError: unsupported operand type(s) for +: 'NoneType' and 'str'
2016-08-25 17:22:00,594 ERROR: Exception on /api/v1.0/node_task/modify_status/aa6bae4eeb66ffe90e5e10600dcdb0ac [POST] [in /home/www/.demo/lib/python2.7/site-packages/flask/app.py:1423]
Traceback (most recent call last):
  File "/home/www/.demo/lib/python2.7/site-packages/flask/app.py", line 1817, in wsgi_app
    response = self.full_dispatch_request()
  File "/home/www/.demo/lib/python2.7/site-packages/flask/app.py", line 1477, in full_dispatch_request
    rv = self.handle_user_exception(e)
  File "/home/www/.demo/lib/python2.7/site-packages/flask/app.py", line 1381, in handle_user_exception
    reraise(exc_type, exc_value, tb)
  File "/home/www/.demo/lib/python2.7/site-packages/flask/app.py", line 1475, in full_dispatch_request
    rv = self.dispatch_request()
  File "/home/www/.demo/lib/python2.7/site-packages/flask/app.py", line 1461, in dispatch_request
    return self.view_functions[rule.endpoint](**req.view_args)
  File "/home/www/aud2/app/views/site.py", line 875, in modify_node_task_status
    mes.sendEmail()
  File "/home/www/aud2/app/utils/message.py", line 45, in sendEmail
    thr = Thread(target=send_async_email, args=[receiver + '@aicai.com', subject, html])
TypeError: unsupported operand type(s) for +: 'NoneType' and 'str'
2016-08-25 17:22:40,648 ERROR: Exception on /api/v1.0/node_task/modify_status/ab1769c20f2ca25f438c878d3d3842b2 [POST] [in /home/www/.demo/lib/python2.7/site-packages/flask/app.py:1423]
Traceback (most recent call last):
  File "/home/www/.demo/lib/python2.7/site-packages/flask/app.py", line 1817, in wsgi_app
    response = self.full_dispatch_request()
  File "/home/www/.demo/lib/python2.7/site-packages/flask/app.py", line 1477, in full_dispatch_request
    rv = self.handle_user_exception(e)
  File "/home/www/.demo/lib/python2.7/site-packages/flask/app.py", line 1381, in handle_user_exception
    reraise(exc_type, exc_value, tb)
  File "/home/www/.demo/lib/python2.7/site-packages/flask/app.py", line 1475, in full_dispatch_request
    rv = self.dispatch_request()
  File "/home/www/.demo/lib/python2.7/site-packages/flask/app.py", line 1461, in dispatch_request
    return self.view_functions[rule.endpoint](**req.view_args)
  File "/home/www/aud2/app/views/site.py", line 875, in modify_node_task_status
    mes.sendEmail()
  File "/home/www/aud2/app/utils/message.py", line 45, in sendEmail
    thr = Thread(target=send_async_email, args=[receiver + '@aicai.com', subject, html])
TypeError: unsupported operand type(s) for +: 'NoneType' and 'str'
2016-08-25 17:24:24,216 ERROR: Exception on /api/v1.0/node_task/modify_status/6803772d768eb191cccf67181eac51cb [POST] [in /home/www/.demo/lib/python2.7/site-packages/flask/app.py:1423]
Traceback (most recent call last):
  File "/home/www/.demo/lib/python2.7/site-packages/flask/app.py", line 1817, in wsgi_app
    response = self.full_dispatch_request()
  File "/home/www/.demo/lib/python2.7/site-packages/flask/app.py", line 1477, in full_dispatch_request
    rv = self.handle_user_exception(e)
  File "/home/www/.demo/lib/python2.7/site-packages/flask/app.py", line 1381, in handle_user_exception
    reraise(exc_type, exc_value, tb)
  File "/home/www/.demo/lib/python2.7/site-packages/flask/app.py", line 1475, in full_dispatch_request
    rv = self.dispatch_request()
  File "/home/www/.demo/lib/python2.7/site-packages/flask/app.py", line 1461, in dispatch_request
    return self.view_functions[rule.endpoint](**req.view_args)
  File "/home/www/aud2/app/views/site.py", line 875, in modify_node_task_status
    mes.sendEmail()
  File "/home/www/aud2/app/utils/message.py", line 45, in sendEmail
    thr = Thread(target=send_async_email, args=[receiver + '@aicai.com', subject, html])
TypeError: unsupported operand type(s) for +: 'NoneType' and 'str'
2016-08-26 07:05:21,091 ERROR: Exception on /favicon.ico [GET] [in /home/www/.demo/lib/python2.7/site-packages/flask/app.py:1423]
Traceback (most recent call last):
  File "/home/www/.demo/lib/python2.7/site-packages/flask/app.py", line 1817, in wsgi_app
    response = self.full_dispatch_request()
  File "/home/www/.demo/lib/python2.7/site-packages/flask/app.py", line 1477, in full_dispatch_request
    rv = self.handle_user_exception(e)
  File "/home/www/.demo/lib/python2.7/site-packages/flask/app.py", line 1370, in handle_user_exception
    return self.handle_http_exception(e)
  File "/home/www/.demo/lib/python2.7/site-packages/flask/app.py", line 1330, in handle_http_exception
    return handler(e)
  File "/home/www/aud2/app/__init__.py", line 150, in page_404
    return render_template('errors/404.html'), 404
  File "/home/www/.demo/lib/python2.7/site-packages/flask/templating.py", line 128, in render_template
    context, ctx.app)
  File "/home/www/.demo/lib/python2.7/site-packages/flask/templating.py", line 110, in _render
    rv = template.render(context)
  File "/home/www/.demo/lib/python2.7/site-packages/jinja2/environment.py", line 969, in render
    return self.environment.handle_exception(exc_info, True)
  File "/home/www/.demo/lib/python2.7/site-packages/jinja2/environment.py", line 742, in handle_exception
    reraise(exc_type, exc_value, tb)
  File "/home/www/aud2/app/templates/errors/404.html", line 2, in top-level template code
    {% extends "base.html" %}
  File "/home/www/aud2/app/templates/base.html", line 26, in top-level template code
    {% include 'nav.html' %}
  File "/home/www/aud2/app/templates/nav.html", line 221, in top-level template code
    {% if g.user.is_admin() %}
UndefinedError: 'werkzeug.local.LocalProxy object' has no attribute 'is_admin'
2016-08-26 07:05:22,867 ERROR: Exception on /favicon.ico [GET] [in /home/www/.demo/lib/python2.7/site-packages/flask/app.py:1423]
Traceback (most recent call last):
  File "/home/www/.demo/lib/python2.7/site-packages/flask/app.py", line 1817, in wsgi_app
    response = self.full_dispatch_request()
  File "/home/www/.demo/lib/python2.7/site-packages/flask/app.py", line 1477, in full_dispatch_request
    rv = self.handle_user_exception(e)
  File "/home/www/.demo/lib/python2.7/site-packages/flask/app.py", line 1370, in handle_user_exception
    return self.handle_http_exception(e)
  File "/home/www/.demo/lib/python2.7/site-packages/flask/app.py", line 1330, in handle_http_exception
    return handler(e)
  File "/home/www/aud2/app/__init__.py", line 150, in page_404
    return render_template('errors/404.html'), 404
  File "/home/www/.demo/lib/python2.7/site-packages/flask/templating.py", line 128, in render_template
    context, ctx.app)
  File "/home/www/.demo/lib/python2.7/site-packages/flask/templating.py", line 110, in _render
    rv = template.render(context)
  File "/home/www/.demo/lib/python2.7/site-packages/jinja2/environment.py", line 969, in render
    return self.environment.handle_exception(exc_info, True)
  File "/home/www/.demo/lib/python2.7/site-packages/jinja2/environment.py", line 742, in handle_exception
    reraise(exc_type, exc_value, tb)
  File "/home/www/aud2/app/templates/errors/404.html", line 2, in top-level template code
    {% extends "base.html" %}
  File "/home/www/aud2/app/templates/base.html", line 26, in top-level template code
    {% include 'nav.html' %}
  File "/home/www/aud2/app/templates/nav.html", line 221, in top-level template code
    {% if g.user.is_admin() %}
UndefinedError: 'werkzeug.local.LocalProxy object' has no attribute 'is_admin'
2016-08-26 07:05:30,437 ERROR: Exception on /favicon.ico [GET] [in /home/www/.demo/lib/python2.7/site-packages/flask/app.py:1423]
Traceback (most recent call last):
  File "/home/www/.demo/lib/python2.7/site-packages/flask/app.py", line 1817, in wsgi_app
    response = self.full_dispatch_request()
  File "/home/www/.demo/lib/python2.7/site-packages/flask/app.py", line 1477, in full_dispatch_request
    rv = self.handle_user_exception(e)
  File "/home/www/.demo/lib/python2.7/site-packages/flask/app.py", line 1370, in handle_user_exception
    return self.handle_http_exception(e)
  File "/home/www/.demo/lib/python2.7/site-packages/flask/app.py", line 1330, in handle_http_exception
    return handler(e)
  File "/home/www/aud2/app/__init__.py", line 150, in page_404
    return render_template('errors/404.html'), 404
  File "/home/www/.demo/lib/python2.7/site-packages/flask/templating.py", line 128, in render_template
    context, ctx.app)
  File "/home/www/.demo/lib/python2.7/site-packages/flask/templating.py", line 110, in _render
    rv = template.render(context)
  File "/home/www/.demo/lib/python2.7/site-packages/jinja2/environment.py", line 969, in render
    return self.environment.handle_exception(exc_info, True)
  File "/home/www/.demo/lib/python2.7/site-packages/jinja2/environment.py", line 742, in handle_exception
    reraise(exc_type, exc_value, tb)
  File "/home/www/aud2/app/templates/errors/404.html", line 2, in top-level template code
    {% extends "base.html" %}
  File "/home/www/aud2/app/templates/base.html", line 26, in top-level template code
    {% include 'nav.html' %}
  File "/home/www/aud2/app/templates/nav.html", line 221, in top-level template code
    {% if g.user.is_admin() %}
UndefinedError: 'werkzeug.local.LocalProxy object' has no attribute 'is_admin'
2016-08-26 07:12:06,543 ERROR: Exception on /api/v1.0/node_task/modify_status/65598c2f136c16546891d34517165792 [POST] [in /home/www/.demo/lib/python2.7/site-packages/flask/app.py:1423]
Traceback (most recent call last):
  File "/home/www/.demo/lib/python2.7/site-packages/flask/app.py", line 1817, in wsgi_app
    response = self.full_dispatch_request()
  File "/home/www/.demo/lib/python2.7/site-packages/flask/app.py", line 1477, in full_dispatch_request
    rv = self.handle_user_exception(e)
  File "/home/www/.demo/lib/python2.7/site-packages/flask/app.py", line 1381, in handle_user_exception
    reraise(exc_type, exc_value, tb)
  File "/home/www/.demo/lib/python2.7/site-packages/flask/app.py", line 1475, in full_dispatch_request
    rv = self.dispatch_request()
  File "/home/www/.demo/lib/python2.7/site-packages/flask/app.py", line 1461, in dispatch_request
    return self.view_functions[rule.endpoint](**req.view_args)
  File "/home/www/aud2/app/views/site.py", line 875, in modify_node_task_status
    mes.sendEmail()
  File "/home/www/aud2/app/utils/message.py", line 45, in sendEmail
    thr = Thread(target=send_async_email, args=[receiver + '@aicai.com', subject, html])
TypeError: unsupported operand type(s) for +: 'NoneType' and 'str'
2016-08-26 07:18:46,722 ERROR: Exception on /api/v1.0/node_task/modify_status/a90a57fcff27ad9ad207be1c85ec52f4 [POST] [in /home/www/.demo/lib/python2.7/site-packages/flask/app.py:1423]
Traceback (most recent call last):
  File "/home/www/.demo/lib/python2.7/site-packages/flask/app.py", line 1817, in wsgi_app
    response = self.full_dispatch_request()
  File "/home/www/.demo/lib/python2.7/site-packages/flask/app.py", line 1477, in full_dispatch_request
    rv = self.handle_user_exception(e)
  File "/home/www/.demo/lib/python2.7/site-packages/flask/app.py", line 1381, in handle_user_exception
    reraise(exc_type, exc_value, tb)
  File "/home/www/.demo/lib/python2.7/site-packages/flask/app.py", line 1475, in full_dispatch_request
    rv = self.dispatch_request()
  File "/home/www/.demo/lib/python2.7/site-packages/flask/app.py", line 1461, in dispatch_request
    return self.view_functions[rule.endpoint](**req.view_args)
  File "/home/www/aud2/app/views/site.py", line 875, in modify_node_task_status
    mes.sendEmail()
  File "/home/www/aud2/app/utils/message.py", line 45, in sendEmail
    thr = Thread(target=send_async_email, args=[receiver + '@aicai.com', subject, html])
TypeError: unsupported operand type(s) for +: 'NoneType' and 'str'
2016-08-26 09:05:32,138 ERROR: Exception on /favicon.ico [GET] [in /home/www/.demo/lib/python2.7/site-packages/flask/app.py:1423]
Traceback (most recent call last):
  File "/home/www/.demo/lib/python2.7/site-packages/flask/app.py", line 1817, in wsgi_app
    response = self.full_dispatch_request()
  File "/home/www/.demo/lib/python2.7/site-packages/flask/app.py", line 1477, in full_dispatch_request
    rv = self.handle_user_exception(e)
  File "/home/www/.demo/lib/python2.7/site-packages/flask/app.py", line 1370, in handle_user_exception
    return self.handle_http_exception(e)
  File "/home/www/.demo/lib/python2.7/site-packages/flask/app.py", line 1330, in handle_http_exception
    return handler(e)
  File "/home/www/aud2/app/__init__.py", line 150, in page_404
    return render_template('errors/404.html'), 404
  File "/home/www/.demo/lib/python2.7/site-packages/flask/templating.py", line 128, in render_template
    context, ctx.app)
  File "/home/www/.demo/lib/python2.7/site-packages/flask/templating.py", line 110, in _render
    rv = template.render(context)
  File "/home/www/.demo/lib/python2.7/site-packages/jinja2/environment.py", line 969, in render
    return self.environment.handle_exception(exc_info, True)
  File "/home/www/.demo/lib/python2.7/site-packages/jinja2/environment.py", line 742, in handle_exception
    reraise(exc_type, exc_value, tb)
  File "/home/www/aud2/app/templates/errors/404.html", line 2, in top-level template code
    {% extends "base.html" %}
  File "/home/www/aud2/app/templates/base.html", line 26, in top-level template code
    {% include 'nav.html' %}
  File "/home/www/aud2/app/templates/nav.html", line 221, in top-level template code
    {% if g.user.is_admin() %}
UndefinedError: 'werkzeug.local.LocalProxy object' has no attribute 'is_admin'
2016-08-26 10:14:28,997 ERROR: Exception on /api/v1.0/node_task/modify_status/46244bedc7f806e5636c728022320b23 [POST] [in /home/www/.demo/lib/python2.7/site-packages/flask/app.py:1423]
Traceback (most recent call last):
  File "/home/www/.demo/lib/python2.7/site-packages/flask/app.py", line 1817, in wsgi_app
    response = self.full_dispatch_request()
  File "/home/www/.demo/lib/python2.7/site-packages/flask/app.py", line 1477, in full_dispatch_request
    rv = self.handle_user_exception(e)
  File "/home/www/.demo/lib/python2.7/site-packages/flask/app.py", line 1381, in handle_user_exception
    reraise(exc_type, exc_value, tb)
  File "/home/www/.demo/lib/python2.7/site-packages/flask/app.py", line 1475, in full_dispatch_request
    rv = self.dispatch_request()
  File "/home/www/.demo/lib/python2.7/site-packages/flask/app.py", line 1461, in dispatch_request
    return self.view_functions[rule.endpoint](**req.view_args)
  File "/home/www/aud2/app/views/site.py", line 875, in modify_node_task_status
    mes.sendEmail()
  File "/home/www/aud2/app/utils/message.py", line 45, in sendEmail
    thr = Thread(target=send_async_email, args=[receiver + '@aicai.com', subject, html])
TypeError: unsupported operand type(s) for +: 'NoneType' and 'str'
2016-08-26 10:32:40,618 ERROR: Exception on /api/v1.0/node_task/modify_status/3a7e2183d97f41557d3f8c2b250b72d2 [POST] [in /home/www/.demo/lib/python2.7/site-packages/flask/app.py:1423]
Traceback (most recent call last):
  File "/home/www/.demo/lib/python2.7/site-packages/flask/app.py", line 1817, in wsgi_app
    response = self.full_dispatch_request()
  File "/home/www/.demo/lib/python2.7/site-packages/flask/app.py", line 1477, in full_dispatch_request
    rv = self.handle_user_exception(e)
  File "/home/www/.demo/lib/python2.7/site-packages/flask/app.py", line 1381, in handle_user_exception
    reraise(exc_type, exc_value, tb)
  File "/home/www/.demo/lib/python2.7/site-packages/flask/app.py", line 1475, in full_dispatch_request
    rv = self.dispatch_request()
  File "/home/www/.demo/lib/python2.7/site-packages/flask/app.py", line 1461, in dispatch_request
    return self.view_functions[rule.endpoint](**req.view_args)
  File "/home/www/aud2/app/views/site.py", line 875, in modify_node_task_status
    mes.sendEmail()
  File "/home/www/aud2/app/utils/message.py", line 45, in sendEmail
    thr = Thread(target=send_async_email, args=[receiver + '@aicai.com', subject, html])
TypeError: unsupported operand type(s) for +: 'NoneType' and 'str'
2016-08-26 10:40:22,054 ERROR: Exception on /api/v1.0/node_task/modify_status/7c48de808678b079c9774b247d754e17 [POST] [in /home/www/.demo/lib/python2.7/site-packages/flask/app.py:1423]
Traceback (most recent call last):
  File "/home/www/.demo/lib/python2.7/site-packages/flask/app.py", line 1817, in wsgi_app
    response = self.full_dispatch_request()
  File "/home/www/.demo/lib/python2.7/site-packages/flask/app.py", line 1477, in full_dispatch_request
    rv = self.handle_user_exception(e)
  File "/home/www/.demo/lib/python2.7/site-packages/flask/app.py", line 1381, in handle_user_exception
    reraise(exc_type, exc_value, tb)
  File "/home/www/.demo/lib/python2.7/site-packages/flask/app.py", line 1475, in full_dispatch_request
    rv = self.dispatch_request()
  File "/home/www/.demo/lib/python2.7/site-packages/flask/app.py", line 1461, in dispatch_request
    return self.view_functions[rule.endpoint](**req.view_args)
  File "/home/www/aud2/app/views/site.py", line 875, in modify_node_task_status
    mes.sendEmail()
  File "/home/www/aud2/app/utils/message.py", line 45, in sendEmail
    thr = Thread(target=send_async_email, args=[receiver + '@aicai.com', subject, html])
TypeError: unsupported operand type(s) for +: 'NoneType' and 'str'
2016-08-26 11:45:06,630 ERROR: Exception on /tomcat/addrestart/ [POST] [in /home/www/.demo/lib/python2.7/site-packages/flask/app.py:1423]
Traceback (most recent call last):
  File "/home/www/.demo/lib/python2.7/site-packages/flask/app.py", line 1817, in wsgi_app
    response = self.full_dispatch_request()
  File "/home/www/.demo/lib/python2.7/site-packages/flask/app.py", line 1477, in full_dispatch_request
    rv = self.handle_user_exception(e)
  File "/home/www/.demo/lib/python2.7/site-packages/flask/app.py", line 1381, in handle_user_exception
    reraise(exc_type, exc_value, tb)
  File "/home/www/.demo/lib/python2.7/site-packages/flask/app.py", line 1475, in full_dispatch_request
    rv = self.dispatch_request()
  File "/home/www/.demo/lib/python2.7/site-packages/flask/app.py", line 1461, in dispatch_request
    return self.view_functions[rule.endpoint](**req.view_args)
  File "/home/www/aud2/app/views/tomcat.py", line 645, in addrestart
    node_ip = node_list[0]
IndexError: list index out of range
2016-08-26 12:09:49,269 ERROR: Exception on /favicon.ico [GET] [in /home/www/.demo/lib/python2.7/site-packages/flask/app.py:1423]
Traceback (most recent call last):
  File "/home/www/.demo/lib/python2.7/site-packages/flask/app.py", line 1817, in wsgi_app
    response = self.full_dispatch_request()
  File "/home/www/.demo/lib/python2.7/site-packages/flask/app.py", line 1477, in full_dispatch_request
    rv = self.handle_user_exception(e)
  File "/home/www/.demo/lib/python2.7/site-packages/flask/app.py", line 1370, in handle_user_exception
    return self.handle_http_exception(e)
  File "/home/www/.demo/lib/python2.7/site-packages/flask/app.py", line 1330, in handle_http_exception
    return handler(e)
  File "/home/www/aud2/app/__init__.py", line 150, in page_404
    return render_template('errors/404.html'), 404
  File "/home/www/.demo/lib/python2.7/site-packages/flask/templating.py", line 128, in render_template
    context, ctx.app)
  File "/home/www/.demo/lib/python2.7/site-packages/flask/templating.py", line 110, in _render
    rv = template.render(context)
  File "/home/www/.demo/lib/python2.7/site-packages/jinja2/environment.py", line 969, in render
    return self.environment.handle_exception(exc_info, True)
  File "/home/www/.demo/lib/python2.7/site-packages/jinja2/environment.py", line 742, in handle_exception
    reraise(exc_type, exc_value, tb)
  File "/home/www/aud2/app/templates/errors/404.html", line 2, in top-level template code
    {% extends "base.html" %}
  File "/home/www/aud2/app/templates/base.html", line 26, in top-level template code
    {% include 'nav.html' %}
  File "/home/www/aud2/app/templates/nav.html", line 221, in top-level template code
    {% if g.user.is_admin() %}
UndefinedError: 'werkzeug.local.LocalProxy object' has no attribute 'is_admin'
2016-08-26 12:09:49,344 ERROR: Exception on /favicon.ico [GET] [in /home/www/.demo/lib/python2.7/site-packages/flask/app.py:1423]
Traceback (most recent call last):
  File "/home/www/.demo/lib/python2.7/site-packages/flask/app.py", line 1817, in wsgi_app
    response = self.full_dispatch_request()
  File "/home/www/.demo/lib/python2.7/site-packages/flask/app.py", line 1477, in full_dispatch_request
    rv = self.handle_user_exception(e)
  File "/home/www/.demo/lib/python2.7/site-packages/flask/app.py", line 1370, in handle_user_exception
    return self.handle_http_exception(e)
  File "/home/www/.demo/lib/python2.7/site-packages/flask/app.py", line 1330, in handle_http_exception
    return handler(e)
  File "/home/www/aud2/app/__init__.py", line 150, in page_404
    return render_template('errors/404.html'), 404
  File "/home/www/.demo/lib/python2.7/site-packages/flask/templating.py", line 128, in render_template
    context, ctx.app)
  File "/home/www/.demo/lib/python2.7/site-packages/flask/templating.py", line 110, in _render
    rv = template.render(context)
  File "/home/www/.demo/lib/python2.7/site-packages/jinja2/environment.py", line 969, in render
    return self.environment.handle_exception(exc_info, True)
  File "/home/www/.demo/lib/python2.7/site-packages/jinja2/environment.py", line 742, in handle_exception
    reraise(exc_type, exc_value, tb)
  File "/home/www/aud2/app/templates/errors/404.html", line 2, in top-level template code
    {% extends "base.html" %}
  File "/home/www/aud2/app/templates/base.html", line 26, in top-level template code
    {% include 'nav.html' %}
  File "/home/www/aud2/app/templates/nav.html", line 221, in top-level template code
    {% if g.user.is_admin() %}
UndefinedError: 'werkzeug.local.LocalProxy object' has no attribute 'is_admin'
2016-08-26 16:05:48,505 ERROR: Exception on /favicon.ico [GET] [in /home/www/.demo/lib/python2.7/site-packages/flask/app.py:1423]
Traceback (most recent call last):
  File "/home/www/.demo/lib/python2.7/site-packages/flask/app.py", line 1817, in wsgi_app
    response = self.full_dispatch_request()
  File "/home/www/.demo/lib/python2.7/site-packages/flask/app.py", line 1477, in full_dispatch_request
    rv = self.handle_user_exception(e)
  File "/home/www/.demo/lib/python2.7/site-packages/flask/app.py", line 1370, in handle_user_exception
    return self.handle_http_exception(e)
  File "/home/www/.demo/lib/python2.7/site-packages/flask/app.py", line 1330, in handle_http_exception
    return handler(e)
  File "/home/www/aud2/app/__init__.py", line 150, in page_404
    return render_template('errors/404.html'), 404
  File "/home/www/.demo/lib/python2.7/site-packages/flask/templating.py", line 128, in render_template
    context, ctx.app)
  File "/home/www/.demo/lib/python2.7/site-packages/flask/templating.py", line 110, in _render
    rv = template.render(context)
  File "/home/www/.demo/lib/python2.7/site-packages/jinja2/environment.py", line 969, in render
    return self.environment.handle_exception(exc_info, True)
  File "/home/www/.demo/lib/python2.7/site-packages/jinja2/environment.py", line 742, in handle_exception
    reraise(exc_type, exc_value, tb)
  File "/home/www/aud2/app/templates/errors/404.html", line 2, in top-level template code
    {% extends "base.html" %}
  File "/home/www/aud2/app/templates/base.html", line 26, in top-level template code
    {% include 'nav.html' %}
  File "/home/www/aud2/app/templates/nav.html", line 221, in top-level template code
    {% if g.user.is_admin() %}
UndefinedError: 'werkzeug.local.LocalProxy object' has no attribute 'is_admin'
2016-08-26 16:06:24,957 ERROR: Exception on /api/v1.0/node_task/modify_status/86e456c3bd9cd726116b4fa376e573cd [POST] [in /home/www/.demo/lib/python2.7/site-packages/flask/app.py:1423]
Traceback (most recent call last):
  File "/home/www/.demo/lib/python2.7/site-packages/flask/app.py", line 1817, in wsgi_app
    response = self.full_dispatch_request()
  File "/home/www/.demo/lib/python2.7/site-packages/flask/app.py", line 1477, in full_dispatch_request
    rv = self.handle_user_exception(e)
  File "/home/www/.demo/lib/python2.7/site-packages/flask/app.py", line 1381, in handle_user_exception
    reraise(exc_type, exc_value, tb)
  File "/home/www/.demo/lib/python2.7/site-packages/flask/app.py", line 1475, in full_dispatch_request
    rv = self.dispatch_request()
  File "/home/www/.demo/lib/python2.7/site-packages/flask/app.py", line 1461, in dispatch_request
    return self.view_functions[rule.endpoint](**req.view_args)
  File "/home/www/aud2/app/views/site.py", line 875, in modify_node_task_status
    mes.sendEmail()
  File "/home/www/aud2/app/utils/message.py", line 45, in sendEmail
    thr = Thread(target=send_async_email, args=[receiver + '@aicai.com', subject, html])
TypeError: unsupported operand type(s) for +: 'NoneType' and 'str'
2016-08-29 09:54:57,740 ERROR: Exception on /favicon.ico [GET] [in /home/www/.demo/lib/python2.7/site-packages/flask/app.py:1423]
Traceback (most recent call last):
  File "/home/www/.demo/lib/python2.7/site-packages/flask/app.py", line 1817, in wsgi_app
    response = self.full_dispatch_request()
  File "/home/www/.demo/lib/python2.7/site-packages/flask/app.py", line 1477, in full_dispatch_request
    rv = self.handle_user_exception(e)
  File "/home/www/.demo/lib/python2.7/site-packages/flask/app.py", line 1370, in handle_user_exception
    return self.handle_http_exception(e)
  File "/home/www/.demo/lib/python2.7/site-packages/flask/app.py", line 1330, in handle_http_exception
    return handler(e)
  File "/home/www/aud2/app/__init__.py", line 150, in page_404
    return render_template('errors/404.html'), 404
  File "/home/www/.demo/lib/python2.7/site-packages/flask/templating.py", line 128, in render_template
    context, ctx.app)
  File "/home/www/.demo/lib/python2.7/site-packages/flask/templating.py", line 110, in _render
    rv = template.render(context)
  File "/home/www/.demo/lib/python2.7/site-packages/jinja2/environment.py", line 969, in render
    return self.environment.handle_exception(exc_info, True)
  File "/home/www/.demo/lib/python2.7/site-packages/jinja2/environment.py", line 742, in handle_exception
    reraise(exc_type, exc_value, tb)
  File "/home/www/aud2/app/templates/errors/404.html", line 2, in top-level template code
    {% extends "base.html" %}
  File "/home/www/aud2/app/templates/base.html", line 26, in top-level template code
    {% include 'nav.html' %}
  File "/home/www/aud2/app/templates/nav.html", line 221, in top-level template code
    {% if g.user.is_admin() %}
UndefinedError: 'werkzeug.local.LocalProxy object' has no attribute 'is_admin'
2016-08-29 09:54:57,755 ERROR: Exception on /favicon.ico [GET] [in /home/www/.demo/lib/python2.7/site-packages/flask/app.py:1423]
Traceback (most recent call last):
  File "/home/www/.demo/lib/python2.7/site-packages/flask/app.py", line 1817, in wsgi_app
    response = self.full_dispatch_request()
  File "/home/www/.demo/lib/python2.7/site-packages/flask/app.py", line 1477, in full_dispatch_request
    rv = self.handle_user_exception(e)
  File "/home/www/.demo/lib/python2.7/site-packages/flask/app.py", line 1370, in handle_user_exception
    return self.handle_http_exception(e)
  File "/home/www/.demo/lib/python2.7/site-packages/flask/app.py", line 1330, in handle_http_exception
    return handler(e)
  File "/home/www/aud2/app/__init__.py", line 150, in page_404
    return render_template('errors/404.html'), 404
  File "/home/www/.demo/lib/python2.7/site-packages/flask/templating.py", line 128, in render_template
    context, ctx.app)
  File "/home/www/.demo/lib/python2.7/site-packages/flask/templating.py", line 110, in _render
    rv = template.render(context)
  File "/home/www/.demo/lib/python2.7/site-packages/jinja2/environment.py", line 969, in render
    return self.environment.handle_exception(exc_info, True)
  File "/home/www/.demo/lib/python2.7/site-packages/jinja2/environment.py", line 742, in handle_exception
    reraise(exc_type, exc_value, tb)
  File "/home/www/aud2/app/templates/errors/404.html", line 2, in top-level template code
    {% extends "base.html" %}
  File "/home/www/aud2/app/templates/base.html", line 26, in top-level template code
    {% include 'nav.html' %}
  File "/home/www/aud2/app/templates/nav.html", line 221, in top-level template code
    {% if g.user.is_admin() %}
UndefinedError: 'werkzeug.local.LocalProxy object' has no attribute 'is_admin'
2016-08-29 10:43:07,836 ERROR: Exception on /api/v1.0/node_task/modify_status/eb9fc4f6cb3575d30b9e86af1d1686a5 [POST] [in /home/www/.demo/lib/python2.7/site-packages/flask/app.py:1423]
Traceback (most recent call last):
  File "/home/www/.demo/lib/python2.7/site-packages/flask/app.py", line 1817, in wsgi_app
    response = self.full_dispatch_request()
  File "/home/www/.demo/lib/python2.7/site-packages/flask/app.py", line 1477, in full_dispatch_request
    rv = self.handle_user_exception(e)
  File "/home/www/.demo/lib/python2.7/site-packages/flask/app.py", line 1381, in handle_user_exception
    reraise(exc_type, exc_value, tb)
  File "/home/www/.demo/lib/python2.7/site-packages/flask/app.py", line 1475, in full_dispatch_request
    rv = self.dispatch_request()
  File "/home/www/.demo/lib/python2.7/site-packages/flask/app.py", line 1461, in dispatch_request
    return self.view_functions[rule.endpoint](**req.view_args)
  File "/home/www/aud2/app/views/site.py", line 875, in modify_node_task_status
    mes.sendEmail()
  File "/home/www/aud2/app/utils/message.py", line 45, in sendEmail
    thr = Thread(target=send_async_email, args=[receiver + '@aicai.com', subject, html])
TypeError: unsupported operand type(s) for +: 'NoneType' and 'str'
2016-08-29 10:46:19,809 ERROR: Exception on /api/v1.0/node_task/modify_status/59c3b3f332ecfd1f282ab0cc241a1bd9 [POST] [in /home/www/.demo/lib/python2.7/site-packages/flask/app.py:1423]
Traceback (most recent call last):
  File "/home/www/.demo/lib/python2.7/site-packages/flask/app.py", line 1817, in wsgi_app
    response = self.full_dispatch_request()
  File "/home/www/.demo/lib/python2.7/site-packages/flask/app.py", line 1477, in full_dispatch_request
    rv = self.handle_user_exception(e)
  File "/home/www/.demo/lib/python2.7/site-packages/flask/app.py", line 1381, in handle_user_exception
    reraise(exc_type, exc_value, tb)
  File "/home/www/.demo/lib/python2.7/site-packages/flask/app.py", line 1475, in full_dispatch_request
    rv = self.dispatch_request()
  File "/home/www/.demo/lib/python2.7/site-packages/flask/app.py", line 1461, in dispatch_request
    return self.view_functions[rule.endpoint](**req.view_args)
  File "/home/www/aud2/app/views/site.py", line 875, in modify_node_task_status
    mes.sendEmail()
  File "/home/www/aud2/app/utils/message.py", line 45, in sendEmail
    thr = Thread(target=send_async_email, args=[receiver + '@aicai.com', subject, html])
TypeError: unsupported operand type(s) for +: 'NoneType' and 'str'
2016-08-29 12:13:33,790 ERROR: Exception on /api/v1.0/node_task/modify_status/facb0cf7f8bca47555a744f0c4bc7a03 [POST] [in /home/www/.demo/lib/python2.7/site-packages/flask/app.py:1423]
Traceback (most recent call last):
  File "/home/www/.demo/lib/python2.7/site-packages/flask/app.py", line 1817, in wsgi_app
    response = self.full_dispatch_request()
  File "/home/www/.demo/lib/python2.7/site-packages/flask/app.py", line 1477, in full_dispatch_request
    rv = self.handle_user_exception(e)
  File "/home/www/.demo/lib/python2.7/site-packages/flask/app.py", line 1381, in handle_user_exception
    reraise(exc_type, exc_value, tb)
  File "/home/www/.demo/lib/python2.7/site-packages/flask/app.py", line 1475, in full_dispatch_request
    rv = self.dispatch_request()
  File "/home/www/.demo/lib/python2.7/site-packages/flask/app.py", line 1461, in dispatch_request
    return self.view_functions[rule.endpoint](**req.view_args)
  File "/home/www/aud2/app/views/site.py", line 875, in modify_node_task_status
    mes.sendEmail()
  File "/home/www/aud2/app/utils/message.py", line 45, in sendEmail
    thr = Thread(target=send_async_email, args=[receiver + '@aicai.com', subject, html])
TypeError: unsupported operand type(s) for +: 'NoneType' and 'str'
2016-08-29 12:16:54,102 ERROR: Exception on /api/v1.0/node_task/modify_status/54079763458939ca04f0cdc9f6967519 [POST] [in /home/www/.demo/lib/python2.7/site-packages/flask/app.py:1423]
Traceback (most recent call last):
  File "/home/www/.demo/lib/python2.7/site-packages/flask/app.py", line 1817, in wsgi_app
    response = self.full_dispatch_request()
  File "/home/www/.demo/lib/python2.7/site-packages/flask/app.py", line 1477, in full_dispatch_request
    rv = self.handle_user_exception(e)
  File "/home/www/.demo/lib/python2.7/site-packages/flask/app.py", line 1381, in handle_user_exception
    reraise(exc_type, exc_value, tb)
  File "/home/www/.demo/lib/python2.7/site-packages/flask/app.py", line 1475, in full_dispatch_request
    rv = self.dispatch_request()
  File "/home/www/.demo/lib/python2.7/site-packages/flask/app.py", line 1461, in dispatch_request
    return self.view_functions[rule.endpoint](**req.view_args)
  File "/home/www/aud2/app/views/site.py", line 875, in modify_node_task_status
    mes.sendEmail()
  File "/home/www/aud2/app/utils/message.py", line 45, in sendEmail
    thr = Thread(target=send_async_email, args=[receiver + '@aicai.com', subject, html])
TypeError: unsupported operand type(s) for +: 'NoneType' and 'str'
2016-08-29 14:07:41,374 ERROR: Exception on /favicon.ico [GET] [in /home/www/.demo/lib/python2.7/site-packages/flask/app.py:1423]
Traceback (most recent call last):
  File "/home/www/.demo/lib/python2.7/site-packages/flask/app.py", line 1817, in wsgi_app
    response = self.full_dispatch_request()
  File "/home/www/.demo/lib/python2.7/site-packages/flask/app.py", line 1477, in full_dispatch_request
    rv = self.handle_user_exception(e)
  File "/home/www/.demo/lib/python2.7/site-packages/flask/app.py", line 1370, in handle_user_exception
    return self.handle_http_exception(e)
  File "/home/www/.demo/lib/python2.7/site-packages/flask/app.py", line 1330, in handle_http_exception
    return handler(e)
  File "/home/www/aud2/app/__init__.py", line 150, in page_404
    return render_template('errors/404.html'), 404
  File "/home/www/.demo/lib/python2.7/site-packages/flask/templating.py", line 128, in render_template
    context, ctx.app)
  File "/home/www/.demo/lib/python2.7/site-packages/flask/templating.py", line 110, in _render
    rv = template.render(context)
  File "/home/www/.demo/lib/python2.7/site-packages/jinja2/environment.py", line 969, in render
    return self.environment.handle_exception(exc_info, True)
  File "/home/www/.demo/lib/python2.7/site-packages/jinja2/environment.py", line 742, in handle_exception
    reraise(exc_type, exc_value, tb)
  File "/home/www/aud2/app/templates/errors/404.html", line 2, in top-level template code
    {% extends "base.html" %}
  File "/home/www/aud2/app/templates/base.html", line 26, in top-level template code
    {% include 'nav.html' %}
  File "/home/www/aud2/app/templates/nav.html", line 221, in top-level template code
    {% if g.user.is_admin() %}
UndefinedError: 'werkzeug.local.LocalProxy object' has no attribute 'is_admin'
2016-08-29 14:07:41,389 ERROR: Exception on /favicon.ico [GET] [in /home/www/.demo/lib/python2.7/site-packages/flask/app.py:1423]
Traceback (most recent call last):
  File "/home/www/.demo/lib/python2.7/site-packages/flask/app.py", line 1817, in wsgi_app
    response = self.full_dispatch_request()
  File "/home/www/.demo/lib/python2.7/site-packages/flask/app.py", line 1477, in full_dispatch_request
    rv = self.handle_user_exception(e)
  File "/home/www/.demo/lib/python2.7/site-packages/flask/app.py", line 1370, in handle_user_exception
    return self.handle_http_exception(e)
  File "/home/www/.demo/lib/python2.7/site-packages/flask/app.py", line 1330, in handle_http_exception
    return handler(e)
  File "/home/www/aud2/app/__init__.py", line 150, in page_404
    return render_template('errors/404.html'), 404
  File "/home/www/.demo/lib/python2.7/site-packages/flask/templating.py", line 128, in render_template
    context, ctx.app)
  File "/home/www/.demo/lib/python2.7/site-packages/flask/templating.py", line 110, in _render
    rv = template.render(context)
  File "/home/www/.demo/lib/python2.7/site-packages/jinja2/environment.py", line 969, in render
    return self.environment.handle_exception(exc_info, True)
  File "/home/www/.demo/lib/python2.7/site-packages/jinja2/environment.py", line 742, in handle_exception
    reraise(exc_type, exc_value, tb)
  File "/home/www/aud2/app/templates/errors/404.html", line 2, in top-level template code
    {% extends "base.html" %}
  File "/home/www/aud2/app/templates/base.html", line 26, in top-level template code
    {% include 'nav.html' %}
  File "/home/www/aud2/app/templates/nav.html", line 221, in top-level template code
    {% if g.user.is_admin() %}
UndefinedError: 'werkzeug.local.LocalProxy object' has no attribute 'is_admin'
2016-08-29 18:27:58,614 ERROR: Exception on /favicon.ico [GET] [in /home/www/.demo/lib/python2.7/site-packages/flask/app.py:1423]
Traceback (most recent call last):
  File "/home/www/.demo/lib/python2.7/site-packages/flask/app.py", line 1817, in wsgi_app
    response = self.full_dispatch_request()
  File "/home/www/.demo/lib/python2.7/site-packages/flask/app.py", line 1477, in full_dispatch_request
    rv = self.handle_user_exception(e)
  File "/home/www/.demo/lib/python2.7/site-packages/flask/app.py", line 1370, in handle_user_exception
    return self.handle_http_exception(e)
  File "/home/www/.demo/lib/python2.7/site-packages/flask/app.py", line 1330, in handle_http_exception
    return handler(e)
  File "/home/www/aud2/app/__init__.py", line 150, in page_404
    return render_template('errors/404.html'), 404
  File "/home/www/.demo/lib/python2.7/site-packages/flask/templating.py", line 128, in render_template
    context, ctx.app)
  File "/home/www/.demo/lib/python2.7/site-packages/flask/templating.py", line 110, in _render
    rv = template.render(context)
  File "/home/www/.demo/lib/python2.7/site-packages/jinja2/environment.py", line 969, in render
    return self.environment.handle_exception(exc_info, True)
  File "/home/www/.demo/lib/python2.7/site-packages/jinja2/environment.py", line 742, in handle_exception
    reraise(exc_type, exc_value, tb)
  File "/home/www/aud2/app/templates/errors/404.html", line 2, in top-level template code
    {% extends "base.html" %}
  File "/home/www/aud2/app/templates/base.html", line 26, in top-level template code
    {% include 'nav.html' %}
  File "/home/www/aud2/app/templates/nav.html", line 221, in top-level template code
    {% if g.user.is_admin() %}
UndefinedError: 'werkzeug.local.LocalProxy object' has no attribute 'is_admin'
2016-08-29 18:27:58,628 ERROR: Exception on /favicon.ico [GET] [in /home/www/.demo/lib/python2.7/site-packages/flask/app.py:1423]
Traceback (most recent call last):
  File "/home/www/.demo/lib/python2.7/site-packages/flask/app.py", line 1817, in wsgi_app
    response = self.full_dispatch_request()
  File "/home/www/.demo/lib/python2.7/site-packages/flask/app.py", line 1477, in full_dispatch_request
    rv = self.handle_user_exception(e)
  File "/home/www/.demo/lib/python2.7/site-packages/flask/app.py", line 1370, in handle_user_exception
    return self.handle_http_exception(e)
  File "/home/www/.demo/lib/python2.7/site-packages/flask/app.py", line 1330, in handle_http_exception
    return handler(e)
  File "/home/www/aud2/app/__init__.py", line 150, in page_404
    return render_template('errors/404.html'), 404
  File "/home/www/.demo/lib/python2.7/site-packages/flask/templating.py", line 128, in render_template
    context, ctx.app)
  File "/home/www/.demo/lib/python2.7/site-packages/flask/templating.py", line 110, in _render
    rv = template.render(context)
  File "/home/www/.demo/lib/python2.7/site-packages/jinja2/environment.py", line 969, in render
    return self.environment.handle_exception(exc_info, True)
  File "/home/www/.demo/lib/python2.7/site-packages/jinja2/environment.py", line 742, in handle_exception
    reraise(exc_type, exc_value, tb)
  File "/home/www/aud2/app/templates/errors/404.html", line 2, in top-level template code
    {% extends "base.html" %}
  File "/home/www/aud2/app/templates/base.html", line 26, in top-level template code
    {% include 'nav.html' %}
  File "/home/www/aud2/app/templates/nav.html", line 221, in top-level template code
    {% if g.user.is_admin() %}
UndefinedError: 'werkzeug.local.LocalProxy object' has no attribute 'is_admin'
2016-08-29 18:29:39,879 ERROR: Exception on /favicon.ico [GET] [in /home/www/.demo/lib/python2.7/site-packages/flask/app.py:1423]
Traceback (most recent call last):
  File "/home/www/.demo/lib/python2.7/site-packages/flask/app.py", line 1817, in wsgi_app
    response = self.full_dispatch_request()
  File "/home/www/.demo/lib/python2.7/site-packages/flask/app.py", line 1477, in full_dispatch_request
    rv = self.handle_user_exception(e)
  File "/home/www/.demo/lib/python2.7/site-packages/flask/app.py", line 1370, in handle_user_exception
    return self.handle_http_exception(e)
  File "/home/www/.demo/lib/python2.7/site-packages/flask/app.py", line 1330, in handle_http_exception
    return handler(e)
  File "/home/www/aud2/app/__init__.py", line 150, in page_404
    return render_template('errors/404.html'), 404
  File "/home/www/.demo/lib/python2.7/site-packages/flask/templating.py", line 128, in render_template
    context, ctx.app)
  File "/home/www/.demo/lib/python2.7/site-packages/flask/templating.py", line 110, in _render
    rv = template.render(context)
  File "/home/www/.demo/lib/python2.7/site-packages/jinja2/environment.py", line 969, in render
    return self.environment.handle_exception(exc_info, True)
  File "/home/www/.demo/lib/python2.7/site-packages/jinja2/environment.py", line 742, in handle_exception
    reraise(exc_type, exc_value, tb)
  File "/home/www/aud2/app/templates/errors/404.html", line 2, in top-level template code
    {% extends "base.html" %}
  File "/home/www/aud2/app/templates/base.html", line 26, in top-level template code
    {% include 'nav.html' %}
  File "/home/www/aud2/app/templates/nav.html", line 221, in top-level template code
    {% if g.user.is_admin() %}
UndefinedError: 'werkzeug.local.LocalProxy object' has no attribute 'is_admin'
2016-08-29 18:33:34,635 ERROR: Exception on /favicon.ico [GET] [in /home/www/.demo/lib/python2.7/site-packages/flask/app.py:1423]
Traceback (most recent call last):
  File "/home/www/.demo/lib/python2.7/site-packages/flask/app.py", line 1817, in wsgi_app
    response = self.full_dispatch_request()
  File "/home/www/.demo/lib/python2.7/site-packages/flask/app.py", line 1477, in full_dispatch_request
    rv = self.handle_user_exception(e)
  File "/home/www/.demo/lib/python2.7/site-packages/flask/app.py", line 1370, in handle_user_exception
    return self.handle_http_exception(e)
  File "/home/www/.demo/lib/python2.7/site-packages/flask/app.py", line 1330, in handle_http_exception
    return handler(e)
  File "/home/www/aud2/app/__init__.py", line 150, in page_404
    return render_template('errors/404.html'), 404
  File "/home/www/.demo/lib/python2.7/site-packages/flask/templating.py", line 128, in render_template
    context, ctx.app)
  File "/home/www/.demo/lib/python2.7/site-packages/flask/templating.py", line 110, in _render
    rv = template.render(context)
  File "/home/www/.demo/lib/python2.7/site-packages/jinja2/environment.py", line 969, in render
    return self.environment.handle_exception(exc_info, True)
  File "/home/www/.demo/lib/python2.7/site-packages/jinja2/environment.py", line 742, in handle_exception
    reraise(exc_type, exc_value, tb)
  File "/home/www/aud2/app/templates/errors/404.html", line 2, in top-level template code
    {% extends "base.html" %}
  File "/home/www/aud2/app/templates/base.html", line 26, in top-level template code
    {% include 'nav.html' %}
  File "/home/www/aud2/app/templates/nav.html", line 221, in top-level template code
    {% if g.user.is_admin() %}
UndefinedError: 'werkzeug.local.LocalProxy object' has no attribute 'is_admin'
2016-08-29 20:50:50,292 ERROR: Exception on /favicon.ico [GET] [in /home/www/.demo/lib/python2.7/site-packages/flask/app.py:1423]
Traceback (most recent call last):
  File "/home/www/.demo/lib/python2.7/site-packages/flask/app.py", line 1817, in wsgi_app
    response = self.full_dispatch_request()
  File "/home/www/.demo/lib/python2.7/site-packages/flask/app.py", line 1477, in full_dispatch_request
    rv = self.handle_user_exception(e)
  File "/home/www/.demo/lib/python2.7/site-packages/flask/app.py", line 1370, in handle_user_exception
    return self.handle_http_exception(e)
  File "/home/www/.demo/lib/python2.7/site-packages/flask/app.py", line 1330, in handle_http_exception
    return handler(e)
  File "/home/www/aud2/app/__init__.py", line 150, in page_404
    return render_template('errors/404.html'), 404
  File "/home/www/.demo/lib/python2.7/site-packages/flask/templating.py", line 128, in render_template
    context, ctx.app)
  File "/home/www/.demo/lib/python2.7/site-packages/flask/templating.py", line 110, in _render
    rv = template.render(context)
  File "/home/www/.demo/lib/python2.7/site-packages/jinja2/environment.py", line 969, in render
    return self.environment.handle_exception(exc_info, True)
  File "/home/www/.demo/lib/python2.7/site-packages/jinja2/environment.py", line 742, in handle_exception
    reraise(exc_type, exc_value, tb)
  File "/home/www/aud2/app/templates/errors/404.html", line 2, in top-level template code
    {% extends "base.html" %}
  File "/home/www/aud2/app/templates/base.html", line 26, in top-level template code
    {% include 'nav.html' %}
  File "/home/www/aud2/app/templates/nav.html", line 221, in top-level template code
    {% if g.user.is_admin() %}
UndefinedError: 'werkzeug.local.LocalProxy object' has no attribute 'is_admin'
2016-08-29 20:50:50,304 ERROR: Exception on /favicon.ico [GET] [in /home/www/.demo/lib/python2.7/site-packages/flask/app.py:1423]
Traceback (most recent call last):
  File "/home/www/.demo/lib/python2.7/site-packages/flask/app.py", line 1817, in wsgi_app
    response = self.full_dispatch_request()
  File "/home/www/.demo/lib/python2.7/site-packages/flask/app.py", line 1477, in full_dispatch_request
    rv = self.handle_user_exception(e)
  File "/home/www/.demo/lib/python2.7/site-packages/flask/app.py", line 1370, in handle_user_exception
    return self.handle_http_exception(e)
  File "/home/www/.demo/lib/python2.7/site-packages/flask/app.py", line 1330, in handle_http_exception
    return handler(e)
  File "/home/www/aud2/app/__init__.py", line 150, in page_404
    return render_template('errors/404.html'), 404
  File "/home/www/.demo/lib/python2.7/site-packages/flask/templating.py", line 128, in render_template
    context, ctx.app)
  File "/home/www/.demo/lib/python2.7/site-packages/flask/templating.py", line 110, in _render
    rv = template.render(context)
  File "/home/www/.demo/lib/python2.7/site-packages/jinja2/environment.py", line 969, in render
    return self.environment.handle_exception(exc_info, True)
  File "/home/www/.demo/lib/python2.7/site-packages/jinja2/environment.py", line 742, in handle_exception
    reraise(exc_type, exc_value, tb)
  File "/home/www/aud2/app/templates/errors/404.html", line 2, in top-level template code
    {% extends "base.html" %}
  File "/home/www/aud2/app/templates/base.html", line 26, in top-level template code
    {% include 'nav.html' %}
  File "/home/www/aud2/app/templates/nav.html", line 221, in top-level template code
    {% if g.user.is_admin() %}
UndefinedError: 'werkzeug.local.LocalProxy object' has no attribute 'is_admin'
2016-08-30 07:10:17,912 ERROR: Exception on /api/v1.0/node_task/modify_status/e7e12d5cceb687e5018dc81d6d82b886 [POST] [in /home/www/.demo/lib/python2.7/site-packages/flask/app.py:1423]
Traceback (most recent call last):
  File "/home/www/.demo/lib/python2.7/site-packages/flask/app.py", line 1817, in wsgi_app
    response = self.full_dispatch_request()
  File "/home/www/.demo/lib/python2.7/site-packages/flask/app.py", line 1477, in full_dispatch_request
    rv = self.handle_user_exception(e)
  File "/home/www/.demo/lib/python2.7/site-packages/flask/app.py", line 1381, in handle_user_exception
    reraise(exc_type, exc_value, tb)
  File "/home/www/.demo/lib/python2.7/site-packages/flask/app.py", line 1475, in full_dispatch_request
    rv = self.dispatch_request()
  File "/home/www/.demo/lib/python2.7/site-packages/flask/app.py", line 1461, in dispatch_request
    return self.view_functions[rule.endpoint](**req.view_args)
  File "/home/www/aud2/app/views/site.py", line 875, in modify_node_task_status
    mes.sendEmail()
  File "/home/www/aud2/app/utils/message.py", line 45, in sendEmail
    thr = Thread(target=send_async_email, args=[receiver + '@aicai.com', subject, html])
TypeError: unsupported operand type(s) for +: 'NoneType' and 'str'
2016-08-30 09:53:22,610 ERROR: Exception on /favicon.ico [GET] [in /home/www/.demo/lib/python2.7/site-packages/flask/app.py:1423]
Traceback (most recent call last):
  File "/home/www/.demo/lib/python2.7/site-packages/flask/app.py", line 1817, in wsgi_app
    response = self.full_dispatch_request()
  File "/home/www/.demo/lib/python2.7/site-packages/flask/app.py", line 1477, in full_dispatch_request
    rv = self.handle_user_exception(e)
  File "/home/www/.demo/lib/python2.7/site-packages/flask/app.py", line 1370, in handle_user_exception
    return self.handle_http_exception(e)
  File "/home/www/.demo/lib/python2.7/site-packages/flask/app.py", line 1330, in handle_http_exception
    return handler(e)
  File "/home/www/aud2/app/__init__.py", line 150, in page_404
    return render_template('errors/404.html'), 404
  File "/home/www/.demo/lib/python2.7/site-packages/flask/templating.py", line 128, in render_template
    context, ctx.app)
  File "/home/www/.demo/lib/python2.7/site-packages/flask/templating.py", line 110, in _render
    rv = template.render(context)
  File "/home/www/.demo/lib/python2.7/site-packages/jinja2/environment.py", line 969, in render
    return self.environment.handle_exception(exc_info, True)
  File "/home/www/.demo/lib/python2.7/site-packages/jinja2/environment.py", line 742, in handle_exception
    reraise(exc_type, exc_value, tb)
  File "/home/www/aud2/app/templates/errors/404.html", line 2, in top-level template code
    {% extends "base.html" %}
  File "/home/www/aud2/app/templates/base.html", line 26, in top-level template code
    {% include 'nav.html' %}
  File "/home/www/aud2/app/templates/nav.html", line 221, in top-level template code
    {% if g.user.is_admin() %}
UndefinedError: 'werkzeug.local.LocalProxy object' has no attribute 'is_admin'
2016-08-30 09:57:04,524 ERROR: Exception on /api/v1.0/node_task/modify_status/023418ed1543c33be5561553ca2d4438 [POST] [in /home/www/.demo/lib/python2.7/site-packages/flask/app.py:1423]
Traceback (most recent call last):
  File "/home/www/.demo/lib/python2.7/site-packages/flask/app.py", line 1817, in wsgi_app
    response = self.full_dispatch_request()
  File "/home/www/.demo/lib/python2.7/site-packages/flask/app.py", line 1477, in full_dispatch_request
    rv = self.handle_user_exception(e)
  File "/home/www/.demo/lib/python2.7/site-packages/flask/app.py", line 1381, in handle_user_exception
    reraise(exc_type, exc_value, tb)
  File "/home/www/.demo/lib/python2.7/site-packages/flask/app.py", line 1475, in full_dispatch_request
    rv = self.dispatch_request()
  File "/home/www/.demo/lib/python2.7/site-packages/flask/app.py", line 1461, in dispatch_request
    return self.view_functions[rule.endpoint](**req.view_args)
  File "/home/www/aud2/app/views/site.py", line 875, in modify_node_task_status
    mes.sendEmail()
  File "/home/www/aud2/app/utils/message.py", line 45, in sendEmail
    thr = Thread(target=send_async_email, args=[receiver + '@aicai.com', subject, html])
TypeError: unsupported operand type(s) for +: 'NoneType' and 'str'
2016-08-30 13:46:00,763 ERROR: Exception on /favicon.ico [GET] [in /home/www/.demo/lib/python2.7/site-packages/flask/app.py:1423]
Traceback (most recent call last):
  File "/home/www/.demo/lib/python2.7/site-packages/flask/app.py", line 1817, in wsgi_app
    response = self.full_dispatch_request()
  File "/home/www/.demo/lib/python2.7/site-packages/flask/app.py", line 1477, in full_dispatch_request
    rv = self.handle_user_exception(e)
  File "/home/www/.demo/lib/python2.7/site-packages/flask/app.py", line 1370, in handle_user_exception
    return self.handle_http_exception(e)
  File "/home/www/.demo/lib/python2.7/site-packages/flask/app.py", line 1330, in handle_http_exception
    return handler(e)
  File "/home/www/aud2/app/__init__.py", line 150, in page_404
    return render_template('errors/404.html'), 404
  File "/home/www/.demo/lib/python2.7/site-packages/flask/templating.py", line 128, in render_template
    context, ctx.app)
  File "/home/www/.demo/lib/python2.7/site-packages/flask/templating.py", line 110, in _render
    rv = template.render(context)
  File "/home/www/.demo/lib/python2.7/site-packages/jinja2/environment.py", line 969, in render
    return self.environment.handle_exception(exc_info, True)
  File "/home/www/.demo/lib/python2.7/site-packages/jinja2/environment.py", line 742, in handle_exception
    reraise(exc_type, exc_value, tb)
  File "/home/www/aud2/app/templates/errors/404.html", line 2, in top-level template code
    {% extends "base.html" %}
  File "/home/www/aud2/app/templates/base.html", line 26, in top-level template code
    {% include 'nav.html' %}
  File "/home/www/aud2/app/templates/nav.html", line 221, in top-level template code
    {% if g.user.is_admin() %}
UndefinedError: 'werkzeug.local.LocalProxy object' has no attribute 'is_admin'
2016-08-30 13:46:00,777 ERROR: Exception on /favicon.ico [GET] [in /home/www/.demo/lib/python2.7/site-packages/flask/app.py:1423]
Traceback (most recent call last):
  File "/home/www/.demo/lib/python2.7/site-packages/flask/app.py", line 1817, in wsgi_app
    response = self.full_dispatch_request()
  File "/home/www/.demo/lib/python2.7/site-packages/flask/app.py", line 1477, in full_dispatch_request
    rv = self.handle_user_exception(e)
  File "/home/www/.demo/lib/python2.7/site-packages/flask/app.py", line 1370, in handle_user_exception
    return self.handle_http_exception(e)
  File "/home/www/.demo/lib/python2.7/site-packages/flask/app.py", line 1330, in handle_http_exception
    return handler(e)
  File "/home/www/aud2/app/__init__.py", line 150, in page_404
    return render_template('errors/404.html'), 404
  File "/home/www/.demo/lib/python2.7/site-packages/flask/templating.py", line 128, in render_template
    context, ctx.app)
  File "/home/www/.demo/lib/python2.7/site-packages/flask/templating.py", line 110, in _render
    rv = template.render(context)
  File "/home/www/.demo/lib/python2.7/site-packages/jinja2/environment.py", line 969, in render
    return self.environment.handle_exception(exc_info, True)
  File "/home/www/.demo/lib/python2.7/site-packages/jinja2/environment.py", line 742, in handle_exception
    reraise(exc_type, exc_value, tb)
  File "/home/www/aud2/app/templates/errors/404.html", line 2, in top-level template code
    {% extends "base.html" %}
  File "/home/www/aud2/app/templates/base.html", line 26, in top-level template code
    {% include 'nav.html' %}
  File "/home/www/aud2/app/templates/nav.html", line 221, in top-level template code
    {% if g.user.is_admin() %}
UndefinedError: 'werkzeug.local.LocalProxy object' has no attribute 'is_admin'
2016-08-30 14:42:13,786 ERROR: Exception on /favicon.ico [GET] [in /home/www/.demo/lib/python2.7/site-packages/flask/app.py:1423]
Traceback (most recent call last):
  File "/home/www/.demo/lib/python2.7/site-packages/flask/app.py", line 1817, in wsgi_app
    response = self.full_dispatch_request()
  File "/home/www/.demo/lib/python2.7/site-packages/flask/app.py", line 1477, in full_dispatch_request
    rv = self.handle_user_exception(e)
  File "/home/www/.demo/lib/python2.7/site-packages/flask/app.py", line 1370, in handle_user_exception
    return self.handle_http_exception(e)
  File "/home/www/.demo/lib/python2.7/site-packages/flask/app.py", line 1330, in handle_http_exception
    return handler(e)
  File "/home/www/aud2/app/__init__.py", line 150, in page_404
    return render_template('errors/404.html'), 404
  File "/home/www/.demo/lib/python2.7/site-packages/flask/templating.py", line 128, in render_template
    context, ctx.app)
  File "/home/www/.demo/lib/python2.7/site-packages/flask/templating.py", line 110, in _render
    rv = template.render(context)
  File "/home/www/.demo/lib/python2.7/site-packages/jinja2/environment.py", line 969, in render
    return self.environment.handle_exception(exc_info, True)
  File "/home/www/.demo/lib/python2.7/site-packages/jinja2/environment.py", line 742, in handle_exception
    reraise(exc_type, exc_value, tb)
  File "/home/www/aud2/app/templates/errors/404.html", line 2, in top-level template code
    {% extends "base.html" %}
  File "/home/www/aud2/app/templates/base.html", line 26, in top-level template code
    {% include 'nav.html' %}
  File "/home/www/aud2/app/templates/nav.html", line 221, in top-level template code
    {% if g.user.is_admin() %}
UndefinedError: 'werkzeug.local.LocalProxy object' has no attribute 'is_admin'
2016-08-30 14:56:43,275 ERROR: Exception on /api/v1.0/node_task/modify_status/c18bd5d8d544e5bb3a4399665a489f1a [POST] [in /home/www/.demo/lib/python2.7/site-packages/flask/app.py:1423]
Traceback (most recent call last):
  File "/home/www/.demo/lib/python2.7/site-packages/flask/app.py", line 1817, in wsgi_app
    response = self.full_dispatch_request()
  File "/home/www/.demo/lib/python2.7/site-packages/flask/app.py", line 1477, in full_dispatch_request
    rv = self.handle_user_exception(e)
  File "/home/www/.demo/lib/python2.7/site-packages/flask/app.py", line 1381, in handle_user_exception
    reraise(exc_type, exc_value, tb)
  File "/home/www/.demo/lib/python2.7/site-packages/flask/app.py", line 1475, in full_dispatch_request
    rv = self.dispatch_request()
  File "/home/www/.demo/lib/python2.7/site-packages/flask/app.py", line 1461, in dispatch_request
    return self.view_functions[rule.endpoint](**req.view_args)
  File "/home/www/aud2/app/views/site.py", line 875, in modify_node_task_status
    mes.sendEmail()
  File "/home/www/aud2/app/utils/message.py", line 45, in sendEmail
    thr = Thread(target=send_async_email, args=[receiver + '@aicai.com', subject, html])
TypeError: unsupported operand type(s) for +: 'NoneType' and 'str'
2016-08-30 15:20:35,646 ERROR: Exception on /favicon.ico [GET] [in /home/www/.demo/lib/python2.7/site-packages/flask/app.py:1423]
Traceback (most recent call last):
  File "/home/www/.demo/lib/python2.7/site-packages/flask/app.py", line 1817, in wsgi_app
    response = self.full_dispatch_request()
  File "/home/www/.demo/lib/python2.7/site-packages/flask/app.py", line 1477, in full_dispatch_request
    rv = self.handle_user_exception(e)
  File "/home/www/.demo/lib/python2.7/site-packages/flask/app.py", line 1370, in handle_user_exception
    return self.handle_http_exception(e)
  File "/home/www/.demo/lib/python2.7/site-packages/flask/app.py", line 1330, in handle_http_exception
    return handler(e)
  File "/home/www/aud2/app/__init__.py", line 150, in page_404
    return render_template('errors/404.html'), 404
  File "/home/www/.demo/lib/python2.7/site-packages/flask/templating.py", line 128, in render_template
    context, ctx.app)
  File "/home/www/.demo/lib/python2.7/site-packages/flask/templating.py", line 110, in _render
    rv = template.render(context)
  File "/home/www/.demo/lib/python2.7/site-packages/jinja2/environment.py", line 969, in render
    return self.environment.handle_exception(exc_info, True)
  File "/home/www/.demo/lib/python2.7/site-packages/jinja2/environment.py", line 742, in handle_exception
    reraise(exc_type, exc_value, tb)
  File "/home/www/aud2/app/templates/errors/404.html", line 2, in top-level template code
    {% extends "base.html" %}
  File "/home/www/aud2/app/templates/base.html", line 26, in top-level template code
    {% include 'nav.html' %}
  File "/home/www/aud2/app/templates/nav.html", line 221, in top-level template code
    {% if g.user.is_admin() %}
UndefinedError: 'werkzeug.local.LocalProxy object' has no attribute 'is_admin'
