2016-08-19 18:48:39,041 ERROR: Exception on /self/app [POST] [in /home/www/.demo/lib/python2.7/site-packages/flask/app.py:1423]
Traceback (most recent call last):
  File "/home/www/.demo/lib/python2.7/site-packages/flask/app.py", line 1817, in wsgi_app
    response = self.full_dispatch_request()
  File "/home/www/.demo/lib/python2.7/site-packages/flask/app.py", line 1477, in full_dispatch_request
    rv = self.handle_user_exception(e)
  File "/home/www/.demo/lib/python2.7/site-packages/flask/app.py", line 1381, in handle_user_exception
    reraise(exc_type, exc_value, tb)
  File "/home/www/.demo/lib/python2.7/site-packages/flask/app.py", line 1475, in full_dispatch_request
    rv = self.dispatch_request()
  File "/home/www/.demo/lib/python2.7/site-packages/flask/app.py", line 1461, in dispatch_request
    return self.view_functions[rule.endpoint](**req.view_args)
  File "/home/www/.demo/lib/python2.7/site-packages/flask_login.py", line 758, in decorated_view
    return func(*args, **kwargs)
  File "/home/www/aud2/app/views/self.py", line 41, in app
    models.App_sites.id == int(item.site)).first()[0]
TypeError: 'NoneType' object has no attribute '__getitem__'
2016-08-19 18:48:48,572 ERROR: Exception on /self/app [POST] [in /home/www/.demo/lib/python2.7/site-packages/flask/app.py:1423]
Traceback (most recent call last):
  File "/home/www/.demo/lib/python2.7/site-packages/flask/app.py", line 1817, in wsgi_app
    response = self.full_dispatch_request()
  File "/home/www/.demo/lib/python2.7/site-packages/flask/app.py", line 1477, in full_dispatch_request
    rv = self.handle_user_exception(e)
  File "/home/www/.demo/lib/python2.7/site-packages/flask/app.py", line 1381, in handle_user_exception
    reraise(exc_type, exc_value, tb)
  File "/home/www/.demo/lib/python2.7/site-packages/flask/app.py", line 1475, in full_dispatch_request
    rv = self.dispatch_request()
  File "/home/www/.demo/lib/python2.7/site-packages/flask/app.py", line 1461, in dispatch_request
    return self.view_functions[rule.endpoint](**req.view_args)
  File "/home/www/.demo/lib/python2.7/site-packages/flask_login.py", line 758, in decorated_view
    return func(*args, **kwargs)
  File "/home/www/aud2/app/views/self.py", line 41, in app
    models.App_sites.id == int(item.site)).first()[0]
TypeError: 'NoneType' object has no attribute '__getitem__'
2016-08-19 18:49:10,508 ERROR: Exception on /self/app [POST] [in /home/www/.demo/lib/python2.7/site-packages/flask/app.py:1423]
Traceback (most recent call last):
  File "/home/www/.demo/lib/python2.7/site-packages/flask/app.py", line 1817, in wsgi_app
    response = self.full_dispatch_request()
  File "/home/www/.demo/lib/python2.7/site-packages/flask/app.py", line 1477, in full_dispatch_request
    rv = self.handle_user_exception(e)
  File "/home/www/.demo/lib/python2.7/site-packages/flask/app.py", line 1381, in handle_user_exception
    reraise(exc_type, exc_value, tb)
  File "/home/www/.demo/lib/python2.7/site-packages/flask/app.py", line 1475, in full_dispatch_request
    rv = self.dispatch_request()
  File "/home/www/.demo/lib/python2.7/site-packages/flask/app.py", line 1461, in dispatch_request
    return self.view_functions[rule.endpoint](**req.view_args)
  File "/home/www/.demo/lib/python2.7/site-packages/flask_login.py", line 758, in decorated_view
    return func(*args, **kwargs)
  File "/home/www/aud2/app/views/self.py", line 41, in app
    models.App_sites.id == int(item.site)).first()[0]
TypeError: 'NoneType' object has no attribute '__getitem__'
2016-08-19 18:56:47,384 ERROR: Exception on /api/v1.0/node_task/modify_status/dfebdea66829ffaab41ff3f199eacf5d [POST] [in /home/www/.demo/lib/python2.7/site-packages/flask/app.py:1423]
Traceback (most recent call last):
  File "/home/www/.demo/lib/python2.7/site-packages/flask/app.py", line 1817, in wsgi_app
    response = self.full_dispatch_request()
  File "/home/www/.demo/lib/python2.7/site-packages/flask/app.py", line 1477, in full_dispatch_request
    rv = self.handle_user_exception(e)
  File "/home/www/.demo/lib/python2.7/site-packages/flask/app.py", line 1381, in handle_user_exception
    reraise(exc_type, exc_value, tb)
  File "/home/www/.demo/lib/python2.7/site-packages/flask/app.py", line 1475, in full_dispatch_request
    rv = self.dispatch_request()
  File "/home/www/.demo/lib/python2.7/site-packages/flask/app.py", line 1461, in dispatch_request
    return self.view_functions[rule.endpoint](**req.view_args)
  File "/home/www/aud2/app/views/site.py", line 875, in modify_node_task_status
    mes.sendEmail()
  File "/home/www/aud2/app/utils/message.py", line 45, in sendEmail
    thr = Thread(target=send_async_email, args=[receiver + '@aicai.com', subject, html])
TypeError: unsupported operand type(s) for +: 'NoneType' and 'str'
2016-08-22 09:06:00,482 ERROR: Exception on /favicon.ico [GET] [in /home/www/.demo/lib/python2.7/site-packages/flask/app.py:1423]
Traceback (most recent call last):
  File "/home/www/.demo/lib/python2.7/site-packages/flask/app.py", line 1817, in wsgi_app
    response = self.full_dispatch_request()
  File "/home/www/.demo/lib/python2.7/site-packages/flask/app.py", line 1477, in full_dispatch_request
    rv = self.handle_user_exception(e)
  File "/home/www/.demo/lib/python2.7/site-packages/flask/app.py", line 1370, in handle_user_exception
    return self.handle_http_exception(e)
  File "/home/www/.demo/lib/python2.7/site-packages/flask/app.py", line 1330, in handle_http_exception
    return handler(e)
  File "/home/www/aud2/app/__init__.py", line 150, in page_404
    return render_template('errors/404.html'), 404
  File "/home/www/.demo/lib/python2.7/site-packages/flask/templating.py", line 128, in render_template
    context, ctx.app)
  File "/home/www/.demo/lib/python2.7/site-packages/flask/templating.py", line 110, in _render
    rv = template.render(context)
  File "/home/www/.demo/lib/python2.7/site-packages/jinja2/environment.py", line 969, in render
    return self.environment.handle_exception(exc_info, True)
  File "/home/www/.demo/lib/python2.7/site-packages/jinja2/environment.py", line 742, in handle_exception
    reraise(exc_type, exc_value, tb)
  File "/home/www/aud2/app/templates/errors/404.html", line 2, in top-level template code
    {% extends "base.html" %}
  File "/home/www/aud2/app/templates/base.html", line 26, in top-level template code
    {% include 'nav.html' %}
  File "/home/www/aud2/app/templates/nav.html", line 221, in top-level template code
    {% if g.user.is_admin() %}
UndefinedError: 'werkzeug.local.LocalProxy object' has no attribute 'is_admin'
2016-08-22 09:58:40,966 ERROR: Exception on /favicon.ico [GET] [in /home/www/.demo/lib/python2.7/site-packages/flask/app.py:1423]
Traceback (most recent call last):
  File "/home/www/.demo/lib/python2.7/site-packages/flask/app.py", line 1817, in wsgi_app
    response = self.full_dispatch_request()
  File "/home/www/.demo/lib/python2.7/site-packages/flask/app.py", line 1477, in full_dispatch_request
    rv = self.handle_user_exception(e)
  File "/home/www/.demo/lib/python2.7/site-packages/flask/app.py", line 1370, in handle_user_exception
    return self.handle_http_exception(e)
  File "/home/www/.demo/lib/python2.7/site-packages/flask/app.py", line 1330, in handle_http_exception
    return handler(e)
  File "/home/www/aud2/app/__init__.py", line 150, in page_404
    return render_template('errors/404.html'), 404
  File "/home/www/.demo/lib/python2.7/site-packages/flask/templating.py", line 128, in render_template
    context, ctx.app)
  File "/home/www/.demo/lib/python2.7/site-packages/flask/templating.py", line 110, in _render
    rv = template.render(context)
  File "/home/www/.demo/lib/python2.7/site-packages/jinja2/environment.py", line 969, in render
    return self.environment.handle_exception(exc_info, True)
  File "/home/www/.demo/lib/python2.7/site-packages/jinja2/environment.py", line 742, in handle_exception
    reraise(exc_type, exc_value, tb)
  File "/home/www/aud2/app/templates/errors/404.html", line 2, in top-level template code
    {% extends "base.html" %}
  File "/home/www/aud2/app/templates/base.html", line 26, in top-level template code
    {% include 'nav.html' %}
  File "/home/www/aud2/app/templates/nav.html", line 221, in top-level template code
    {% if g.user.is_admin() %}
UndefinedError: 'werkzeug.local.LocalProxy object' has no attribute 'is_admin'
2016-08-22 10:47:34,690 ERROR: Exception on /api/v1.0/tomcat_task/modify_status/TC-quiz_service-10-71-65-32-20160822104613 [POST] [in /home/www/.demo/lib/python2.7/site-packages/flask/app.py:1423]
Traceback (most recent call last):
  File "/home/www/.demo/lib/python2.7/site-packages/flask/app.py", line 1817, in wsgi_app
    response = self.full_dispatch_request()
  File "/home/www/.demo/lib/python2.7/site-packages/flask/app.py", line 1477, in full_dispatch_request
    rv = self.handle_user_exception(e)
  File "/home/www/.demo/lib/python2.7/site-packages/flask/app.py", line 1370, in handle_user_exception
    return self.handle_http_exception(e)
  File "/home/www/.demo/lib/python2.7/site-packages/flask/app.py", line 1330, in handle_http_exception
    return handler(e)
  File "/home/www/aud2/app/__init__.py", line 150, in page_404
    return render_template('errors/404.html'), 404
  File "/home/www/.demo/lib/python2.7/site-packages/flask/templating.py", line 128, in render_template
    context, ctx.app)
  File "/home/www/.demo/lib/python2.7/site-packages/flask/templating.py", line 110, in _render
    rv = template.render(context)
  File "/home/www/.demo/lib/python2.7/site-packages/jinja2/environment.py", line 969, in render
    return self.environment.handle_exception(exc_info, True)
  File "/home/www/.demo/lib/python2.7/site-packages/jinja2/environment.py", line 742, in handle_exception
    reraise(exc_type, exc_value, tb)
  File "/home/www/aud2/app/templates/errors/404.html", line 2, in top-level template code
    {% extends "base.html" %}
  File "/home/www/aud2/app/templates/base.html", line 26, in top-level template code
    {% include 'nav.html' %}
  File "/home/www/aud2/app/templates/nav.html", line 221, in top-level template code
    {% if g.user.is_admin() %}
UndefinedError: 'werkzeug.local.LocalProxy object' has no attribute 'is_admin'
2016-08-22 11:15:27,205 ERROR: Exception on /favicon.ico [GET] [in /home/www/.demo/lib/python2.7/site-packages/flask/app.py:1423]
Traceback (most recent call last):
  File "/home/www/.demo/lib/python2.7/site-packages/flask/app.py", line 1817, in wsgi_app
    response = self.full_dispatch_request()
  File "/home/www/.demo/lib/python2.7/site-packages/flask/app.py", line 1477, in full_dispatch_request
    rv = self.handle_user_exception(e)
  File "/home/www/.demo/lib/python2.7/site-packages/flask/app.py", line 1370, in handle_user_exception
    return self.handle_http_exception(e)
  File "/home/www/.demo/lib/python2.7/site-packages/flask/app.py", line 1330, in handle_http_exception
    return handler(e)
  File "/home/www/aud2/app/__init__.py", line 150, in page_404
    return render_template('errors/404.html'), 404
  File "/home/www/.demo/lib/python2.7/site-packages/flask/templating.py", line 128, in render_template
    context, ctx.app)
  File "/home/www/.demo/lib/python2.7/site-packages/flask/templating.py", line 110, in _render
    rv = template.render(context)
  File "/home/www/.demo/lib/python2.7/site-packages/jinja2/environment.py", line 969, in render
    return self.environment.handle_exception(exc_info, True)
  File "/home/www/.demo/lib/python2.7/site-packages/jinja2/environment.py", line 742, in handle_exception
    reraise(exc_type, exc_value, tb)
  File "/home/www/aud2/app/templates/errors/404.html", line 2, in top-level template code
    {% extends "base.html" %}
  File "/home/www/aud2/app/templates/base.html", line 26, in top-level template code
    {% include 'nav.html' %}
  File "/home/www/aud2/app/templates/nav.html", line 221, in top-level template code
    {% if g.user.is_admin() %}
UndefinedError: 'werkzeug.local.LocalProxy object' has no attribute 'is_admin'
2016-08-22 13:01:04,952 ERROR: Exception on /api/v1.0/node_task/modify_status/d295e4c2f822885591040a452cc37b1e [POST] [in /home/www/.demo/lib/python2.7/site-packages/flask/app.py:1423]
Traceback (most recent call last):
  File "/home/www/.demo/lib/python2.7/site-packages/flask/app.py", line 1817, in wsgi_app
    response = self.full_dispatch_request()
  File "/home/www/.demo/lib/python2.7/site-packages/flask/app.py", line 1477, in full_dispatch_request
    rv = self.handle_user_exception(e)
  File "/home/www/.demo/lib/python2.7/site-packages/flask/app.py", line 1381, in handle_user_exception
    reraise(exc_type, exc_value, tb)
  File "/home/www/.demo/lib/python2.7/site-packages/flask/app.py", line 1475, in full_dispatch_request
    rv = self.dispatch_request()
  File "/home/www/.demo/lib/python2.7/site-packages/flask/app.py", line 1461, in dispatch_request
    return self.view_functions[rule.endpoint](**req.view_args)
  File "/home/www/aud2/app/views/site.py", line 875, in modify_node_task_status
    mes.sendEmail()
  File "/home/www/aud2/app/utils/message.py", line 45, in sendEmail
    thr = Thread(target=send_async_email, args=[receiver + '@aicai.com', subject, html])
TypeError: unsupported operand type(s) for +: 'NoneType' and 'str'
2016-08-22 13:58:44,018 ERROR: Exception on /favicon.ico [GET] [in /home/www/.demo/lib/python2.7/site-packages/flask/app.py:1423]
Traceback (most recent call last):
  File "/home/www/.demo/lib/python2.7/site-packages/flask/app.py", line 1817, in wsgi_app
    response = self.full_dispatch_request()
  File "/home/www/.demo/lib/python2.7/site-packages/flask/app.py", line 1477, in full_dispatch_request
    rv = self.handle_user_exception(e)
  File "/home/www/.demo/lib/python2.7/site-packages/flask/app.py", line 1370, in handle_user_exception
    return self.handle_http_exception(e)
  File "/home/www/.demo/lib/python2.7/site-packages/flask/app.py", line 1330, in handle_http_exception
    return handler(e)
  File "/home/www/aud2/app/__init__.py", line 150, in page_404
    return render_template('errors/404.html'), 404
  File "/home/www/.demo/lib/python2.7/site-packages/flask/templating.py", line 128, in render_template
    context, ctx.app)
  File "/home/www/.demo/lib/python2.7/site-packages/flask/templating.py", line 110, in _render
    rv = template.render(context)
  File "/home/www/.demo/lib/python2.7/site-packages/jinja2/environment.py", line 969, in render
    return self.environment.handle_exception(exc_info, True)
  File "/home/www/.demo/lib/python2.7/site-packages/jinja2/environment.py", line 742, in handle_exception
    reraise(exc_type, exc_value, tb)
  File "/home/www/aud2/app/templates/errors/404.html", line 2, in top-level template code
    {% extends "base.html" %}
  File "/home/www/aud2/app/templates/base.html", line 26, in top-level template code
    {% include 'nav.html' %}
  File "/home/www/aud2/app/templates/nav.html", line 221, in top-level template code
    {% if g.user.is_admin() %}
UndefinedError: 'werkzeug.local.LocalProxy object' has no attribute 'is_admin'
2016-08-22 13:59:26,846 ERROR: Exception on /self/app [POST] [in /home/www/.demo/lib/python2.7/site-packages/flask/app.py:1423]
Traceback (most recent call last):
  File "/home/www/.demo/lib/python2.7/site-packages/flask/app.py", line 1817, in wsgi_app
    response = self.full_dispatch_request()
  File "/home/www/.demo/lib/python2.7/site-packages/flask/app.py", line 1477, in full_dispatch_request
    rv = self.handle_user_exception(e)
  File "/home/www/.demo/lib/python2.7/site-packages/flask/app.py", line 1381, in handle_user_exception
    reraise(exc_type, exc_value, tb)
  File "/home/www/.demo/lib/python2.7/site-packages/flask/app.py", line 1475, in full_dispatch_request
    rv = self.dispatch_request()
  File "/home/www/.demo/lib/python2.7/site-packages/flask/app.py", line 1461, in dispatch_request
    return self.view_functions[rule.endpoint](**req.view_args)
  File "/home/www/.demo/lib/python2.7/site-packages/flask_login.py", line 758, in decorated_view
    return func(*args, **kwargs)
  File "/home/www/aud2/app/views/self.py", line 41, in app
    models.App_sites.id == int(item.site)).first()[0]
TypeError: 'NoneType' object has no attribute '__getitem__'
2016-08-22 15:26:51,988 ERROR: Exception on /favicon.ico [GET] [in /home/www/.demo/lib/python2.7/site-packages/flask/app.py:1423]
Traceback (most recent call last):
  File "/home/www/.demo/lib/python2.7/site-packages/flask/app.py", line 1817, in wsgi_app
    response = self.full_dispatch_request()
  File "/home/www/.demo/lib/python2.7/site-packages/flask/app.py", line 1477, in full_dispatch_request
    rv = self.handle_user_exception(e)
  File "/home/www/.demo/lib/python2.7/site-packages/flask/app.py", line 1370, in handle_user_exception
    return self.handle_http_exception(e)
  File "/home/www/.demo/lib/python2.7/site-packages/flask/app.py", line 1330, in handle_http_exception
    return handler(e)
  File "/home/www/aud2/app/__init__.py", line 150, in page_404
    return render_template('errors/404.html'), 404
  File "/home/www/.demo/lib/python2.7/site-packages/flask/templating.py", line 128, in render_template
    context, ctx.app)
  File "/home/www/.demo/lib/python2.7/site-packages/flask/templating.py", line 110, in _render
    rv = template.render(context)
  File "/home/www/.demo/lib/python2.7/site-packages/jinja2/environment.py", line 969, in render
    return self.environment.handle_exception(exc_info, True)
  File "/home/www/.demo/lib/python2.7/site-packages/jinja2/environment.py", line 742, in handle_exception
    reraise(exc_type, exc_value, tb)
  File "/home/www/aud2/app/templates/errors/404.html", line 2, in top-level template code
    {% extends "base.html" %}
  File "/home/www/aud2/app/templates/base.html", line 26, in top-level template code
    {% include 'nav.html' %}
  File "/home/www/aud2/app/templates/nav.html", line 221, in top-level template code
    {% if g.user.is_admin() %}
UndefinedError: 'werkzeug.local.LocalProxy object' has no attribute 'is_admin'
2016-08-22 15:26:52,016 ERROR: Exception on /favicon.ico [GET] [in /home/www/.demo/lib/python2.7/site-packages/flask/app.py:1423]
Traceback (most recent call last):
  File "/home/www/.demo/lib/python2.7/site-packages/flask/app.py", line 1817, in wsgi_app
    response = self.full_dispatch_request()
  File "/home/www/.demo/lib/python2.7/site-packages/flask/app.py", line 1477, in full_dispatch_request
    rv = self.handle_user_exception(e)
  File "/home/www/.demo/lib/python2.7/site-packages/flask/app.py", line 1370, in handle_user_exception
    return self.handle_http_exception(e)
  File "/home/www/.demo/lib/python2.7/site-packages/flask/app.py", line 1330, in handle_http_exception
    return handler(e)
  File "/home/www/aud2/app/__init__.py", line 150, in page_404
    return render_template('errors/404.html'), 404
  File "/home/www/.demo/lib/python2.7/site-packages/flask/templating.py", line 128, in render_template
    context, ctx.app)
  File "/home/www/.demo/lib/python2.7/site-packages/flask/templating.py", line 110, in _render
    rv = template.render(context)
  File "/home/www/.demo/lib/python2.7/site-packages/jinja2/environment.py", line 969, in render
    return self.environment.handle_exception(exc_info, True)
  File "/home/www/.demo/lib/python2.7/site-packages/jinja2/environment.py", line 742, in handle_exception
    reraise(exc_type, exc_value, tb)
  File "/home/www/aud2/app/templates/errors/404.html", line 2, in top-level template code
    {% extends "base.html" %}
  File "/home/www/aud2/app/templates/base.html", line 26, in top-level template code
    {% include 'nav.html' %}
  File "/home/www/aud2/app/templates/nav.html", line 221, in top-level template code
    {% if g.user.is_admin() %}
UndefinedError: 'werkzeug.local.LocalProxy object' has no attribute 'is_admin'
2016-08-22 15:58:36,237 ERROR: Exception on /favicon.ico [GET] [in /home/www/.demo/lib/python2.7/site-packages/flask/app.py:1423]
Traceback (most recent call last):
  File "/home/www/.demo/lib/python2.7/site-packages/flask/app.py", line 1817, in wsgi_app
    response = self.full_dispatch_request()
  File "/home/www/.demo/lib/python2.7/site-packages/flask/app.py", line 1477, in full_dispatch_request
    rv = self.handle_user_exception(e)
  File "/home/www/.demo/lib/python2.7/site-packages/flask/app.py", line 1370, in handle_user_exception
    return self.handle_http_exception(e)
  File "/home/www/.demo/lib/python2.7/site-packages/flask/app.py", line 1330, in handle_http_exception
    return handler(e)
  File "/home/www/aud2/app/__init__.py", line 150, in page_404
    return render_template('errors/404.html'), 404
  File "/home/www/.demo/lib/python2.7/site-packages/flask/templating.py", line 128, in render_template
    context, ctx.app)
  File "/home/www/.demo/lib/python2.7/site-packages/flask/templating.py", line 110, in _render
    rv = template.render(context)
  File "/home/www/.demo/lib/python2.7/site-packages/jinja2/environment.py", line 969, in render
    return self.environment.handle_exception(exc_info, True)
  File "/home/www/.demo/lib/python2.7/site-packages/jinja2/environment.py", line 742, in handle_exception
    reraise(exc_type, exc_value, tb)
  File "/home/www/aud2/app/templates/errors/404.html", line 2, in top-level template code
    {% extends "base.html" %}
  File "/home/www/aud2/app/templates/base.html", line 26, in top-level template code
    {% include 'nav.html' %}
  File "/home/www/aud2/app/templates/nav.html", line 221, in top-level template code
    {% if g.user.is_admin() %}
UndefinedError: 'werkzeug.local.LocalProxy object' has no attribute 'is_admin'
2016-08-22 16:15:45,537 ERROR: Exception on /api/v1.0/node_task/modify_status/34300a9186522e623d677dc65f91183f [POST] [in /home/www/.demo/lib/python2.7/site-packages/flask/app.py:1423]
Traceback (most recent call last):
  File "/home/www/.demo/lib/python2.7/site-packages/flask/app.py", line 1817, in wsgi_app
    response = self.full_dispatch_request()
  File "/home/www/.demo/lib/python2.7/site-packages/flask/app.py", line 1477, in full_dispatch_request
    rv = self.handle_user_exception(e)
  File "/home/www/.demo/lib/python2.7/site-packages/flask/app.py", line 1381, in handle_user_exception
    reraise(exc_type, exc_value, tb)
  File "/home/www/.demo/lib/python2.7/site-packages/flask/app.py", line 1475, in full_dispatch_request
    rv = self.dispatch_request()
  File "/home/www/.demo/lib/python2.7/site-packages/flask/app.py", line 1461, in dispatch_request
    return self.view_functions[rule.endpoint](**req.view_args)
  File "/home/www/aud2/app/views/site.py", line 875, in modify_node_task_status
    mes.sendEmail()
  File "/home/www/aud2/app/utils/message.py", line 45, in sendEmail
    thr = Thread(target=send_async_email, args=[receiver + '@aicai.com', subject, html])
TypeError: unsupported operand type(s) for +: 'NoneType' and 'str'
2016-08-22 16:36:14,272 ERROR: Exception on /favicon.ico [GET] [in /home/www/.demo/lib/python2.7/site-packages/flask/app.py:1423]
Traceback (most recent call last):
  File "/home/www/.demo/lib/python2.7/site-packages/flask/app.py", line 1817, in wsgi_app
    response = self.full_dispatch_request()
  File "/home/www/.demo/lib/python2.7/site-packages/flask/app.py", line 1477, in full_dispatch_request
    rv = self.handle_user_exception(e)
  File "/home/www/.demo/lib/python2.7/site-packages/flask/app.py", line 1370, in handle_user_exception
    return self.handle_http_exception(e)
  File "/home/www/.demo/lib/python2.7/site-packages/flask/app.py", line 1330, in handle_http_exception
    return handler(e)
  File "/home/www/aud2/app/__init__.py", line 150, in page_404
    return render_template('errors/404.html'), 404
  File "/home/www/.demo/lib/python2.7/site-packages/flask/templating.py", line 128, in render_template
    context, ctx.app)
  File "/home/www/.demo/lib/python2.7/site-packages/flask/templating.py", line 110, in _render
    rv = template.render(context)
  File "/home/www/.demo/lib/python2.7/site-packages/jinja2/environment.py", line 969, in render
    return self.environment.handle_exception(exc_info, True)
  File "/home/www/.demo/lib/python2.7/site-packages/jinja2/environment.py", line 742, in handle_exception
    reraise(exc_type, exc_value, tb)
  File "/home/www/aud2/app/templates/errors/404.html", line 2, in top-level template code
    {% extends "base.html" %}
  File "/home/www/aud2/app/templates/base.html", line 26, in top-level template code
    {% include 'nav.html' %}
  File "/home/www/aud2/app/templates/nav.html", line 221, in top-level template code
    {% if g.user.is_admin() %}
UndefinedError: 'werkzeug.local.LocalProxy object' has no attribute 'is_admin'
2016-08-22 17:48:35,009 ERROR: Exception on /favicon.ico [GET] [in /home/www/.demo/lib/python2.7/site-packages/flask/app.py:1423]
Traceback (most recent call last):
  File "/home/www/.demo/lib/python2.7/site-packages/flask/app.py", line 1817, in wsgi_app
    response = self.full_dispatch_request()
  File "/home/www/.demo/lib/python2.7/site-packages/flask/app.py", line 1477, in full_dispatch_request
    rv = self.handle_user_exception(e)
  File "/home/www/.demo/lib/python2.7/site-packages/flask/app.py", line 1370, in handle_user_exception
    return self.handle_http_exception(e)
  File "/home/www/.demo/lib/python2.7/site-packages/flask/app.py", line 1330, in handle_http_exception
    return handler(e)
  File "/home/www/aud2/app/__init__.py", line 150, in page_404
    return render_template('errors/404.html'), 404
  File "/home/www/.demo/lib/python2.7/site-packages/flask/templating.py", line 128, in render_template
    context, ctx.app)
  File "/home/www/.demo/lib/python2.7/site-packages/flask/templating.py", line 110, in _render
    rv = template.render(context)
  File "/home/www/.demo/lib/python2.7/site-packages/jinja2/environment.py", line 969, in render
    return self.environment.handle_exception(exc_info, True)
  File "/home/www/.demo/lib/python2.7/site-packages/jinja2/environment.py", line 742, in handle_exception
    reraise(exc_type, exc_value, tb)
  File "/home/www/aud2/app/templates/errors/404.html", line 2, in top-level template code
    {% extends "base.html" %}
  File "/home/www/aud2/app/templates/base.html", line 26, in top-level template code
    {% include 'nav.html' %}
  File "/home/www/aud2/app/templates/nav.html", line 221, in top-level template code
    {% if g.user.is_admin() %}
UndefinedError: 'werkzeug.local.LocalProxy object' has no attribute 'is_admin'
2016-08-22 17:59:00,554 ERROR: Exception on /favicon.ico [GET] [in /home/www/.demo/lib/python2.7/site-packages/flask/app.py:1423]
Traceback (most recent call last):
  File "/home/www/.demo/lib/python2.7/site-packages/flask/app.py", line 1817, in wsgi_app
    response = self.full_dispatch_request()
  File "/home/www/.demo/lib/python2.7/site-packages/flask/app.py", line 1477, in full_dispatch_request
    rv = self.handle_user_exception(e)
  File "/home/www/.demo/lib/python2.7/site-packages/flask/app.py", line 1370, in handle_user_exception
    return self.handle_http_exception(e)
  File "/home/www/.demo/lib/python2.7/site-packages/flask/app.py", line 1330, in handle_http_exception
    return handler(e)
  File "/home/www/aud2/app/__init__.py", line 150, in page_404
    return render_template('errors/404.html'), 404
  File "/home/www/.demo/lib/python2.7/site-packages/flask/templating.py", line 128, in render_template
    context, ctx.app)
  File "/home/www/.demo/lib/python2.7/site-packages/flask/templating.py", line 110, in _render
    rv = template.render(context)
  File "/home/www/.demo/lib/python2.7/site-packages/jinja2/environment.py", line 969, in render
    return self.environment.handle_exception(exc_info, True)
  File "/home/www/.demo/lib/python2.7/site-packages/jinja2/environment.py", line 742, in handle_exception
    reraise(exc_type, exc_value, tb)
  File "/home/www/aud2/app/templates/errors/404.html", line 2, in top-level template code
    {% extends "base.html" %}
  File "/home/www/aud2/app/templates/base.html", line 26, in top-level template code
    {% include 'nav.html' %}
  File "/home/www/aud2/app/templates/nav.html", line 221, in top-level template code
    {% if g.user.is_admin() %}
UndefinedError: 'werkzeug.local.LocalProxy object' has no attribute 'is_admin'
2016-08-22 18:04:08,727 ERROR: Exception on /api/v1.0/tomcat_task/modify_status/TC-hs_admin-172-16-168-5-20160822180405 [POST] [in /home/www/.demo/lib/python2.7/site-packages/flask/app.py:1423]
Traceback (most recent call last):
  File "/home/www/.demo/lib/python2.7/site-packages/flask/app.py", line 1817, in wsgi_app
    response = self.full_dispatch_request()
  File "/home/www/.demo/lib/python2.7/site-packages/flask/app.py", line 1477, in full_dispatch_request
    rv = self.handle_user_exception(e)
  File "/home/www/.demo/lib/python2.7/site-packages/flask/app.py", line 1370, in handle_user_exception
    return self.handle_http_exception(e)
  File "/home/www/.demo/lib/python2.7/site-packages/flask/app.py", line 1330, in handle_http_exception
    return handler(e)
  File "/home/www/aud2/app/__init__.py", line 150, in page_404
    return render_template('errors/404.html'), 404
  File "/home/www/.demo/lib/python2.7/site-packages/flask/templating.py", line 128, in render_template
    context, ctx.app)
  File "/home/www/.demo/lib/python2.7/site-packages/flask/templating.py", line 110, in _render
    rv = template.render(context)
  File "/home/www/.demo/lib/python2.7/site-packages/jinja2/environment.py", line 969, in render
    return self.environment.handle_exception(exc_info, True)
  File "/home/www/.demo/lib/python2.7/site-packages/jinja2/environment.py", line 742, in handle_exception
    reraise(exc_type, exc_value, tb)
  File "/home/www/aud2/app/templates/errors/404.html", line 2, in top-level template code
    {% extends "base.html" %}
  File "/home/www/aud2/app/templates/base.html", line 26, in top-level template code
    {% include 'nav.html' %}
  File "/home/www/aud2/app/templates/nav.html", line 221, in top-level template code
    {% if g.user.is_admin() %}
UndefinedError: 'werkzeug.local.LocalProxy object' has no attribute 'is_admin'
2016-08-22 18:05:44,632 ERROR: Exception on /deploy/tasklog/ [GET] [in /home/www/.demo/lib/python2.7/site-packages/flask/app.py:1423]
Traceback (most recent call last):
  File "/home/www/.demo/lib/python2.7/site-packages/flask/app.py", line 1817, in wsgi_app
    response = self.full_dispatch_request()
  File "/home/www/.demo/lib/python2.7/site-packages/flask/app.py", line 1477, in full_dispatch_request
    rv = self.handle_user_exception(e)
  File "/home/www/.demo/lib/python2.7/site-packages/flask/app.py", line 1381, in handle_user_exception
    reraise(exc_type, exc_value, tb)
  File "/home/www/.demo/lib/python2.7/site-packages/flask/app.py", line 1475, in full_dispatch_request
    rv = self.dispatch_request()
  File "/home/www/.demo/lib/python2.7/site-packages/flask/app.py", line 1461, in dispatch_request
    return self.view_functions[rule.endpoint](**req.view_args)
  File "/home/www/.demo/lib/python2.7/site-packages/flask_login.py", line 758, in decorated_view
    return func(*args, **kwargs)
  File "/home/www/aud2/app/views/deploy.py", line 1072, in tasklog
    with open(tasklog, 'r') as file:
IOError: [Errno 2] No such file or directory: u'/data0/www/aud.inzwc.com/tasklogs/TC-hs_admin-172-16-168-5-20160822180405.log'
2016-08-22 18:19:59,390 ERROR: Exception on /api/v1.0/tomcat_task/modify_status/TC-hs_admin-172-16-168-6-20160822181955 [POST] [in /home/www/.demo/lib/python2.7/site-packages/flask/app.py:1423]
Traceback (most recent call last):
  File "/home/www/.demo/lib/python2.7/site-packages/flask/app.py", line 1817, in wsgi_app
    response = self.full_dispatch_request()
  File "/home/www/.demo/lib/python2.7/site-packages/flask/app.py", line 1477, in full_dispatch_request
    rv = self.handle_user_exception(e)
  File "/home/www/.demo/lib/python2.7/site-packages/flask/app.py", line 1370, in handle_user_exception
    return self.handle_http_exception(e)
  File "/home/www/.demo/lib/python2.7/site-packages/flask/app.py", line 1330, in handle_http_exception
    return handler(e)
  File "/home/www/aud2/app/__init__.py", line 150, in page_404
    return render_template('errors/404.html'), 404
  File "/home/www/.demo/lib/python2.7/site-packages/flask/templating.py", line 128, in render_template
    context, ctx.app)
  File "/home/www/.demo/lib/python2.7/site-packages/flask/templating.py", line 110, in _render
    rv = template.render(context)
  File "/home/www/.demo/lib/python2.7/site-packages/jinja2/environment.py", line 969, in render
    return self.environment.handle_exception(exc_info, True)
  File "/home/www/.demo/lib/python2.7/site-packages/jinja2/environment.py", line 742, in handle_exception
    reraise(exc_type, exc_value, tb)
  File "/home/www/aud2/app/templates/errors/404.html", line 2, in top-level template code
    {% extends "base.html" %}
  File "/home/www/aud2/app/templates/base.html", line 26, in top-level template code
    {% include 'nav.html' %}
  File "/home/www/aud2/app/templates/nav.html", line 221, in top-level template code
    {% if g.user.is_admin() %}
UndefinedError: 'werkzeug.local.LocalProxy object' has no attribute 'is_admin'
2016-08-22 19:26:21,763 ERROR: Exception on /favicon.ico [GET] [in /home/www/.demo/lib/python2.7/site-packages/flask/app.py:1423]
Traceback (most recent call last):
  File "/home/www/.demo/lib/python2.7/site-packages/flask/app.py", line 1817, in wsgi_app
    response = self.full_dispatch_request()
  File "/home/www/.demo/lib/python2.7/site-packages/flask/app.py", line 1477, in full_dispatch_request
    rv = self.handle_user_exception(e)
  File "/home/www/.demo/lib/python2.7/site-packages/flask/app.py", line 1370, in handle_user_exception
    return self.handle_http_exception(e)
  File "/home/www/.demo/lib/python2.7/site-packages/flask/app.py", line 1330, in handle_http_exception
    return handler(e)
  File "/home/www/aud2/app/__init__.py", line 150, in page_404
    return render_template('errors/404.html'), 404
  File "/home/www/.demo/lib/python2.7/site-packages/flask/templating.py", line 128, in render_template
    context, ctx.app)
  File "/home/www/.demo/lib/python2.7/site-packages/flask/templating.py", line 110, in _render
    rv = template.render(context)
  File "/home/www/.demo/lib/python2.7/site-packages/jinja2/environment.py", line 969, in render
    return self.environment.handle_exception(exc_info, True)
  File "/home/www/.demo/lib/python2.7/site-packages/jinja2/environment.py", line 742, in handle_exception
    reraise(exc_type, exc_value, tb)
  File "/home/www/aud2/app/templates/errors/404.html", line 2, in top-level template code
    {% extends "base.html" %}
  File "/home/www/aud2/app/templates/base.html", line 26, in top-level template code
    {% include 'nav.html' %}
  File "/home/www/aud2/app/templates/nav.html", line 221, in top-level template code
    {% if g.user.is_admin() %}
UndefinedError: 'werkzeug.local.LocalProxy object' has no attribute 'is_admin'
2016-08-22 19:57:21,232 ERROR: Exception on /favicon.ico [GET] [in /home/www/.demo/lib/python2.7/site-packages/flask/app.py:1423]
Traceback (most recent call last):
  File "/home/www/.demo/lib/python2.7/site-packages/flask/app.py", line 1817, in wsgi_app
    response = self.full_dispatch_request()
  File "/home/www/.demo/lib/python2.7/site-packages/flask/app.py", line 1477, in full_dispatch_request
    rv = self.handle_user_exception(e)
  File "/home/www/.demo/lib/python2.7/site-packages/flask/app.py", line 1370, in handle_user_exception
    return self.handle_http_exception(e)
  File "/home/www/.demo/lib/python2.7/site-packages/flask/app.py", line 1330, in handle_http_exception
    return handler(e)
  File "/home/www/aud2/app/__init__.py", line 150, in page_404
    return render_template('errors/404.html'), 404
  File "/home/www/.demo/lib/python2.7/site-packages/flask/templating.py", line 128, in render_template
    context, ctx.app)
  File "/home/www/.demo/lib/python2.7/site-packages/flask/templating.py", line 110, in _render
    rv = template.render(context)
  File "/home/www/.demo/lib/python2.7/site-packages/jinja2/environment.py", line 969, in render
    return self.environment.handle_exception(exc_info, True)
  File "/home/www/.demo/lib/python2.7/site-packages/jinja2/environment.py", line 742, in handle_exception
    reraise(exc_type, exc_value, tb)
  File "/home/www/aud2/app/templates/errors/404.html", line 2, in top-level template code
    {% extends "base.html" %}
  File "/home/www/aud2/app/templates/base.html", line 26, in top-level template code
    {% include 'nav.html' %}
  File "/home/www/aud2/app/templates/nav.html", line 221, in top-level template code
    {% if g.user.is_admin() %}
UndefinedError: 'werkzeug.local.LocalProxy object' has no attribute 'is_admin'
2016-08-22 19:57:27,506 ERROR: Exception on /favicon.ico [GET] [in /home/www/.demo/lib/python2.7/site-packages/flask/app.py:1423]
Traceback (most recent call last):
  File "/home/www/.demo/lib/python2.7/site-packages/flask/app.py", line 1817, in wsgi_app
    response = self.full_dispatch_request()
  File "/home/www/.demo/lib/python2.7/site-packages/flask/app.py", line 1477, in full_dispatch_request
    rv = self.handle_user_exception(e)
  File "/home/www/.demo/lib/python2.7/site-packages/flask/app.py", line 1370, in handle_user_exception
    return self.handle_http_exception(e)
  File "/home/www/.demo/lib/python2.7/site-packages/flask/app.py", line 1330, in handle_http_exception
    return handler(e)
  File "/home/www/aud2/app/__init__.py", line 150, in page_404
    return render_template('errors/404.html'), 404
  File "/home/www/.demo/lib/python2.7/site-packages/flask/templating.py", line 128, in render_template
    context, ctx.app)
  File "/home/www/.demo/lib/python2.7/site-packages/flask/templating.py", line 110, in _render
    rv = template.render(context)
  File "/home/www/.demo/lib/python2.7/site-packages/jinja2/environment.py", line 969, in render
    return self.environment.handle_exception(exc_info, True)
  File "/home/www/.demo/lib/python2.7/site-packages/jinja2/environment.py", line 742, in handle_exception
    reraise(exc_type, exc_value, tb)
  File "/home/www/aud2/app/templates/errors/404.html", line 2, in top-level template code
    {% extends "base.html" %}
  File "/home/www/aud2/app/templates/base.html", line 26, in top-level template code
    {% include 'nav.html' %}
  File "/home/www/aud2/app/templates/nav.html", line 221, in top-level template code
    {% if g.user.is_admin() %}
UndefinedError: 'werkzeug.local.LocalProxy object' has no attribute 'is_admin'
2016-08-22 19:57:39,724 ERROR: Exception on /favicon.ico [GET] [in /home/www/.demo/lib/python2.7/site-packages/flask/app.py:1423]
Traceback (most recent call last):
  File "/home/www/.demo/lib/python2.7/site-packages/flask/app.py", line 1817, in wsgi_app
    response = self.full_dispatch_request()
  File "/home/www/.demo/lib/python2.7/site-packages/flask/app.py", line 1477, in full_dispatch_request
    rv = self.handle_user_exception(e)
  File "/home/www/.demo/lib/python2.7/site-packages/flask/app.py", line 1370, in handle_user_exception
    return self.handle_http_exception(e)
  File "/home/www/.demo/lib/python2.7/site-packages/flask/app.py", line 1330, in handle_http_exception
    return handler(e)
  File "/home/www/aud2/app/__init__.py", line 150, in page_404
    return render_template('errors/404.html'), 404
  File "/home/www/.demo/lib/python2.7/site-packages/flask/templating.py", line 128, in render_template
    context, ctx.app)
  File "/home/www/.demo/lib/python2.7/site-packages/flask/templating.py", line 110, in _render
    rv = template.render(context)
  File "/home/www/.demo/lib/python2.7/site-packages/jinja2/environment.py", line 969, in render
    return self.environment.handle_exception(exc_info, True)
  File "/home/www/.demo/lib/python2.7/site-packages/jinja2/environment.py", line 742, in handle_exception
    reraise(exc_type, exc_value, tb)
  File "/home/www/aud2/app/templates/errors/404.html", line 2, in top-level template code
    {% extends "base.html" %}
  File "/home/www/aud2/app/templates/base.html", line 26, in top-level template code
    {% include 'nav.html' %}
  File "/home/www/aud2/app/templates/nav.html", line 221, in top-level template code
    {% if g.user.is_admin() %}
UndefinedError: 'werkzeug.local.LocalProxy object' has no attribute 'is_admin'
2016-08-22 21:57:24,101 ERROR: Exception on /favicon.ico [GET] [in /home/www/.demo/lib/python2.7/site-packages/flask/app.py:1423]
Traceback (most recent call last):
  File "/home/www/.demo/lib/python2.7/site-packages/flask/app.py", line 1817, in wsgi_app
    response = self.full_dispatch_request()
  File "/home/www/.demo/lib/python2.7/site-packages/flask/app.py", line 1477, in full_dispatch_request
    rv = self.handle_user_exception(e)
  File "/home/www/.demo/lib/python2.7/site-packages/flask/app.py", line 1370, in handle_user_exception
    return self.handle_http_exception(e)
  File "/home/www/.demo/lib/python2.7/site-packages/flask/app.py", line 1330, in handle_http_exception
    return handler(e)
  File "/home/www/aud2/app/__init__.py", line 150, in page_404
    return render_template('errors/404.html'), 404
  File "/home/www/.demo/lib/python2.7/site-packages/flask/templating.py", line 128, in render_template
    context, ctx.app)
  File "/home/www/.demo/lib/python2.7/site-packages/flask/templating.py", line 110, in _render
    rv = template.render(context)
  File "/home/www/.demo/lib/python2.7/site-packages/jinja2/environment.py", line 969, in render
    return self.environment.handle_exception(exc_info, True)
  File "/home/www/.demo/lib/python2.7/site-packages/jinja2/environment.py", line 742, in handle_exception
    reraise(exc_type, exc_value, tb)
  File "/home/www/aud2/app/templates/errors/404.html", line 2, in top-level template code
    {% extends "base.html" %}
  File "/home/www/aud2/app/templates/base.html", line 26, in top-level template code
    {% include 'nav.html' %}
  File "/home/www/aud2/app/templates/nav.html", line 221, in top-level template code
    {% if g.user.is_admin() %}
UndefinedError: 'werkzeug.local.LocalProxy object' has no attribute 'is_admin'
2016-08-22 23:04:23,014 ERROR: Exception on /favicon.ico [GET] [in /home/www/.demo/lib/python2.7/site-packages/flask/app.py:1423]
Traceback (most recent call last):
  File "/home/www/.demo/lib/python2.7/site-packages/flask/app.py", line 1817, in wsgi_app
    response = self.full_dispatch_request()
  File "/home/www/.demo/lib/python2.7/site-packages/flask/app.py", line 1477, in full_dispatch_request
    rv = self.handle_user_exception(e)
  File "/home/www/.demo/lib/python2.7/site-packages/flask/app.py", line 1370, in handle_user_exception
    return self.handle_http_exception(e)
  File "/home/www/.demo/lib/python2.7/site-packages/flask/app.py", line 1330, in handle_http_exception
    return handler(e)
  File "/home/www/aud2/app/__init__.py", line 150, in page_404
    return render_template('errors/404.html'), 404
  File "/home/www/.demo/lib/python2.7/site-packages/flask/templating.py", line 128, in render_template
    context, ctx.app)
  File "/home/www/.demo/lib/python2.7/site-packages/flask/templating.py", line 110, in _render
    rv = template.render(context)
  File "/home/www/.demo/lib/python2.7/site-packages/jinja2/environment.py", line 969, in render
    return self.environment.handle_exception(exc_info, True)
  File "/home/www/.demo/lib/python2.7/site-packages/jinja2/environment.py", line 742, in handle_exception
    reraise(exc_type, exc_value, tb)
  File "/home/www/aud2/app/templates/errors/404.html", line 2, in top-level template code
    {% extends "base.html" %}
  File "/home/www/aud2/app/templates/base.html", line 26, in top-level template code
    {% include 'nav.html' %}
  File "/home/www/aud2/app/templates/nav.html", line 221, in top-level template code
    {% if g.user.is_admin() %}
UndefinedError: 'werkzeug.local.LocalProxy object' has no attribute 'is_admin'
2016-08-22 23:04:23,031 ERROR: Exception on /favicon.ico [GET] [in /home/www/.demo/lib/python2.7/site-packages/flask/app.py:1423]
Traceback (most recent call last):
  File "/home/www/.demo/lib/python2.7/site-packages/flask/app.py", line 1817, in wsgi_app
    response = self.full_dispatch_request()
  File "/home/www/.demo/lib/python2.7/site-packages/flask/app.py", line 1477, in full_dispatch_request
    rv = self.handle_user_exception(e)
  File "/home/www/.demo/lib/python2.7/site-packages/flask/app.py", line 1370, in handle_user_exception
    return self.handle_http_exception(e)
  File "/home/www/.demo/lib/python2.7/site-packages/flask/app.py", line 1330, in handle_http_exception
    return handler(e)
  File "/home/www/aud2/app/__init__.py", line 150, in page_404
    return render_template('errors/404.html'), 404
  File "/home/www/.demo/lib/python2.7/site-packages/flask/templating.py", line 128, in render_template
    context, ctx.app)
  File "/home/www/.demo/lib/python2.7/site-packages/flask/templating.py", line 110, in _render
    rv = template.render(context)
  File "/home/www/.demo/lib/python2.7/site-packages/jinja2/environment.py", line 969, in render
    return self.environment.handle_exception(exc_info, True)
  File "/home/www/.demo/lib/python2.7/site-packages/jinja2/environment.py", line 742, in handle_exception
    reraise(exc_type, exc_value, tb)
  File "/home/www/aud2/app/templates/errors/404.html", line 2, in top-level template code
    {% extends "base.html" %}
  File "/home/www/aud2/app/templates/base.html", line 26, in top-level template code
    {% include 'nav.html' %}
  File "/home/www/aud2/app/templates/nav.html", line 221, in top-level template code
    {% if g.user.is_admin() %}
UndefinedError: 'werkzeug.local.LocalProxy object' has no attribute 'is_admin'
2016-08-23 07:11:24,346 ERROR: Exception on /favicon.ico [GET] [in /home/www/.demo/lib/python2.7/site-packages/flask/app.py:1423]
Traceback (most recent call last):
  File "/home/www/.demo/lib/python2.7/site-packages/flask/app.py", line 1817, in wsgi_app
    response = self.full_dispatch_request()
  File "/home/www/.demo/lib/python2.7/site-packages/flask/app.py", line 1477, in full_dispatch_request
    rv = self.handle_user_exception(e)
  File "/home/www/.demo/lib/python2.7/site-packages/flask/app.py", line 1370, in handle_user_exception
    return self.handle_http_exception(e)
  File "/home/www/.demo/lib/python2.7/site-packages/flask/app.py", line 1330, in handle_http_exception
    return handler(e)
  File "/home/www/aud2/app/__init__.py", line 150, in page_404
    return render_template('errors/404.html'), 404
  File "/home/www/.demo/lib/python2.7/site-packages/flask/templating.py", line 128, in render_template
    context, ctx.app)
  File "/home/www/.demo/lib/python2.7/site-packages/flask/templating.py", line 110, in _render
    rv = template.render(context)
  File "/home/www/.demo/lib/python2.7/site-packages/jinja2/environment.py", line 969, in render
    return self.environment.handle_exception(exc_info, True)
  File "/home/www/.demo/lib/python2.7/site-packages/jinja2/environment.py", line 742, in handle_exception
    reraise(exc_type, exc_value, tb)
  File "/home/www/aud2/app/templates/errors/404.html", line 2, in top-level template code
    {% extends "base.html" %}
  File "/home/www/aud2/app/templates/base.html", line 26, in top-level template code
    {% include 'nav.html' %}
  File "/home/www/aud2/app/templates/nav.html", line 221, in top-level template code
    {% if g.user.is_admin() %}
UndefinedError: 'werkzeug.local.LocalProxy object' has no attribute 'is_admin'
2016-08-23 07:11:24,372 ERROR: Exception on /favicon.ico [GET] [in /home/www/.demo/lib/python2.7/site-packages/flask/app.py:1423]
Traceback (most recent call last):
  File "/home/www/.demo/lib/python2.7/site-packages/flask/app.py", line 1817, in wsgi_app
    response = self.full_dispatch_request()
  File "/home/www/.demo/lib/python2.7/site-packages/flask/app.py", line 1477, in full_dispatch_request
    rv = self.handle_user_exception(e)
  File "/home/www/.demo/lib/python2.7/site-packages/flask/app.py", line 1370, in handle_user_exception
    return self.handle_http_exception(e)
  File "/home/www/.demo/lib/python2.7/site-packages/flask/app.py", line 1330, in handle_http_exception
    return handler(e)
  File "/home/www/aud2/app/__init__.py", line 150, in page_404
    return render_template('errors/404.html'), 404
  File "/home/www/.demo/lib/python2.7/site-packages/flask/templating.py", line 128, in render_template
    context, ctx.app)
  File "/home/www/.demo/lib/python2.7/site-packages/flask/templating.py", line 110, in _render
    rv = template.render(context)
  File "/home/www/.demo/lib/python2.7/site-packages/jinja2/environment.py", line 969, in render
    return self.environment.handle_exception(exc_info, True)
  File "/home/www/.demo/lib/python2.7/site-packages/jinja2/environment.py", line 742, in handle_exception
    reraise(exc_type, exc_value, tb)
  File "/home/www/aud2/app/templates/errors/404.html", line 2, in top-level template code
    {% extends "base.html" %}
  File "/home/www/aud2/app/templates/base.html", line 26, in top-level template code
    {% include 'nav.html' %}
  File "/home/www/aud2/app/templates/nav.html", line 221, in top-level template code
    {% if g.user.is_admin() %}
UndefinedError: 'werkzeug.local.LocalProxy object' has no attribute 'is_admin'
2016-08-23 07:23:14,309 ERROR: Exception on /api/v1.0/node_task/modify_status/7f99d1138ac6ff14adca5c70d780b74b [POST] [in /home/www/.demo/lib/python2.7/site-packages/flask/app.py:1423]
Traceback (most recent call last):
  File "/home/www/.demo/lib/python2.7/site-packages/flask/app.py", line 1817, in wsgi_app
    response = self.full_dispatch_request()
  File "/home/www/.demo/lib/python2.7/site-packages/flask/app.py", line 1477, in full_dispatch_request
    rv = self.handle_user_exception(e)
  File "/home/www/.demo/lib/python2.7/site-packages/flask/app.py", line 1381, in handle_user_exception
    reraise(exc_type, exc_value, tb)
  File "/home/www/.demo/lib/python2.7/site-packages/flask/app.py", line 1475, in full_dispatch_request
    rv = self.dispatch_request()
  File "/home/www/.demo/lib/python2.7/site-packages/flask/app.py", line 1461, in dispatch_request
    return self.view_functions[rule.endpoint](**req.view_args)
  File "/home/www/aud2/app/views/site.py", line 875, in modify_node_task_status
    mes.sendEmail()
  File "/home/www/aud2/app/utils/message.py", line 45, in sendEmail
    thr = Thread(target=send_async_email, args=[receiver + '@aicai.com', subject, html])
TypeError: unsupported operand type(s) for +: 'NoneType' and 'str'
2016-08-23 07:24:47,507 ERROR: Exception on /api/v1.0/node_task/modify_status/87253d2ef40faddb0614e70f35286374 [POST] [in /home/www/.demo/lib/python2.7/site-packages/flask/app.py:1423]
Traceback (most recent call last):
  File "/home/www/.demo/lib/python2.7/site-packages/flask/app.py", line 1817, in wsgi_app
    response = self.full_dispatch_request()
  File "/home/www/.demo/lib/python2.7/site-packages/flask/app.py", line 1477, in full_dispatch_request
    rv = self.handle_user_exception(e)
  File "/home/www/.demo/lib/python2.7/site-packages/flask/app.py", line 1381, in handle_user_exception
    reraise(exc_type, exc_value, tb)
  File "/home/www/.demo/lib/python2.7/site-packages/flask/app.py", line 1475, in full_dispatch_request
    rv = self.dispatch_request()
  File "/home/www/.demo/lib/python2.7/site-packages/flask/app.py", line 1461, in dispatch_request
    return self.view_functions[rule.endpoint](**req.view_args)
  File "/home/www/aud2/app/views/site.py", line 875, in modify_node_task_status
    mes.sendEmail()
  File "/home/www/aud2/app/utils/message.py", line 45, in sendEmail
    thr = Thread(target=send_async_email, args=[receiver + '@aicai.com', subject, html])
TypeError: unsupported operand type(s) for +: 'NoneType' and 'str'
2016-08-23 07:26:32,305 ERROR: Exception on /api/v1.0/node_task/modify_status/65b4c6e02a2fc6473a359b65975cf7b7 [POST] [in /home/www/.demo/lib/python2.7/site-packages/flask/app.py:1423]
Traceback (most recent call last):
  File "/home/www/.demo/lib/python2.7/site-packages/flask/app.py", line 1817, in wsgi_app
    response = self.full_dispatch_request()
  File "/home/www/.demo/lib/python2.7/site-packages/flask/app.py", line 1477, in full_dispatch_request
    rv = self.handle_user_exception(e)
  File "/home/www/.demo/lib/python2.7/site-packages/flask/app.py", line 1381, in handle_user_exception
    reraise(exc_type, exc_value, tb)
  File "/home/www/.demo/lib/python2.7/site-packages/flask/app.py", line 1475, in full_dispatch_request
    rv = self.dispatch_request()
  File "/home/www/.demo/lib/python2.7/site-packages/flask/app.py", line 1461, in dispatch_request
    return self.view_functions[rule.endpoint](**req.view_args)
  File "/home/www/aud2/app/views/site.py", line 875, in modify_node_task_status
    mes.sendEmail()
  File "/home/www/aud2/app/utils/message.py", line 45, in sendEmail
    thr = Thread(target=send_async_email, args=[receiver + '@aicai.com', subject, html])
TypeError: unsupported operand type(s) for +: 'NoneType' and 'str'
2016-08-23 07:28:03,924 ERROR: Exception on /api/v1.0/node_task/modify_status/005603fac9633b1663eb165c6b6b5ce6 [POST] [in /home/www/.demo/lib/python2.7/site-packages/flask/app.py:1423]
Traceback (most recent call last):
  File "/home/www/.demo/lib/python2.7/site-packages/flask/app.py", line 1817, in wsgi_app
    response = self.full_dispatch_request()
  File "/home/www/.demo/lib/python2.7/site-packages/flask/app.py", line 1477, in full_dispatch_request
    rv = self.handle_user_exception(e)
  File "/home/www/.demo/lib/python2.7/site-packages/flask/app.py", line 1381, in handle_user_exception
    reraise(exc_type, exc_value, tb)
  File "/home/www/.demo/lib/python2.7/site-packages/flask/app.py", line 1475, in full_dispatch_request
    rv = self.dispatch_request()
  File "/home/www/.demo/lib/python2.7/site-packages/flask/app.py", line 1461, in dispatch_request
    return self.view_functions[rule.endpoint](**req.view_args)
  File "/home/www/aud2/app/views/site.py", line 875, in modify_node_task_status
    mes.sendEmail()
  File "/home/www/aud2/app/utils/message.py", line 45, in sendEmail
    thr = Thread(target=send_async_email, args=[receiver + '@aicai.com', subject, html])
TypeError: unsupported operand type(s) for +: 'NoneType' and 'str'
2016-08-23 07:29:44,350 ERROR: Exception on /api/v1.0/node_task/modify_status/6641895467dd3dfa205f28815ca53a25 [POST] [in /home/www/.demo/lib/python2.7/site-packages/flask/app.py:1423]
Traceback (most recent call last):
  File "/home/www/.demo/lib/python2.7/site-packages/flask/app.py", line 1817, in wsgi_app
    response = self.full_dispatch_request()
  File "/home/www/.demo/lib/python2.7/site-packages/flask/app.py", line 1477, in full_dispatch_request
    rv = self.handle_user_exception(e)
  File "/home/www/.demo/lib/python2.7/site-packages/flask/app.py", line 1381, in handle_user_exception
    reraise(exc_type, exc_value, tb)
  File "/home/www/.demo/lib/python2.7/site-packages/flask/app.py", line 1475, in full_dispatch_request
    rv = self.dispatch_request()
  File "/home/www/.demo/lib/python2.7/site-packages/flask/app.py", line 1461, in dispatch_request
    return self.view_functions[rule.endpoint](**req.view_args)
  File "/home/www/aud2/app/views/site.py", line 875, in modify_node_task_status
    mes.sendEmail()
  File "/home/www/aud2/app/utils/message.py", line 45, in sendEmail
    thr = Thread(target=send_async_email, args=[receiver + '@aicai.com', subject, html])
TypeError: unsupported operand type(s) for +: 'NoneType' and 'str'
2016-08-23 07:31:45,099 ERROR: Exception on /api/v1.0/node_task/modify_status/e7c54f7b402d040391e0b55cf174f586 [POST] [in /home/www/.demo/lib/python2.7/site-packages/flask/app.py:1423]
Traceback (most recent call last):
  File "/home/www/.demo/lib/python2.7/site-packages/flask/app.py", line 1817, in wsgi_app
    response = self.full_dispatch_request()
  File "/home/www/.demo/lib/python2.7/site-packages/flask/app.py", line 1477, in full_dispatch_request
    rv = self.handle_user_exception(e)
  File "/home/www/.demo/lib/python2.7/site-packages/flask/app.py", line 1381, in handle_user_exception
    reraise(exc_type, exc_value, tb)
  File "/home/www/.demo/lib/python2.7/site-packages/flask/app.py", line 1475, in full_dispatch_request
    rv = self.dispatch_request()
  File "/home/www/.demo/lib/python2.7/site-packages/flask/app.py", line 1461, in dispatch_request
    return self.view_functions[rule.endpoint](**req.view_args)
  File "/home/www/aud2/app/views/site.py", line 875, in modify_node_task_status
    mes.sendEmail()
  File "/home/www/aud2/app/utils/message.py", line 45, in sendEmail
    thr = Thread(target=send_async_email, args=[receiver + '@aicai.com', subject, html])
TypeError: unsupported operand type(s) for +: 'NoneType' and 'str'
2016-08-23 09:06:37,117 ERROR: Exception on /api/v1.0/node_task/modify_status/bf77d2613810864c9e84c676ed91b981 [POST] [in /home/www/.demo/lib/python2.7/site-packages/flask/app.py:1423]
Traceback (most recent call last):
  File "/home/www/.demo/lib/python2.7/site-packages/flask/app.py", line 1817, in wsgi_app
    response = self.full_dispatch_request()
  File "/home/www/.demo/lib/python2.7/site-packages/flask/app.py", line 1477, in full_dispatch_request
    rv = self.handle_user_exception(e)
  File "/home/www/.demo/lib/python2.7/site-packages/flask/app.py", line 1381, in handle_user_exception
    reraise(exc_type, exc_value, tb)
  File "/home/www/.demo/lib/python2.7/site-packages/flask/app.py", line 1475, in full_dispatch_request
    rv = self.dispatch_request()
  File "/home/www/.demo/lib/python2.7/site-packages/flask/app.py", line 1461, in dispatch_request
    return self.view_functions[rule.endpoint](**req.view_args)
  File "/home/www/aud2/app/views/site.py", line 875, in modify_node_task_status
    mes.sendEmail()
  File "/home/www/aud2/app/utils/message.py", line 45, in sendEmail
    thr = Thread(target=send_async_email, args=[receiver + '@aicai.com', subject, html])
TypeError: unsupported operand type(s) for +: 'NoneType' and 'str'
2016-08-23 09:13:09,349 ERROR: Exception on /api/v1.0/node_task/modify_status/3966ce845806a241d515b35a7063c301 [POST] [in /home/www/.demo/lib/python2.7/site-packages/flask/app.py:1423]
Traceback (most recent call last):
  File "/home/www/.demo/lib/python2.7/site-packages/flask/app.py", line 1817, in wsgi_app
    response = self.full_dispatch_request()
  File "/home/www/.demo/lib/python2.7/site-packages/flask/app.py", line 1477, in full_dispatch_request
    rv = self.handle_user_exception(e)
  File "/home/www/.demo/lib/python2.7/site-packages/flask/app.py", line 1381, in handle_user_exception
    reraise(exc_type, exc_value, tb)
  File "/home/www/.demo/lib/python2.7/site-packages/flask/app.py", line 1475, in full_dispatch_request
    rv = self.dispatch_request()
  File "/home/www/.demo/lib/python2.7/site-packages/flask/app.py", line 1461, in dispatch_request
    return self.view_functions[rule.endpoint](**req.view_args)
  File "/home/www/aud2/app/views/site.py", line 875, in modify_node_task_status
    mes.sendEmail()
  File "/home/www/aud2/app/utils/message.py", line 45, in sendEmail
    thr = Thread(target=send_async_email, args=[receiver + '@aicai.com', subject, html])
TypeError: unsupported operand type(s) for +: 'NoneType' and 'str'
2016-08-23 09:33:56,754 ERROR: Exception on /favicon.ico [GET] [in /home/www/.demo/lib/python2.7/site-packages/flask/app.py:1423]
Traceback (most recent call last):
  File "/home/www/.demo/lib/python2.7/site-packages/flask/app.py", line 1817, in wsgi_app
    response = self.full_dispatch_request()
  File "/home/www/.demo/lib/python2.7/site-packages/flask/app.py", line 1477, in full_dispatch_request
    rv = self.handle_user_exception(e)
  File "/home/www/.demo/lib/python2.7/site-packages/flask/app.py", line 1370, in handle_user_exception
    return self.handle_http_exception(e)
  File "/home/www/.demo/lib/python2.7/site-packages/flask/app.py", line 1330, in handle_http_exception
    return handler(e)
  File "/home/www/aud2/app/__init__.py", line 150, in page_404
    return render_template('errors/404.html'), 404
  File "/home/www/.demo/lib/python2.7/site-packages/flask/templating.py", line 128, in render_template
    context, ctx.app)
  File "/home/www/.demo/lib/python2.7/site-packages/flask/templating.py", line 110, in _render
    rv = template.render(context)
  File "/home/www/.demo/lib/python2.7/site-packages/jinja2/environment.py", line 969, in render
    return self.environment.handle_exception(exc_info, True)
  File "/home/www/.demo/lib/python2.7/site-packages/jinja2/environment.py", line 742, in handle_exception
    reraise(exc_type, exc_value, tb)
  File "/home/www/aud2/app/templates/errors/404.html", line 2, in top-level template code
    {% extends "base.html" %}
  File "/home/www/aud2/app/templates/base.html", line 26, in top-level template code
    {% include 'nav.html' %}
  File "/home/www/aud2/app/templates/nav.html", line 221, in top-level template code
    {% if g.user.is_admin() %}
UndefinedError: 'werkzeug.local.LocalProxy object' has no attribute 'is_admin'
2016-08-23 09:49:00,194 ERROR: Exception on /favicon.ico [GET] [in /home/www/.demo/lib/python2.7/site-packages/flask/app.py:1423]
Traceback (most recent call last):
  File "/home/www/.demo/lib/python2.7/site-packages/flask/app.py", line 1817, in wsgi_app
    response = self.full_dispatch_request()
  File "/home/www/.demo/lib/python2.7/site-packages/flask/app.py", line 1477, in full_dispatch_request
    rv = self.handle_user_exception(e)
  File "/home/www/.demo/lib/python2.7/site-packages/flask/app.py", line 1370, in handle_user_exception
    return self.handle_http_exception(e)
  File "/home/www/.demo/lib/python2.7/site-packages/flask/app.py", line 1330, in handle_http_exception
    return handler(e)
  File "/home/www/aud2/app/__init__.py", line 150, in page_404
    return render_template('errors/404.html'), 404
  File "/home/www/.demo/lib/python2.7/site-packages/flask/templating.py", line 128, in render_template
    context, ctx.app)
  File "/home/www/.demo/lib/python2.7/site-packages/flask/templating.py", line 110, in _render
    rv = template.render(context)
  File "/home/www/.demo/lib/python2.7/site-packages/jinja2/environment.py", line 969, in render
    return self.environment.handle_exception(exc_info, True)
  File "/home/www/.demo/lib/python2.7/site-packages/jinja2/environment.py", line 742, in handle_exception
    reraise(exc_type, exc_value, tb)
  File "/home/www/aud2/app/templates/errors/404.html", line 2, in top-level template code
    {% extends "base.html" %}
  File "/home/www/aud2/app/templates/base.html", line 26, in top-level template code
    {% include 'nav.html' %}
  File "/home/www/aud2/app/templates/nav.html", line 221, in top-level template code
    {% if g.user.is_admin() %}
UndefinedError: 'werkzeug.local.LocalProxy object' has no attribute 'is_admin'
2016-08-23 09:49:00,217 ERROR: Exception on /favicon.ico [GET] [in /home/www/.demo/lib/python2.7/site-packages/flask/app.py:1423]
Traceback (most recent call last):
  File "/home/www/.demo/lib/python2.7/site-packages/flask/app.py", line 1817, in wsgi_app
    response = self.full_dispatch_request()
  File "/home/www/.demo/lib/python2.7/site-packages/flask/app.py", line 1477, in full_dispatch_request
    rv = self.handle_user_exception(e)
  File "/home/www/.demo/lib/python2.7/site-packages/flask/app.py", line 1370, in handle_user_exception
    return self.handle_http_exception(e)
  File "/home/www/.demo/lib/python2.7/site-packages/flask/app.py", line 1330, in handle_http_exception
    return handler(e)
  File "/home/www/aud2/app/__init__.py", line 150, in page_404
    return render_template('errors/404.html'), 404
  File "/home/www/.demo/lib/python2.7/site-packages/flask/templating.py", line 128, in render_template
    context, ctx.app)
  File "/home/www/.demo/lib/python2.7/site-packages/flask/templating.py", line 110, in _render
    rv = template.render(context)
  File "/home/www/.demo/lib/python2.7/site-packages/jinja2/environment.py", line 969, in render
    return self.environment.handle_exception(exc_info, True)
  File "/home/www/.demo/lib/python2.7/site-packages/jinja2/environment.py", line 742, in handle_exception
    reraise(exc_type, exc_value, tb)
  File "/home/www/aud2/app/templates/errors/404.html", line 2, in top-level template code
    {% extends "base.html" %}
  File "/home/www/aud2/app/templates/base.html", line 26, in top-level template code
    {% include 'nav.html' %}
  File "/home/www/aud2/app/templates/nav.html", line 221, in top-level template code
    {% if g.user.is_admin() %}
UndefinedError: 'werkzeug.local.LocalProxy object' has no attribute 'is_admin'
2016-08-23 09:56:34,681 ERROR: Exception on /favicon.ico [GET] [in /home/www/.demo/lib/python2.7/site-packages/flask/app.py:1423]
Traceback (most recent call last):
  File "/home/www/.demo/lib/python2.7/site-packages/flask/app.py", line 1817, in wsgi_app
    response = self.full_dispatch_request()
  File "/home/www/.demo/lib/python2.7/site-packages/flask/app.py", line 1477, in full_dispatch_request
    rv = self.handle_user_exception(e)
  File "/home/www/.demo/lib/python2.7/site-packages/flask/app.py", line 1370, in handle_user_exception
    return self.handle_http_exception(e)
  File "/home/www/.demo/lib/python2.7/site-packages/flask/app.py", line 1330, in handle_http_exception
    return handler(e)
  File "/home/www/aud2/app/__init__.py", line 150, in page_404
    return render_template('errors/404.html'), 404
  File "/home/www/.demo/lib/python2.7/site-packages/flask/templating.py", line 128, in render_template
    context, ctx.app)
  File "/home/www/.demo/lib/python2.7/site-packages/flask/templating.py", line 110, in _render
    rv = template.render(context)
  File "/home/www/.demo/lib/python2.7/site-packages/jinja2/environment.py", line 969, in render
    return self.environment.handle_exception(exc_info, True)
  File "/home/www/.demo/lib/python2.7/site-packages/jinja2/environment.py", line 742, in handle_exception
    reraise(exc_type, exc_value, tb)
  File "/home/www/aud2/app/templates/errors/404.html", line 2, in top-level template code
    {% extends "base.html" %}
  File "/home/www/aud2/app/templates/base.html", line 26, in top-level template code
    {% include 'nav.html' %}
  File "/home/www/aud2/app/templates/nav.html", line 221, in top-level template code
    {% if g.user.is_admin() %}
UndefinedError: 'werkzeug.local.LocalProxy object' has no attribute 'is_admin'
2016-08-23 10:01:27,767 ERROR: Exception on /deploy/approve_success/UOA-didi_sms-20160823100122 [GET] [in /home/www/.demo/lib/python2.7/site-packages/flask/app.py:1423]
Traceback (most recent call last):
  File "/home/www/.demo/lib/python2.7/site-packages/flask/app.py", line 1817, in wsgi_app
    response = self.full_dispatch_request()
  File "/home/www/.demo/lib/python2.7/site-packages/flask/app.py", line 1477, in full_dispatch_request
    rv = self.handle_user_exception(e)
  File "/home/www/.demo/lib/python2.7/site-packages/flask/app.py", line 1370, in handle_user_exception
    return self.handle_http_exception(e)
  File "/home/www/.demo/lib/python2.7/site-packages/flask/app.py", line 1330, in handle_http_exception
    return handler(e)
  File "/home/www/aud2/app/__init__.py", line 146, in page_403
    return render_template('errors/403.html'), 403
  File "/home/www/.demo/lib/python2.7/site-packages/flask/templating.py", line 127, in render_template
    return _render(ctx.app.jinja_env.get_or_select_template(template_name_or_list),
  File "/home/www/.demo/lib/python2.7/site-packages/jinja2/environment.py", line 830, in get_or_select_template
    return self.get_template(template_name_or_list, parent, globals)
  File "/home/www/.demo/lib/python2.7/site-packages/jinja2/environment.py", line 791, in get_template
    return self._load_template(name, self.make_globals(globals))
  File "/home/www/.demo/lib/python2.7/site-packages/jinja2/environment.py", line 765, in _load_template
    template = self.loader.load(self, name, globals)
  File "/home/www/.demo/lib/python2.7/site-packages/jinja2/loaders.py", line 113, in load
    source, filename, uptodate = self.get_source(environment, name)
  File "/home/www/.demo/lib/python2.7/site-packages/flask/templating.py", line 64, in get_source
    raise TemplateNotFound(template)
TemplateNotFound: errors/403.html
2016-08-23 10:06:01,987 ERROR: Exception on /api/v1.0/node_task/modify_status/141951dbb83de7485e6110f32a7e7949 [POST] [in /home/www/.demo/lib/python2.7/site-packages/flask/app.py:1423]
Traceback (most recent call last):
  File "/home/www/.demo/lib/python2.7/site-packages/flask/app.py", line 1817, in wsgi_app
    response = self.full_dispatch_request()
  File "/home/www/.demo/lib/python2.7/site-packages/flask/app.py", line 1477, in full_dispatch_request
    rv = self.handle_user_exception(e)
  File "/home/www/.demo/lib/python2.7/site-packages/flask/app.py", line 1381, in handle_user_exception
    reraise(exc_type, exc_value, tb)
  File "/home/www/.demo/lib/python2.7/site-packages/flask/app.py", line 1475, in full_dispatch_request
    rv = self.dispatch_request()
  File "/home/www/.demo/lib/python2.7/site-packages/flask/app.py", line 1461, in dispatch_request
    return self.view_functions[rule.endpoint](**req.view_args)
  File "/home/www/aud2/app/views/site.py", line 875, in modify_node_task_status
    mes.sendEmail()
  File "/home/www/aud2/app/utils/message.py", line 45, in sendEmail
    thr = Thread(target=send_async_email, args=[receiver + '@aicai.com', subject, html])
TypeError: unsupported operand type(s) for +: 'NoneType' and 'str'
2016-08-23 10:25:29,181 ERROR: Exception on /favicon.ico [GET] [in /home/www/.demo/lib/python2.7/site-packages/flask/app.py:1423]
Traceback (most recent call last):
  File "/home/www/.demo/lib/python2.7/site-packages/flask/app.py", line 1817, in wsgi_app
    response = self.full_dispatch_request()
  File "/home/www/.demo/lib/python2.7/site-packages/flask/app.py", line 1477, in full_dispatch_request
    rv = self.handle_user_exception(e)
  File "/home/www/.demo/lib/python2.7/site-packages/flask/app.py", line 1370, in handle_user_exception
    return self.handle_http_exception(e)
  File "/home/www/.demo/lib/python2.7/site-packages/flask/app.py", line 1330, in handle_http_exception
    return handler(e)
  File "/home/www/aud2/app/__init__.py", line 150, in page_404
    return render_template('errors/404.html'), 404
  File "/home/www/.demo/lib/python2.7/site-packages/flask/templating.py", line 128, in render_template
    context, ctx.app)
  File "/home/www/.demo/lib/python2.7/site-packages/flask/templating.py", line 110, in _render
    rv = template.render(context)
  File "/home/www/.demo/lib/python2.7/site-packages/jinja2/environment.py", line 969, in render
    return self.environment.handle_exception(exc_info, True)
  File "/home/www/.demo/lib/python2.7/site-packages/jinja2/environment.py", line 742, in handle_exception
    reraise(exc_type, exc_value, tb)
  File "/home/www/aud2/app/templates/errors/404.html", line 2, in top-level template code
    {% extends "base.html" %}
  File "/home/www/aud2/app/templates/base.html", line 26, in top-level template code
    {% include 'nav.html' %}
  File "/home/www/aud2/app/templates/nav.html", line 221, in top-level template code
    {% if g.user.is_admin() %}
UndefinedError: 'werkzeug.local.LocalProxy object' has no attribute 'is_admin'
2016-08-23 10:25:29,218 ERROR: Exception on /favicon.ico [GET] [in /home/www/.demo/lib/python2.7/site-packages/flask/app.py:1423]
Traceback (most recent call last):
  File "/home/www/.demo/lib/python2.7/site-packages/flask/app.py", line 1817, in wsgi_app
    response = self.full_dispatch_request()
  File "/home/www/.demo/lib/python2.7/site-packages/flask/app.py", line 1477, in full_dispatch_request
    rv = self.handle_user_exception(e)
  File "/home/www/.demo/lib/python2.7/site-packages/flask/app.py", line 1370, in handle_user_exception
    return self.handle_http_exception(e)
  File "/home/www/.demo/lib/python2.7/site-packages/flask/app.py", line 1330, in handle_http_exception
    return handler(e)
  File "/home/www/aud2/app/__init__.py", line 150, in page_404
    return render_template('errors/404.html'), 404
  File "/home/www/.demo/lib/python2.7/site-packages/flask/templating.py", line 128, in render_template
    context, ctx.app)
  File "/home/www/.demo/lib/python2.7/site-packages/flask/templating.py", line 110, in _render
    rv = template.render(context)
  File "/home/www/.demo/lib/python2.7/site-packages/jinja2/environment.py", line 969, in render
    return self.environment.handle_exception(exc_info, True)
  File "/home/www/.demo/lib/python2.7/site-packages/jinja2/environment.py", line 742, in handle_exception
    reraise(exc_type, exc_value, tb)
  File "/home/www/aud2/app/templates/errors/404.html", line 2, in top-level template code
    {% extends "base.html" %}
  File "/home/www/aud2/app/templates/base.html", line 26, in top-level template code
    {% include 'nav.html' %}
  File "/home/www/aud2/app/templates/nav.html", line 221, in top-level template code
    {% if g.user.is_admin() %}
UndefinedError: 'werkzeug.local.LocalProxy object' has no attribute 'is_admin'
2016-08-23 10:54:13,120 ERROR: Exception on /api/v1.0/node_task/modify_status/72690815b356da71df883e58a37d856b [POST] [in /home/www/.demo/lib/python2.7/site-packages/flask/app.py:1423]
Traceback (most recent call last):
  File "/home/www/.demo/lib/python2.7/site-packages/flask/app.py", line 1817, in wsgi_app
    response = self.full_dispatch_request()
  File "/home/www/.demo/lib/python2.7/site-packages/flask/app.py", line 1477, in full_dispatch_request
    rv = self.handle_user_exception(e)
  File "/home/www/.demo/lib/python2.7/site-packages/flask/app.py", line 1381, in handle_user_exception
    reraise(exc_type, exc_value, tb)
  File "/home/www/.demo/lib/python2.7/site-packages/flask/app.py", line 1475, in full_dispatch_request
    rv = self.dispatch_request()
  File "/home/www/.demo/lib/python2.7/site-packages/flask/app.py", line 1461, in dispatch_request
    return self.view_functions[rule.endpoint](**req.view_args)
  File "/home/www/aud2/app/views/site.py", line 875, in modify_node_task_status
    mes.sendEmail()
  File "/home/www/aud2/app/utils/message.py", line 45, in sendEmail
    thr = Thread(target=send_async_email, args=[receiver + '@aicai.com', subject, html])
TypeError: unsupported operand type(s) for +: 'NoneType' and 'str'
2016-08-23 10:54:23,138 ERROR: Exception on /api/v1.0/node_task/modify_status/c8a0a659e319d58df30c1e62783c55e5 [POST] [in /home/www/.demo/lib/python2.7/site-packages/flask/app.py:1423]
Traceback (most recent call last):
  File "/home/www/.demo/lib/python2.7/site-packages/flask/app.py", line 1817, in wsgi_app
    response = self.full_dispatch_request()
  File "/home/www/.demo/lib/python2.7/site-packages/flask/app.py", line 1477, in full_dispatch_request
    rv = self.handle_user_exception(e)
  File "/home/www/.demo/lib/python2.7/site-packages/flask/app.py", line 1381, in handle_user_exception
    reraise(exc_type, exc_value, tb)
  File "/home/www/.demo/lib/python2.7/site-packages/flask/app.py", line 1475, in full_dispatch_request
    rv = self.dispatch_request()
  File "/home/www/.demo/lib/python2.7/site-packages/flask/app.py", line 1461, in dispatch_request
    return self.view_functions[rule.endpoint](**req.view_args)
  File "/home/www/aud2/app/views/site.py", line 875, in modify_node_task_status
    mes.sendEmail()
  File "/home/www/aud2/app/utils/message.py", line 45, in sendEmail
    thr = Thread(target=send_async_email, args=[receiver + '@aicai.com', subject, html])
TypeError: unsupported operand type(s) for +: 'NoneType' and 'str'
2016-08-23 11:44:46,895 ERROR: Exception on /self/app [POST] [in /home/www/.demo/lib/python2.7/site-packages/flask/app.py:1423]
Traceback (most recent call last):
  File "/home/www/.demo/lib/python2.7/site-packages/flask/app.py", line 1817, in wsgi_app
    response = self.full_dispatch_request()
  File "/home/www/.demo/lib/python2.7/site-packages/flask/app.py", line 1477, in full_dispatch_request
    rv = self.handle_user_exception(e)
  File "/home/www/.demo/lib/python2.7/site-packages/flask/app.py", line 1381, in handle_user_exception
    reraise(exc_type, exc_value, tb)
  File "/home/www/.demo/lib/python2.7/site-packages/flask/app.py", line 1475, in full_dispatch_request
    rv = self.dispatch_request()
  File "/home/www/.demo/lib/python2.7/site-packages/flask/app.py", line 1461, in dispatch_request
    return self.view_functions[rule.endpoint](**req.view_args)
  File "/home/www/.demo/lib/python2.7/site-packages/flask_login.py", line 758, in decorated_view
    return func(*args, **kwargs)
  File "/home/www/aud2/app/views/self.py", line 41, in app
    models.App_sites.id == int(item.site)).first()[0]
TypeError: 'NoneType' object has no attribute '__getitem__'
2016-08-23 11:47:22,732 ERROR: Exception on /self/app/4 [POST] [in /home/www/.demo/lib/python2.7/site-packages/flask/app.py:1423]
Traceback (most recent call last):
  File "/home/www/.demo/lib/python2.7/site-packages/flask/app.py", line 1817, in wsgi_app
    response = self.full_dispatch_request()
  File "/home/www/.demo/lib/python2.7/site-packages/flask/app.py", line 1477, in full_dispatch_request
    rv = self.handle_user_exception(e)
  File "/home/www/.demo/lib/python2.7/site-packages/flask/app.py", line 1381, in handle_user_exception
    reraise(exc_type, exc_value, tb)
  File "/home/www/.demo/lib/python2.7/site-packages/flask/app.py", line 1475, in full_dispatch_request
    rv = self.dispatch_request()
  File "/home/www/.demo/lib/python2.7/site-packages/flask/app.py", line 1461, in dispatch_request
    return self.view_functions[rule.endpoint](**req.view_args)
  File "/home/www/.demo/lib/python2.7/site-packages/flask_login.py", line 758, in decorated_view
    return func(*args, **kwargs)
  File "/home/www/aud2/app/views/self.py", line 41, in app
    models.App_sites.id == int(item.site)).first()[0]
TypeError: 'NoneType' object has no attribute '__getitem__'
2016-08-23 11:48:20,619 ERROR: Exception on /self/app [POST] [in /home/www/.demo/lib/python2.7/site-packages/flask/app.py:1423]
Traceback (most recent call last):
  File "/home/www/.demo/lib/python2.7/site-packages/flask/app.py", line 1817, in wsgi_app
    response = self.full_dispatch_request()
  File "/home/www/.demo/lib/python2.7/site-packages/flask/app.py", line 1477, in full_dispatch_request
    rv = self.handle_user_exception(e)
  File "/home/www/.demo/lib/python2.7/site-packages/flask/app.py", line 1381, in handle_user_exception
    reraise(exc_type, exc_value, tb)
  File "/home/www/.demo/lib/python2.7/site-packages/flask/app.py", line 1475, in full_dispatch_request
    rv = self.dispatch_request()
  File "/home/www/.demo/lib/python2.7/site-packages/flask/app.py", line 1461, in dispatch_request
    return self.view_functions[rule.endpoint](**req.view_args)
  File "/home/www/.demo/lib/python2.7/site-packages/flask_login.py", line 758, in decorated_view
    return func(*args, **kwargs)
  File "/home/www/aud2/app/views/self.py", line 41, in app
    models.App_sites.id == int(item.site)).first()[0]
TypeError: 'NoneType' object has no attribute '__getitem__'
2016-08-23 11:48:26,393 ERROR: Exception on /self/app [POST] [in /home/www/.demo/lib/python2.7/site-packages/flask/app.py:1423]
Traceback (most recent call last):
  File "/home/www/.demo/lib/python2.7/site-packages/flask/app.py", line 1817, in wsgi_app
    response = self.full_dispatch_request()
  File "/home/www/.demo/lib/python2.7/site-packages/flask/app.py", line 1477, in full_dispatch_request
    rv = self.handle_user_exception(e)
  File "/home/www/.demo/lib/python2.7/site-packages/flask/app.py", line 1381, in handle_user_exception
    reraise(exc_type, exc_value, tb)
  File "/home/www/.demo/lib/python2.7/site-packages/flask/app.py", line 1475, in full_dispatch_request
    rv = self.dispatch_request()
  File "/home/www/.demo/lib/python2.7/site-packages/flask/app.py", line 1461, in dispatch_request
    return self.view_functions[rule.endpoint](**req.view_args)
  File "/home/www/.demo/lib/python2.7/site-packages/flask_login.py", line 758, in decorated_view
    return func(*args, **kwargs)
  File "/home/www/aud2/app/views/self.py", line 41, in app
    models.App_sites.id == int(item.site)).first()[0]
TypeError: 'NoneType' object has no attribute '__getitem__'
2016-08-23 11:48:46,564 ERROR: Exception on /self/app [POST] [in /home/www/.demo/lib/python2.7/site-packages/flask/app.py:1423]
Traceback (most recent call last):
  File "/home/www/.demo/lib/python2.7/site-packages/flask/app.py", line 1817, in wsgi_app
    response = self.full_dispatch_request()
  File "/home/www/.demo/lib/python2.7/site-packages/flask/app.py", line 1477, in full_dispatch_request
    rv = self.handle_user_exception(e)
  File "/home/www/.demo/lib/python2.7/site-packages/flask/app.py", line 1381, in handle_user_exception
    reraise(exc_type, exc_value, tb)
  File "/home/www/.demo/lib/python2.7/site-packages/flask/app.py", line 1475, in full_dispatch_request
    rv = self.dispatch_request()
  File "/home/www/.demo/lib/python2.7/site-packages/flask/app.py", line 1461, in dispatch_request
    return self.view_functions[rule.endpoint](**req.view_args)
  File "/home/www/.demo/lib/python2.7/site-packages/flask_login.py", line 758, in decorated_view
    return func(*args, **kwargs)
  File "/home/www/aud2/app/views/self.py", line 41, in app
    models.App_sites.id == int(item.site)).first()[0]
TypeError: 'NoneType' object has no attribute '__getitem__'
2016-08-23 11:48:52,251 ERROR: Exception on /self/app [POST] [in /home/www/.demo/lib/python2.7/site-packages/flask/app.py:1423]
Traceback (most recent call last):
  File "/home/www/.demo/lib/python2.7/site-packages/flask/app.py", line 1817, in wsgi_app
    response = self.full_dispatch_request()
  File "/home/www/.demo/lib/python2.7/site-packages/flask/app.py", line 1477, in full_dispatch_request
    rv = self.handle_user_exception(e)
  File "/home/www/.demo/lib/python2.7/site-packages/flask/app.py", line 1381, in handle_user_exception
    reraise(exc_type, exc_value, tb)
  File "/home/www/.demo/lib/python2.7/site-packages/flask/app.py", line 1475, in full_dispatch_request
    rv = self.dispatch_request()
  File "/home/www/.demo/lib/python2.7/site-packages/flask/app.py", line 1461, in dispatch_request
    return self.view_functions[rule.endpoint](**req.view_args)
  File "/home/www/.demo/lib/python2.7/site-packages/flask_login.py", line 758, in decorated_view
    return func(*args, **kwargs)
  File "/home/www/aud2/app/views/self.py", line 41, in app
    models.App_sites.id == int(item.site)).first()[0]
TypeError: 'NoneType' object has no attribute '__getitem__'
2016-08-23 11:49:10,961 ERROR: Exception on /api/v1.0/node_task/modify_status/12c3b20c0c9f9541bc4ed242eb15534b [POST] [in /home/www/.demo/lib/python2.7/site-packages/flask/app.py:1423]
Traceback (most recent call last):
  File "/home/www/.demo/lib/python2.7/site-packages/flask/app.py", line 1817, in wsgi_app
    response = self.full_dispatch_request()
  File "/home/www/.demo/lib/python2.7/site-packages/flask/app.py", line 1477, in full_dispatch_request
    rv = self.handle_user_exception(e)
  File "/home/www/.demo/lib/python2.7/site-packages/flask/app.py", line 1381, in handle_user_exception
    reraise(exc_type, exc_value, tb)
  File "/home/www/.demo/lib/python2.7/site-packages/flask/app.py", line 1475, in full_dispatch_request
    rv = self.dispatch_request()
  File "/home/www/.demo/lib/python2.7/site-packages/flask/app.py", line 1461, in dispatch_request
    return self.view_functions[rule.endpoint](**req.view_args)
  File "/home/www/aud2/app/views/site.py", line 875, in modify_node_task_status
    mes.sendEmail()
  File "/home/www/aud2/app/utils/message.py", line 45, in sendEmail
    thr = Thread(target=send_async_email, args=[receiver + '@aicai.com', subject, html])
TypeError: unsupported operand type(s) for +: 'NoneType' and 'str'
2016-08-23 11:50:29,743 ERROR: Exception on /self/app [POST] [in /home/www/.demo/lib/python2.7/site-packages/flask/app.py:1423]
Traceback (most recent call last):
  File "/home/www/.demo/lib/python2.7/site-packages/flask/app.py", line 1817, in wsgi_app
    response = self.full_dispatch_request()
  File "/home/www/.demo/lib/python2.7/site-packages/flask/app.py", line 1477, in full_dispatch_request
    rv = self.handle_user_exception(e)
  File "/home/www/.demo/lib/python2.7/site-packages/flask/app.py", line 1381, in handle_user_exception
    reraise(exc_type, exc_value, tb)
  File "/home/www/.demo/lib/python2.7/site-packages/flask/app.py", line 1475, in full_dispatch_request
    rv = self.dispatch_request()
  File "/home/www/.demo/lib/python2.7/site-packages/flask/app.py", line 1461, in dispatch_request
    return self.view_functions[rule.endpoint](**req.view_args)
  File "/home/www/.demo/lib/python2.7/site-packages/flask_login.py", line 758, in decorated_view
    return func(*args, **kwargs)
  File "/home/www/aud2/app/views/self.py", line 41, in app
    models.App_sites.id == int(item.site)).first()[0]
TypeError: 'NoneType' object has no attribute '__getitem__'
2016-08-23 11:50:38,600 ERROR: Exception on /self/app [POST] [in /home/www/.demo/lib/python2.7/site-packages/flask/app.py:1423]
Traceback (most recent call last):
  File "/home/www/.demo/lib/python2.7/site-packages/flask/app.py", line 1817, in wsgi_app
    response = self.full_dispatch_request()
  File "/home/www/.demo/lib/python2.7/site-packages/flask/app.py", line 1477, in full_dispatch_request
    rv = self.handle_user_exception(e)
  File "/home/www/.demo/lib/python2.7/site-packages/flask/app.py", line 1381, in handle_user_exception
    reraise(exc_type, exc_value, tb)
  File "/home/www/.demo/lib/python2.7/site-packages/flask/app.py", line 1475, in full_dispatch_request
    rv = self.dispatch_request()
  File "/home/www/.demo/lib/python2.7/site-packages/flask/app.py", line 1461, in dispatch_request
    return self.view_functions[rule.endpoint](**req.view_args)
  File "/home/www/.demo/lib/python2.7/site-packages/flask_login.py", line 758, in decorated_view
    return func(*args, **kwargs)
  File "/home/www/aud2/app/views/self.py", line 41, in app
    models.App_sites.id == int(item.site)).first()[0]
TypeError: 'NoneType' object has no attribute '__getitem__'
2016-08-23 11:50:43,937 ERROR: Exception on /self/app [POST] [in /home/www/.demo/lib/python2.7/site-packages/flask/app.py:1423]
Traceback (most recent call last):
  File "/home/www/.demo/lib/python2.7/site-packages/flask/app.py", line 1817, in wsgi_app
    response = self.full_dispatch_request()
  File "/home/www/.demo/lib/python2.7/site-packages/flask/app.py", line 1477, in full_dispatch_request
    rv = self.handle_user_exception(e)
  File "/home/www/.demo/lib/python2.7/site-packages/flask/app.py", line 1381, in handle_user_exception
    reraise(exc_type, exc_value, tb)
  File "/home/www/.demo/lib/python2.7/site-packages/flask/app.py", line 1475, in full_dispatch_request
    rv = self.dispatch_request()
  File "/home/www/.demo/lib/python2.7/site-packages/flask/app.py", line 1461, in dispatch_request
    return self.view_functions[rule.endpoint](**req.view_args)
  File "/home/www/.demo/lib/python2.7/site-packages/flask_login.py", line 758, in decorated_view
    return func(*args, **kwargs)
  File "/home/www/aud2/app/views/self.py", line 41, in app
    models.App_sites.id == int(item.site)).first()[0]
TypeError: 'NoneType' object has no attribute '__getitem__'
2016-08-23 11:50:48,620 ERROR: Exception on /self/app [POST] [in /home/www/.demo/lib/python2.7/site-packages/flask/app.py:1423]
Traceback (most recent call last):
  File "/home/www/.demo/lib/python2.7/site-packages/flask/app.py", line 1817, in wsgi_app
    response = self.full_dispatch_request()
  File "/home/www/.demo/lib/python2.7/site-packages/flask/app.py", line 1477, in full_dispatch_request
    rv = self.handle_user_exception(e)
  File "/home/www/.demo/lib/python2.7/site-packages/flask/app.py", line 1381, in handle_user_exception
    reraise(exc_type, exc_value, tb)
  File "/home/www/.demo/lib/python2.7/site-packages/flask/app.py", line 1475, in full_dispatch_request
    rv = self.dispatch_request()
  File "/home/www/.demo/lib/python2.7/site-packages/flask/app.py", line 1461, in dispatch_request
    return self.view_functions[rule.endpoint](**req.view_args)
  File "/home/www/.demo/lib/python2.7/site-packages/flask_login.py", line 758, in decorated_view
    return func(*args, **kwargs)
  File "/home/www/aud2/app/views/self.py", line 41, in app
    models.App_sites.id == int(item.site)).first()[0]
TypeError: 'NoneType' object has no attribute '__getitem__'
2016-08-23 11:55:13,870 ERROR: Exception on /api/v1.0/node_task/modify_status/da377c602bdb337e1e6c95b1d079ce1a [POST] [in /home/www/.demo/lib/python2.7/site-packages/flask/app.py:1423]
Traceback (most recent call last):
  File "/home/www/.demo/lib/python2.7/site-packages/flask/app.py", line 1817, in wsgi_app
    response = self.full_dispatch_request()
  File "/home/www/.demo/lib/python2.7/site-packages/flask/app.py", line 1477, in full_dispatch_request
    rv = self.handle_user_exception(e)
  File "/home/www/.demo/lib/python2.7/site-packages/flask/app.py", line 1381, in handle_user_exception
    reraise(exc_type, exc_value, tb)
  File "/home/www/.demo/lib/python2.7/site-packages/flask/app.py", line 1475, in full_dispatch_request
    rv = self.dispatch_request()
  File "/home/www/.demo/lib/python2.7/site-packages/flask/app.py", line 1461, in dispatch_request
    return self.view_functions[rule.endpoint](**req.view_args)
  File "/home/www/aud2/app/views/site.py", line 875, in modify_node_task_status
    mes.sendEmail()
  File "/home/www/aud2/app/utils/message.py", line 45, in sendEmail
    thr = Thread(target=send_async_email, args=[receiver + '@aicai.com', subject, html])
TypeError: unsupported operand type(s) for +: 'NoneType' and 'str'
2016-08-23 14:04:24,872 ERROR: Exception on /self/app [POST] [in /home/www/.demo/lib/python2.7/site-packages/flask/app.py:1423]
Traceback (most recent call last):
  File "/home/www/.demo/lib/python2.7/site-packages/flask/app.py", line 1817, in wsgi_app
    response = self.full_dispatch_request()
  File "/home/www/.demo/lib/python2.7/site-packages/flask/app.py", line 1477, in full_dispatch_request
    rv = self.handle_user_exception(e)
  File "/home/www/.demo/lib/python2.7/site-packages/flask/app.py", line 1381, in handle_user_exception
    reraise(exc_type, exc_value, tb)
  File "/home/www/.demo/lib/python2.7/site-packages/flask/app.py", line 1475, in full_dispatch_request
    rv = self.dispatch_request()
  File "/home/www/.demo/lib/python2.7/site-packages/flask/app.py", line 1461, in dispatch_request
    return self.view_functions[rule.endpoint](**req.view_args)
  File "/home/www/.demo/lib/python2.7/site-packages/flask_login.py", line 758, in decorated_view
    return func(*args, **kwargs)
  File "/home/www/aud2/app/views/self.py", line 41, in app
    models.App_sites.id == int(item.site)).first()[0]
TypeError: 'NoneType' object has no attribute '__getitem__'
2016-08-23 14:04:30,990 ERROR: Exception on /self/app [POST] [in /home/www/.demo/lib/python2.7/site-packages/flask/app.py:1423]
Traceback (most recent call last):
  File "/home/www/.demo/lib/python2.7/site-packages/flask/app.py", line 1817, in wsgi_app
    response = self.full_dispatch_request()
  File "/home/www/.demo/lib/python2.7/site-packages/flask/app.py", line 1477, in full_dispatch_request
    rv = self.handle_user_exception(e)
  File "/home/www/.demo/lib/python2.7/site-packages/flask/app.py", line 1381, in handle_user_exception
    reraise(exc_type, exc_value, tb)
  File "/home/www/.demo/lib/python2.7/site-packages/flask/app.py", line 1475, in full_dispatch_request
    rv = self.dispatch_request()
  File "/home/www/.demo/lib/python2.7/site-packages/flask/app.py", line 1461, in dispatch_request
    return self.view_functions[rule.endpoint](**req.view_args)
  File "/home/www/.demo/lib/python2.7/site-packages/flask_login.py", line 758, in decorated_view
    return func(*args, **kwargs)
  File "/home/www/aud2/app/views/self.py", line 41, in app
    models.App_sites.id == int(item.site)).first()[0]
TypeError: 'NoneType' object has no attribute '__getitem__'
2016-08-23 14:05:00,087 ERROR: Exception on /favicon.ico [GET] [in /home/www/.demo/lib/python2.7/site-packages/flask/app.py:1423]
Traceback (most recent call last):
  File "/home/www/.demo/lib/python2.7/site-packages/flask/app.py", line 1817, in wsgi_app
    response = self.full_dispatch_request()
  File "/home/www/.demo/lib/python2.7/site-packages/flask/app.py", line 1477, in full_dispatch_request
    rv = self.handle_user_exception(e)
  File "/home/www/.demo/lib/python2.7/site-packages/flask/app.py", line 1370, in handle_user_exception
    return self.handle_http_exception(e)
  File "/home/www/.demo/lib/python2.7/site-packages/flask/app.py", line 1330, in handle_http_exception
    return handler(e)
  File "/home/www/aud2/app/__init__.py", line 150, in page_404
    return render_template('errors/404.html'), 404
  File "/home/www/.demo/lib/python2.7/site-packages/flask/templating.py", line 128, in render_template
    context, ctx.app)
  File "/home/www/.demo/lib/python2.7/site-packages/flask/templating.py", line 110, in _render
    rv = template.render(context)
  File "/home/www/.demo/lib/python2.7/site-packages/jinja2/environment.py", line 969, in render
    return self.environment.handle_exception(exc_info, True)
  File "/home/www/.demo/lib/python2.7/site-packages/jinja2/environment.py", line 742, in handle_exception
    reraise(exc_type, exc_value, tb)
  File "/home/www/aud2/app/templates/errors/404.html", line 2, in top-level template code
    {% extends "base.html" %}
  File "/home/www/aud2/app/templates/base.html", line 26, in top-level template code
    {% include 'nav.html' %}
  File "/home/www/aud2/app/templates/nav.html", line 221, in top-level template code
    {% if g.user.is_admin() %}
UndefinedError: 'werkzeug.local.LocalProxy object' has no attribute 'is_admin'
2016-08-23 14:10:07,608 ERROR: Exception on /self/app [POST] [in /home/www/.demo/lib/python2.7/site-packages/flask/app.py:1423]
Traceback (most recent call last):
  File "/home/www/.demo/lib/python2.7/site-packages/flask/app.py", line 1817, in wsgi_app
    response = self.full_dispatch_request()
  File "/home/www/.demo/lib/python2.7/site-packages/flask/app.py", line 1477, in full_dispatch_request
    rv = self.handle_user_exception(e)
  File "/home/www/.demo/lib/python2.7/site-packages/flask/app.py", line 1381, in handle_user_exception
    reraise(exc_type, exc_value, tb)
  File "/home/www/.demo/lib/python2.7/site-packages/flask/app.py", line 1475, in full_dispatch_request
    rv = self.dispatch_request()
  File "/home/www/.demo/lib/python2.7/site-packages/flask/app.py", line 1461, in dispatch_request
    return self.view_functions[rule.endpoint](**req.view_args)
  File "/home/www/.demo/lib/python2.7/site-packages/flask_login.py", line 758, in decorated_view
    return func(*args, **kwargs)
  File "/home/www/aud2/app/views/self.py", line 41, in app
    models.App_sites.id == int(item.site)).first()[0]
TypeError: 'NoneType' object has no attribute '__getitem__'
2016-08-23 14:10:12,203 ERROR: Exception on /self/app [POST] [in /home/www/.demo/lib/python2.7/site-packages/flask/app.py:1423]
Traceback (most recent call last):
  File "/home/www/.demo/lib/python2.7/site-packages/flask/app.py", line 1817, in wsgi_app
    response = self.full_dispatch_request()
  File "/home/www/.demo/lib/python2.7/site-packages/flask/app.py", line 1477, in full_dispatch_request
    rv = self.handle_user_exception(e)
  File "/home/www/.demo/lib/python2.7/site-packages/flask/app.py", line 1381, in handle_user_exception
    reraise(exc_type, exc_value, tb)
  File "/home/www/.demo/lib/python2.7/site-packages/flask/app.py", line 1475, in full_dispatch_request
    rv = self.dispatch_request()
  File "/home/www/.demo/lib/python2.7/site-packages/flask/app.py", line 1461, in dispatch_request
    return self.view_functions[rule.endpoint](**req.view_args)
  File "/home/www/.demo/lib/python2.7/site-packages/flask_login.py", line 758, in decorated_view
    return func(*args, **kwargs)
  File "/home/www/aud2/app/views/self.py", line 41, in app
    models.App_sites.id == int(item.site)).first()[0]
TypeError: 'NoneType' object has no attribute '__getitem__'
2016-08-23 14:10:22,837 ERROR: Exception on /self/app [POST] [in /home/www/.demo/lib/python2.7/site-packages/flask/app.py:1423]
Traceback (most recent call last):
  File "/home/www/.demo/lib/python2.7/site-packages/flask/app.py", line 1817, in wsgi_app
    response = self.full_dispatch_request()
  File "/home/www/.demo/lib/python2.7/site-packages/flask/app.py", line 1477, in full_dispatch_request
    rv = self.handle_user_exception(e)
  File "/home/www/.demo/lib/python2.7/site-packages/flask/app.py", line 1381, in handle_user_exception
    reraise(exc_type, exc_value, tb)
  File "/home/www/.demo/lib/python2.7/site-packages/flask/app.py", line 1475, in full_dispatch_request
    rv = self.dispatch_request()
  File "/home/www/.demo/lib/python2.7/site-packages/flask/app.py", line 1461, in dispatch_request
    return self.view_functions[rule.endpoint](**req.view_args)
  File "/home/www/.demo/lib/python2.7/site-packages/flask_login.py", line 758, in decorated_view
    return func(*args, **kwargs)
  File "/home/www/aud2/app/views/self.py", line 41, in app
    models.App_sites.id == int(item.site)).first()[0]
TypeError: 'NoneType' object has no attribute '__getitem__'
2016-08-23 14:15:18,345 ERROR: Exception on /self/app [POST] [in /home/www/.demo/lib/python2.7/site-packages/flask/app.py:1423]
Traceback (most recent call last):
  File "/home/www/.demo/lib/python2.7/site-packages/flask/app.py", line 1817, in wsgi_app
    response = self.full_dispatch_request()
  File "/home/www/.demo/lib/python2.7/site-packages/flask/app.py", line 1477, in full_dispatch_request
    rv = self.handle_user_exception(e)
  File "/home/www/.demo/lib/python2.7/site-packages/flask/app.py", line 1381, in handle_user_exception
    reraise(exc_type, exc_value, tb)
  File "/home/www/.demo/lib/python2.7/site-packages/flask/app.py", line 1475, in full_dispatch_request
    rv = self.dispatch_request()
  File "/home/www/.demo/lib/python2.7/site-packages/flask/app.py", line 1461, in dispatch_request
    return self.view_functions[rule.endpoint](**req.view_args)
  File "/home/www/.demo/lib/python2.7/site-packages/flask_login.py", line 758, in decorated_view
    return func(*args, **kwargs)
  File "/home/www/aud2/app/views/self.py", line 41, in app
    models.App_sites.id == int(item.site)).first()[0]
TypeError: 'NoneType' object has no attribute '__getitem__'
