2016-08-23 14:17:03,005 ERROR: Exception on /api/v1.0/node_task/modify_status/9fcfbfb105c1b3f49b5f6b4401222557 [POST] [in /home/www/.demo/lib/python2.7/site-packages/flask/app.py:1423]
Traceback (most recent call last):
  File "/home/www/.demo/lib/python2.7/site-packages/flask/app.py", line 1817, in wsgi_app
    response = self.full_dispatch_request()
  File "/home/www/.demo/lib/python2.7/site-packages/flask/app.py", line 1477, in full_dispatch_request
    rv = self.handle_user_exception(e)
  File "/home/www/.demo/lib/python2.7/site-packages/flask/app.py", line 1381, in handle_user_exception
    reraise(exc_type, exc_value, tb)
  File "/home/www/.demo/lib/python2.7/site-packages/flask/app.py", line 1475, in full_dispatch_request
    rv = self.dispatch_request()
  File "/home/www/.demo/lib/python2.7/site-packages/flask/app.py", line 1461, in dispatch_request
    return self.view_functions[rule.endpoint](**req.view_args)
  File "/home/www/aud2/app/views/site.py", line 875, in modify_node_task_status
    mes.sendEmail()
  File "/home/www/aud2/app/utils/message.py", line 45, in sendEmail
    thr = Thread(target=send_async_email, args=[receiver + '@aicai.com', subject, html])
TypeError: unsupported operand type(s) for +: 'NoneType' and 'str'
2016-08-23 14:19:10,403 ERROR: Exception on /api/v1.0/node_task/modify_status/a9ac787d985c7d478c85910f72d07c1d [POST] [in /home/www/.demo/lib/python2.7/site-packages/flask/app.py:1423]
Traceback (most recent call last):
  File "/home/www/.demo/lib/python2.7/site-packages/flask/app.py", line 1817, in wsgi_app
    response = self.full_dispatch_request()
  File "/home/www/.demo/lib/python2.7/site-packages/flask/app.py", line 1477, in full_dispatch_request
    rv = self.handle_user_exception(e)
  File "/home/www/.demo/lib/python2.7/site-packages/flask/app.py", line 1381, in handle_user_exception
    reraise(exc_type, exc_value, tb)
  File "/home/www/.demo/lib/python2.7/site-packages/flask/app.py", line 1475, in full_dispatch_request
    rv = self.dispatch_request()
  File "/home/www/.demo/lib/python2.7/site-packages/flask/app.py", line 1461, in dispatch_request
    return self.view_functions[rule.endpoint](**req.view_args)
  File "/home/www/aud2/app/views/site.py", line 875, in modify_node_task_status
    mes.sendEmail()
  File "/home/www/aud2/app/utils/message.py", line 45, in sendEmail
    thr = Thread(target=send_async_email, args=[receiver + '@aicai.com', subject, html])
TypeError: unsupported operand type(s) for +: 'NoneType' and 'str'
2016-08-23 14:20:42,231 ERROR: Exception on /api/v1.0/node_task/modify_status/18ce8f2de06bf405f6d716720ce2638f [POST] [in /home/www/.demo/lib/python2.7/site-packages/flask/app.py:1423]
Traceback (most recent call last):
  File "/home/www/.demo/lib/python2.7/site-packages/flask/app.py", line 1817, in wsgi_app
    response = self.full_dispatch_request()
  File "/home/www/.demo/lib/python2.7/site-packages/flask/app.py", line 1477, in full_dispatch_request
    rv = self.handle_user_exception(e)
  File "/home/www/.demo/lib/python2.7/site-packages/flask/app.py", line 1381, in handle_user_exception
    reraise(exc_type, exc_value, tb)
  File "/home/www/.demo/lib/python2.7/site-packages/flask/app.py", line 1475, in full_dispatch_request
    rv = self.dispatch_request()
  File "/home/www/.demo/lib/python2.7/site-packages/flask/app.py", line 1461, in dispatch_request
    return self.view_functions[rule.endpoint](**req.view_args)
  File "/home/www/aud2/app/views/site.py", line 875, in modify_node_task_status
    mes.sendEmail()
  File "/home/www/aud2/app/utils/message.py", line 45, in sendEmail
    thr = Thread(target=send_async_email, args=[receiver + '@aicai.com', subject, html])
TypeError: unsupported operand type(s) for +: 'NoneType' and 'str'
2016-08-23 14:21:40,358 ERROR: Exception on /api/v1.0/node_task/modify_status/0ebf5856929b950661f9bf9b9777f173 [POST] [in /home/www/.demo/lib/python2.7/site-packages/flask/app.py:1423]
Traceback (most recent call last):
  File "/home/www/.demo/lib/python2.7/site-packages/flask/app.py", line 1817, in wsgi_app
    response = self.full_dispatch_request()
  File "/home/www/.demo/lib/python2.7/site-packages/flask/app.py", line 1477, in full_dispatch_request
    rv = self.handle_user_exception(e)
  File "/home/www/.demo/lib/python2.7/site-packages/flask/app.py", line 1381, in handle_user_exception
    reraise(exc_type, exc_value, tb)
  File "/home/www/.demo/lib/python2.7/site-packages/flask/app.py", line 1475, in full_dispatch_request
    rv = self.dispatch_request()
  File "/home/www/.demo/lib/python2.7/site-packages/flask/app.py", line 1461, in dispatch_request
    return self.view_functions[rule.endpoint](**req.view_args)
  File "/home/www/aud2/app/views/site.py", line 875, in modify_node_task_status
    mes.sendEmail()
  File "/home/www/aud2/app/utils/message.py", line 45, in sendEmail
    thr = Thread(target=send_async_email, args=[receiver + '@aicai.com', subject, html])
TypeError: unsupported operand type(s) for +: 'NoneType' and 'str'
2016-08-23 14:28:39,423 ERROR: Exception on /api/v1.0/tomcat_task/modify_status/TC-hq_test-172-17-168-6-20160823142826 [POST] [in /home/www/.demo/lib/python2.7/site-packages/flask/app.py:1423]
Traceback (most recent call last):
  File "/home/www/.demo/lib/python2.7/site-packages/flask/app.py", line 1817, in wsgi_app
    response = self.full_dispatch_request()
  File "/home/www/.demo/lib/python2.7/site-packages/flask/app.py", line 1477, in full_dispatch_request
    rv = self.handle_user_exception(e)
  File "/home/www/.demo/lib/python2.7/site-packages/flask/app.py", line 1370, in handle_user_exception
    return self.handle_http_exception(e)
  File "/home/www/.demo/lib/python2.7/site-packages/flask/app.py", line 1330, in handle_http_exception
    return handler(e)
  File "/home/www/aud2/app/__init__.py", line 150, in page_404
    return render_template('errors/404.html'), 404
  File "/home/www/.demo/lib/python2.7/site-packages/flask/templating.py", line 128, in render_template
    context, ctx.app)
  File "/home/www/.demo/lib/python2.7/site-packages/flask/templating.py", line 110, in _render
    rv = template.render(context)
  File "/home/www/.demo/lib/python2.7/site-packages/jinja2/environment.py", line 969, in render
    return self.environment.handle_exception(exc_info, True)
  File "/home/www/.demo/lib/python2.7/site-packages/jinja2/environment.py", line 742, in handle_exception
    reraise(exc_type, exc_value, tb)
  File "/home/www/aud2/app/templates/errors/404.html", line 2, in top-level template code
    {% extends "base.html" %}
  File "/home/www/aud2/app/templates/base.html", line 26, in top-level template code
    {% include 'nav.html' %}
  File "/home/www/aud2/app/templates/nav.html", line 221, in top-level template code
    {% if g.user.is_admin() %}
UndefinedError: 'werkzeug.local.LocalProxy object' has no attribute 'is_admin'
2016-08-23 14:29:25,096 ERROR: Exception on /api/v1.0/tomcat_task/modify_status/TC-hq_test-172-17-168-6-20160823142855 [POST] [in /home/www/.demo/lib/python2.7/site-packages/flask/app.py:1423]
Traceback (most recent call last):
  File "/home/www/.demo/lib/python2.7/site-packages/flask/app.py", line 1817, in wsgi_app
    response = self.full_dispatch_request()
  File "/home/www/.demo/lib/python2.7/site-packages/flask/app.py", line 1477, in full_dispatch_request
    rv = self.handle_user_exception(e)
  File "/home/www/.demo/lib/python2.7/site-packages/flask/app.py", line 1370, in handle_user_exception
    return self.handle_http_exception(e)
  File "/home/www/.demo/lib/python2.7/site-packages/flask/app.py", line 1330, in handle_http_exception
    return handler(e)
  File "/home/www/aud2/app/__init__.py", line 150, in page_404
    return render_template('errors/404.html'), 404
  File "/home/www/.demo/lib/python2.7/site-packages/flask/templating.py", line 128, in render_template
    context, ctx.app)
  File "/home/www/.demo/lib/python2.7/site-packages/flask/templating.py", line 110, in _render
    rv = template.render(context)
  File "/home/www/.demo/lib/python2.7/site-packages/jinja2/environment.py", line 969, in render
    return self.environment.handle_exception(exc_info, True)
  File "/home/www/.demo/lib/python2.7/site-packages/jinja2/environment.py", line 742, in handle_exception
    reraise(exc_type, exc_value, tb)
  File "/home/www/aud2/app/templates/errors/404.html", line 2, in top-level template code
    {% extends "base.html" %}
  File "/home/www/aud2/app/templates/base.html", line 26, in top-level template code
    {% include 'nav.html' %}
  File "/home/www/aud2/app/templates/nav.html", line 221, in top-level template code
    {% if g.user.is_admin() %}
UndefinedError: 'werkzeug.local.LocalProxy object' has no attribute 'is_admin'
2016-08-23 14:35:51,246 ERROR: Exception on /api/v1.0/tomcat_task/modify_status/TC-hs_task-172-18-168-9-20160823143543 [POST] [in /home/www/.demo/lib/python2.7/site-packages/flask/app.py:1423]
Traceback (most recent call last):
  File "/home/www/.demo/lib/python2.7/site-packages/flask/app.py", line 1817, in wsgi_app
    response = self.full_dispatch_request()
  File "/home/www/.demo/lib/python2.7/site-packages/flask/app.py", line 1477, in full_dispatch_request
    rv = self.handle_user_exception(e)
  File "/home/www/.demo/lib/python2.7/site-packages/flask/app.py", line 1370, in handle_user_exception
    return self.handle_http_exception(e)
  File "/home/www/.demo/lib/python2.7/site-packages/flask/app.py", line 1330, in handle_http_exception
    return handler(e)
  File "/home/www/aud2/app/__init__.py", line 150, in page_404
    return render_template('errors/404.html'), 404
  File "/home/www/.demo/lib/python2.7/site-packages/flask/templating.py", line 128, in render_template
    context, ctx.app)
  File "/home/www/.demo/lib/python2.7/site-packages/flask/templating.py", line 110, in _render
    rv = template.render(context)
  File "/home/www/.demo/lib/python2.7/site-packages/jinja2/environment.py", line 969, in render
    return self.environment.handle_exception(exc_info, True)
  File "/home/www/.demo/lib/python2.7/site-packages/jinja2/environment.py", line 742, in handle_exception
    reraise(exc_type, exc_value, tb)
  File "/home/www/aud2/app/templates/errors/404.html", line 2, in top-level template code
    {% extends "base.html" %}
  File "/home/www/aud2/app/templates/base.html", line 26, in top-level template code
    {% include 'nav.html' %}
  File "/home/www/aud2/app/templates/nav.html", line 221, in top-level template code
    {% if g.user.is_admin() %}
UndefinedError: 'werkzeug.local.LocalProxy object' has no attribute 'is_admin'
2016-08-23 14:36:29,873 ERROR: Exception on /api/v1.0/tomcat_task/modify_status/TC-hs_push-172-18-168-9-20160823143622 [POST] [in /home/www/.demo/lib/python2.7/site-packages/flask/app.py:1423]
Traceback (most recent call last):
  File "/home/www/.demo/lib/python2.7/site-packages/flask/app.py", line 1817, in wsgi_app
    response = self.full_dispatch_request()
  File "/home/www/.demo/lib/python2.7/site-packages/flask/app.py", line 1477, in full_dispatch_request
    rv = self.handle_user_exception(e)
  File "/home/www/.demo/lib/python2.7/site-packages/flask/app.py", line 1370, in handle_user_exception
    return self.handle_http_exception(e)
  File "/home/www/.demo/lib/python2.7/site-packages/flask/app.py", line 1330, in handle_http_exception
    return handler(e)
  File "/home/www/aud2/app/__init__.py", line 150, in page_404
    return render_template('errors/404.html'), 404
  File "/home/www/.demo/lib/python2.7/site-packages/flask/templating.py", line 128, in render_template
    context, ctx.app)
  File "/home/www/.demo/lib/python2.7/site-packages/flask/templating.py", line 110, in _render
    rv = template.render(context)
  File "/home/www/.demo/lib/python2.7/site-packages/jinja2/environment.py", line 969, in render
    return self.environment.handle_exception(exc_info, True)
  File "/home/www/.demo/lib/python2.7/site-packages/jinja2/environment.py", line 742, in handle_exception
    reraise(exc_type, exc_value, tb)
  File "/home/www/aud2/app/templates/errors/404.html", line 2, in top-level template code
    {% extends "base.html" %}
  File "/home/www/aud2/app/templates/base.html", line 26, in top-level template code
    {% include 'nav.html' %}
  File "/home/www/aud2/app/templates/nav.html", line 221, in top-level template code
    {% if g.user.is_admin() %}
UndefinedError: 'werkzeug.local.LocalProxy object' has no attribute 'is_admin'
2016-08-23 14:41:44,385 ERROR: Exception on /api/v1.0/tomcat_task/modify_status/TC-hs_task-172-18-168-12-20160823144126 [POST] [in /home/www/.demo/lib/python2.7/site-packages/flask/app.py:1423]
Traceback (most recent call last):
  File "/home/www/.demo/lib/python2.7/site-packages/flask/app.py", line 1817, in wsgi_app
    response = self.full_dispatch_request()
  File "/home/www/.demo/lib/python2.7/site-packages/flask/app.py", line 1477, in full_dispatch_request
    rv = self.handle_user_exception(e)
  File "/home/www/.demo/lib/python2.7/site-packages/flask/app.py", line 1370, in handle_user_exception
    return self.handle_http_exception(e)
  File "/home/www/.demo/lib/python2.7/site-packages/flask/app.py", line 1330, in handle_http_exception
    return handler(e)
  File "/home/www/aud2/app/__init__.py", line 150, in page_404
    return render_template('errors/404.html'), 404
  File "/home/www/.demo/lib/python2.7/site-packages/flask/templating.py", line 128, in render_template
    context, ctx.app)
  File "/home/www/.demo/lib/python2.7/site-packages/flask/templating.py", line 110, in _render
    rv = template.render(context)
  File "/home/www/.demo/lib/python2.7/site-packages/jinja2/environment.py", line 969, in render
    return self.environment.handle_exception(exc_info, True)
  File "/home/www/.demo/lib/python2.7/site-packages/jinja2/environment.py", line 742, in handle_exception
    reraise(exc_type, exc_value, tb)
  File "/home/www/aud2/app/templates/errors/404.html", line 2, in top-level template code
    {% extends "base.html" %}
  File "/home/www/aud2/app/templates/base.html", line 26, in top-level template code
    {% include 'nav.html' %}
  File "/home/www/aud2/app/templates/nav.html", line 221, in top-level template code
    {% if g.user.is_admin() %}
UndefinedError: 'werkzeug.local.LocalProxy object' has no attribute 'is_admin'
2016-08-23 14:49:04,987 ERROR: Exception on /favicon.ico [GET] [in /home/www/.demo/lib/python2.7/site-packages/flask/app.py:1423]
Traceback (most recent call last):
  File "/home/www/.demo/lib/python2.7/site-packages/flask/app.py", line 1817, in wsgi_app
    response = self.full_dispatch_request()
  File "/home/www/.demo/lib/python2.7/site-packages/flask/app.py", line 1477, in full_dispatch_request
    rv = self.handle_user_exception(e)
  File "/home/www/.demo/lib/python2.7/site-packages/flask/app.py", line 1370, in handle_user_exception
    return self.handle_http_exception(e)
  File "/home/www/.demo/lib/python2.7/site-packages/flask/app.py", line 1330, in handle_http_exception
    return handler(e)
  File "/home/www/aud2/app/__init__.py", line 150, in page_404
    return render_template('errors/404.html'), 404
  File "/home/www/.demo/lib/python2.7/site-packages/flask/templating.py", line 128, in render_template
    context, ctx.app)
  File "/home/www/.demo/lib/python2.7/site-packages/flask/templating.py", line 110, in _render
    rv = template.render(context)
  File "/home/www/.demo/lib/python2.7/site-packages/jinja2/environment.py", line 969, in render
    return self.environment.handle_exception(exc_info, True)
  File "/home/www/.demo/lib/python2.7/site-packages/jinja2/environment.py", line 742, in handle_exception
    reraise(exc_type, exc_value, tb)
  File "/home/www/aud2/app/templates/errors/404.html", line 2, in top-level template code
    {% extends "base.html" %}
  File "/home/www/aud2/app/templates/base.html", line 26, in top-level template code
    {% include 'nav.html' %}
  File "/home/www/aud2/app/templates/nav.html", line 221, in top-level template code
    {% if g.user.is_admin() %}
UndefinedError: 'werkzeug.local.LocalProxy object' has no attribute 'is_admin'
2016-08-23 14:49:05,049 ERROR: Exception on /favicon.ico [GET] [in /home/www/.demo/lib/python2.7/site-packages/flask/app.py:1423]
Traceback (most recent call last):
  File "/home/www/.demo/lib/python2.7/site-packages/flask/app.py", line 1817, in wsgi_app
    response = self.full_dispatch_request()
  File "/home/www/.demo/lib/python2.7/site-packages/flask/app.py", line 1477, in full_dispatch_request
    rv = self.handle_user_exception(e)
  File "/home/www/.demo/lib/python2.7/site-packages/flask/app.py", line 1370, in handle_user_exception
    return self.handle_http_exception(e)
  File "/home/www/.demo/lib/python2.7/site-packages/flask/app.py", line 1330, in handle_http_exception
    return handler(e)
  File "/home/www/aud2/app/__init__.py", line 150, in page_404
    return render_template('errors/404.html'), 404
  File "/home/www/.demo/lib/python2.7/site-packages/flask/templating.py", line 128, in render_template
    context, ctx.app)
  File "/home/www/.demo/lib/python2.7/site-packages/flask/templating.py", line 110, in _render
    rv = template.render(context)
  File "/home/www/.demo/lib/python2.7/site-packages/jinja2/environment.py", line 969, in render
    return self.environment.handle_exception(exc_info, True)
  File "/home/www/.demo/lib/python2.7/site-packages/jinja2/environment.py", line 742, in handle_exception
    reraise(exc_type, exc_value, tb)
  File "/home/www/aud2/app/templates/errors/404.html", line 2, in top-level template code
    {% extends "base.html" %}
  File "/home/www/aud2/app/templates/base.html", line 26, in top-level template code
    {% include 'nav.html' %}
  File "/home/www/aud2/app/templates/nav.html", line 221, in top-level template code
    {% if g.user.is_admin() %}
UndefinedError: 'werkzeug.local.LocalProxy object' has no attribute 'is_admin'
2016-08-23 14:59:31,018 ERROR: Exception on /favicon.ico [GET] [in /home/www/.demo/lib/python2.7/site-packages/flask/app.py:1423]
Traceback (most recent call last):
  File "/home/www/.demo/lib/python2.7/site-packages/flask/app.py", line 1817, in wsgi_app
    response = self.full_dispatch_request()
  File "/home/www/.demo/lib/python2.7/site-packages/flask/app.py", line 1477, in full_dispatch_request
    rv = self.handle_user_exception(e)
  File "/home/www/.demo/lib/python2.7/site-packages/flask/app.py", line 1370, in handle_user_exception
    return self.handle_http_exception(e)
  File "/home/www/.demo/lib/python2.7/site-packages/flask/app.py", line 1330, in handle_http_exception
    return handler(e)
  File "/home/www/aud2/app/__init__.py", line 150, in page_404
    return render_template('errors/404.html'), 404
  File "/home/www/.demo/lib/python2.7/site-packages/flask/templating.py", line 128, in render_template
    context, ctx.app)
  File "/home/www/.demo/lib/python2.7/site-packages/flask/templating.py", line 110, in _render
    rv = template.render(context)
  File "/home/www/.demo/lib/python2.7/site-packages/jinja2/environment.py", line 969, in render
    return self.environment.handle_exception(exc_info, True)
  File "/home/www/.demo/lib/python2.7/site-packages/jinja2/environment.py", line 742, in handle_exception
    reraise(exc_type, exc_value, tb)
  File "/home/www/aud2/app/templates/errors/404.html", line 2, in top-level template code
    {% extends "base.html" %}
  File "/home/www/aud2/app/templates/base.html", line 26, in top-level template code
    {% include 'nav.html' %}
  File "/home/www/aud2/app/templates/nav.html", line 221, in top-level template code
    {% if g.user.is_admin() %}
UndefinedError: 'werkzeug.local.LocalProxy object' has no attribute 'is_admin'
2016-08-23 14:59:31,134 ERROR: Exception on /favicon.ico [GET] [in /home/www/.demo/lib/python2.7/site-packages/flask/app.py:1423]
Traceback (most recent call last):
  File "/home/www/.demo/lib/python2.7/site-packages/flask/app.py", line 1817, in wsgi_app
    response = self.full_dispatch_request()
  File "/home/www/.demo/lib/python2.7/site-packages/flask/app.py", line 1477, in full_dispatch_request
    rv = self.handle_user_exception(e)
  File "/home/www/.demo/lib/python2.7/site-packages/flask/app.py", line 1370, in handle_user_exception
    return self.handle_http_exception(e)
  File "/home/www/.demo/lib/python2.7/site-packages/flask/app.py", line 1330, in handle_http_exception
    return handler(e)
  File "/home/www/aud2/app/__init__.py", line 150, in page_404
    return render_template('errors/404.html'), 404
  File "/home/www/.demo/lib/python2.7/site-packages/flask/templating.py", line 128, in render_template
    context, ctx.app)
  File "/home/www/.demo/lib/python2.7/site-packages/flask/templating.py", line 110, in _render
    rv = template.render(context)
  File "/home/www/.demo/lib/python2.7/site-packages/jinja2/environment.py", line 969, in render
    return self.environment.handle_exception(exc_info, True)
  File "/home/www/.demo/lib/python2.7/site-packages/jinja2/environment.py", line 742, in handle_exception
    reraise(exc_type, exc_value, tb)
  File "/home/www/aud2/app/templates/errors/404.html", line 2, in top-level template code
    {% extends "base.html" %}
  File "/home/www/aud2/app/templates/base.html", line 26, in top-level template code
    {% include 'nav.html' %}
  File "/home/www/aud2/app/templates/nav.html", line 221, in top-level template code
    {% if g.user.is_admin() %}
UndefinedError: 'werkzeug.local.LocalProxy object' has no attribute 'is_admin'
2016-08-23 14:59:56,145 ERROR: Exception on /favicon.ico [GET] [in /home/www/.demo/lib/python2.7/site-packages/flask/app.py:1423]
Traceback (most recent call last):
  File "/home/www/.demo/lib/python2.7/site-packages/flask/app.py", line 1817, in wsgi_app
    response = self.full_dispatch_request()
  File "/home/www/.demo/lib/python2.7/site-packages/flask/app.py", line 1477, in full_dispatch_request
    rv = self.handle_user_exception(e)
  File "/home/www/.demo/lib/python2.7/site-packages/flask/app.py", line 1370, in handle_user_exception
    return self.handle_http_exception(e)
  File "/home/www/.demo/lib/python2.7/site-packages/flask/app.py", line 1330, in handle_http_exception
    return handler(e)
  File "/home/www/aud2/app/__init__.py", line 150, in page_404
    return render_template('errors/404.html'), 404
  File "/home/www/.demo/lib/python2.7/site-packages/flask/templating.py", line 128, in render_template
    context, ctx.app)
  File "/home/www/.demo/lib/python2.7/site-packages/flask/templating.py", line 110, in _render
    rv = template.render(context)
  File "/home/www/.demo/lib/python2.7/site-packages/jinja2/environment.py", line 969, in render
    return self.environment.handle_exception(exc_info, True)
  File "/home/www/.demo/lib/python2.7/site-packages/jinja2/environment.py", line 742, in handle_exception
    reraise(exc_type, exc_value, tb)
  File "/home/www/aud2/app/templates/errors/404.html", line 2, in top-level template code
    {% extends "base.html" %}
  File "/home/www/aud2/app/templates/base.html", line 26, in top-level template code
    {% include 'nav.html' %}
  File "/home/www/aud2/app/templates/nav.html", line 221, in top-level template code
    {% if g.user.is_admin() %}
UndefinedError: 'werkzeug.local.LocalProxy object' has no attribute 'is_admin'
2016-08-23 15:00:01,338 ERROR: Exception on /favicon.ico [GET] [in /home/www/.demo/lib/python2.7/site-packages/flask/app.py:1423]
Traceback (most recent call last):
  File "/home/www/.demo/lib/python2.7/site-packages/flask/app.py", line 1817, in wsgi_app
    response = self.full_dispatch_request()
  File "/home/www/.demo/lib/python2.7/site-packages/flask/app.py", line 1477, in full_dispatch_request
    rv = self.handle_user_exception(e)
  File "/home/www/.demo/lib/python2.7/site-packages/flask/app.py", line 1370, in handle_user_exception
    return self.handle_http_exception(e)
  File "/home/www/.demo/lib/python2.7/site-packages/flask/app.py", line 1330, in handle_http_exception
    return handler(e)
  File "/home/www/aud2/app/__init__.py", line 150, in page_404
    return render_template('errors/404.html'), 404
  File "/home/www/.demo/lib/python2.7/site-packages/flask/templating.py", line 128, in render_template
    context, ctx.app)
  File "/home/www/.demo/lib/python2.7/site-packages/flask/templating.py", line 110, in _render
    rv = template.render(context)
  File "/home/www/.demo/lib/python2.7/site-packages/jinja2/environment.py", line 969, in render
    return self.environment.handle_exception(exc_info, True)
  File "/home/www/.demo/lib/python2.7/site-packages/jinja2/environment.py", line 742, in handle_exception
    reraise(exc_type, exc_value, tb)
  File "/home/www/aud2/app/templates/errors/404.html", line 2, in top-level template code
    {% extends "base.html" %}
  File "/home/www/aud2/app/templates/base.html", line 26, in top-level template code
    {% include 'nav.html' %}
  File "/home/www/aud2/app/templates/nav.html", line 221, in top-level template code
    {% if g.user.is_admin() %}
UndefinedError: 'werkzeug.local.LocalProxy object' has no attribute 'is_admin'
2016-08-23 15:00:06,317 ERROR: Exception on /favicon.ico [GET] [in /home/www/.demo/lib/python2.7/site-packages/flask/app.py:1423]
Traceback (most recent call last):
  File "/home/www/.demo/lib/python2.7/site-packages/flask/app.py", line 1817, in wsgi_app
    response = self.full_dispatch_request()
  File "/home/www/.demo/lib/python2.7/site-packages/flask/app.py", line 1477, in full_dispatch_request
    rv = self.handle_user_exception(e)
  File "/home/www/.demo/lib/python2.7/site-packages/flask/app.py", line 1370, in handle_user_exception
    return self.handle_http_exception(e)
  File "/home/www/.demo/lib/python2.7/site-packages/flask/app.py", line 1330, in handle_http_exception
    return handler(e)
  File "/home/www/aud2/app/__init__.py", line 150, in page_404
    return render_template('errors/404.html'), 404
  File "/home/www/.demo/lib/python2.7/site-packages/flask/templating.py", line 128, in render_template
    context, ctx.app)
  File "/home/www/.demo/lib/python2.7/site-packages/flask/templating.py", line 110, in _render
    rv = template.render(context)
  File "/home/www/.demo/lib/python2.7/site-packages/jinja2/environment.py", line 969, in render
    return self.environment.handle_exception(exc_info, True)
  File "/home/www/.demo/lib/python2.7/site-packages/jinja2/environment.py", line 742, in handle_exception
    reraise(exc_type, exc_value, tb)
  File "/home/www/aud2/app/templates/errors/404.html", line 2, in top-level template code
    {% extends "base.html" %}
  File "/home/www/aud2/app/templates/base.html", line 26, in top-level template code
    {% include 'nav.html' %}
  File "/home/www/aud2/app/templates/nav.html", line 221, in top-level template code
    {% if g.user.is_admin() %}
UndefinedError: 'werkzeug.local.LocalProxy object' has no attribute 'is_admin'
2016-08-23 15:00:16,979 ERROR: Exception on /favicon.ico [GET] [in /home/www/.demo/lib/python2.7/site-packages/flask/app.py:1423]
Traceback (most recent call last):
  File "/home/www/.demo/lib/python2.7/site-packages/flask/app.py", line 1817, in wsgi_app
    response = self.full_dispatch_request()
  File "/home/www/.demo/lib/python2.7/site-packages/flask/app.py", line 1477, in full_dispatch_request
    rv = self.handle_user_exception(e)
  File "/home/www/.demo/lib/python2.7/site-packages/flask/app.py", line 1370, in handle_user_exception
    return self.handle_http_exception(e)
  File "/home/www/.demo/lib/python2.7/site-packages/flask/app.py", line 1330, in handle_http_exception
    return handler(e)
  File "/home/www/aud2/app/__init__.py", line 150, in page_404
    return render_template('errors/404.html'), 404
  File "/home/www/.demo/lib/python2.7/site-packages/flask/templating.py", line 128, in render_template
    context, ctx.app)
  File "/home/www/.demo/lib/python2.7/site-packages/flask/templating.py", line 110, in _render
    rv = template.render(context)
  File "/home/www/.demo/lib/python2.7/site-packages/jinja2/environment.py", line 969, in render
    return self.environment.handle_exception(exc_info, True)
  File "/home/www/.demo/lib/python2.7/site-packages/jinja2/environment.py", line 742, in handle_exception
    reraise(exc_type, exc_value, tb)
  File "/home/www/aud2/app/templates/errors/404.html", line 2, in top-level template code
    {% extends "base.html" %}
  File "/home/www/aud2/app/templates/base.html", line 26, in top-level template code
    {% include 'nav.html' %}
  File "/home/www/aud2/app/templates/nav.html", line 221, in top-level template code
    {% if g.user.is_admin() %}
UndefinedError: 'werkzeug.local.LocalProxy object' has no attribute 'is_admin'
2016-08-23 15:58:41,714 ERROR: Exception on /api/v1.0/node_task/modify_status/5649a2e6272be562387553b9f07ac114 [POST] [in /home/www/.demo/lib/python2.7/site-packages/flask/app.py:1423]
Traceback (most recent call last):
  File "/home/www/.demo/lib/python2.7/site-packages/flask/app.py", line 1817, in wsgi_app
    response = self.full_dispatch_request()
  File "/home/www/.demo/lib/python2.7/site-packages/flask/app.py", line 1477, in full_dispatch_request
    rv = self.handle_user_exception(e)
  File "/home/www/.demo/lib/python2.7/site-packages/flask/app.py", line 1381, in handle_user_exception
    reraise(exc_type, exc_value, tb)
  File "/home/www/.demo/lib/python2.7/site-packages/flask/app.py", line 1475, in full_dispatch_request
    rv = self.dispatch_request()
  File "/home/www/.demo/lib/python2.7/site-packages/flask/app.py", line 1461, in dispatch_request
    return self.view_functions[rule.endpoint](**req.view_args)
  File "/home/www/aud2/app/views/site.py", line 875, in modify_node_task_status
    mes.sendEmail()
  File "/home/www/aud2/app/utils/message.py", line 45, in sendEmail
    thr = Thread(target=send_async_email, args=[receiver + '@aicai.com', subject, html])
TypeError: unsupported operand type(s) for +: 'NoneType' and 'str'
2016-08-23 16:01:43,228 ERROR: Exception on /favicon.ico [GET] [in /home/www/.demo/lib/python2.7/site-packages/flask/app.py:1423]
Traceback (most recent call last):
  File "/home/www/.demo/lib/python2.7/site-packages/flask/app.py", line 1817, in wsgi_app
    response = self.full_dispatch_request()
  File "/home/www/.demo/lib/python2.7/site-packages/flask/app.py", line 1477, in full_dispatch_request
    rv = self.handle_user_exception(e)
  File "/home/www/.demo/lib/python2.7/site-packages/flask/app.py", line 1370, in handle_user_exception
    return self.handle_http_exception(e)
  File "/home/www/.demo/lib/python2.7/site-packages/flask/app.py", line 1330, in handle_http_exception
    return handler(e)
  File "/home/www/aud2/app/__init__.py", line 150, in page_404
    return render_template('errors/404.html'), 404
  File "/home/www/.demo/lib/python2.7/site-packages/flask/templating.py", line 128, in render_template
    context, ctx.app)
  File "/home/www/.demo/lib/python2.7/site-packages/flask/templating.py", line 110, in _render
    rv = template.render(context)
  File "/home/www/.demo/lib/python2.7/site-packages/jinja2/environment.py", line 969, in render
    return self.environment.handle_exception(exc_info, True)
  File "/home/www/.demo/lib/python2.7/site-packages/jinja2/environment.py", line 742, in handle_exception
    reraise(exc_type, exc_value, tb)
  File "/home/www/aud2/app/templates/errors/404.html", line 2, in top-level template code
    {% extends "base.html" %}
  File "/home/www/aud2/app/templates/base.html", line 26, in top-level template code
    {% include 'nav.html' %}
  File "/home/www/aud2/app/templates/nav.html", line 221, in top-level template code
    {% if g.user.is_admin() %}
UndefinedError: 'werkzeug.local.LocalProxy object' has no attribute 'is_admin'
2016-08-23 16:38:39,141 ERROR: Exception on /api/v1.0/node_task/modify_status/7897114a82ed34541db1c92b450d8dba [POST] [in /home/www/.demo/lib/python2.7/site-packages/flask/app.py:1423]
Traceback (most recent call last):
  File "/home/www/.demo/lib/python2.7/site-packages/flask/app.py", line 1817, in wsgi_app
    response = self.full_dispatch_request()
  File "/home/www/.demo/lib/python2.7/site-packages/flask/app.py", line 1477, in full_dispatch_request
    rv = self.handle_user_exception(e)
  File "/home/www/.demo/lib/python2.7/site-packages/flask/app.py", line 1381, in handle_user_exception
    reraise(exc_type, exc_value, tb)
  File "/home/www/.demo/lib/python2.7/site-packages/flask/app.py", line 1475, in full_dispatch_request
    rv = self.dispatch_request()
  File "/home/www/.demo/lib/python2.7/site-packages/flask/app.py", line 1461, in dispatch_request
    return self.view_functions[rule.endpoint](**req.view_args)
  File "/home/www/aud2/app/views/site.py", line 875, in modify_node_task_status
    mes.sendEmail()
  File "/home/www/aud2/app/utils/message.py", line 45, in sendEmail
    thr = Thread(target=send_async_email, args=[receiver + '@aicai.com', subject, html])
TypeError: unsupported operand type(s) for +: 'NoneType' and 'str'
2016-08-23 17:04:39,209 ERROR: Exception on /favicon.ico [GET] [in /home/www/.demo/lib/python2.7/site-packages/flask/app.py:1423]
Traceback (most recent call last):
  File "/home/www/.demo/lib/python2.7/site-packages/flask/app.py", line 1817, in wsgi_app
    response = self.full_dispatch_request()
  File "/home/www/.demo/lib/python2.7/site-packages/flask/app.py", line 1477, in full_dispatch_request
    rv = self.handle_user_exception(e)
  File "/home/www/.demo/lib/python2.7/site-packages/flask/app.py", line 1370, in handle_user_exception
    return self.handle_http_exception(e)
  File "/home/www/.demo/lib/python2.7/site-packages/flask/app.py", line 1330, in handle_http_exception
    return handler(e)
  File "/home/www/aud2/app/__init__.py", line 150, in page_404
    return render_template('errors/404.html'), 404
  File "/home/www/.demo/lib/python2.7/site-packages/flask/templating.py", line 128, in render_template
    context, ctx.app)
  File "/home/www/.demo/lib/python2.7/site-packages/flask/templating.py", line 110, in _render
    rv = template.render(context)
  File "/home/www/.demo/lib/python2.7/site-packages/jinja2/environment.py", line 969, in render
    return self.environment.handle_exception(exc_info, True)
  File "/home/www/.demo/lib/python2.7/site-packages/jinja2/environment.py", line 742, in handle_exception
    reraise(exc_type, exc_value, tb)
  File "/home/www/aud2/app/templates/errors/404.html", line 2, in top-level template code
    {% extends "base.html" %}
  File "/home/www/aud2/app/templates/base.html", line 26, in top-level template code
    {% include 'nav.html' %}
  File "/home/www/aud2/app/templates/nav.html", line 221, in top-level template code
    {% if g.user.is_admin() %}
UndefinedError: 'werkzeug.local.LocalProxy object' has no attribute 'is_admin'
2016-08-23 17:13:40,651 ERROR: Exception on /api/v1.0/node_task/modify_status/74d108be9b1832cc6aa9bde4a09ea691 [POST] [in /home/www/.demo/lib/python2.7/site-packages/flask/app.py:1423]
Traceback (most recent call last):
  File "/home/www/.demo/lib/python2.7/site-packages/flask/app.py", line 1817, in wsgi_app
    response = self.full_dispatch_request()
  File "/home/www/.demo/lib/python2.7/site-packages/flask/app.py", line 1477, in full_dispatch_request
    rv = self.handle_user_exception(e)
  File "/home/www/.demo/lib/python2.7/site-packages/flask/app.py", line 1381, in handle_user_exception
    reraise(exc_type, exc_value, tb)
  File "/home/www/.demo/lib/python2.7/site-packages/flask/app.py", line 1475, in full_dispatch_request
    rv = self.dispatch_request()
  File "/home/www/.demo/lib/python2.7/site-packages/flask/app.py", line 1461, in dispatch_request
    return self.view_functions[rule.endpoint](**req.view_args)
  File "/home/www/aud2/app/views/site.py", line 875, in modify_node_task_status
    mes.sendEmail()
  File "/home/www/aud2/app/utils/message.py", line 45, in sendEmail
    thr = Thread(target=send_async_email, args=[receiver + '@aicai.com', subject, html])
TypeError: unsupported operand type(s) for +: 'NoneType' and 'str'
2016-08-23 17:49:28,074 ERROR: Exception on /favicon.ico [GET] [in /home/www/.demo/lib/python2.7/site-packages/flask/app.py:1423]
Traceback (most recent call last):
  File "/home/www/.demo/lib/python2.7/site-packages/flask/app.py", line 1817, in wsgi_app
    response = self.full_dispatch_request()
  File "/home/www/.demo/lib/python2.7/site-packages/flask/app.py", line 1477, in full_dispatch_request
    rv = self.handle_user_exception(e)
  File "/home/www/.demo/lib/python2.7/site-packages/flask/app.py", line 1370, in handle_user_exception
    return self.handle_http_exception(e)
  File "/home/www/.demo/lib/python2.7/site-packages/flask/app.py", line 1330, in handle_http_exception
    return handler(e)
  File "/home/www/aud2/app/__init__.py", line 150, in page_404
    return render_template('errors/404.html'), 404
  File "/home/www/.demo/lib/python2.7/site-packages/flask/templating.py", line 128, in render_template
    context, ctx.app)
  File "/home/www/.demo/lib/python2.7/site-packages/flask/templating.py", line 110, in _render
    rv = template.render(context)
  File "/home/www/.demo/lib/python2.7/site-packages/jinja2/environment.py", line 969, in render
    return self.environment.handle_exception(exc_info, True)
  File "/home/www/.demo/lib/python2.7/site-packages/jinja2/environment.py", line 742, in handle_exception
    reraise(exc_type, exc_value, tb)
  File "/home/www/aud2/app/templates/errors/404.html", line 2, in top-level template code
    {% extends "base.html" %}
  File "/home/www/aud2/app/templates/base.html", line 26, in top-level template code
    {% include 'nav.html' %}
  File "/home/www/aud2/app/templates/nav.html", line 221, in top-level template code
    {% if g.user.is_admin() %}
UndefinedError: 'werkzeug.local.LocalProxy object' has no attribute 'is_admin'
2016-08-23 17:49:28,086 ERROR: Exception on /favicon.ico [GET] [in /home/www/.demo/lib/python2.7/site-packages/flask/app.py:1423]
Traceback (most recent call last):
  File "/home/www/.demo/lib/python2.7/site-packages/flask/app.py", line 1817, in wsgi_app
    response = self.full_dispatch_request()
  File "/home/www/.demo/lib/python2.7/site-packages/flask/app.py", line 1477, in full_dispatch_request
    rv = self.handle_user_exception(e)
  File "/home/www/.demo/lib/python2.7/site-packages/flask/app.py", line 1370, in handle_user_exception
    return self.handle_http_exception(e)
  File "/home/www/.demo/lib/python2.7/site-packages/flask/app.py", line 1330, in handle_http_exception
    return handler(e)
  File "/home/www/aud2/app/__init__.py", line 150, in page_404
    return render_template('errors/404.html'), 404
  File "/home/www/.demo/lib/python2.7/site-packages/flask/templating.py", line 128, in render_template
    context, ctx.app)
  File "/home/www/.demo/lib/python2.7/site-packages/flask/templating.py", line 110, in _render
    rv = template.render(context)
  File "/home/www/.demo/lib/python2.7/site-packages/jinja2/environment.py", line 969, in render
    return self.environment.handle_exception(exc_info, True)
  File "/home/www/.demo/lib/python2.7/site-packages/jinja2/environment.py", line 742, in handle_exception
    reraise(exc_type, exc_value, tb)
  File "/home/www/aud2/app/templates/errors/404.html", line 2, in top-level template code
    {% extends "base.html" %}
  File "/home/www/aud2/app/templates/base.html", line 26, in top-level template code
    {% include 'nav.html' %}
  File "/home/www/aud2/app/templates/nav.html", line 221, in top-level template code
    {% if g.user.is_admin() %}
UndefinedError: 'werkzeug.local.LocalProxy object' has no attribute 'is_admin'
2016-08-23 18:05:09,715 ERROR: Exception on /favicon.ico [GET] [in /home/www/.demo/lib/python2.7/site-packages/flask/app.py:1423]
Traceback (most recent call last):
  File "/home/www/.demo/lib/python2.7/site-packages/flask/app.py", line 1817, in wsgi_app
    response = self.full_dispatch_request()
  File "/home/www/.demo/lib/python2.7/site-packages/flask/app.py", line 1477, in full_dispatch_request
    rv = self.handle_user_exception(e)
  File "/home/www/.demo/lib/python2.7/site-packages/flask/app.py", line 1370, in handle_user_exception
    return self.handle_http_exception(e)
  File "/home/www/.demo/lib/python2.7/site-packages/flask/app.py", line 1330, in handle_http_exception
    return handler(e)
  File "/home/www/aud2/app/__init__.py", line 150, in page_404
    return render_template('errors/404.html'), 404
  File "/home/www/.demo/lib/python2.7/site-packages/flask/templating.py", line 128, in render_template
    context, ctx.app)
  File "/home/www/.demo/lib/python2.7/site-packages/flask/templating.py", line 110, in _render
    rv = template.render(context)
  File "/home/www/.demo/lib/python2.7/site-packages/jinja2/environment.py", line 969, in render
    return self.environment.handle_exception(exc_info, True)
  File "/home/www/.demo/lib/python2.7/site-packages/jinja2/environment.py", line 742, in handle_exception
    reraise(exc_type, exc_value, tb)
  File "/home/www/aud2/app/templates/errors/404.html", line 2, in top-level template code
    {% extends "base.html" %}
  File "/home/www/aud2/app/templates/base.html", line 26, in top-level template code
    {% include 'nav.html' %}
  File "/home/www/aud2/app/templates/nav.html", line 221, in top-level template code
    {% if g.user.is_admin() %}
UndefinedError: 'werkzeug.local.LocalProxy object' has no attribute 'is_admin'
2016-08-23 18:05:14,272 ERROR: Exception on /favicon.ico [GET] [in /home/www/.demo/lib/python2.7/site-packages/flask/app.py:1423]
Traceback (most recent call last):
  File "/home/www/.demo/lib/python2.7/site-packages/flask/app.py", line 1817, in wsgi_app
    response = self.full_dispatch_request()
  File "/home/www/.demo/lib/python2.7/site-packages/flask/app.py", line 1477, in full_dispatch_request
    rv = self.handle_user_exception(e)
  File "/home/www/.demo/lib/python2.7/site-packages/flask/app.py", line 1370, in handle_user_exception
    return self.handle_http_exception(e)
  File "/home/www/.demo/lib/python2.7/site-packages/flask/app.py", line 1330, in handle_http_exception
    return handler(e)
  File "/home/www/aud2/app/__init__.py", line 150, in page_404
    return render_template('errors/404.html'), 404
  File "/home/www/.demo/lib/python2.7/site-packages/flask/templating.py", line 128, in render_template
    context, ctx.app)
  File "/home/www/.demo/lib/python2.7/site-packages/flask/templating.py", line 110, in _render
    rv = template.render(context)
  File "/home/www/.demo/lib/python2.7/site-packages/jinja2/environment.py", line 969, in render
    return self.environment.handle_exception(exc_info, True)
  File "/home/www/.demo/lib/python2.7/site-packages/jinja2/environment.py", line 742, in handle_exception
    reraise(exc_type, exc_value, tb)
  File "/home/www/aud2/app/templates/errors/404.html", line 2, in top-level template code
    {% extends "base.html" %}
  File "/home/www/aud2/app/templates/base.html", line 26, in top-level template code
    {% include 'nav.html' %}
  File "/home/www/aud2/app/templates/nav.html", line 221, in top-level template code
    {% if g.user.is_admin() %}
UndefinedError: 'werkzeug.local.LocalProxy object' has no attribute 'is_admin'
2016-08-23 18:05:21,586 ERROR: Exception on /（ [GET] [in /home/www/.demo/lib/python2.7/site-packages/flask/app.py:1423]
Traceback (most recent call last):
  File "/home/www/.demo/lib/python2.7/site-packages/flask/app.py", line 1817, in wsgi_app
    response = self.full_dispatch_request()
  File "/home/www/.demo/lib/python2.7/site-packages/flask/app.py", line 1477, in full_dispatch_request
    rv = self.handle_user_exception(e)
  File "/home/www/.demo/lib/python2.7/site-packages/flask/app.py", line 1370, in handle_user_exception
    return self.handle_http_exception(e)
  File "/home/www/.demo/lib/python2.7/site-packages/flask/app.py", line 1330, in handle_http_exception
    return handler(e)
  File "/home/www/aud2/app/__init__.py", line 150, in page_404
    return render_template('errors/404.html'), 404
  File "/home/www/.demo/lib/python2.7/site-packages/flask/templating.py", line 128, in render_template
    context, ctx.app)
  File "/home/www/.demo/lib/python2.7/site-packages/flask/templating.py", line 110, in _render
    rv = template.render(context)
  File "/home/www/.demo/lib/python2.7/site-packages/jinja2/environment.py", line 969, in render
    return self.environment.handle_exception(exc_info, True)
  File "/home/www/.demo/lib/python2.7/site-packages/jinja2/environment.py", line 742, in handle_exception
    reraise(exc_type, exc_value, tb)
  File "/home/www/aud2/app/templates/errors/404.html", line 2, in top-level template code
    {% extends "base.html" %}
  File "/home/www/aud2/app/templates/base.html", line 26, in top-level template code
    {% include 'nav.html' %}
  File "/home/www/aud2/app/templates/nav.html", line 221, in top-level template code
    {% if g.user.is_admin() %}
UndefinedError: 'werkzeug.local.LocalProxy object' has no attribute 'is_admin'
2016-08-23 18:05:21,643 ERROR: Exception on /favicon.ico [GET] [in /home/www/.demo/lib/python2.7/site-packages/flask/app.py:1423]
Traceback (most recent call last):
  File "/home/www/.demo/lib/python2.7/site-packages/flask/app.py", line 1817, in wsgi_app
    response = self.full_dispatch_request()
  File "/home/www/.demo/lib/python2.7/site-packages/flask/app.py", line 1477, in full_dispatch_request
    rv = self.handle_user_exception(e)
  File "/home/www/.demo/lib/python2.7/site-packages/flask/app.py", line 1370, in handle_user_exception
    return self.handle_http_exception(e)
  File "/home/www/.demo/lib/python2.7/site-packages/flask/app.py", line 1330, in handle_http_exception
    return handler(e)
  File "/home/www/aud2/app/__init__.py", line 150, in page_404
    return render_template('errors/404.html'), 404
  File "/home/www/.demo/lib/python2.7/site-packages/flask/templating.py", line 128, in render_template
    context, ctx.app)
  File "/home/www/.demo/lib/python2.7/site-packages/flask/templating.py", line 110, in _render
    rv = template.render(context)
  File "/home/www/.demo/lib/python2.7/site-packages/jinja2/environment.py", line 969, in render
    return self.environment.handle_exception(exc_info, True)
  File "/home/www/.demo/lib/python2.7/site-packages/jinja2/environment.py", line 742, in handle_exception
    reraise(exc_type, exc_value, tb)
  File "/home/www/aud2/app/templates/errors/404.html", line 2, in top-level template code
    {% extends "base.html" %}
  File "/home/www/aud2/app/templates/base.html", line 26, in top-level template code
    {% include 'nav.html' %}
  File "/home/www/aud2/app/templates/nav.html", line 221, in top-level template code
    {% if g.user.is_admin() %}
UndefinedError: 'werkzeug.local.LocalProxy object' has no attribute 'is_admin'
2016-08-23 18:05:24,760 ERROR: Exception on /favicon.ico [GET] [in /home/www/.demo/lib/python2.7/site-packages/flask/app.py:1423]
Traceback (most recent call last):
  File "/home/www/.demo/lib/python2.7/site-packages/flask/app.py", line 1817, in wsgi_app
    response = self.full_dispatch_request()
  File "/home/www/.demo/lib/python2.7/site-packages/flask/app.py", line 1477, in full_dispatch_request
    rv = self.handle_user_exception(e)
  File "/home/www/.demo/lib/python2.7/site-packages/flask/app.py", line 1370, in handle_user_exception
    return self.handle_http_exception(e)
  File "/home/www/.demo/lib/python2.7/site-packages/flask/app.py", line 1330, in handle_http_exception
    return handler(e)
  File "/home/www/aud2/app/__init__.py", line 150, in page_404
    return render_template('errors/404.html'), 404
  File "/home/www/.demo/lib/python2.7/site-packages/flask/templating.py", line 128, in render_template
    context, ctx.app)
  File "/home/www/.demo/lib/python2.7/site-packages/flask/templating.py", line 110, in _render
    rv = template.render(context)
  File "/home/www/.demo/lib/python2.7/site-packages/jinja2/environment.py", line 969, in render
    return self.environment.handle_exception(exc_info, True)
  File "/home/www/.demo/lib/python2.7/site-packages/jinja2/environment.py", line 742, in handle_exception
    reraise(exc_type, exc_value, tb)
  File "/home/www/aud2/app/templates/errors/404.html", line 2, in top-level template code
    {% extends "base.html" %}
  File "/home/www/aud2/app/templates/base.html", line 26, in top-level template code
    {% include 'nav.html' %}
  File "/home/www/aud2/app/templates/nav.html", line 221, in top-level template code
    {% if g.user.is_admin() %}
UndefinedError: 'werkzeug.local.LocalProxy object' has no attribute 'is_admin'
2016-08-23 18:10:05,996 ERROR: Exception on /favicon.ico [GET] [in /home/www/.demo/lib/python2.7/site-packages/flask/app.py:1423]
Traceback (most recent call last):
  File "/home/www/.demo/lib/python2.7/site-packages/flask/app.py", line 1817, in wsgi_app
    response = self.full_dispatch_request()
  File "/home/www/.demo/lib/python2.7/site-packages/flask/app.py", line 1477, in full_dispatch_request
    rv = self.handle_user_exception(e)
  File "/home/www/.demo/lib/python2.7/site-packages/flask/app.py", line 1370, in handle_user_exception
    return self.handle_http_exception(e)
  File "/home/www/.demo/lib/python2.7/site-packages/flask/app.py", line 1330, in handle_http_exception
    return handler(e)
  File "/home/www/aud2/app/__init__.py", line 150, in page_404
    return render_template('errors/404.html'), 404
  File "/home/www/.demo/lib/python2.7/site-packages/flask/templating.py", line 128, in render_template
    context, ctx.app)
  File "/home/www/.demo/lib/python2.7/site-packages/flask/templating.py", line 110, in _render
    rv = template.render(context)
  File "/home/www/.demo/lib/python2.7/site-packages/jinja2/environment.py", line 969, in render
    return self.environment.handle_exception(exc_info, True)
  File "/home/www/.demo/lib/python2.7/site-packages/jinja2/environment.py", line 742, in handle_exception
    reraise(exc_type, exc_value, tb)
  File "/home/www/aud2/app/templates/errors/404.html", line 2, in top-level template code
    {% extends "base.html" %}
  File "/home/www/aud2/app/templates/base.html", line 26, in top-level template code
    {% include 'nav.html' %}
  File "/home/www/aud2/app/templates/nav.html", line 221, in top-level template code
    {% if g.user.is_admin() %}
UndefinedError: 'werkzeug.local.LocalProxy object' has no attribute 'is_admin'
2016-08-23 18:10:12,369 ERROR: Exception on /favicon.ico [GET] [in /home/www/.demo/lib/python2.7/site-packages/flask/app.py:1423]
Traceback (most recent call last):
  File "/home/www/.demo/lib/python2.7/site-packages/flask/app.py", line 1817, in wsgi_app
    response = self.full_dispatch_request()
  File "/home/www/.demo/lib/python2.7/site-packages/flask/app.py", line 1477, in full_dispatch_request
    rv = self.handle_user_exception(e)
  File "/home/www/.demo/lib/python2.7/site-packages/flask/app.py", line 1370, in handle_user_exception
    return self.handle_http_exception(e)
  File "/home/www/.demo/lib/python2.7/site-packages/flask/app.py", line 1330, in handle_http_exception
    return handler(e)
  File "/home/www/aud2/app/__init__.py", line 150, in page_404
    return render_template('errors/404.html'), 404
  File "/home/www/.demo/lib/python2.7/site-packages/flask/templating.py", line 128, in render_template
    context, ctx.app)
  File "/home/www/.demo/lib/python2.7/site-packages/flask/templating.py", line 110, in _render
    rv = template.render(context)
  File "/home/www/.demo/lib/python2.7/site-packages/jinja2/environment.py", line 969, in render
    return self.environment.handle_exception(exc_info, True)
  File "/home/www/.demo/lib/python2.7/site-packages/jinja2/environment.py", line 742, in handle_exception
    reraise(exc_type, exc_value, tb)
  File "/home/www/aud2/app/templates/errors/404.html", line 2, in top-level template code
    {% extends "base.html" %}
  File "/home/www/aud2/app/templates/base.html", line 26, in top-level template code
    {% include 'nav.html' %}
  File "/home/www/aud2/app/templates/nav.html", line 221, in top-level template code
    {% if g.user.is_admin() %}
UndefinedError: 'werkzeug.local.LocalProxy object' has no attribute 'is_admin'
2016-08-23 18:14:38,673 ERROR: Exception on /favicon.ico [GET] [in /home/www/.demo/lib/python2.7/site-packages/flask/app.py:1423]
Traceback (most recent call last):
  File "/home/www/.demo/lib/python2.7/site-packages/flask/app.py", line 1817, in wsgi_app
    response = self.full_dispatch_request()
  File "/home/www/.demo/lib/python2.7/site-packages/flask/app.py", line 1477, in full_dispatch_request
    rv = self.handle_user_exception(e)
  File "/home/www/.demo/lib/python2.7/site-packages/flask/app.py", line 1370, in handle_user_exception
    return self.handle_http_exception(e)
  File "/home/www/.demo/lib/python2.7/site-packages/flask/app.py", line 1330, in handle_http_exception
    return handler(e)
  File "/home/www/aud2/app/__init__.py", line 150, in page_404
    return render_template('errors/404.html'), 404
  File "/home/www/.demo/lib/python2.7/site-packages/flask/templating.py", line 128, in render_template
    context, ctx.app)
  File "/home/www/.demo/lib/python2.7/site-packages/flask/templating.py", line 110, in _render
    rv = template.render(context)
  File "/home/www/.demo/lib/python2.7/site-packages/jinja2/environment.py", line 969, in render
    return self.environment.handle_exception(exc_info, True)
  File "/home/www/.demo/lib/python2.7/site-packages/jinja2/environment.py", line 742, in handle_exception
    reraise(exc_type, exc_value, tb)
  File "/home/www/aud2/app/templates/errors/404.html", line 2, in top-level template code
    {% extends "base.html" %}
  File "/home/www/aud2/app/templates/base.html", line 26, in top-level template code
    {% include 'nav.html' %}
  File "/home/www/aud2/app/templates/nav.html", line 221, in top-level template code
    {% if g.user.is_admin() %}
UndefinedError: 'werkzeug.local.LocalProxy object' has no attribute 'is_admin'
2016-08-23 18:14:39,544 ERROR: Exception on /favicon.ico [GET] [in /home/www/.demo/lib/python2.7/site-packages/flask/app.py:1423]
Traceback (most recent call last):
  File "/home/www/.demo/lib/python2.7/site-packages/flask/app.py", line 1817, in wsgi_app
    response = self.full_dispatch_request()
  File "/home/www/.demo/lib/python2.7/site-packages/flask/app.py", line 1477, in full_dispatch_request
    rv = self.handle_user_exception(e)
  File "/home/www/.demo/lib/python2.7/site-packages/flask/app.py", line 1370, in handle_user_exception
    return self.handle_http_exception(e)
  File "/home/www/.demo/lib/python2.7/site-packages/flask/app.py", line 1330, in handle_http_exception
    return handler(e)
  File "/home/www/aud2/app/__init__.py", line 150, in page_404
    return render_template('errors/404.html'), 404
  File "/home/www/.demo/lib/python2.7/site-packages/flask/templating.py", line 128, in render_template
    context, ctx.app)
  File "/home/www/.demo/lib/python2.7/site-packages/flask/templating.py", line 110, in _render
    rv = template.render(context)
  File "/home/www/.demo/lib/python2.7/site-packages/jinja2/environment.py", line 969, in render
    return self.environment.handle_exception(exc_info, True)
  File "/home/www/.demo/lib/python2.7/site-packages/jinja2/environment.py", line 742, in handle_exception
    reraise(exc_type, exc_value, tb)
  File "/home/www/aud2/app/templates/errors/404.html", line 2, in top-level template code
    {% extends "base.html" %}
  File "/home/www/aud2/app/templates/base.html", line 26, in top-level template code
    {% include 'nav.html' %}
  File "/home/www/aud2/app/templates/nav.html", line 221, in top-level template code
    {% if g.user.is_admin() %}
UndefinedError: 'werkzeug.local.LocalProxy object' has no attribute 'is_admin'
2016-08-23 18:16:20,287 ERROR: Exception on /api/v1.0/node_task/modify_status/f005292acd7961e5b815dbcb61f74e5f [POST] [in /home/www/.demo/lib/python2.7/site-packages/flask/app.py:1423]
Traceback (most recent call last):
  File "/home/www/.demo/lib/python2.7/site-packages/flask/app.py", line 1817, in wsgi_app
    response = self.full_dispatch_request()
  File "/home/www/.demo/lib/python2.7/site-packages/flask/app.py", line 1477, in full_dispatch_request
    rv = self.handle_user_exception(e)
  File "/home/www/.demo/lib/python2.7/site-packages/flask/app.py", line 1381, in handle_user_exception
    reraise(exc_type, exc_value, tb)
  File "/home/www/.demo/lib/python2.7/site-packages/flask/app.py", line 1475, in full_dispatch_request
    rv = self.dispatch_request()
  File "/home/www/.demo/lib/python2.7/site-packages/flask/app.py", line 1461, in dispatch_request
    return self.view_functions[rule.endpoint](**req.view_args)
  File "/home/www/aud2/app/views/site.py", line 875, in modify_node_task_status
    mes.sendEmail()
  File "/home/www/aud2/app/utils/message.py", line 45, in sendEmail
    thr = Thread(target=send_async_email, args=[receiver + '@aicai.com', subject, html])
TypeError: unsupported operand type(s) for +: 'NoneType' and 'str'
2016-08-23 18:38:58,223 ERROR: Exception on /api/v1.0/node_task/modify_status/8ae4a506e61ce77ec1d88607e1ab9a85 [POST] [in /home/www/.demo/lib/python2.7/site-packages/flask/app.py:1423]
Traceback (most recent call last):
  File "/home/www/.demo/lib/python2.7/site-packages/flask/app.py", line 1817, in wsgi_app
    response = self.full_dispatch_request()
  File "/home/www/.demo/lib/python2.7/site-packages/flask/app.py", line 1477, in full_dispatch_request
    rv = self.handle_user_exception(e)
  File "/home/www/.demo/lib/python2.7/site-packages/flask/app.py", line 1381, in handle_user_exception
    reraise(exc_type, exc_value, tb)
  File "/home/www/.demo/lib/python2.7/site-packages/flask/app.py", line 1475, in full_dispatch_request
    rv = self.dispatch_request()
  File "/home/www/.demo/lib/python2.7/site-packages/flask/app.py", line 1461, in dispatch_request
    return self.view_functions[rule.endpoint](**req.view_args)
  File "/home/www/aud2/app/views/site.py", line 875, in modify_node_task_status
    mes.sendEmail()
  File "/home/www/aud2/app/utils/message.py", line 45, in sendEmail
    thr = Thread(target=send_async_email, args=[receiver + '@aicai.com', subject, html])
TypeError: unsupported operand type(s) for +: 'NoneType' and 'str'
2016-08-23 18:40:50,531 ERROR: Exception on /api/v1.0/node_task/modify_status/09e7b7c81b948534ee21873d22d0ec27 [POST] [in /home/www/.demo/lib/python2.7/site-packages/flask/app.py:1423]
Traceback (most recent call last):
  File "/home/www/.demo/lib/python2.7/site-packages/flask/app.py", line 1817, in wsgi_app
    response = self.full_dispatch_request()
  File "/home/www/.demo/lib/python2.7/site-packages/flask/app.py", line 1477, in full_dispatch_request
    rv = self.handle_user_exception(e)
  File "/home/www/.demo/lib/python2.7/site-packages/flask/app.py", line 1381, in handle_user_exception
    reraise(exc_type, exc_value, tb)
  File "/home/www/.demo/lib/python2.7/site-packages/flask/app.py", line 1475, in full_dispatch_request
    rv = self.dispatch_request()
  File "/home/www/.demo/lib/python2.7/site-packages/flask/app.py", line 1461, in dispatch_request
    return self.view_functions[rule.endpoint](**req.view_args)
  File "/home/www/aud2/app/views/site.py", line 875, in modify_node_task_status
    mes.sendEmail()
  File "/home/www/aud2/app/utils/message.py", line 45, in sendEmail
    thr = Thread(target=send_async_email, args=[receiver + '@aicai.com', subject, html])
TypeError: unsupported operand type(s) for +: 'NoneType' and 'str'
2016-08-23 18:41:19,092 ERROR: Exception on /api/v1.0/node_task/modify_status/96062a8803931dd77811e662ae0b2b6b [POST] [in /home/www/.demo/lib/python2.7/site-packages/flask/app.py:1423]
Traceback (most recent call last):
  File "/home/www/.demo/lib/python2.7/site-packages/flask/app.py", line 1817, in wsgi_app
    response = self.full_dispatch_request()
  File "/home/www/.demo/lib/python2.7/site-packages/flask/app.py", line 1477, in full_dispatch_request
    rv = self.handle_user_exception(e)
  File "/home/www/.demo/lib/python2.7/site-packages/flask/app.py", line 1381, in handle_user_exception
    reraise(exc_type, exc_value, tb)
  File "/home/www/.demo/lib/python2.7/site-packages/flask/app.py", line 1475, in full_dispatch_request
    rv = self.dispatch_request()
  File "/home/www/.demo/lib/python2.7/site-packages/flask/app.py", line 1461, in dispatch_request
    return self.view_functions[rule.endpoint](**req.view_args)
  File "/home/www/aud2/app/views/site.py", line 875, in modify_node_task_status
    mes.sendEmail()
  File "/home/www/aud2/app/utils/message.py", line 45, in sendEmail
    thr = Thread(target=send_async_email, args=[receiver + '@aicai.com', subject, html])
TypeError: unsupported operand type(s) for +: 'NoneType' and 'str'
2016-08-23 18:50:57,838 ERROR: Exception on /api/v1.0/node_task/modify_status/7200004a936d966492e194b8e20f5b53 [POST] [in /home/www/.demo/lib/python2.7/site-packages/flask/app.py:1423]
Traceback (most recent call last):
  File "/home/www/.demo/lib/python2.7/site-packages/flask/app.py", line 1817, in wsgi_app
    response = self.full_dispatch_request()
  File "/home/www/.demo/lib/python2.7/site-packages/flask/app.py", line 1477, in full_dispatch_request
    rv = self.handle_user_exception(e)
  File "/home/www/.demo/lib/python2.7/site-packages/flask/app.py", line 1381, in handle_user_exception
    reraise(exc_type, exc_value, tb)
  File "/home/www/.demo/lib/python2.7/site-packages/flask/app.py", line 1475, in full_dispatch_request
    rv = self.dispatch_request()
  File "/home/www/.demo/lib/python2.7/site-packages/flask/app.py", line 1461, in dispatch_request
    return self.view_functions[rule.endpoint](**req.view_args)
  File "/home/www/aud2/app/views/site.py", line 875, in modify_node_task_status
    mes.sendEmail()
  File "/home/www/aud2/app/utils/message.py", line 45, in sendEmail
    thr = Thread(target=send_async_email, args=[receiver + '@aicai.com', subject, html])
TypeError: unsupported operand type(s) for +: 'NoneType' and 'str'
2016-08-23 20:01:23,054 ERROR: Exception on /favicon.ico [GET] [in /home/www/.demo/lib/python2.7/site-packages/flask/app.py:1423]
Traceback (most recent call last):
  File "/home/www/.demo/lib/python2.7/site-packages/flask/app.py", line 1817, in wsgi_app
    response = self.full_dispatch_request()
  File "/home/www/.demo/lib/python2.7/site-packages/flask/app.py", line 1477, in full_dispatch_request
    rv = self.handle_user_exception(e)
  File "/home/www/.demo/lib/python2.7/site-packages/flask/app.py", line 1370, in handle_user_exception
    return self.handle_http_exception(e)
  File "/home/www/.demo/lib/python2.7/site-packages/flask/app.py", line 1330, in handle_http_exception
    return handler(e)
  File "/home/www/aud2/app/__init__.py", line 150, in page_404
    return render_template('errors/404.html'), 404
  File "/home/www/.demo/lib/python2.7/site-packages/flask/templating.py", line 128, in render_template
    context, ctx.app)
  File "/home/www/.demo/lib/python2.7/site-packages/flask/templating.py", line 110, in _render
    rv = template.render(context)
  File "/home/www/.demo/lib/python2.7/site-packages/jinja2/environment.py", line 969, in render
    return self.environment.handle_exception(exc_info, True)
  File "/home/www/.demo/lib/python2.7/site-packages/jinja2/environment.py", line 742, in handle_exception
    reraise(exc_type, exc_value, tb)
  File "/home/www/aud2/app/templates/errors/404.html", line 2, in top-level template code
    {% extends "base.html" %}
  File "/home/www/aud2/app/templates/base.html", line 26, in top-level template code
    {% include 'nav.html' %}
  File "/home/www/aud2/app/templates/nav.html", line 221, in top-level template code
    {% if g.user.is_admin() %}
UndefinedError: 'werkzeug.local.LocalProxy object' has no attribute 'is_admin'
2016-08-23 20:03:25,174 ERROR: Exception on /api/v1.0/node_task/modify_status/659d98e6f25dc5f6a995b8645859589a [POST] [in /home/www/.demo/lib/python2.7/site-packages/flask/app.py:1423]
Traceback (most recent call last):
  File "/home/www/.demo/lib/python2.7/site-packages/flask/app.py", line 1817, in wsgi_app
    response = self.full_dispatch_request()
  File "/home/www/.demo/lib/python2.7/site-packages/flask/app.py", line 1477, in full_dispatch_request
    rv = self.handle_user_exception(e)
  File "/home/www/.demo/lib/python2.7/site-packages/flask/app.py", line 1381, in handle_user_exception
    reraise(exc_type, exc_value, tb)
  File "/home/www/.demo/lib/python2.7/site-packages/flask/app.py", line 1475, in full_dispatch_request
    rv = self.dispatch_request()
  File "/home/www/.demo/lib/python2.7/site-packages/flask/app.py", line 1461, in dispatch_request
    return self.view_functions[rule.endpoint](**req.view_args)
  File "/home/www/aud2/app/views/site.py", line 875, in modify_node_task_status
    mes.sendEmail()
  File "/home/www/aud2/app/utils/message.py", line 45, in sendEmail
    thr = Thread(target=send_async_email, args=[receiver + '@aicai.com', subject, html])
TypeError: unsupported operand type(s) for +: 'NoneType' and 'str'
2016-08-23 20:03:42,814 ERROR: Exception on /api/v1.0/node_task/modify_status/dc55f0b6600754c7a33ac3f95b68b299 [POST] [in /home/www/.demo/lib/python2.7/site-packages/flask/app.py:1423]
Traceback (most recent call last):
  File "/home/www/.demo/lib/python2.7/site-packages/flask/app.py", line 1817, in wsgi_app
    response = self.full_dispatch_request()
  File "/home/www/.demo/lib/python2.7/site-packages/flask/app.py", line 1477, in full_dispatch_request
    rv = self.handle_user_exception(e)
  File "/home/www/.demo/lib/python2.7/site-packages/flask/app.py", line 1381, in handle_user_exception
    reraise(exc_type, exc_value, tb)
  File "/home/www/.demo/lib/python2.7/site-packages/flask/app.py", line 1475, in full_dispatch_request
    rv = self.dispatch_request()
  File "/home/www/.demo/lib/python2.7/site-packages/flask/app.py", line 1461, in dispatch_request
    return self.view_functions[rule.endpoint](**req.view_args)
  File "/home/www/aud2/app/views/site.py", line 875, in modify_node_task_status
    mes.sendEmail()
  File "/home/www/aud2/app/utils/message.py", line 45, in sendEmail
    thr = Thread(target=send_async_email, args=[receiver + '@aicai.com', subject, html])
TypeError: unsupported operand type(s) for +: 'NoneType' and 'str'
2016-08-23 20:03:46,822 ERROR: Exception on /api/v1.0/node_task/modify_status/9fcecf1598a39b82d08354f184a8f2f8 [POST] [in /home/www/.demo/lib/python2.7/site-packages/flask/app.py:1423]
Traceback (most recent call last):
  File "/home/www/.demo/lib/python2.7/site-packages/flask/app.py", line 1817, in wsgi_app
    response = self.full_dispatch_request()
  File "/home/www/.demo/lib/python2.7/site-packages/flask/app.py", line 1477, in full_dispatch_request
    rv = self.handle_user_exception(e)
  File "/home/www/.demo/lib/python2.7/site-packages/flask/app.py", line 1381, in handle_user_exception
    reraise(exc_type, exc_value, tb)
  File "/home/www/.demo/lib/python2.7/site-packages/flask/app.py", line 1475, in full_dispatch_request
    rv = self.dispatch_request()
  File "/home/www/.demo/lib/python2.7/site-packages/flask/app.py", line 1461, in dispatch_request
    return self.view_functions[rule.endpoint](**req.view_args)
  File "/home/www/aud2/app/views/site.py", line 875, in modify_node_task_status
    mes.sendEmail()
  File "/home/www/aud2/app/utils/message.py", line 45, in sendEmail
    thr = Thread(target=send_async_email, args=[receiver + '@aicai.com', subject, html])
TypeError: unsupported operand type(s) for +: 'NoneType' and 'str'
2016-08-23 20:05:05,838 ERROR: Exception on /favicon.ico [GET] [in /home/www/.demo/lib/python2.7/site-packages/flask/app.py:1423]
Traceback (most recent call last):
  File "/home/www/.demo/lib/python2.7/site-packages/flask/app.py", line 1817, in wsgi_app
    response = self.full_dispatch_request()
  File "/home/www/.demo/lib/python2.7/site-packages/flask/app.py", line 1477, in full_dispatch_request
    rv = self.handle_user_exception(e)
  File "/home/www/.demo/lib/python2.7/site-packages/flask/app.py", line 1370, in handle_user_exception
    return self.handle_http_exception(e)
  File "/home/www/.demo/lib/python2.7/site-packages/flask/app.py", line 1330, in handle_http_exception
    return handler(e)
  File "/home/www/aud2/app/__init__.py", line 150, in page_404
    return render_template('errors/404.html'), 404
  File "/home/www/.demo/lib/python2.7/site-packages/flask/templating.py", line 128, in render_template
    context, ctx.app)
  File "/home/www/.demo/lib/python2.7/site-packages/flask/templating.py", line 110, in _render
    rv = template.render(context)
  File "/home/www/.demo/lib/python2.7/site-packages/jinja2/environment.py", line 969, in render
    return self.environment.handle_exception(exc_info, True)
  File "/home/www/.demo/lib/python2.7/site-packages/jinja2/environment.py", line 742, in handle_exception
    reraise(exc_type, exc_value, tb)
  File "/home/www/aud2/app/templates/errors/404.html", line 2, in top-level template code
    {% extends "base.html" %}
  File "/home/www/aud2/app/templates/base.html", line 26, in top-level template code
    {% include 'nav.html' %}
  File "/home/www/aud2/app/templates/nav.html", line 221, in top-level template code
    {% if g.user.is_admin() %}
UndefinedError: 'werkzeug.local.LocalProxy object' has no attribute 'is_admin'
2016-08-23 20:11:07,769 ERROR: Exception on /api/v1.0/node_task/modify_status/b8f37d0a55f25726d39bdfd400686a9e [POST] [in /home/www/.demo/lib/python2.7/site-packages/flask/app.py:1423]
Traceback (most recent call last):
  File "/home/www/.demo/lib/python2.7/site-packages/flask/app.py", line 1817, in wsgi_app
    response = self.full_dispatch_request()
  File "/home/www/.demo/lib/python2.7/site-packages/flask/app.py", line 1477, in full_dispatch_request
    rv = self.handle_user_exception(e)
  File "/home/www/.demo/lib/python2.7/site-packages/flask/app.py", line 1381, in handle_user_exception
    reraise(exc_type, exc_value, tb)
  File "/home/www/.demo/lib/python2.7/site-packages/flask/app.py", line 1475, in full_dispatch_request
    rv = self.dispatch_request()
  File "/home/www/.demo/lib/python2.7/site-packages/flask/app.py", line 1461, in dispatch_request
    return self.view_functions[rule.endpoint](**req.view_args)
  File "/home/www/aud2/app/views/site.py", line 875, in modify_node_task_status
    mes.sendEmail()
  File "/home/www/aud2/app/utils/message.py", line 45, in sendEmail
    thr = Thread(target=send_async_email, args=[receiver + '@aicai.com', subject, html])
TypeError: unsupported operand type(s) for +: 'NoneType' and 'str'
2016-08-23 20:11:28,550 ERROR: Exception on /api/v1.0/node_task/modify_status/6285c7f393c178b86aedb7ebe62280b9 [POST] [in /home/www/.demo/lib/python2.7/site-packages/flask/app.py:1423]
Traceback (most recent call last):
  File "/home/www/.demo/lib/python2.7/site-packages/flask/app.py", line 1817, in wsgi_app
    response = self.full_dispatch_request()
  File "/home/www/.demo/lib/python2.7/site-packages/flask/app.py", line 1477, in full_dispatch_request
    rv = self.handle_user_exception(e)
  File "/home/www/.demo/lib/python2.7/site-packages/flask/app.py", line 1381, in handle_user_exception
    reraise(exc_type, exc_value, tb)
  File "/home/www/.demo/lib/python2.7/site-packages/flask/app.py", line 1475, in full_dispatch_request
    rv = self.dispatch_request()
  File "/home/www/.demo/lib/python2.7/site-packages/flask/app.py", line 1461, in dispatch_request
    return self.view_functions[rule.endpoint](**req.view_args)
  File "/home/www/aud2/app/views/site.py", line 875, in modify_node_task_status
    mes.sendEmail()
  File "/home/www/aud2/app/utils/message.py", line 45, in sendEmail
    thr = Thread(target=send_async_email, args=[receiver + '@aicai.com', subject, html])
TypeError: unsupported operand type(s) for +: 'NoneType' and 'str'
2016-08-23 20:11:28,653 ERROR: Exception on /api/v1.0/node_task/modify_status/b990dd79f2a3dfc49ae318c27ad49f8c [POST] [in /home/www/.demo/lib/python2.7/site-packages/flask/app.py:1423]
Traceback (most recent call last):
  File "/home/www/.demo/lib/python2.7/site-packages/flask/app.py", line 1817, in wsgi_app
    response = self.full_dispatch_request()
  File "/home/www/.demo/lib/python2.7/site-packages/flask/app.py", line 1477, in full_dispatch_request
    rv = self.handle_user_exception(e)
  File "/home/www/.demo/lib/python2.7/site-packages/flask/app.py", line 1381, in handle_user_exception
    reraise(exc_type, exc_value, tb)
  File "/home/www/.demo/lib/python2.7/site-packages/flask/app.py", line 1475, in full_dispatch_request
    rv = self.dispatch_request()
  File "/home/www/.demo/lib/python2.7/site-packages/flask/app.py", line 1461, in dispatch_request
    return self.view_functions[rule.endpoint](**req.view_args)
  File "/home/www/aud2/app/views/site.py", line 875, in modify_node_task_status
    mes.sendEmail()
  File "/home/www/aud2/app/utils/message.py", line 45, in sendEmail
    thr = Thread(target=send_async_email, args=[receiver + '@aicai.com', subject, html])
TypeError: unsupported operand type(s) for +: 'NoneType' and 'str'
2016-08-23 20:20:42,357 ERROR: Exception on /api/v1.0/node_task/modify_status/916f9bab76ba0428534bcddd99f0d4c3 [POST] [in /home/www/.demo/lib/python2.7/site-packages/flask/app.py:1423]
Traceback (most recent call last):
  File "/home/www/.demo/lib/python2.7/site-packages/flask/app.py", line 1817, in wsgi_app
    response = self.full_dispatch_request()
  File "/home/www/.demo/lib/python2.7/site-packages/flask/app.py", line 1477, in full_dispatch_request
    rv = self.handle_user_exception(e)
  File "/home/www/.demo/lib/python2.7/site-packages/flask/app.py", line 1381, in handle_user_exception
    reraise(exc_type, exc_value, tb)
  File "/home/www/.demo/lib/python2.7/site-packages/flask/app.py", line 1475, in full_dispatch_request
    rv = self.dispatch_request()
  File "/home/www/.demo/lib/python2.7/site-packages/flask/app.py", line 1461, in dispatch_request
    return self.view_functions[rule.endpoint](**req.view_args)
  File "/home/www/aud2/app/views/site.py", line 875, in modify_node_task_status
    mes.sendEmail()
  File "/home/www/aud2/app/utils/message.py", line 45, in sendEmail
    thr = Thread(target=send_async_email, args=[receiver + '@aicai.com', subject, html])
TypeError: unsupported operand type(s) for +: 'NoneType' and 'str'
2016-08-24 07:30:52,792 ERROR: Exception on /favicon.ico [GET] [in /home/www/.demo/lib/python2.7/site-packages/flask/app.py:1423]
Traceback (most recent call last):
  File "/home/www/.demo/lib/python2.7/site-packages/flask/app.py", line 1817, in wsgi_app
    response = self.full_dispatch_request()
  File "/home/www/.demo/lib/python2.7/site-packages/flask/app.py", line 1477, in full_dispatch_request
    rv = self.handle_user_exception(e)
  File "/home/www/.demo/lib/python2.7/site-packages/flask/app.py", line 1370, in handle_user_exception
    return self.handle_http_exception(e)
  File "/home/www/.demo/lib/python2.7/site-packages/flask/app.py", line 1330, in handle_http_exception
    return handler(e)
  File "/home/www/aud2/app/__init__.py", line 150, in page_404
    return render_template('errors/404.html'), 404
  File "/home/www/.demo/lib/python2.7/site-packages/flask/templating.py", line 128, in render_template
    context, ctx.app)
  File "/home/www/.demo/lib/python2.7/site-packages/flask/templating.py", line 110, in _render
    rv = template.render(context)
  File "/home/www/.demo/lib/python2.7/site-packages/jinja2/environment.py", line 969, in render
    return self.environment.handle_exception(exc_info, True)
  File "/home/www/.demo/lib/python2.7/site-packages/jinja2/environment.py", line 742, in handle_exception
    reraise(exc_type, exc_value, tb)
  File "/home/www/aud2/app/templates/errors/404.html", line 2, in top-level template code
    {% extends "base.html" %}
  File "/home/www/aud2/app/templates/base.html", line 26, in top-level template code
    {% include 'nav.html' %}
  File "/home/www/aud2/app/templates/nav.html", line 221, in top-level template code
    {% if g.user.is_admin() %}
UndefinedError: 'werkzeug.local.LocalProxy object' has no attribute 'is_admin'
2016-08-24 07:30:52,824 ERROR: Exception on /favicon.ico [GET] [in /home/www/.demo/lib/python2.7/site-packages/flask/app.py:1423]
Traceback (most recent call last):
  File "/home/www/.demo/lib/python2.7/site-packages/flask/app.py", line 1817, in wsgi_app
    response = self.full_dispatch_request()
  File "/home/www/.demo/lib/python2.7/site-packages/flask/app.py", line 1477, in full_dispatch_request
    rv = self.handle_user_exception(e)
  File "/home/www/.demo/lib/python2.7/site-packages/flask/app.py", line 1370, in handle_user_exception
    return self.handle_http_exception(e)
  File "/home/www/.demo/lib/python2.7/site-packages/flask/app.py", line 1330, in handle_http_exception
    return handler(e)
  File "/home/www/aud2/app/__init__.py", line 150, in page_404
    return render_template('errors/404.html'), 404
  File "/home/www/.demo/lib/python2.7/site-packages/flask/templating.py", line 128, in render_template
    context, ctx.app)
  File "/home/www/.demo/lib/python2.7/site-packages/flask/templating.py", line 110, in _render
    rv = template.render(context)
  File "/home/www/.demo/lib/python2.7/site-packages/jinja2/environment.py", line 969, in render
    return self.environment.handle_exception(exc_info, True)
  File "/home/www/.demo/lib/python2.7/site-packages/jinja2/environment.py", line 742, in handle_exception
    reraise(exc_type, exc_value, tb)
  File "/home/www/aud2/app/templates/errors/404.html", line 2, in top-level template code
    {% extends "base.html" %}
  File "/home/www/aud2/app/templates/base.html", line 26, in top-level template code
    {% include 'nav.html' %}
  File "/home/www/aud2/app/templates/nav.html", line 221, in top-level template code
    {% if g.user.is_admin() %}
UndefinedError: 'werkzeug.local.LocalProxy object' has no attribute 'is_admin'
2016-08-24 09:01:29,963 ERROR: Exception on /favicon.ico [GET] [in /home/www/.demo/lib/python2.7/site-packages/flask/app.py:1423]
Traceback (most recent call last):
  File "/home/www/.demo/lib/python2.7/site-packages/flask/app.py", line 1817, in wsgi_app
    response = self.full_dispatch_request()
  File "/home/www/.demo/lib/python2.7/site-packages/flask/app.py", line 1477, in full_dispatch_request
    rv = self.handle_user_exception(e)
  File "/home/www/.demo/lib/python2.7/site-packages/flask/app.py", line 1370, in handle_user_exception
    return self.handle_http_exception(e)
  File "/home/www/.demo/lib/python2.7/site-packages/flask/app.py", line 1330, in handle_http_exception
    return handler(e)
  File "/home/www/aud2/app/__init__.py", line 150, in page_404
    return render_template('errors/404.html'), 404
  File "/home/www/.demo/lib/python2.7/site-packages/flask/templating.py", line 128, in render_template
    context, ctx.app)
  File "/home/www/.demo/lib/python2.7/site-packages/flask/templating.py", line 110, in _render
    rv = template.render(context)
  File "/home/www/.demo/lib/python2.7/site-packages/jinja2/environment.py", line 969, in render
    return self.environment.handle_exception(exc_info, True)
  File "/home/www/.demo/lib/python2.7/site-packages/jinja2/environment.py", line 742, in handle_exception
    reraise(exc_type, exc_value, tb)
  File "/home/www/aud2/app/templates/errors/404.html", line 2, in top-level template code
    {% extends "base.html" %}
  File "/home/www/aud2/app/templates/base.html", line 26, in top-level template code
    {% include 'nav.html' %}
  File "/home/www/aud2/app/templates/nav.html", line 221, in top-level template code
    {% if g.user.is_admin() %}
UndefinedError: 'werkzeug.local.LocalProxy object' has no attribute 'is_admin'
2016-08-24 10:45:15,743 ERROR: Exception on /favicon.ico [GET] [in /home/www/.demo/lib/python2.7/site-packages/flask/app.py:1423]
Traceback (most recent call last):
  File "/home/www/.demo/lib/python2.7/site-packages/flask/app.py", line 1817, in wsgi_app
    response = self.full_dispatch_request()
  File "/home/www/.demo/lib/python2.7/site-packages/flask/app.py", line 1477, in full_dispatch_request
    rv = self.handle_user_exception(e)
  File "/home/www/.demo/lib/python2.7/site-packages/flask/app.py", line 1370, in handle_user_exception
    return self.handle_http_exception(e)
  File "/home/www/.demo/lib/python2.7/site-packages/flask/app.py", line 1330, in handle_http_exception
    return handler(e)
  File "/home/www/aud2/app/__init__.py", line 150, in page_404
    return render_template('errors/404.html'), 404
  File "/home/www/.demo/lib/python2.7/site-packages/flask/templating.py", line 128, in render_template
    context, ctx.app)
  File "/home/www/.demo/lib/python2.7/site-packages/flask/templating.py", line 110, in _render
    rv = template.render(context)
  File "/home/www/.demo/lib/python2.7/site-packages/jinja2/environment.py", line 969, in render
    return self.environment.handle_exception(exc_info, True)
  File "/home/www/.demo/lib/python2.7/site-packages/jinja2/environment.py", line 742, in handle_exception
    reraise(exc_type, exc_value, tb)
  File "/home/www/aud2/app/templates/errors/404.html", line 2, in top-level template code
    {% extends "base.html" %}
  File "/home/www/aud2/app/templates/base.html", line 26, in top-level template code
    {% include 'nav.html' %}
  File "/home/www/aud2/app/templates/nav.html", line 221, in top-level template code
    {% if g.user.is_admin() %}
UndefinedError: 'werkzeug.local.LocalProxy object' has no attribute 'is_admin'
2016-08-24 10:45:15,819 ERROR: Exception on /favicon.ico [GET] [in /home/www/.demo/lib/python2.7/site-packages/flask/app.py:1423]
Traceback (most recent call last):
  File "/home/www/.demo/lib/python2.7/site-packages/flask/app.py", line 1817, in wsgi_app
    response = self.full_dispatch_request()
  File "/home/www/.demo/lib/python2.7/site-packages/flask/app.py", line 1477, in full_dispatch_request
    rv = self.handle_user_exception(e)
  File "/home/www/.demo/lib/python2.7/site-packages/flask/app.py", line 1370, in handle_user_exception
    return self.handle_http_exception(e)
  File "/home/www/.demo/lib/python2.7/site-packages/flask/app.py", line 1330, in handle_http_exception
    return handler(e)
  File "/home/www/aud2/app/__init__.py", line 150, in page_404
    return render_template('errors/404.html'), 404
  File "/home/www/.demo/lib/python2.7/site-packages/flask/templating.py", line 128, in render_template
    context, ctx.app)
  File "/home/www/.demo/lib/python2.7/site-packages/flask/templating.py", line 110, in _render
    rv = template.render(context)
  File "/home/www/.demo/lib/python2.7/site-packages/jinja2/environment.py", line 969, in render
    return self.environment.handle_exception(exc_info, True)
  File "/home/www/.demo/lib/python2.7/site-packages/jinja2/environment.py", line 742, in handle_exception
    reraise(exc_type, exc_value, tb)
  File "/home/www/aud2/app/templates/errors/404.html", line 2, in top-level template code
    {% extends "base.html" %}
  File "/home/www/aud2/app/templates/base.html", line 26, in top-level template code
    {% include 'nav.html' %}
  File "/home/www/aud2/app/templates/nav.html", line 221, in top-level template code
    {% if g.user.is_admin() %}
UndefinedError: 'werkzeug.local.LocalProxy object' has no attribute 'is_admin'
2016-08-24 11:09:49,874 ERROR: Exception on /favicon.ico [GET] [in /home/www/.demo/lib/python2.7/site-packages/flask/app.py:1423]
Traceback (most recent call last):
  File "/home/www/.demo/lib/python2.7/site-packages/flask/app.py", line 1817, in wsgi_app
    response = self.full_dispatch_request()
  File "/home/www/.demo/lib/python2.7/site-packages/flask/app.py", line 1477, in full_dispatch_request
    rv = self.handle_user_exception(e)
  File "/home/www/.demo/lib/python2.7/site-packages/flask/app.py", line 1370, in handle_user_exception
    return self.handle_http_exception(e)
  File "/home/www/.demo/lib/python2.7/site-packages/flask/app.py", line 1330, in handle_http_exception
    return handler(e)
  File "/home/www/aud2/app/__init__.py", line 150, in page_404
    return render_template('errors/404.html'), 404
  File "/home/www/.demo/lib/python2.7/site-packages/flask/templating.py", line 128, in render_template
    context, ctx.app)
  File "/home/www/.demo/lib/python2.7/site-packages/flask/templating.py", line 110, in _render
    rv = template.render(context)
  File "/home/www/.demo/lib/python2.7/site-packages/jinja2/environment.py", line 969, in render
    return self.environment.handle_exception(exc_info, True)
  File "/home/www/.demo/lib/python2.7/site-packages/jinja2/environment.py", line 742, in handle_exception
    reraise(exc_type, exc_value, tb)
  File "/home/www/aud2/app/templates/errors/404.html", line 2, in top-level template code
    {% extends "base.html" %}
  File "/home/www/aud2/app/templates/base.html", line 26, in top-level template code
    {% include 'nav.html' %}
  File "/home/www/aud2/app/templates/nav.html", line 221, in top-level template code
    {% if g.user.is_admin() %}
UndefinedError: 'werkzeug.local.LocalProxy object' has no attribute 'is_admin'
2016-08-24 11:09:49,885 ERROR: Exception on /favicon.ico [GET] [in /home/www/.demo/lib/python2.7/site-packages/flask/app.py:1423]
Traceback (most recent call last):
  File "/home/www/.demo/lib/python2.7/site-packages/flask/app.py", line 1817, in wsgi_app
    response = self.full_dispatch_request()
  File "/home/www/.demo/lib/python2.7/site-packages/flask/app.py", line 1477, in full_dispatch_request
    rv = self.handle_user_exception(e)
  File "/home/www/.demo/lib/python2.7/site-packages/flask/app.py", line 1370, in handle_user_exception
    return self.handle_http_exception(e)
  File "/home/www/.demo/lib/python2.7/site-packages/flask/app.py", line 1330, in handle_http_exception
    return handler(e)
  File "/home/www/aud2/app/__init__.py", line 150, in page_404
    return render_template('errors/404.html'), 404
  File "/home/www/.demo/lib/python2.7/site-packages/flask/templating.py", line 128, in render_template
    context, ctx.app)
  File "/home/www/.demo/lib/python2.7/site-packages/flask/templating.py", line 110, in _render
    rv = template.render(context)
  File "/home/www/.demo/lib/python2.7/site-packages/jinja2/environment.py", line 969, in render
    return self.environment.handle_exception(exc_info, True)
  File "/home/www/.demo/lib/python2.7/site-packages/jinja2/environment.py", line 742, in handle_exception
    reraise(exc_type, exc_value, tb)
  File "/home/www/aud2/app/templates/errors/404.html", line 2, in top-level template code
    {% extends "base.html" %}
  File "/home/www/aud2/app/templates/base.html", line 26, in top-level template code
    {% include 'nav.html' %}
  File "/home/www/aud2/app/templates/nav.html", line 221, in top-level template code
    {% if g.user.is_admin() %}
UndefinedError: 'werkzeug.local.LocalProxy object' has no attribute 'is_admin'
2016-08-24 11:14:20,884 ERROR: Exception on /api/v1.0/node_task/modify_status/0ffa4c882799ee284fd23a56144f1ca5 [POST] [in /home/www/.demo/lib/python2.7/site-packages/flask/app.py:1423]
Traceback (most recent call last):
  File "/home/www/.demo/lib/python2.7/site-packages/flask/app.py", line 1817, in wsgi_app
    response = self.full_dispatch_request()
  File "/home/www/.demo/lib/python2.7/site-packages/flask/app.py", line 1477, in full_dispatch_request
    rv = self.handle_user_exception(e)
  File "/home/www/.demo/lib/python2.7/site-packages/flask/app.py", line 1381, in handle_user_exception
    reraise(exc_type, exc_value, tb)
  File "/home/www/.demo/lib/python2.7/site-packages/flask/app.py", line 1475, in full_dispatch_request
    rv = self.dispatch_request()
  File "/home/www/.demo/lib/python2.7/site-packages/flask/app.py", line 1461, in dispatch_request
    return self.view_functions[rule.endpoint](**req.view_args)
  File "/home/www/aud2/app/views/site.py", line 875, in modify_node_task_status
    mes.sendEmail()
  File "/home/www/aud2/app/utils/message.py", line 45, in sendEmail
    thr = Thread(target=send_async_email, args=[receiver + '@aicai.com', subject, html])
TypeError: unsupported operand type(s) for +: 'NoneType' and 'str'
2016-08-24 11:42:14,539 ERROR: Exception on /api/v1.0/node_task/modify_status/c52f5832acff707c1efb6b9ca5943b46 [POST] [in /home/www/.demo/lib/python2.7/site-packages/flask/app.py:1423]
Traceback (most recent call last):
  File "/home/www/.demo/lib/python2.7/site-packages/flask/app.py", line 1817, in wsgi_app
    response = self.full_dispatch_request()
  File "/home/www/.demo/lib/python2.7/site-packages/flask/app.py", line 1477, in full_dispatch_request
    rv = self.handle_user_exception(e)
  File "/home/www/.demo/lib/python2.7/site-packages/flask/app.py", line 1381, in handle_user_exception
    reraise(exc_type, exc_value, tb)
  File "/home/www/.demo/lib/python2.7/site-packages/flask/app.py", line 1475, in full_dispatch_request
    rv = self.dispatch_request()
  File "/home/www/.demo/lib/python2.7/site-packages/flask/app.py", line 1461, in dispatch_request
    return self.view_functions[rule.endpoint](**req.view_args)
  File "/home/www/aud2/app/views/site.py", line 875, in modify_node_task_status
    mes.sendEmail()
  File "/home/www/aud2/app/utils/message.py", line 45, in sendEmail
    thr = Thread(target=send_async_email, args=[receiver + '@aicai.com', subject, html])
TypeError: unsupported operand type(s) for +: 'NoneType' and 'str'
2016-08-24 12:15:36,357 ERROR: Exception on /api/v1.0/node_task/modify_status/f1011c6a50b8976b9366e6c085de0c51 [POST] [in /home/www/.demo/lib/python2.7/site-packages/flask/app.py:1423]
Traceback (most recent call last):
  File "/home/www/.demo/lib/python2.7/site-packages/flask/app.py", line 1817, in wsgi_app
    response = self.full_dispatch_request()
  File "/home/www/.demo/lib/python2.7/site-packages/flask/app.py", line 1477, in full_dispatch_request
    rv = self.handle_user_exception(e)
  File "/home/www/.demo/lib/python2.7/site-packages/flask/app.py", line 1381, in handle_user_exception
    reraise(exc_type, exc_value, tb)
  File "/home/www/.demo/lib/python2.7/site-packages/flask/app.py", line 1475, in full_dispatch_request
    rv = self.dispatch_request()
  File "/home/www/.demo/lib/python2.7/site-packages/flask/app.py", line 1461, in dispatch_request
    return self.view_functions[rule.endpoint](**req.view_args)
  File "/home/www/aud2/app/views/site.py", line 875, in modify_node_task_status
    mes.sendEmail()
  File "/home/www/aud2/app/utils/message.py", line 45, in sendEmail
    thr = Thread(target=send_async_email, args=[receiver + '@aicai.com', subject, html])
TypeError: unsupported operand type(s) for +: 'NoneType' and 'str'
2016-08-24 12:18:41,181 ERROR: Exception on /deploy/approve_success/UOA-worldcup-20160824121838 [GET] [in /home/www/.demo/lib/python2.7/site-packages/flask/app.py:1423]
Traceback (most recent call last):
  File "/home/www/.demo/lib/python2.7/site-packages/flask/app.py", line 1817, in wsgi_app
    response = self.full_dispatch_request()
  File "/home/www/.demo/lib/python2.7/site-packages/flask/app.py", line 1477, in full_dispatch_request
    rv = self.handle_user_exception(e)
  File "/home/www/.demo/lib/python2.7/site-packages/flask/app.py", line 1370, in handle_user_exception
    return self.handle_http_exception(e)
  File "/home/www/.demo/lib/python2.7/site-packages/flask/app.py", line 1330, in handle_http_exception
    return handler(e)
  File "/home/www/aud2/app/__init__.py", line 146, in page_403
    return render_template('errors/403.html'), 403
  File "/home/www/.demo/lib/python2.7/site-packages/flask/templating.py", line 127, in render_template
    return _render(ctx.app.jinja_env.get_or_select_template(template_name_or_list),
  File "/home/www/.demo/lib/python2.7/site-packages/jinja2/environment.py", line 830, in get_or_select_template
    return self.get_template(template_name_or_list, parent, globals)
  File "/home/www/.demo/lib/python2.7/site-packages/jinja2/environment.py", line 791, in get_template
    return self._load_template(name, self.make_globals(globals))
  File "/home/www/.demo/lib/python2.7/site-packages/jinja2/environment.py", line 765, in _load_template
    template = self.loader.load(self, name, globals)
  File "/home/www/.demo/lib/python2.7/site-packages/jinja2/loaders.py", line 113, in load
    source, filename, uptodate = self.get_source(environment, name)
  File "/home/www/.demo/lib/python2.7/site-packages/flask/templating.py", line 64, in get_source
    raise TemplateNotFound(template)
TemplateNotFound: errors/403.html
2016-08-24 12:19:22,569 ERROR: Exception on /deploy/approve_success/UOA-worldcup-20160824121838 [GET] [in /home/www/.demo/lib/python2.7/site-packages/flask/app.py:1423]
Traceback (most recent call last):
  File "/home/www/.demo/lib/python2.7/site-packages/flask/app.py", line 1817, in wsgi_app
    response = self.full_dispatch_request()
  File "/home/www/.demo/lib/python2.7/site-packages/flask/app.py", line 1477, in full_dispatch_request
    rv = self.handle_user_exception(e)
  File "/home/www/.demo/lib/python2.7/site-packages/flask/app.py", line 1370, in handle_user_exception
    return self.handle_http_exception(e)
  File "/home/www/.demo/lib/python2.7/site-packages/flask/app.py", line 1330, in handle_http_exception
    return handler(e)
  File "/home/www/aud2/app/__init__.py", line 146, in page_403
    return render_template('errors/403.html'), 403
  File "/home/www/.demo/lib/python2.7/site-packages/flask/templating.py", line 127, in render_template
    return _render(ctx.app.jinja_env.get_or_select_template(template_name_or_list),
  File "/home/www/.demo/lib/python2.7/site-packages/jinja2/environment.py", line 830, in get_or_select_template
    return self.get_template(template_name_or_list, parent, globals)
  File "/home/www/.demo/lib/python2.7/site-packages/jinja2/environment.py", line 791, in get_template
    return self._load_template(name, self.make_globals(globals))
  File "/home/www/.demo/lib/python2.7/site-packages/jinja2/environment.py", line 765, in _load_template
    template = self.loader.load(self, name, globals)
  File "/home/www/.demo/lib/python2.7/site-packages/jinja2/loaders.py", line 113, in load
    source, filename, uptodate = self.get_source(environment, name)
  File "/home/www/.demo/lib/python2.7/site-packages/flask/templating.py", line 64, in get_source
    raise TemplateNotFound(template)
TemplateNotFound: errors/403.html
2016-08-24 12:20:56,754 ERROR: Exception on /api/v1.0/node_task/modify_status/d6e8aba936a7391550e221e57e149fa1 [POST] [in /home/www/.demo/lib/python2.7/site-packages/flask/app.py:1423]
Traceback (most recent call last):
  File "/home/www/.demo/lib/python2.7/site-packages/flask/app.py", line 1817, in wsgi_app
    response = self.full_dispatch_request()
  File "/home/www/.demo/lib/python2.7/site-packages/flask/app.py", line 1477, in full_dispatch_request
    rv = self.handle_user_exception(e)
  File "/home/www/.demo/lib/python2.7/site-packages/flask/app.py", line 1381, in handle_user_exception
    reraise(exc_type, exc_value, tb)
  File "/home/www/.demo/lib/python2.7/site-packages/flask/app.py", line 1475, in full_dispatch_request
    rv = self.dispatch_request()
  File "/home/www/.demo/lib/python2.7/site-packages/flask/app.py", line 1461, in dispatch_request
    return self.view_functions[rule.endpoint](**req.view_args)
  File "/home/www/aud2/app/views/site.py", line 875, in modify_node_task_status
    mes.sendEmail()
  File "/home/www/aud2/app/utils/message.py", line 45, in sendEmail
    thr = Thread(target=send_async_email, args=[receiver + '@aicai.com', subject, html])
TypeError: unsupported operand type(s) for +: 'NoneType' and 'str'
2016-08-24 13:07:52,380 ERROR: Exception on /api/v1.0/node_task/modify_status/1dd2ae0e67a8ab5bceb4f014f7bea680 [POST] [in /home/www/.demo/lib/python2.7/site-packages/flask/app.py:1423]
Traceback (most recent call last):
  File "/home/www/.demo/lib/python2.7/site-packages/flask/app.py", line 1817, in wsgi_app
    response = self.full_dispatch_request()
  File "/home/www/.demo/lib/python2.7/site-packages/flask/app.py", line 1477, in full_dispatch_request
    rv = self.handle_user_exception(e)
  File "/home/www/.demo/lib/python2.7/site-packages/flask/app.py", line 1381, in handle_user_exception
    reraise(exc_type, exc_value, tb)
  File "/home/www/.demo/lib/python2.7/site-packages/flask/app.py", line 1475, in full_dispatch_request
    rv = self.dispatch_request()
  File "/home/www/.demo/lib/python2.7/site-packages/flask/app.py", line 1461, in dispatch_request
    return self.view_functions[rule.endpoint](**req.view_args)
  File "/home/www/aud2/app/views/site.py", line 875, in modify_node_task_status
    mes.sendEmail()
  File "/home/www/aud2/app/utils/message.py", line 45, in sendEmail
    thr = Thread(target=send_async_email, args=[receiver + '@aicai.com', subject, html])
TypeError: unsupported operand type(s) for +: 'NoneType' and 'str'
2016-08-24 13:08:23,287 ERROR: Exception on /api/v1.0/node_task/modify_status/c9c8467529cda90f1774d6e21e168bfb [POST] [in /home/www/.demo/lib/python2.7/site-packages/flask/app.py:1423]
Traceback (most recent call last):
  File "/home/www/.demo/lib/python2.7/site-packages/flask/app.py", line 1817, in wsgi_app
    response = self.full_dispatch_request()
  File "/home/www/.demo/lib/python2.7/site-packages/flask/app.py", line 1477, in full_dispatch_request
    rv = self.handle_user_exception(e)
  File "/home/www/.demo/lib/python2.7/site-packages/flask/app.py", line 1381, in handle_user_exception
    reraise(exc_type, exc_value, tb)
  File "/home/www/.demo/lib/python2.7/site-packages/flask/app.py", line 1475, in full_dispatch_request
    rv = self.dispatch_request()
  File "/home/www/.demo/lib/python2.7/site-packages/flask/app.py", line 1461, in dispatch_request
    return self.view_functions[rule.endpoint](**req.view_args)
  File "/home/www/aud2/app/views/site.py", line 875, in modify_node_task_status
    mes.sendEmail()
  File "/home/www/aud2/app/utils/message.py", line 45, in sendEmail
    thr = Thread(target=send_async_email, args=[receiver + '@aicai.com', subject, html])
TypeError: unsupported operand type(s) for +: 'NoneType' and 'str'
2016-08-24 13:09:01,359 ERROR: Exception on /api/v1.0/node_task/modify_status/6d6f7db1b24bd0956e5b3328d1271095 [POST] [in /home/www/.demo/lib/python2.7/site-packages/flask/app.py:1423]
Traceback (most recent call last):
  File "/home/www/.demo/lib/python2.7/site-packages/flask/app.py", line 1817, in wsgi_app
    response = self.full_dispatch_request()
  File "/home/www/.demo/lib/python2.7/site-packages/flask/app.py", line 1477, in full_dispatch_request
    rv = self.handle_user_exception(e)
  File "/home/www/.demo/lib/python2.7/site-packages/flask/app.py", line 1381, in handle_user_exception
    reraise(exc_type, exc_value, tb)
  File "/home/www/.demo/lib/python2.7/site-packages/flask/app.py", line 1475, in full_dispatch_request
    rv = self.dispatch_request()
  File "/home/www/.demo/lib/python2.7/site-packages/flask/app.py", line 1461, in dispatch_request
    return self.view_functions[rule.endpoint](**req.view_args)
  File "/home/www/aud2/app/views/site.py", line 875, in modify_node_task_status
    mes.sendEmail()
  File "/home/www/aud2/app/utils/message.py", line 45, in sendEmail
    thr = Thread(target=send_async_email, args=[receiver + '@aicai.com', subject, html])
TypeError: unsupported operand type(s) for +: 'NoneType' and 'str'
